Workbook

Sheet เปรียบเทียบทุก Solution
A1: ตารางเปรียบเทียบความเป็นไปได้ของทุกข้อเสนอ (Multi-Solution Feasibility Summary)
A2: วิเคราะห์เปรียบเทียบเชิงระบบตามเกณฑ์ TELOS 5 เสาหลัก (เต็ม 100) และเมทริกซ์ศักยภาพด้านวิศวกรรมหุ่นยนต์ (เต็ม 10 แยกอิสระ)
A4: ลำดับ | B4: รหัสข้อเสนอ (Solution ID) | C4: ชื่อแนวทางแก้ปัญหา (Title / Concept) | D4: คะแนนรวม (เต็ม 100) | E4: T: เทคนิค (/20) | F4: E: เศรษฐศาสตร์ (/20) | G4: L: กฎหมายและสถาบัน (/20) | H4: O: ปฏิบัติการ (/20) | I4: S: แผนงาน (/20) | J4: ผลการประเมิน (Verdict) | K4: จุดแข็งสำคัญ (Key Strengths) | L4: จุดติดขัดวิกฤต (Critical Bottlenecks) | M4: คำแนะนำเชิงระบบ (Strategic Advice) | N4: Robotics Potential (/10) | O4: เหตุผลความเข้ากันได้ด้านหุ่นยนต์ (Robotics Engineering Rationale)
A5: 1 | B5: Solution-1 | C5: Recession Rate (dh/dt) Predictive Filtering for QRT Dispatch (Ann Arbor Case) | D5: ='Solution-1'!Q9 | E5: ='Solution-1'!D17 | F5: ='Solution-1'!D18 | G5: ='Solution-1'!D19 | H5: ='Solution-1'!D20 | I5: ='Solution-1'!D21 | J5: ='Solution-1'!Q12 | K5: ใช้สมการอนุพันธ์ชลศาสตร์คำนวณอัตราน้ำลด dh/dt เทียบกับเวลาเดินทาง 20-30 นาที ตัด Empty Cases ได้ 40-50% สมาชิกแบ่งงานชัดเจน ต้นทุนต่ำ (< 3,500 บ.) | L5: ต้องมีหลักฐาน Digital Evidence Card ประกอบการปิดงานบน Traffy Fondue และเซนเซอร์ต้องกรองฟองคลื่นน้ำเพื่อเลี่ยง Derivative Kick | M5: พัฒนาโมดูลคำนวณ dh/dt บน Python/ROS 2 ร่วมกับ Screw Terminal Shield และออกแบบ Median Filter กรองสัญญาณผิวน้ำ | N5: 7.5 | O5: มีความเข้ากันได้สูงในแกนคณิตศาสตร์วิศวกรรม ทฤษฎีระบบควบคุม (Control Theory) และการประมวลผลสัญญาณ (Signal Processing & State Estimation) ของ JK แต่คะแนนอยู่ที่ 7.5 เนื่องจากขาด Physical Actuation และกลไกการเคลื่อนที่
A6: 2 | B6: Solution-2 | C6: PUB Singapore CWOS 2-Factor Authentication Dispatch Filter | D6: ='Solution-2'!Q9 | E6: ='Solution-2'!D17 | F6: ='Solution-2'!D18 | G6: ='Solution-2'!D19 | H6: ='Solution-2'!D20 | I6: ='Solution-2'!D21 | J6: ='Solution-2'!Q12 | K6: กรองการสั่งการเจ้าหน้าที่หน่วยเคลื่อนที่เร็วด้วยปัจจัยคู่ (Radar Rainfall API + Ultrasonic Water Level) สกัด False Alarms ฝนตกไม่ท่วมได้เด็ดขาด ต้นทุนต่ำมาก | L6: ต้องพึ่งพา Radar Rainfall API ภายนอก หาก API ล่มหรือข้อมูลดีเลย์ 10-15 นาที จะกระทบการตัดสินใจ | M6: ทำระบบ Fallback ไปใช้ค่าจากเซนเซอร์ระดับน้ำหน้างานแบบเดี่ยวหาก API ขาดการเชื่อมต่อ และเชื่อมเข้า LINE Official ของเขต | N6: 5 | O6: มีความเข้ากันได้ในแกนการประมวลผลข้อมูลและสถาปัตยกรรมตรรกะควบคุม (Control & Decision Logic) แต่ขาดแกนกลไก (Mechanics) และ Actuation ของหุ่นยนต์อย่างสิ้นเชิง คะแนนจึงอยู่ที่ 5.0
A7: 3 | B7: Solution-3 | C7: Acoustic Sewer Measurement & Pre-Screening Maintenance (UK/USA SL-RAT Case) | D7: ='Solution-3'!Q9 | E7: ='Solution-3'!D17 | F7: ='Solution-3'!D18 | G7: ='Solution-3'!D19 | H7: ='Solution-3'!D20 | I7: ='Solution-3'!D21 | J7: ='Solution-3'!Q12 | K7: คัดกรองสภาพความสะอาดท่อระบายน้ำด้วยคลื่นเสียงสะท้อน (Acoustic SL-RAT) จัดเทียร์ 3 กลุ่ม (0-3 ล้างทันที, 4-6 จัดคิว, 7-10 ปกติ) ลดงบขุดลอกสุ่มได้มหาศาล | L7: หัววัด Transducer มีต้นทุนสูง และการปฏิบัติงานต้องเปิดฝาท่อริมถนนสาธารณะ เสี่ยงต่อความปลอดภัยทางจราจรและต้องขออนุญาต กทม. | M7: ใช้ชุด Acoustic Horn ที่ขึ้นรูปด้วย 3D Print ร่วมกับลำโพง/ไมค์กันน้ำ COTS และกำหนด SOP ติดตั้งกรวยจราจรรอบฝาท่อ 5 เมตร | N7: 8.5 | O7: มีความเข้ากันได้อย่างโดดเด่นในแกน Perception & Sensing ขั้นสูง และการประมวลผลสัญญาณ (DSP / Frequency Domain Analysis) รวมถึงกลไกการทำงานหน้างานในระบบท่อใต้ดิน จัดเป็นหัวข้อวิศวกรรมหุ่นยนต์ตรวจสอบโครงสร้างพื้นฐาน (Infrastructure Inspection Robotics)
A8: 4 | B8: Solution-4 | C8: Jakarta Drainage Pipe Telemetry & Prioritized Flushing DSS | D8: ='Solution-4'!Q9 | E8: ='Solution-4'!D17 | F8: ='Solution-4'!D18 | G8: ='Solution-4'!D19 | H8: ='Solution-4'!D20 | I8: ='Solution-4'!D21 | J8: ='Solution-4'!Q12 | K8: ติดตั้งโครงข่ายเซนเซอร์วัดระดับน้ำและตะกอนใต้ท่อระบายน้ำเมือง พร้อมระบบจัดลำดับคิวรถล้างท่ออัตโนมัติ จัดการปัญหาเชิงพื้นที่ได้เป็นระบบ | L8: สภาพแวดล้อมใต้ท่อมีก๊าซไข่เน่า H2S และคราบไขมันกัดกร่อนสูงมาก และการติดตั้งใต้ฝาท่อเป็นพื้นที่อับอากาศ (Confined Space) | M8: ใช้วัสดุกล่อง Polycarbonate เคลือบ Conformal Coating ป้องกันก๊าซกัดกร่อน และนำเซนเซอร์ Non-contact มาใช้ทดแทน | N8: 6.5 | O8: มีความเข้ากันได้ในแกน Sensor Network, Telemetry, Embedded IoT และการวิเคราะห์โครงข่ายท่อระบายน้ำ แต่คะแนนอยู่ที่ 6.5 เนื่องจากระบบเน้นหนักที่การติดตั้งเซนเซอร์ประจำที่ (Stationary Sensing Rig) มากกว่าหุ่นยนต์เคลื่อนที่อัตโนมัติ
A9: 5 | B9: Solution-5 | C9: UHI Latent Heat Precision Road Cooling (Micro-dosing 0.2-0.4 mm Evaporative Spraying) | D9: ='Solution-5'!Q9 | E9: ='Solution-5'!D17 | F9: ='Solution-5'!D18 | G9: ='Solution-5'!D19 | H9: ='Solution-5'!D20 | I9: ='Solution-5'!D21 | J9: ='Solution-5'!Q12 | K9: ระบบพ่นละอองน้ำละเอียด (0.2–0.4 mm) ระบายความร้อนผิวทางเท้าและถนนด้วยความร้อนแฝงการกลายเป็นไอ (Latent Heat) มีศักยภาพด้าน Mechatronics และ Actuation สูงสุด | L9: การพ่นน้ำบนถนนหลวงมีความเสี่ยงต่อกฎหมายจราจร (ผิวทางลื่น) และโครงสร้างบูมฉีดน้ำบนรถเสี่ยงต่อการสั่นสะเทือนและหัวฉีดอุดตันจากตะกรัน | M9: ติดตั้งเซนเซอร์วัดความชื้นผิวถนนแบบเรียลไทม์เพื่อตัดการฉีดพ่นทันที และติดตั้งระบบกรองน้ำ 2 ชั้น (Sediment + Anti-scale) | N9: 9 | O9: มีความเข้ากันได้อย่างสมบูรณ์แบบสูงสุดกับหลักสูตรวิศวกรรมหุ่นยนต์และระบบอัตโนมัติ (FIBO) ครบทั้ง 3 เสาหลัก: Perception (Thermal Imaging), Control (Thermodynamic Closed-loop Control) และ Actuation/Mechatronics (Vehicle-mounted High-pressure Hydraulics & Mechanics) ได้คะแนน 9.0

Sheet Solution-1
A1: เมทริกซ์ประเมินความเป็นไปได้เชิงระบบ TELOS+S: Recession Rate (dh/dt) Predictive Filtering for QRT Dispatch (Ann Arbor Case)
A2: ระบบคะแนนจำนวนเต็มเด็ดขาด: 1, 2, 3, 4, 5 เท่านั้น (ไม่มีจุดทศนิยม / ไม่มี 0.5) | โครงสร้างแบบ Transposed แนวนอน
A4: รหัสคำถาม (Question Code) | B4: T-01 | C4: T-02 | D4: E-01 | E4: E-02 | F4: E-03 | G4: L-01 | H4: L-02 | I4: O-01 | J4: O-02 | K4: O-03 | L4: O-04 | M4: O-05 | N4: O-06 | O4: S-01 | P4: S-02 | Q4: สรุปภาพรวม (SUMMARY)
A5: มิติการประเมิน (TELOS+S Pillar) | B5: ด้านเทคนิค (Technical Feasibility) | C5: ด้านเทคนิค (Technical Feasibility) | D5: ด้านเศรษฐศาสตร์ (Economic Feasibility) | E5: ด้านเศรษฐศาสตร์ (Economic Feasibility) | F5: ด้านเศรษฐศาสตร์ (Economic Feasibility) | G5: ด้านกฎหมายและสถาบัน (Legal & Institutional Feasibility) | H5: ด้านกฎหมายและสถาบัน (Legal & Institutional Feasibility) | I5: ด้านการปฏิบัติการ (Operational Feasibility) | J5: ด้านการปฏิบัติการ (Operational Feasibility) | K5: ด้านการปฏิบัติการ (Operational Feasibility) | L5: ด้านการปฏิบัติการ (Operational Feasibility) | M5: ด้านการปฏิบัติการ (Operational Feasibility) | N5: ด้านการปฏิบัติการ (Operational Feasibility) | O5: ด้านแผนงานและเวลา (Schedule Feasibility) | P5: ด้านแผนงานและเวลา (Schedule Feasibility) | Q5: ผลรวมทุกมิติ (All Pillars)
A6: คำถามทดสอบความเสี่ยงจริง (Stress-Test Question) | B6: Implementation (Build vs. Buy Burden): โครงการมีความจำเป็นต้องวิจัยและพัฒนาชิ้นส่วนขึ้นเอง (Build from Scratch) มากน้อยเพียงใด หรือสามารถจัดหาโมดูลสำเร็จรูปมาตรฐาน (COTS) มาประกอบและปรับแต่งได้โดยตรง? | C6: Team Redundancy (Bus Factor): มีจำนวนสมาชิกในทีมกี่คนที่เข้าใจสถาปัตยกรรมทั้งเชิงกล วงจรไฟฟ้า และโค้ด จนสามารถพัฒนา ประกอบ และแก้ไขข้อผิดพลาดของระบบย่อยนี้ได้อย่างอิสระ? | D6: ROI (Payback Period / Value Horizon): โครงการมีระยะเวลาคืนทุน (Payback Period) และความคุ้มค่าในการลดความสูญเสียหรือลดค่าใช้จ่ายในการดำเนินงาน (OpEx Reduction) รวดเร็วเพียงใด? | E6: Dependencies of Component (Vendor Lock-in & Service Autonomy): ระบบมีความเป็นอิสระจากการผูกขาดของผู้ผลิต (Vendor Lock-in) มากน้อยเพียงใด และทีมงานหรือวิศวกรทั่วไปสามารถซ่อมบำรุงด้วยเครื่องมือเปิดได้เองหรือไม่? | F6: Scrap Margin (Safety Allowance for Blown ICs & Iterations): โครงการมีการจัดสรรงบประมาณสำรองสำหรับชิ้นส่วนทดแทนกรณีเสียหาย (Scrap Margin) และการทดลองซ้ำ (Iterations) ในสัดส่วนเท่าใดของรายการวัสดุ (BOM)? | G6: Felony and Civil Law (Regulatory & Public Safety Compliance): ระบบและการติดตั้งมีความสอดคล้องต่อข้อบังคับทางกฎหมายอาญา แพ่ง ระเบียบจราจร และการคุ้มครองข้อมูลส่วนบุคคล (PDPA / Public Safety) โดยไม่สร้างความรับผิดทางกฎหมายหรือไม่? | H6: IP and Licensing: ทรัพย์สินทางปัญญา ซอฟต์แวร์ไลบรารี และสิทธิบัตรที่นำมาใช้ มีความเปิดกว้างและปลอดภาระผูกพันทางการค้าหรือการละเมิดลิขสิทธิ์ (Licensing Freedom) มากน้อยเพียงใด? | I6: User — Implementation (Field Deployment / Setup Friction): ขั้นตอนการติดตั้ง ติดตั้งเครื่องมือ ปรับเทียบศูนย์ (Calibration) และเตรียมพร้อมใช้งานหน้างานจริงโดยผู้ปฏิบัติงาน มีความยุ่งยากหรือกินเวลาเพียงใด? | J6: User — Customer / Public Safety & Failsafes: มาตรการรักษาความปลอดภัย การป้องกันอุบัติเหตุ (Failsafes, Interlocks, E-stops) และการควบคุมอันตรายต่อเจ้าหน้าที่และสาธารณชนมีความรัดกุมเพียงใด? | K6: User — Behavior & Workflow Disruption: ระบบสร้างภาระงานเอกสาร ขั้นตอนปฏิบัติงาน หรือบังคับเปลี่ยนพฤติกรรมเจ้าหน้าที่หน้างาน (SOP Disruption) มากน้อยเพียงใด? | L6: Developer — Task Dependency (Critical Path Architecture): สถาปัตยกรรมการพัฒนาฮาร์ดแวร์ ไฟฟ้า และซอฟต์แวร์ มีการเชื่อมต่อแบบขนาน (Parallel Architecture / Modularity) หรือผูกติดกันเป็นเส้นตรงบนเส้นทางวิกฤต (Critical Path)? | M6: Developer — Contribution Dependency (Bureaucratic & Lab Gatekeeping): การเข้าถึงเครื่องมือในห้องปฏิบัติการ การอนุมัติงบประมาณ และกระบวนการทางธุรการ (Lab Access & Purchasing Bureaucracy) มีอุปสรรคขัดขวางความคล่องตัวเพียงใด? | N6: Developer — Task & Skill Compatibility: ความเข้ากันได้ระหว่างทักษะเดิมของทีมกับเทคโนโลยีสแตกของระบบ (Task & Skill Compatibility: 'Water and Oil' vs. 'Oil and Engine') อยู่ในระดับใด? | O6: Production Time (Engineering Design Maturity by Milestone): ความพร้อมของแบบวิศวกรรม (3D CAD, Schematics, PCB Gerbers, Firmware Architecture, BOM) อยู่ในระดับความสมบูรณ์ใดเทียบกับหมุดหมายการผลิตจริง? | P6: Shipping (Component Procurement Lead Time): ระยะเวลาในการจัดหาและขนส่งชิ้นส่วน อุปกรณ์ และเซนเซอร์ (Procurement Lead Time) อยู่ในกรอบเวลาที่ปลอดภัยต่อกำหนดส่งมอบงานหรือไม่? | Q6: ประเมินคำถามทั้งสิ้น 15 ข้อ
A7: เหตุผลในการถาม & โหมดความล้มเหลวที่เฝ้าระวัง (Rationale) | B7: มุ่งตรวจสอบ Build vs. Buy Burden และ Machine Access หากระบบต้อง R&D กลไกหรือวงจรขึ้นเอง 100% โดยไม่มี Reference Design จะเกิดความเสี่ยงวิกฤตต่อกรอบเวลาของโครงงานวิศวกรรม | C7: ตรวจสอบความต่อเนื่องของทีม (Team Knowledge Distribution) ป้องกัน Single Point of Failure หากมีผู้เชี่ยวชาญเพียงคนเดียวเมื่อติดสอบหรือเจ็บป่วยโครงการจะล้มเหลวทันที | D7: ประเมินความคุ้มค่าในการลงทุนและระยะเวลาคืนทุนเชิงสาธารณูปโภคหรือเชิงพาณิชย์ เทียบกับเงินลงทุนเริ่มต้น (CapEx) และเงินประหยัดค่าแรงงาน/ค่าน้ำมันหน้างาน | E7: ตรวจสอบภาระค่าใช้จ่ายแฝงระยะยาว (Recurring Cloud/Licensing Fees) และความเสี่ยงจากการถูกผูกขาดด้วยฮาร์ดแวร์หรือระบบคลาวด์ปิดของผู้ผลิตรายเดียว | F7: ตรวจสอบ The Scrap Budget Rule งานฮาร์ดแวร์มีความเสี่ยงต่อชิปไหม้ แผ่นวงจรช็อต หรือขายึดหัก หากไม่มีงบสำรองจัดซื้อชุดที่ 2 การพัฒนาจะหยุดชะงักทันที | G7: ตรวจสอบความเสี่ยงต่อการทำผิดกฎหมายสาธารณะ (พ.ร.บ. จราจรทางบก, พ.ร.บ. คุ้มครองข้อมูลส่วนบุคคล PDPA, กฎหมายสิ่งแวดล้อม และระเบียบทางหลวง) | H7: ตรวจสอบข้อจำกัดด้านสิทธิ์ซอฟต์แวร์และฮาร์ดแวร์ ป้องกันการติดไวรัสไลเซนส์ (Copyleft GPLv3) หรือการละเมิดสิทธิบัตรเชิงพาณิชย์ของบุคคลภายนอก | I7: ประเมินความยากลำบากของเจ้าหน้าที่หน้างาน (Field Setup Friction) หากอุปกรณ์ต้องใช้เวลาตั้งค่าหรือ Calibrate นานเกินไป เจ้าหน้าที่จะปฏิเสธการใช้งาน | J7: ตรวจสอบความปลอดภัยต่อชีวิตและทรัพย์สิน ป้องกันอันตรายจากไฟฟ้าแรงสูง สารเคมี ก๊าซพิษในที่อับอากาศ หรืออุบัติเหตุทางรถยนต์ขณะปฏิบัติงาน | K7: ประเมินแรงต้านจากเจ้าหน้าที่ผู้ใช้งาน (The Tech Trap) ระบบที่ดีต้องลดภาระ ไม่ใช่สร้างแบบฟอร์มเอกสารหรือบังคับเปลี่ยนกระบวนการทำงานหลัก | L7: ตรวจสอบ Critical Path การพัฒนา หากงานซอฟต์แวร์ต้องรอฮาร์ดแวร์จริงเสร็จก่อนเท่านั้น จะเกิดคอขวดสะสมจนส่งมอบงานไม่ทันกำหนด | M7: ประเมินอุปสรรคด้านการบริหารและเครื่องมือ (Institutional Gatekeeping) เช่น คิวรอเครื่องจักร การล็อกแล็บ หรือขั้นตอนเบิกจ่ายงบประมาณที่ล่าช้า | N7: ตรวจสอบความสอดคล้องระหว่างทักษะที่ทีมมีอยู่จริงกับเทคโนโลยีที่เลือกใช้ เพื่อป้องกัน Learning Curve ที่สูงเกินไปจนงานล้มเหลว | O7: ประเมินความพร้อมของพิมพ์เขียวการผลิต (Design Maturity Package) ก่อนเริ่มสั่งผลิตจริง เพื่อป้องกันการรื้อแก้แบบกลางคัน | P7: ตรวจสอบห่วงโซ่อุปทาน (Supply Chain Lead Time) ชิ้นส่วนที่ต้องรอส่งจากต่างประเทศเกิน 3 สัปดาห์ถือเป็นความเสี่ยงต่อวิกฤตสัปดาห์สอบและกำหนดส่งมอบ | Q7: สังเคราะห์จาก AI Agents Group 2
A8: เกณฑ์การให้คะแนน (Scoring Rubric Definition: ระดับ 1, 2, 3, 4, 5 ครบทุกระดับ) | B8: 1: Build from Scratch — 100% custom R&D required (custom mechanism, custom PCB, raw algorithm derivation); no reference designs available. 2: Heavy Customization — Core components exist, but requires extensive custom adaptation, structural machining, and custom wrapper code. 3: Hybrid / COTS Integration — Standard COTS modules (e.g., standard dev board + breakout sensors) assembled with custom brackets and intermediate wiring. 4: Modular COTS Assembly — Pre-engineered building blocks with standard mounting and standard communication buses (e.g., Din-rail modules, I2C/CAN shields); minimal custom fabrication. 5: Commercial Off-the-Shelf (COTS) — Turnkey commercial solution; zero custom fabrication or circuitry required, immediate plug-and-play operation. | C8: 1: Single Point of Failure (Bus Factor = 1) — Only 1 teammate understands the codebase/hardware; if they are absent or drop out, the project completely halts. 2: Fragile Redundancy (Bus Factor = 1.5) — 1 primary expert with minimal notes; a second member has rough familiarity but requires steep ramp-up to debug. 3: Moderate Redundancy (Bus Factor = 2) — 2 teammates can independently maintain, test, and troubleshoot the core subsystem. 4: High Team Redundancy (3+ Teammates) — 3+ teammates can actively design, assemble, and debug the subsystem with low ramp-up time. 5: Full Team Redundancy — All team members are fully proficient; tasks can be swapped across anyone with zero friction or velocity loss. | D8: 1: Long Payback (≥ 10 Years) — High initial CapEx and low recurring savings; economically non-viable for rapid deployment. 2: Slow Return (6–9 Years) — Substantial capital investment with long break-even horizon; requires long-term institutional subsidization. 3: Moderate Return (3–5 Years) — Reasonable public infrastructure payback; offsets costs across multi-year operational cycles. 4: Fast Return (2–3 Years) — Strong operational cost reduction (fuel, labor, scrap); breaks even within normal equipment lifecycle. 5: Immediate Payback (≤ 1–2 Years) — Rapid break-even; eliminates major recurring losses within the first operating season. | E8: 1: Total Vendor Lock-in — Proprietary cloud backend, encrypted telemetry, and proprietary connectors; completely dependent on vendor survival. 2: High Dependency — Hardware requires vendor-licensed diagnostic tools or annual subscription fees to maintain operation. 3: Semi-Independent — Core hardware relies on proprietary firmware, but allows open API export and standard electrical interfaces. 4: High Autonomy — Uses standard open communication protocols (e.g., Modbus, MQTT, CAN); parts can be serviced using generic tools. 5: Complete Independence — 100% open architecture; hardware is interchangeable with generic substitutes; self-serviceable by any engineer. | F8: 1: Zero Buffer (0%) — Exactly 1x BOM purchased; any fried chip, cracked bracket, or wiring mistake kills the project. 2: Fragile Buffer (20–30%) — Spares only for passive components (resistors, connectors); no backup microcontrollers or expensive sensors. 3: Moderate Buffer (50%) — Spares for all critical passive parts and 1 spare for the primary controller board. 4: High Buffer (80%) — Spares for nearly every active component and sensor; can sustain multiple prototype burn-ins. 5: Full Redundancy (≥ 100%) — Complete 2x BOM budget on hand; can build two complete working units simultaneously. | G8: 1: Severe Violation / No Privilege — Direct breach of statutory law (e.g., unconsented public surveillance/PDPA, hazardous road blockage, RF jammer). 2: High Legal Exposure — Ambiguous legal zone; high risk of civic complaints or traffic disruption; requires complex technical waivers. 3: Conditional / Requires Permit — Allowed under explicit written approval, official agency MoU, or municipal permit (e.g., BMA/Highway dept permit). 4: Low Legal Friction — Operates within standard public engineering exemptions; simple standard notification/safety compliance needed. 5: 100% Compliant / Free Domain — Completely exempt from statutory licensing; zero public safety risk, zero personal data (Zero PII), fully unrestricted. | H8: 1: Closed / Commercial Barrier — Proprietary commercial license; cannot compile, flash, or operate without paying expensive commercial seat licenses. 2: Ambiguous / Gray IP — Unclear licensing terms or unlicensed GitHub repos; risk of copyright strike or IP dispute upon public demonstration. 3: Restrictive Open Source (Copyleft) — Permitted for educational use, but viral licenses (e.g., GPLv3) force your entire codebase to be made public if distributed. 4: Permissive Open Source — Open source with minimal conditions (e.g., LGPL, CC-BY); allows proprietary wrapping with simple attribution. 5: Completely Permissive / Public Domain — Permissive open source (MIT, Apache 2.0, BSD) or Public Domain; unrestricted freedom to commercialize, modify, and contribute. | I8: 1: Laborious Recalibration — Requires multi-point manual physical zeroing, chemical calibration, or oscilloscope tuning before every run. 2: Complex Setup — Requires trained technician 20–30 minutes to adjust potentiometers, align brackets, or enter configuration commands. 3: Moderate Field Setup — Simple 5-minute calibration procedure (e.g., tare button or basic mobile app zeroing) performed by non-engineers. 4: Minimal Setup — Fast clamp-on mounting with automated self-calibration on power-up; ready in < 1 minute. 5: True Plug and Go — Pure plug-and-play; zero calibration required, zero buttons; power on and immediately operational. | J8: 1: Critical Hazard — Failure can directly cause electrocution, fire, traffic crashes, chemical exposure, or confined-space asphyxiation. 2: High Risk / Manual Oversight — High mechanical/electrical hazard requiring constant operator vigilance and full PPE. 3: Moderate Safety — Protected by passive mechanical guards, fuses, and warning labels; requires basic safety precautions. 4: High Safety & Interlocks — Active software limits, hardware thermal shutoffs, and reverse polarity protection; minimal hazard on failure. 5: Inherently Safe & Redundant — Failsafe by physics (cannot store lethal energy); isolated, dual-rated enclosures, redundant E-stops, zero injury risk. | K8: 1: Disruptive Overhaul — Forces operators to abandon existing SOPs, adds 5+ extra tedious forms/steps, and faces fierce institutional union/worker resistance. 2: Significant Friction — Adds notable extra documentation or redundant verification steps; operators will actively look for ways to bypass it. 3: Moderate Adaptation — Modifies daily routine slightly; requires 1–2 training workshops, but delivers clear convenience trade-offs. 4: Low Friction — Integrates into existing tools (e.g., sends automated alerts to existing LINE/Telegram or ticketing dashboard); minimal change in habits. 5: Transparent / Seamless Integration — Zero workflow disruption; runs invisibly in background and automates existing manual paperwork without operator intervention. | L8: 1: Strictly Sequential (Linear) — A depends on B depends on C; if the PCB fab is delayed, software and testing halt 100%. 2: Bottlenecked Pipelines — Major subsystems are tightly coupled; frequent integration stalls waiting for hardware bench access. 3: Semi-Decoupled — Hardware and software teams can work independently for 1–2 weeks using rough mockups before needing physical integration. 4: Modular Parallelism — Clear API/interface boundaries; software builds against mock data/simulators while hardware is routed; integration takes < 2 days. 5: Fully Parallel Architecture — Microservices/modular nodes with standard contracts; mechanical, electrical, and firmware develop, simulate, and unit-test completely in parallel. | M8: 1: Heavy Gatekeeping — Blocked by supervisor approvals, locked lab cabinets, NDA signatures, purchasing bureaucracy, and restricted git branches. 2: Moderate Bureaucracy — Requires departmental request forms, tool booking queues, and waiting 3–5 days for administrative sign-offs. 3: Standard Campus Access — Workable access during university open hours; minor approval delays for equipment or lab keys. 4: High Autonomy — Team has full repository write access, open 24/7 lab entry, and pre-approved discretionary debit cards/stipends for rapid purchases. 5: Frictionless Contribution — Complete autonomy; decentralized cloud CI/CD, local prototyping tools at home/bench, zero administrative blockers. | N8: 1: Complete Mismatch ('Water and Oil') — Team has zero foundation in the stack (e.g., pure mechanical students forced to train deep neural nets in C++ from scratch). 2: Steep Learning Curve — High theoretical knowledge, but zero production hands-on experience; debugging basic syntax/wiring stalls progress. 3: Adjacent Competence — Strong mastery in related tools (e.g., proficient in Arduino/ESP32 migrating to STM32, or SolidWorks migrating to Fusion360); manageable 1-week curve. 4: Proven Experience — Team has built similar subsystems in past semester coursework or competition robots; rapid ramp-up. 5: Perfect Synergy ('Oil and Engine') — Complete domain mastery; team members have built this exact architecture multiple times with verified libraries and muscle memory. | O8: 1: Concept Only (0% Design) — Napkin sketches and verbal concepts; 0% CAD models, 0% schematics, 0% code written. 2: Rough Drafts (25% Design) — Preliminary block diagrams, hand-drawn schematics, unverified parts list, incomplete 3D bounding boxes. 3: Intermediate Maturity (50% Design) — Complete CAD assembly (untested clearances), schematic capture complete, draft firmware architecture mapped out. 4: Pre-Production (80% Design) — Fully detailed 3D CAD ready for 3D print/CNC, routed PCB Gerber files validated with DRC, pinouts locked down. 5: Fully Engineered Design (100% Production Ready) — Complete drawing package: BOM with part numbers, verified manufacturing Gerbers, 2D tolerance drawings, assembly SOP, and flashing scripts ready. | P8: 1: Extreme Lead Time (≥ 4 Weeks) — Custom overseas fabrication, customs clearance delays, or parts with long factory lead times (critical path hazard). 2: High Lead Time (3–4 Weeks) — Standard overseas shipping (e.g., standard AliExpress/international postal surface mail); vulnerable to logistics delays. 3: Moderate Lead Time (2 Weeks) — Express international courier (DHL, FedEx, JLCPCB express) or regional distributors (7–14 days). 4: Short Lead Time (1 Week) — Domestic couriers or express domestic stockists (3–5 business days). 5: Immediate / Next-Day (≤ 1–2 Days) — Shelf stock available locally at retail shops or next-day domestic express delivery. | Q8: เกณฑ์รวม: >=80 ผ่านสูง, >=60 มีเงื่อนไข, <60 เสี่ยงสูง | หากมีข้อใดได้ 1 = VETOED ตกเกณฑ์ทันที
A9: คะแนนที่ได้รับ (ASSIGNED SCORE: 1, 2, 3, 4, 5 STRICT INTEGER) | B9: 4 | C9: 4 | D9: 5 | E9: 5 | F9: 4 | G9: 5 | H9: 5 | I9: 4 | J9: 5 | K9: 5 | L9: 4 | M9: 5 | N9: 5 | O9: 4 | P9: 5 | Q9: =IF(Q10>0, (Q11/Q10)*20, 0)
A10: ค่าน้ำหนัก (Weight %) | B10: 0.1 | C10: 0.1 | D10: 0.0667 | E10: 0.0667 | F10: 0.0666 | G10: 0.1 | H10: 0.1 | I10: 0.0333 | J10: 0.0333 | K10: 0.0334 | L10: 0.0333 | M10: 0.0333 | N10: 0.0334 | O10: 0.1 | P10: 0.1 | Q10: =SUM(B10:P10)
A11: คะแนนถ่วงน้ำหนัก (=Score * Weight) | B11: =B9*B10 | C11: =C9*C10 | D11: =D9*D10 | E11: =E9*E10 | F11: =F9*F10 | G11: =G9*G10 | H11: =H9*H10 | I11: =I9*I10 | ... P11: =P9*P10 | Q11: =SUM(B11:P11)
A12: คำอธิบาย & หลักฐานอ้างอิงจากไฟล์ Intake (Evidence Citation) | B12: อ้างอิง solution-details/solution-1.md หน้า 2 เลือกใช้กล่องพักสายไฟสำเร็จรูปมาตรฐาน COTS IP67 ยึดด้วยแคลมป์สแตนเลส สอดคล้องกับ team-skills/fifa.md ที่เชี่ยวชาญการออกแบบระบบยึดจับ และ due.md ที่เชี่ยวชาญ 3D CAD | C12: อ้างอิง team-skills/jk.md เชี่ยวชาญสมการอนุพันธ์, due.md เชี่ยวชาญวงจรและ ESP32, และ fifa.md เชี่ยวชาญกลไกยึดจับ สมาชิก 3 คนเข้าใจระบบย่อยและช่วยแก้ไขบั๊กได้ทันที | D12: อ้างอิง solution-details/solution-1.md ต้นทุนรวมอุปกรณ์ต่อจุดต่ำมาก (< 3,500 บาท) การตัด Empty Cases 40-50% ประหยัดค่าน้ำมันและเบี้ยเลี้ยงเจ้าหน้าที่ได้คืนทุนภายใน 1 ฤดูฝนแรก (≤ 1-2 ปี) | E12: สถาปัตยกรรมเปิด 100% รันบนบอร์ด ESP32 และ Python/ROS 2 โค้ดทั้งหมดเปิดเผย ไม่พึ่งพา Cloud ปิด อะไหล่เซนเซอร์หาซื้อเปลี่ยนได้ทั่วไป | F12: ด้วยต้นทุนอุปกรณ์ < 3,500 บาท จากงบโครงงาน 5,000 บาท มีส่วนต่างงบประมาณสำรอง (Scrap Margin) เกิน 80% สำหรับจัดซื้อบอร์ด ESP32 และเซนเซอร์สำรอง | G12: ระบบติดตั้งวัดระดับน้ำผิวดินในท่อสาธารณะ ไม่มีการบันทึกภาพใบหน้าหรือป้ายทะเบียน (Zero PII 100%) และกล่องยึดไม่ล้ำกีดขวางช่องจราจรทางบก | H12: ใช้ไลบรารีเปิดมาตรฐานภายใต้สัญญาอนุญาต MIT และ Apache 2.0 (ROS 2, FreeRTOS, MicroPython) ปลอดข้อพิพาทสิทธิบัตรเชิงพาณิชย์ | I12: ใช้แคลมป์รัดท่อแบบปลดเร็ว ตัวเครื่องมีระบบ Zero Calibration อัตโนมัติเมื่อเปิดไฟเข้า พร้อมตรวจวัดระดับน้ำภายในเวลา < 1 นาที | J12: ทำงานด้วยไฟกระแสตรงแรงดันต่ำ (5V/12V จากแบตเตอรี่) ปลอดภัยต่อผู้ปฏิบัติงาน กล่องกันน้ำมาตรฐาน IP67 ไร้ความเสี่ยงต่อการเกิดประกายไฟหรือไฟฟ้าดูด | K12: ผลการคำนวณ dh/dt ส่งออกเป็น Digital Evidence Card ผ่าน Webhook ตรงเข้า Traffy Fondue และระบบแจ้งเตือนเดิมของ กทม. โดยเจ้าหน้าที่ไม่ต้องกรอกฟอร์มเพิ่ม | L12: แยก API และโครงสร้างข้อมูลระหว่างเฟิร์มแวร์ ESP32 กับอัลกอริทึมคำนวณ dh/dt บน Python ชัดเจน สามารถใช้ข้อมูลจำลองระดับน้ำทดสอบโค้ดขนานไปกับการเดินสายฮาร์ดแวร์ได้ | M12: พัฒนาบนเครื่องคอมพิวเตอร์ส่วนตัวและโต๊ะช่างที่บ้านได้โดยสมบูรณ์ ไม่มีการติดกุญแจห้องแล็บหรือขั้นตอนขออนุมัติจัดซื้อซับซ้อน | N12: สอดคล้องกับทักษะของทีมอย่างสมบูรณ์แบบ: JK ชำนาญ Dynamic Systems & Control, Due ชำนาญ ESP32 & PCB, Fifa ชำนาญ CAD/กลไก ('Oil and Engine') | O12: แบบจำลอง 3D CAD ของกล่องและแคลมป์ยึดเสร็จสมบูรณ์ วงจรเชื่อมต่อผ่าน Screw Terminal Shield มี DRC ผ่านเกณฑ์ พร้อมเข้าสู่ Pre-production ในสัปดาห์ที่ 9 | P12: ชิ้นส่วนหลักทั้งหมด (ESP32, Ultrasonic Sensor, IP67 Enclosure) มีสต็อกจำหน่ายในประเทศ จัดส่งด่วนถึงภายใน 1-2 วันทำการ | Q12: =IF(MIN(B9:P9)=1, "VETOED / ตกเกณฑ์ข้อบังคับวิกฤต (คะแนนระดับ 1)", IF(Q9>=80, "ผ่านเกณฑ์ระดับสูง (HIGHLY VIABLE)", IF(Q9>=60, "ผ่านแบบมีเงื่อนไข (CONDITIONALLY VIABLE)", "ความเสี่ยงสูง (HIGH RISK)")))
A13: แผนลดขอบเขตงาน & มาตรการลดความเสี่ยง (De-scoping Action) | B13: ใช้กล่องพักสายไฟมาตรฐาน IP67 พร้อมแคลมป์รัดท่อสำเร็จรูป | C13: จัดทำเอกสาร Interface Contract และ Pinout ชัดเจนเพื่อให้ Due และ Fifa ช่วยแก้บั๊กฮาร์ดแวร์ได้ทันที | D13: ใช้ ESP32 รุ่นมาตรฐานและเซนเซอร์ COTS เพื่อควบคุมต้นทุนไม่ให้เกิน 3,500 บาท | E13: ใช้โปรโตคอล MQTT มาตรฐานเชื่อมต่อกับเซิร์ฟเวอร์เปิด | F13: จัดซื้อบอร์ด ESP32 และเซนเซอร์สำรองอย่างละ 2 ชุดเป็นอะไหล่สำรองในงบ | G13: ติดตั้งป้ายชื่อโครงการวิศวกรรมและหน่วยงานรับผิดชอบบนกล่องอุปกรณ์ | H13: ตรวจสอบลิขสิทธิ์ของไลบรารีทั้งหมดให้เป็น MIT/Apache 2.0 | I13: ออกแบบปุ่มสวิตช์เปิดเครื่องพร้อมไฟ LED แสดงสถานะการ Calibrate สำเร็จ | J13: ติดตั้งฟิวส์ตัดวงจรและไดโอดป้องกันไฟย้อนกลับในวงจรจ่ายไฟ | K13: เชื่อมต่อระบบส่งข้อมูลเข้า LINE Notify หรือ Telegram กลุ่มเจ้าหน้าที่โดยตรง | L13: ทำ Mock Data จำลองค่าระดับน้ำส่งเข้าโมดูล Python สำหรับพัฒนาอัลกอริทึม | M13: จัดเตรียมบอร์ดทดลองส่วนตัวให้สมาชิกแต่ละคนทำงานจากที่พักได้ | N13: แบ่งงานตามความถนัดเดิมของสมาชิกเพื่อรักษาความเร็วในการพัฒนาสูงสุด | O13: ล็อกสเปกฮาร์ดแวร์และเซนเซอร์ก่อนสัปดาห์ที่ 7 เพื่อทดสอบระบบรวม | P13: สั่งซื้อชิ้นส่วนจากร้านค้าในไทยล่วงหน้า 2 สัปดาห์ก่อนกำหนดประกอบ | Q13: ปฏิบัติตามแผนลดขอบเขตงาน (De-scoping Advisory)
A15: ตารางสรุปคะแนนแยกตามมิติ TELOS+S (Pillar Score Breakdown)
A16: มิติการประเมิน (TELOS+S Pillar) | B16: สัดส่วนน้ำหนัก (Weight %) | C16: คะแนนเต็มมิติ (Max Points) | D16: คะแนนที่ได้รับจริง (Earned Points) | E16: คะแนนเฉลี่ย (Score 1-5) | F16: ระดับความพร้อม (Readiness Level)
A17: T : ด้านเทคโนโลยีและวิศวกรรม (Technical) | B17: 0.2 | C17: 20 | D17: =SUM(B11:C11)*20 | E17: =IF(C17>0, (D17/C17)*5, 0) | F17: =IF(D17>=16.0, "พร้อมระดับสูง (High)", IF(D17>=12.0, "ปานกลาง (Medium)", "เสี่ยงวิกฤต (Critical)"))
A18: E : ด้านเศรษฐศาสตร์และความคุ้มค่า (Economic) | B18: 0.2 | C18: 20 | D18: =SUM(D11:F11)*20 | E18: =IF(C18>0, (D18/C18)*5, 0) | F18: =IF(D18>=16.0, "พร้อมระดับสูง (High)", IF(D18>=12.0, "ปานกลาง (Medium)", "เสี่ยงวิกฤต (Critical)"))
A19: L : ด้านกฎหมายและสถาบัน (Legal & Institutional) | B19: 0.2 | C19: 20 | D19: =SUM(G11:H11)*20 | E19: =IF(C19>0, (D19/C19)*5, 0) | F19: =IF(D19>=16.0, "พร้อมระดับสูง (High)", IF(D19>=12.0, "ปานกลาง (Medium)", "เสี่ยงวิกฤต (Critical)"))
A20: O : ด้านการปฏิบัติการและหน้างาน (Operational) | B20: 0.2 | C20: 20 | D20: =SUM(I11:N11)*20 | E20: =IF(C20>0, (D20/C20)*5, 0) | F20: =IF(D20>=16.0, "พร้อมระดับสูง (High)", IF(D20>=12.0, "ปานกลาง (Medium)", "เสี่ยงวิกฤต (Critical)"))
A21: S : ด้านแผนงานและเวลาส่งมอบ (Schedule) | B21: 0.2 | C21: 20 | D21: =SUM(O11:P11)*20 | E21: =IF(C21>0, (D21/C21)*5, 0) | F21: =IF(D21>=16.0, "พร้อมระดับสูง (High)", IF(D21>=12.0, "ปานกลาง (Medium)", "เสี่ยงวิกฤต (Critical)"))
A22: คะแนนรวมทุกมิติ (Total Feasibility Score) | B22: =SUM(B17:B21) | C22: =SUM(C17:C21) | D22: =SUM(D17:D21) | E22: =IF(C22>0, (D22/C22)*5, 0) | F22: =IF(D22>=80, "ผ่านเกณฑ์ระดับสูง (HIGHLY VIABLE)", IF(D22>=60, "ผ่านแบบมีเงื่อนไข (CONDITIONALLY VIABLE)", "ความเสี่ยงสูง (HIGH RISK)"))
A24: เมทริกซ์ประเมินความเข้ากันได้กับองค์ความรู้ด้านวิศวกรรมหุ่นยนต์ (Robotics Knowledge Compatibility)
A25: * หมายเหตุ: การประเมินส่วนนี้วัดศักยภาพในการประยุกต์ใช้องค์ความรู้ด้านวิศวกรรมหุ่นยนต์ (Perception, Control, Actuation, Mechatronics) เต็ม 10 คะแนน | เป็นเอกเทศ ไม่นับรวมในคะแนน TELOS 100 คะแนน
A26: มิติการประเมิน (Robotics Dimension) | B26: คะแนนศักยภาพ (/10) | C26: แกน Perception & Sensing (การรับรู้) | D26: แกน Control & Algorithms (การควบคุม) | E26: แกน Actuation & Mechanisms (กลไก) | F26: บทวิเคราะห์เชิงวิศวกรรมหุ่นยนต์ (FIBO Alignment Rationale)
A27: ศักยภาพการประยุกต์ใช้องค์ความรู้หุ่นยนต์และระบบอัตโนมัติ | B27: 7.5 | C27: เซนเซอร์วัดระดับน้ำและอัตราการไหล (Ultrasonic/Pressure) พร้อมอัลกอริทึมกรองสัญญาณคลื่นผิวน้ำ (Low-pass & Median Filter) | D27: โดดเด่นมากในวิชา Dynamic Systems & Control Theory: การแก้สมการอนุพันธ์ชลศาสตร์ dh/dt, Discrete Time Derivative, State Estimation และ Predictive Time Horizon (เทียบเวลาเดินทาง 20-30 นาที) | E27: ระดับต่ำ: ไม่มีระบบกลไกเคลื่อนที่ (Manipulator หรือ Mobile Chassis) เป็นระบบตัดสินใจแบบ Cyber-Physical Monitoring & Edge-DSS | F27: มีความเข้ากันได้สูงในแกนคณิตศาสตร์วิศวกรรม ทฤษฎีระบบควบคุม (Control Theory) และการประมวลผลสัญญาณ (Signal Processing & State Estimation) ของ JK แต่คะแนนอยู่ที่ 7.5 เนื่องจากขาด Physical Actuation และกลไกการเคลื่อนที่

Sheet Solution-2
A1: เมทริกซ์ประเมินความเป็นไปได้เชิงระบบ TELOS+S: PUB Singapore CWOS 2-Factor Authentication Dispatch Filter
A2: ระบบคะแนนจำนวนเต็มเด็ดขาด: 1, 2, 3, 4, 5 เท่านั้น (ไม่มีจุดทศนิยม / ไม่มี 0.5) | โครงสร้างแบบ Transposed แนวนอน
A4: รหัสคำถาม (Question Code) | B4: T-01 | C4: T-02 | D4: E-01 | E4: E-02 | F4: E-03 | G4: L-01 | H4: L-02 | I4: O-01 | J4: O-02 | K4: O-03 | L4: O-04 | M4: O-05 | N4: O-06 | O4: S-01 | P4: S-02 | Q4: สรุปภาพรวม (SUMMARY)
A5: มิติการประเมิน (TELOS+S Pillar) | B5: ด้านเทคนิค (Technical Feasibility) | C5: ด้านเทคนิค (Technical Feasibility) | D5: ด้านเศรษฐศาสตร์ (Economic Feasibility) | E5: ด้านเศรษฐศาสตร์ (Economic Feasibility) | F5: ด้านเศรษฐศาสตร์ (Economic Feasibility) | G5: ด้านกฎหมายและสถาบัน (Legal & Institutional Feasibility) | H5: ด้านกฎหมายและสถาบัน (Legal & Institutional Feasibility) | I5: ด้านการปฏิบัติการ (Operational Feasibility) | J5: ด้านการปฏิบัติการ (Operational Feasibility) | K5: ด้านการปฏิบัติการ (Operational Feasibility) | L5: ด้านการปฏิบัติการ (Operational Feasibility) | M5: ด้านการปฏิบัติการ (Operational Feasibility) | N5: ด้านการปฏิบัติการ (Operational Feasibility) | O5: ด้านแผนงานและเวลา (Schedule Feasibility) | P5: ด้านแผนงานและเวลา (Schedule Feasibility) | Q5: ผลรวมทุกมิติ (All Pillars)
A6: คำถามทดสอบความเสี่ยงจริง (Stress-Test Question) | B6: Implementation (Build vs. Buy Burden): โครงการมีความจำเป็นต้องวิจัยและพัฒนาชิ้นส่วนขึ้นเอง (Build from Scratch) มากน้อยเพียงใด หรือสามารถจัดหาโมดูลสำเร็จรูปมาตรฐาน (COTS) มาประกอบและปรับแต่งได้โดยตรง? | C6: Team Redundancy (Bus Factor): มีจำนวนสมาชิกในทีมกี่คนที่เข้าใจสถาปัตยกรรมทั้งเชิงกล วงจรไฟฟ้า และโค้ด จนสามารถพัฒนา ประกอบ และแก้ไขข้อผิดพลาดของระบบย่อยนี้ได้อย่างอิสระ? | D6: ROI (Payback Period / Value Horizon): โครงการมีระยะเวลาคืนทุน (Payback Period) และความคุ้มค่าในการลดความสูญเสียหรือลดค่าใช้จ่ายในการดำเนินงาน (OpEx Reduction) รวดเร็วเพียงใด? | E6: Dependencies of Component (Vendor Lock-in & Service Autonomy): ระบบมีความเป็นอิสระจากการผูกขาดของผู้ผลิต (Vendor Lock-in) มากน้อยเพียงใด และทีมงานหรือวิศวกรทั่วไปสามารถซ่อมบำรุงด้วยเครื่องมือเปิดได้เองหรือไม่? | F6: Scrap Margin (Safety Allowance for Blown ICs & Iterations): โครงการมีการจัดสรรงบประมาณสำรองสำหรับชิ้นส่วนทดแทนกรณีเสียหาย (Scrap Margin) และการทดลองซ้ำ (Iterations) ในสัดส่วนเท่าใดของรายการวัสดุ (BOM)? | G6: Felony and Civil Law (Regulatory & Public Safety Compliance): ระบบและการติดตั้งมีความสอดคล้องต่อข้อบังคับทางกฎหมายอาญา แพ่ง ระเบียบจราจร และการคุ้มครองข้อมูลส่วนบุคคล (PDPA / Public Safety) โดยไม่สร้างความรับผิดทางกฎหมายหรือไม่? | H6: IP and Licensing: ทรัพย์สินทางปัญญา ซอฟต์แวร์ไลบรารี และสิทธิบัตรที่นำมาใช้ มีความเปิดกว้างและปลอดภาระผูกพันทางการค้าหรือการละเมิดลิขสิทธิ์ (Licensing Freedom) มากน้อยเพียงใด? | I6: User — Implementation (Field Deployment / Setup Friction): ขั้นตอนการติดตั้ง ติดตั้งเครื่องมือ ปรับเทียบศูนย์ (Calibration) และเตรียมพร้อมใช้งานหน้างานจริงโดยผู้ปฏิบัติงาน มีความยุ่งยากหรือกินเวลาเพียงใด? | J6: User — Customer / Public Safety & Failsafes: มาตรการรักษาความปลอดภัย การป้องกันอุบัติเหตุ (Failsafes, Interlocks, E-stops) และการควบคุมอันตรายต่อเจ้าหน้าที่และสาธารณชนมีความรัดกุมเพียงใด? | K6: User — Behavior & Workflow Disruption: ระบบสร้างภาระงานเอกสาร ขั้นตอนปฏิบัติงาน หรือบังคับเปลี่ยนพฤติกรรมเจ้าหน้าที่หน้างาน (SOP Disruption) มากน้อยเพียงใด? | L6: Developer — Task Dependency (Critical Path Architecture): สถาปัตยกรรมการพัฒนาฮาร์ดแวร์ ไฟฟ้า และซอฟต์แวร์ มีการเชื่อมต่อแบบขนาน (Parallel Architecture / Modularity) หรือผูกติดกันเป็นเส้นตรงบนเส้นทางวิกฤต (Critical Path)? | M6: Developer — Contribution Dependency (Bureaucratic & Lab Gatekeeping): การเข้าถึงเครื่องมือในห้องปฏิบัติการ การอนุมัติงบประมาณ และกระบวนการทางธุรการ (Lab Access & Purchasing Bureaucracy) มีอุปสรรคขัดขวางความคล่องตัวเพียงใด? | N6: Developer — Task & Skill Compatibility: ความเข้ากันได้ระหว่างทักษะเดิมของทีมกับเทคโนโลยีสแตกของระบบ (Task & Skill Compatibility: 'Water and Oil' vs. 'Oil and Engine') อยู่ในระดับใด? | O6: Production Time (Engineering Design Maturity by Milestone): ความพร้อมของแบบวิศวกรรม (3D CAD, Schematics, PCB Gerbers, Firmware Architecture, BOM) อยู่ในระดับความสมบูรณ์ใดเทียบกับหมุดหมายการผลิตจริง? | P6: Shipping (Component Procurement Lead Time): ระยะเวลาในการจัดหาและขนส่งชิ้นส่วน อุปกรณ์ และเซนเซอร์ (Procurement Lead Time) อยู่ในกรอบเวลาที่ปลอดภัยต่อกำหนดส่งมอบงานหรือไม่? | Q6: ประเมินคำถามทั้งสิ้น 15 ข้อ
A7: เหตุผลในการถาม & โหมดความล้มเหลวที่เฝ้าระวัง (Rationale) | B7: มุ่งตรวจสอบ Build vs. Buy Burden และ Machine Access หากระบบต้อง R&D กลไกหรือวงจรขึ้นเอง 100% โดยไม่มี Reference Design จะเกิดความเสี่ยงวิกฤตต่อกรอบเวลาของโครงงานวิศวกรรม | C7: ตรวจสอบความต่อเนื่องของทีม (Team Knowledge Distribution) ป้องกัน Single Point of Failure หากมีผู้เชี่ยวชาญเพียงคนเดียวเมื่อติดสอบหรือเจ็บป่วยโครงการจะล้มเหลวทันที | D7: ประเมินความคุ้มค่าในการลงทุนและระยะเวลาคืนทุนเชิงสาธารณูปโภคหรือเชิงพาณิชย์ เทียบกับเงินลงทุนเริ่มต้น (CapEx) และเงินประหยัดค่าแรงงาน/ค่าน้ำมันหน้างาน | E7: ตรวจสอบภาระค่าใช้จ่ายแฝงระยะยาว (Recurring Cloud/Licensing Fees) และความเสี่ยงจากการถูกผูกขาดด้วยฮาร์ดแวร์หรือระบบคลาวด์ปิดของผู้ผลิตรายเดียว | F7: ตรวจสอบ The Scrap Budget Rule งานฮาร์ดแวร์มีความเสี่ยงต่อชิปไหม้ แผ่นวงจรช็อต หรือขายึดหัก หากไม่มีงบสำรองจัดซื้อชุดที่ 2 การพัฒนาจะหยุดชะงักทันที | G7: ตรวจสอบความเสี่ยงต่อการทำผิดกฎหมายสาธารณะ (พ.ร.บ. จราจรทางบก, พ.ร.บ. คุ้มครองข้อมูลส่วนบุคคล PDPA, กฎหมายสิ่งแวดล้อม และระเบียบทางหลวง) | H7: ตรวจสอบข้อจำกัดด้านสิทธิ์ซอฟต์แวร์และฮาร์ดแวร์ ป้องกันการติดไวรัสไลเซนส์ (Copyleft GPLv3) หรือการละเมิดสิทธิบัตรเชิงพาณิชย์ของบุคคลภายนอก | I7: ประเมินความยากลำบากของเจ้าหน้าที่หน้างาน (Field Setup Friction) หากอุปกรณ์ต้องใช้เวลาตั้งค่าหรือ Calibrate นานเกินไป เจ้าหน้าที่จะปฏิเสธการใช้งาน | J7: ตรวจสอบความปลอดภัยต่อชีวิตและทรัพย์สิน ป้องกันอันตรายจากไฟฟ้าแรงสูง สารเคมี ก๊าซพิษในที่อับอากาศ หรืออุบัติเหตุทางรถยนต์ขณะปฏิบัติงาน | K7: ประเมินแรงต้านจากเจ้าหน้าที่ผู้ใช้งาน (The Tech Trap) ระบบที่ดีต้องลดภาระ ไม่ใช่สร้างแบบฟอร์มเอกสารหรือบังคับเปลี่ยนกระบวนการทำงานหลัก | L7: ตรวจสอบ Critical Path การพัฒนา หากงานซอฟต์แวร์ต้องรอฮาร์ดแวร์จริงเสร็จก่อนเท่านั้น จะเกิดคอขวดสะสมจนส่งมอบงานไม่ทันกำหนด | M7: ประเมินอุปสรรคด้านการบริหารและเครื่องมือ (Institutional Gatekeeping) เช่น คิวรอเครื่องจักร การล็อกแล็บ หรือขั้นตอนเบิกจ่ายงบประมาณที่ล่าช้า | N7: ตรวจสอบความสอดคล้องระหว่างทักษะที่ทีมมีอยู่จริงกับเทคโนโลยีที่เลือกใช้ เพื่อป้องกัน Learning Curve ที่สูงเกินไปจนงานล้มเหลว | O7: ประเมินความพร้อมของพิมพ์เขียวการผลิต (Design Maturity Package) ก่อนเริ่มสั่งผลิตจริง เพื่อป้องกันการรื้อแก้แบบกลางคัน | P7: ตรวจสอบห่วงโซ่อุปทาน (Supply Chain Lead Time) ชิ้นส่วนที่ต้องรอส่งจากต่างประเทศเกิน 3 สัปดาห์ถือเป็นความเสี่ยงต่อวิกฤตสัปดาห์สอบและกำหนดส่งมอบ | Q7: สังเคราะห์จาก AI Agents Group 2
A8: เกณฑ์การให้คะแนน (Scoring Rubric Definition: ระดับ 1, 2, 3, 4, 5 ครบทุกระดับ) | B8: 1: Build from Scratch — 100% custom R&D required (custom mechanism, custom PCB, raw algorithm derivation); no reference designs available. 2: Heavy Customization — Core components exist, but requires extensive custom adaptation, structural machining, and custom wrapper code. 3: Hybrid / COTS Integration — Standard COTS modules (e.g., standard dev board + breakout sensors) assembled with custom brackets and intermediate wiring. 4: Modular COTS Assembly — Pre-engineered building blocks with standard mounting and standard communication buses (e.g., Din-rail modules, I2C/CAN shields); minimal custom fabrication. 5: Commercial Off-the-Shelf (COTS) — Turnkey commercial solution; zero custom fabrication or circuitry required, immediate plug-and-play operation. | C8: 1: Single Point of Failure (Bus Factor = 1) — Only 1 teammate understands the codebase/hardware; if they are absent or drop out, the project completely halts. 2: Fragile Redundancy (Bus Factor = 1.5) — 1 primary expert with minimal notes; a second member has rough familiarity but requires steep ramp-up to debug. 3: Moderate Redundancy (Bus Factor = 2) — 2 teammates can independently maintain, test, and troubleshoot the core subsystem. 4: High Team Redundancy (3+ Teammates) — 3+ teammates can actively design, assemble, and debug the subsystem with low ramp-up time. 5: Full Team Redundancy — All team members are fully proficient; tasks can be swapped across anyone with zero friction or velocity loss. | D8: 1: Long Payback (≥ 10 Years) — High initial CapEx and low recurring savings; economically non-viable for rapid deployment. 2: Slow Return (6–9 Years) — Substantial capital investment with long break-even horizon; requires long-term institutional subsidization. 3: Moderate Return (3–5 Years) — Reasonable public infrastructure payback; offsets costs across multi-year operational cycles. 4: Fast Return (2–3 Years) — Strong operational cost reduction (fuel, labor, scrap); breaks even within normal equipment lifecycle. 5: Immediate Payback (≤ 1–2 Years) — Rapid break-even; eliminates major recurring losses within the first operating season. | E8: 1: Total Vendor Lock-in — Proprietary cloud backend, encrypted telemetry, and proprietary connectors; completely dependent on vendor survival. 2: High Dependency — Hardware requires vendor-licensed diagnostic tools or annual subscription fees to maintain operation. 3: Semi-Independent — Core hardware relies on proprietary firmware, but allows open API export and standard electrical interfaces. 4: High Autonomy — Uses standard open communication protocols (e.g., Modbus, MQTT, CAN); parts can be serviced using generic tools. 5: Complete Independence — 100% open architecture; hardware is interchangeable with generic substitutes; self-serviceable by any engineer. | F8: 1: Zero Buffer (0%) — Exactly 1x BOM purchased; any fried chip, cracked bracket, or wiring mistake kills the project. 2: Fragile Buffer (20–30%) — Spares only for passive components (resistors, connectors); no backup microcontrollers or expensive sensors. 3: Moderate Buffer (50%) — Spares for all critical passive parts and 1 spare for the primary controller board. 4: High Buffer (80%) — Spares for nearly every active component and sensor; can sustain multiple prototype burn-ins. 5: Full Redundancy (≥ 100%) — Complete 2x BOM budget on hand; can build two complete working units simultaneously. | G8: 1: Severe Violation / No Privilege — Direct breach of statutory law (e.g., unconsented public surveillance/PDPA, hazardous road blockage, RF jammer). 2: High Legal Exposure — Ambiguous legal zone; high risk of civic complaints or traffic disruption; requires complex technical waivers. 3: Conditional / Requires Permit — Allowed under explicit written approval, official agency MoU, or municipal permit (e.g., BMA/Highway dept permit). 4: Low Legal Friction — Operates within standard public engineering exemptions; simple standard notification/safety compliance needed. 5: 100% Compliant / Free Domain — Completely exempt from statutory licensing; zero public safety risk, zero personal data (Zero PII), fully unrestricted. | H8: 1: Closed / Commercial Barrier — Proprietary commercial license; cannot compile, flash, or operate without paying expensive commercial seat licenses. 2: Ambiguous / Gray IP — Unclear licensing terms or unlicensed GitHub repos; risk of copyright strike or IP dispute upon public demonstration. 3: Restrictive Open Source (Copyleft) — Permitted for educational use, but viral licenses (e.g., GPLv3) force your entire codebase to be made public if distributed. 4: Permissive Open Source — Open source with minimal conditions (e.g., LGPL, CC-BY); allows proprietary wrapping with simple attribution. 5: Completely Permissive / Public Domain — Permissive open source (MIT, Apache 2.0, BSD) or Public Domain; unrestricted freedom to commercialize, modify, and contribute. | I8: 1: Laborious Recalibration — Requires multi-point manual physical zeroing, chemical calibration, or oscilloscope tuning before every run. 2: Complex Setup — Requires trained technician 20–30 minutes to adjust potentiometers, align brackets, or enter configuration commands. 3: Moderate Field Setup — Simple 5-minute calibration procedure (e.g., tare button or basic mobile app zeroing) performed by non-engineers. 4: Minimal Setup — Fast clamp-on mounting with automated self-calibration on power-up; ready in < 1 minute. 5: True Plug and Go — Pure plug-and-play; zero calibration required, zero buttons; power on and immediately operational. | J8: 1: Critical Hazard — Failure can directly cause electrocution, fire, traffic crashes, chemical exposure, or confined-space asphyxiation. 2: High Risk / Manual Oversight — High mechanical/electrical hazard requiring constant operator vigilance and full PPE. 3: Moderate Safety — Protected by passive mechanical guards, fuses, and warning labels; requires basic safety precautions. 4: High Safety & Interlocks — Active software limits, hardware thermal shutoffs, and reverse polarity protection; minimal hazard on failure. 5: Inherently Safe & Redundant — Failsafe by physics (cannot store lethal energy); isolated, dual-rated enclosures, redundant E-stops, zero injury risk. | K8: 1: Disruptive Overhaul — Forces operators to abandon existing SOPs, adds 5+ extra tedious forms/steps, and faces fierce institutional union/worker resistance. 2: Significant Friction — Adds notable extra documentation or redundant verification steps; operators will actively look for ways to bypass it. 3: Moderate Adaptation — Modifies daily routine slightly; requires 1–2 training workshops, but delivers clear convenience trade-offs. 4: Low Friction — Integrates into existing tools (e.g., sends automated alerts to existing LINE/Telegram or ticketing dashboard); minimal change in habits. 5: Transparent / Seamless Integration — Zero workflow disruption; runs invisibly in background and automates existing manual paperwork without operator intervention. | L8: 1: Strictly Sequential (Linear) — A depends on B depends on C; if the PCB fab is delayed, software and testing halt 100%. 2: Bottlenecked Pipelines — Major subsystems are tightly coupled; frequent integration stalls waiting for hardware bench access. 3: Semi-Decoupled — Hardware and software teams can work independently for 1–2 weeks using rough mockups before needing physical integration. 4: Modular Parallelism — Clear API/interface boundaries; software builds against mock data/simulators while hardware is routed; integration takes < 2 days. 5: Fully Parallel Architecture — Microservices/modular nodes with standard contracts; mechanical, electrical, and firmware develop, simulate, and unit-test completely in parallel. | M8: 1: Heavy Gatekeeping — Blocked by supervisor approvals, locked lab cabinets, NDA signatures, purchasing bureaucracy, and restricted git branches. 2: Moderate Bureaucracy — Requires departmental request forms, tool booking queues, and waiting 3–5 days for administrative sign-offs. 3: Standard Campus Access — Workable access during university open hours; minor approval delays for equipment or lab keys. 4: High Autonomy — Team has full repository write access, open 24/7 lab entry, and pre-approved discretionary debit cards/stipends for rapid purchases. 5: Frictionless Contribution — Complete autonomy; decentralized cloud CI/CD, local prototyping tools at home/bench, zero administrative blockers. | N8: 1: Complete Mismatch ('Water and Oil') — Team has zero foundation in the stack (e.g., pure mechanical students forced to train deep neural nets in C++ from scratch). 2: Steep Learning Curve — High theoretical knowledge, but zero production hands-on experience; debugging basic syntax/wiring stalls progress. 3: Adjacent Competence — Strong mastery in related tools (e.g., proficient in Arduino/ESP32 migrating to STM32, or SolidWorks migrating to Fusion360); manageable 1-week curve. 4: Proven Experience — Team has built similar subsystems in past semester coursework or competition robots; rapid ramp-up. 5: Perfect Synergy ('Oil and Engine') — Complete domain mastery; team members have built this exact architecture multiple times with verified libraries and muscle memory. | O8: 1: Concept Only (0% Design) — Napkin sketches and verbal concepts; 0% CAD models, 0% schematics, 0% code written. 2: Rough Drafts (25% Design) — Preliminary block diagrams, hand-drawn schematics, unverified parts list, incomplete 3D bounding boxes. 3: Intermediate Maturity (50% Design) — Complete CAD assembly (untested clearances), schematic capture complete, draft firmware architecture mapped out. 4: Pre-Production (80% Design) — Fully detailed 3D CAD ready for 3D print/CNC, routed PCB Gerber files validated with DRC, pinouts locked down. 5: Fully Engineered Design (100% Production Ready) — Complete drawing package: BOM with part numbers, verified manufacturing Gerbers, 2D tolerance drawings, assembly SOP, and flashing scripts ready. | P8: 1: Extreme Lead Time (≥ 4 Weeks) — Custom overseas fabrication, customs clearance delays, or parts with long factory lead times (critical path hazard). 2: High Lead Time (3–4 Weeks) — Standard overseas shipping (e.g., standard AliExpress/international postal surface mail); vulnerable to logistics delays. 3: Moderate Lead Time (2 Weeks) — Express international courier (DHL, FedEx, JLCPCB express) or regional distributors (7–14 days). 4: Short Lead Time (1 Week) — Domestic couriers or express domestic stockists (3–5 business days). 5: Immediate / Next-Day (≤ 1–2 Days) — Shelf stock available locally at retail shops or next-day domestic express delivery. | Q8: เกณฑ์รวม: >=80 ผ่านสูง, >=60 มีเงื่อนไข, <60 เสี่ยงสูง | หากมีข้อใดได้ 1 = VETOED ตกเกณฑ์ทันที
A9: คะแนนที่ได้รับ (ASSIGNED SCORE: 1, 2, 3, 4, 5 STRICT INTEGER) | B9: 4 | C9: 4 | D9: 5 | E9: 3 | F9: 5 | G9: 5 | H9: 5 | I9: 4 | J9: 5 | K9: 5 | L9: 5 | M9: 5 | N9: 5 | O9: 4 | P9: 5 | Q9: =IF(Q10>0, (Q11/Q10)*20, 0)
A10: ค่าน้ำหนัก (Weight %) | B10: 0.1 | C10: 0.1 | D10: 0.0667 | E10: 0.0667 | F10: 0.0666 | G10: 0.1 | H10: 0.1 | I10: 0.0333 | J10: 0.0333 | K10: 0.0334 | L10: 0.0333 | M10: 0.0333 | N10: 0.0334 | O10: 0.1 | P10: 0.1 | Q10: =SUM(B10:P10)
A11: คะแนนถ่วงน้ำหนัก (=Score * Weight) | B11: =B9*B10 | C11: =C9*C10 | D11: =D9*D10 | E11: =E9*E10 | F11: =F9*F10 | G11: =G9*G10 | H11: =H9*H10 | I11: =I9*I10 | ... P11: =P9*P10 | Q11: =SUM(B11:P11)
A12: คำอธิบาย & หลักฐานอ้างอิงจากไฟล์ Intake (Evidence Citation) | B12: อ้างอิง solution-details/solution-2.md พัฒนาเป็นระบบซอฟต์แวร์ API Gateway ร่วมกับบอร์ดเซนเซอร์ COTS สำเร็จรูป ไม่ต้องขึ้นรูปกลไกพิเศษ | C12: สมาชิก 3 คน (JK, Due, Kin) มีความเชี่ยวชาญด้าน Python, Webhook API และไมโครคอนโทรลเลอร์ สามารถร่วมกันพัฒนาและทดสอบระบบได้โดยไม่มีคอขวด | D12: ตัดปัญหาการสั่งการรถบริการผิดเป้าหมาย ต้นทุนระบบต่ำมาก คืนทุนภายใน 1 ฤดูฝนแรก (≤ 1-2 ปี) | E12: พึ่งพาข้อมูล Radar API จากกรมอุตุนิยมวิทยาหรือสำนักระบายน้ำ หาก API ภายนอกปิดปรับปรุงจำเป็นต้องเขียนระบบเชื่อมต่อใหม่ | F12: เน้นงานซอฟต์แวร์และบอร์ด MCU ตัวเดียว งบประมาณโครงการสามารถจัดซื้อบอร์ดสำรองได้เกิน 100% (Full Redundancy) | G12: ไม่ใช้กล้องบันทึกภาพ ไม่เก็บข้อมูลส่วนบุคคล (Zero PII 100%) ใช้งานข้อมูลอุตุนิยมวิทยาเปิดของภาครัฐอย่างถูกต้อง | H12: สถาปัตยกรรมซอฟต์แวร์พัฒนาด้วยโอเพนซอร์สมาตรฐาน (FastAPI, Leaflet, SQLite ภายใต้ MIT License) ปลอดภาระลิขสิทธิ์ | I12: เซนเซอร์หน้างานเชื่อมต่อคลาวด์อัตโนมัติ ติดตั้งด้วยแคลมป์มาตรฐาน ใช้เวลาเปิดเครื่องพร้อมส่งข้อมูล < 1 นาที | J12: ระบบใช้ไฟกระแสตรง 5V ไม่มีความเสี่ยงไฟฟ้าแรงดันสูง ปลอดภัยตามธรรมชาติทางฟิสิกส์ (Inherently Safe) | K12: ส่งการแจ้งเตือนยืนยัน 2-Factor ตรงเข้ากลุ่ม LINE ของเจ้าหน้าที่เขตโดยอัตโนมัติ ไม่ต้องเปลี่ยนหน้าจอทำงานเดิม | L12: ฝั่งดึง Radar API, ฝั่งประมวลผลตรรกะ 2-Factor, และฝั่ง Web Dashboard แยกกันเป็น Microservices อิสระ พัฒนาคู่ขนานได้ 100% | M12: พัฒนาบนระบบคลาวด์และคอมพิวเตอร์ส่วนตัว ไร้การพึ่งพาห้องปฏิบัติการหรือขั้นตอนอนุมัติทางธุรการ | N12: สมาชิกมีความเชี่ยวชาญสูงด้าน Python, Cloud Webhook และ Data Integration สอดคล้องกับโครงงานแข่งขันเดิม ('Oil and Engine') | O12: ซอฟต์แวร์ Backend API และ Logic Flowchart เสร็จสมบูรณ์ระดับ Pre-production พร้อมทดสอบเชื่อมต่อข้อมูลจริง | P12: บอร์ด MCU และโมดูลสื่อสารจัดซื้อจากตัวแทนจำหน่ายในประเทศ ได้รับของภายใน 1-2 วันทำการ | Q12: =IF(MIN(B9:P9)=1, "VETOED / ตกเกณฑ์ข้อบังคับวิกฤต (คะแนนระดับ 1)", IF(Q9>=80, "ผ่านเกณฑ์ระดับสูง (HIGHLY VIABLE)", IF(Q9>=60, "ผ่านแบบมีเงื่อนไข (CONDITIONALLY VIABLE)", "ความเสี่ยงสูง (HIGH RISK)")))
A13: แผนลดขอบเขตงาน & มาตรการลดความเสี่ยง (De-scoping Action) | B13: ใช้บอร์ด ESP32 สำเร็จรูปพร้อมเสาอากาศมาตรฐาน | C13: กำหนดโครงสร้าง REST API ให้ชัดเจนเพื่อให้สมาชิกสลับงานกันเขียนโค้ดได้ | D13: ใช้บริการคลาวด์ระดับ Free Tier (เช่น Supabase หรือ Railway) เพื่อลดต้นทุนดำเนินงาน | E13: ทำระบบ Local Fallback รับค่าเฉพาะเซนเซอร์ผิวน้ำหาก Radar API ขัดข้อง | F13: สำรองบอร์ดไมโครคอนโทรลเลอร์ 2 ชุดสำหรับทดสอบและใช้งานจริง | G13: ปฏิบัติตามข้อกำหนดการดึงข้อมูล Open Data ของภาครัฐ | H13: ใช้ไลบรารีโอเพนซอร์สที่มีสัญญาอนุญาต MIT หรือ BSD เท่านั้น | I13: ออกแบบระบบ Auto-provisioning สำหรับเชื่อมต่อ Wi-Fi/Cellular อัตโนมัติ | J13: ใส่เคสกันฝุ่นและกันละอองน้ำมาตรฐาน IP65 ให้กับชุดรับสัญญาณ | K13: จัดรูปแบบข้อความแจ้งเตือนใน LINE ให้กระชับ ระบุพิกัดและระดับน้ำชัดเจน | L13: สร้าง Mock Service จำลองฝนตกเพื่อทดสอบระบบตรรกะโดยไม่ต้องรอฝนตกจริง | M13: ใช้ GitHub Actions รัน Unit Test อัตโนมัติทุกครั้งที่ Pull Request | N13: ให้ Kin ดูแลฝั่ง Dashboard และ JK ดูแลอัลกอริทึม 2-Factor Logic | O13: ทดสอบระบบรวมกับข้อมูลย้อนหลังของ กทม. ก่อนสัปดาห์ที่ 8 | P13: จัดเตรียมอะไหล่โมดูลสำรองไว้ล่วงหน้าก่อนเริ่มช่วงมิดเทอม | Q13: ปฏิบัติตามแผนลดขอบเขตงาน (De-scoping Advisory)
A15: ตารางสรุปคะแนนแยกตามมิติ TELOS+S (Pillar Score Breakdown)
A16: มิติการประเมิน (TELOS+S Pillar) | B16: สัดส่วนน้ำหนัก (Weight %) | C16: คะแนนเต็มมิติ (Max Points) | D16: คะแนนที่ได้รับจริง (Earned Points) | E16: คะแนนเฉลี่ย (Score 1-5) | F16: ระดับความพร้อม (Readiness Level)
A17: T : ด้านเทคโนโลยีและวิศวกรรม (Technical) | B17: 0.2 | C17: 20 | D17: =SUM(B11:C11)*20 | E17: =IF(C17>0, (D17/C17)*5, 0) | F17: =IF(D17>=16.0, "พร้อมระดับสูง (High)", IF(D17>=12.0, "ปานกลาง (Medium)", "เสี่ยงวิกฤต (Critical)"))
A18: E : ด้านเศรษฐศาสตร์และความคุ้มค่า (Economic) | B18: 0.2 | C18: 20 | D18: =SUM(D11:F11)*20 | E18: =IF(C18>0, (D18/C18)*5, 0) | F18: =IF(D18>=16.0, "พร้อมระดับสูง (High)", IF(D18>=12.0, "ปานกลาง (Medium)", "เสี่ยงวิกฤต (Critical)"))
A19: L : ด้านกฎหมายและสถาบัน (Legal & Institutional) | B19: 0.2 | C19: 20 | D19: =SUM(G11:H11)*20 | E19: =IF(C19>0, (D19/C19)*5, 0) | F19: =IF(D19>=16.0, "พร้อมระดับสูง (High)", IF(D19>=12.0, "ปานกลาง (Medium)", "เสี่ยงวิกฤต (Critical)"))
A20: O : ด้านการปฏิบัติการและหน้างาน (Operational) | B20: 0.2 | C20: 20 | D20: =SUM(I11:N11)*20 | E20: =IF(C20>0, (D20/C20)*5, 0) | F20: =IF(D20>=16.0, "พร้อมระดับสูง (High)", IF(D20>=12.0, "ปานกลาง (Medium)", "เสี่ยงวิกฤต (Critical)"))
A21: S : ด้านแผนงานและเวลาส่งมอบ (Schedule) | B21: 0.2 | C21: 20 | D21: =SUM(O11:P11)*20 | E21: =IF(C21>0, (D21/C21)*5, 0) | F21: =IF(D21>=16.0, "พร้อมระดับสูง (High)", IF(D21>=12.0, "ปานกลาง (Medium)", "เสี่ยงวิกฤต (Critical)"))
A22: คะแนนรวมทุกมิติ (Total Feasibility Score) | B22: =SUM(B17:B21) | C22: =SUM(C17:C21) | D22: =SUM(D17:D21) | E22: =IF(C22>0, (D22/C22)*5, 0) | F22: =IF(D22>=80, "ผ่านเกณฑ์ระดับสูง (HIGHLY VIABLE)", IF(D22>=60, "ผ่านแบบมีเงื่อนไข (CONDITIONALLY VIABLE)", "ความเสี่ยงสูง (HIGH RISK)"))
A24: เมทริกซ์ประเมินความเข้ากันได้กับองค์ความรู้ด้านวิศวกรรมหุ่นยนต์ (Robotics Knowledge Compatibility)
A25: * หมายเหตุ: การประเมินส่วนนี้วัดศักยภาพในการประยุกต์ใช้องค์ความรู้ด้านวิศวกรรมหุ่นยนต์ (Perception, Control, Actuation, Mechatronics) เต็ม 10 คะแนน | เป็นเอกเทศ ไม่นับรวมในคะแนน TELOS 100 คะแนน
A26: มิติการประเมิน (Robotics Dimension) | B26: คะแนนศักยภาพ (/10) | C26: แกน Perception & Sensing (การรับรู้) | D26: แกน Control & Algorithms (การควบคุม) | E26: แกน Actuation & Mechanisms (กลไก) | F26: บทวิเคราะห์เชิงวิศวกรรมหุ่นยนต์ (FIBO Alignment Rationale)
A27: ศักยภาพการประยุกต์ใช้องค์ความรู้หุ่นยนต์และระบบอัตโนมัติ | B27: 5 | C27: ดึงข้อมูลเรดาร์ปริมาณฝนผ่าน API ร่วมกับเซนเซอร์วัดระดับน้ำและอัตราการไหล (Dual-stream Data Ingestion) | D27: ใช้อัลกอริทึมคัดกรอง 2-Factor Authentication Logic, Boolean Decision Trees และ Spatial-Temporal Correlation Filter | E27: ไม่มีระบบกลไกหรือฮาร์ดแวร์เคลื่อนที่ เป็นระบบ Decision Support System (DSS) บนคลาวด์และเว็บแดชบอร์ด | F27: มีความเข้ากันได้ในแกนการประมวลผลข้อมูลและสถาปัตยกรรมตรรกะควบคุม (Control & Decision Logic) แต่ขาดแกนกลไก (Mechanics) และ Actuation ของหุ่นยนต์อย่างสิ้นเชิง คะแนนจึงอยู่ที่ 5.0

Sheet Solution-3
A1: เมทริกซ์ประเมินความเป็นไปได้เชิงระบบ TELOS+S: Acoustic Sewer Measurement & Pre-Screening Maintenance (UK/USA SL-RAT Case)
A2: ระบบคะแนนจำนวนเต็มเด็ดขาด: 1, 2, 3, 4, 5 เท่านั้น (ไม่มีจุดทศนิยม / ไม่มี 0.5) | โครงสร้างแบบ Transposed แนวนอน
A4: รหัสคำถาม (Question Code) | B4: T-01 | C4: T-02 | D4: E-01 | E4: E-02 | F4: E-03 | G4: L-01 | H4: L-02 | I4: O-01 | J4: O-02 | K4: O-03 | L4: O-04 | M4: O-05 | N4: O-06 | O4: S-01 | P4: S-02 | Q4: สรุปภาพรวม (SUMMARY)
A5: มิติการประเมิน (TELOS+S Pillar) | B5: ด้านเทคนิค (Technical Feasibility) | C5: ด้านเทคนิค (Technical Feasibility) | D5: ด้านเศรษฐศาสตร์ (Economic Feasibility) | E5: ด้านเศรษฐศาสตร์ (Economic Feasibility) | F5: ด้านเศรษฐศาสตร์ (Economic Feasibility) | G5: ด้านกฎหมายและสถาบัน (Legal & Institutional Feasibility) | H5: ด้านกฎหมายและสถาบัน (Legal & Institutional Feasibility) | I5: ด้านการปฏิบัติการ (Operational Feasibility) | J5: ด้านการปฏิบัติการ (Operational Feasibility) | K5: ด้านการปฏิบัติการ (Operational Feasibility) | L5: ด้านการปฏิบัติการ (Operational Feasibility) | M5: ด้านการปฏิบัติการ (Operational Feasibility) | N5: ด้านการปฏิบัติการ (Operational Feasibility) | O5: ด้านแผนงานและเวลา (Schedule Feasibility) | P5: ด้านแผนงานและเวลา (Schedule Feasibility) | Q5: ผลรวมทุกมิติ (All Pillars)
A6: คำถามทดสอบความเสี่ยงจริง (Stress-Test Question) | B6: Implementation (Build vs. Buy Burden): โครงการมีความจำเป็นต้องวิจัยและพัฒนาชิ้นส่วนขึ้นเอง (Build from Scratch) มากน้อยเพียงใด หรือสามารถจัดหาโมดูลสำเร็จรูปมาตรฐาน (COTS) มาประกอบและปรับแต่งได้โดยตรง? | C6: Team Redundancy (Bus Factor): มีจำนวนสมาชิกในทีมกี่คนที่เข้าใจสถาปัตยกรรมทั้งเชิงกล วงจรไฟฟ้า และโค้ด จนสามารถพัฒนา ประกอบ และแก้ไขข้อผิดพลาดของระบบย่อยนี้ได้อย่างอิสระ? | D6: ROI (Payback Period / Value Horizon): โครงการมีระยะเวลาคืนทุน (Payback Period) และความคุ้มค่าในการลดความสูญเสียหรือลดค่าใช้จ่ายในการดำเนินงาน (OpEx Reduction) รวดเร็วเพียงใด? | E6: Dependencies of Component (Vendor Lock-in & Service Autonomy): ระบบมีความเป็นอิสระจากการผูกขาดของผู้ผลิต (Vendor Lock-in) มากน้อยเพียงใด และทีมงานหรือวิศวกรทั่วไปสามารถซ่อมบำรุงด้วยเครื่องมือเปิดได้เองหรือไม่? | F6: Scrap Margin (Safety Allowance for Blown ICs & Iterations): โครงการมีการจัดสรรงบประมาณสำรองสำหรับชิ้นส่วนทดแทนกรณีเสียหาย (Scrap Margin) และการทดลองซ้ำ (Iterations) ในสัดส่วนเท่าใดของรายการวัสดุ (BOM)? | G6: Felony and Civil Law (Regulatory & Public Safety Compliance): ระบบและการติดตั้งมีความสอดคล้องต่อข้อบังคับทางกฎหมายอาญา แพ่ง ระเบียบจราจร และการคุ้มครองข้อมูลส่วนบุคคล (PDPA / Public Safety) โดยไม่สร้างความรับผิดทางกฎหมายหรือไม่? | H6: IP and Licensing: ทรัพย์สินทางปัญญา ซอฟต์แวร์ไลบรารี และสิทธิบัตรที่นำมาใช้ มีความเปิดกว้างและปลอดภาระผูกพันทางการค้าหรือการละเมิดลิขสิทธิ์ (Licensing Freedom) มากน้อยเพียงใด? | I6: User — Implementation (Field Deployment / Setup Friction): ขั้นตอนการติดตั้ง ติดตั้งเครื่องมือ ปรับเทียบศูนย์ (Calibration) และเตรียมพร้อมใช้งานหน้างานจริงโดยผู้ปฏิบัติงาน มีความยุ่งยากหรือกินเวลาเพียงใด? | J6: User — Customer / Public Safety & Failsafes: มาตรการรักษาความปลอดภัย การป้องกันอุบัติเหตุ (Failsafes, Interlocks, E-stops) และการควบคุมอันตรายต่อเจ้าหน้าที่และสาธารณชนมีความรัดกุมเพียงใด? | K6: User — Behavior & Workflow Disruption: ระบบสร้างภาระงานเอกสาร ขั้นตอนปฏิบัติงาน หรือบังคับเปลี่ยนพฤติกรรมเจ้าหน้าที่หน้างาน (SOP Disruption) มากน้อยเพียงใด? | L6: Developer — Task Dependency (Critical Path Architecture): สถาปัตยกรรมการพัฒนาฮาร์ดแวร์ ไฟฟ้า และซอฟต์แวร์ มีการเชื่อมต่อแบบขนาน (Parallel Architecture / Modularity) หรือผูกติดกันเป็นเส้นตรงบนเส้นทางวิกฤต (Critical Path)? | M6: Developer — Contribution Dependency (Bureaucratic & Lab Gatekeeping): การเข้าถึงเครื่องมือในห้องปฏิบัติการ การอนุมัติงบประมาณ และกระบวนการทางธุรการ (Lab Access & Purchasing Bureaucracy) มีอุปสรรคขัดขวางความคล่องตัวเพียงใด? | N6: Developer — Task & Skill Compatibility: ความเข้ากันได้ระหว่างทักษะเดิมของทีมกับเทคโนโลยีสแตกของระบบ (Task & Skill Compatibility: 'Water and Oil' vs. 'Oil and Engine') อยู่ในระดับใด? | O6: Production Time (Engineering Design Maturity by Milestone): ความพร้อมของแบบวิศวกรรม (3D CAD, Schematics, PCB Gerbers, Firmware Architecture, BOM) อยู่ในระดับความสมบูรณ์ใดเทียบกับหมุดหมายการผลิตจริง? | P6: Shipping (Component Procurement Lead Time): ระยะเวลาในการจัดหาและขนส่งชิ้นส่วน อุปกรณ์ และเซนเซอร์ (Procurement Lead Time) อยู่ในกรอบเวลาที่ปลอดภัยต่อกำหนดส่งมอบงานหรือไม่? | Q6: ประเมินคำถามทั้งสิ้น 15 ข้อ
