Workbook

Sheet เปรียบเทียบทุก Solution
A1: ตารางเปรียบเทียบความเป็นไปได้ของทุกข้อเสนอ (Multi-Solution Feasibility Summary)
A2: วิเคราะห์เปรียบเทียบเชิงระบบ (Systems-Thinking) ตามเกณฑ์ TELOS+S (เต็ม 100) และเมทริกซ์ศักยภาพด้านวิศวกรรมหุ่นยนต์ (เต็ม 10 แยกอิสระ)
A4: ลำดับ | B4: รหัสข้อเสนอ (Solution ID) | C4: ชื่อแนวทางแก้ปัญหา (Title / Concept) | D4: คะแนนรวม (เต็ม 100) | E4: T: เทคนิค (/20) | F4: E: เศรษฐศาสตร์ (/20) | G4: L: กฎหมาย (/15) | H4: O: ปฏิบัติการ (/20) | I4: S: แผนงาน (/15) | J4: +S: ยั่งยืน (/10) | K4: ผลการประเมิน (Verdict) | L4: จุดแข็งสำคัญ (Key Strengths) | M4: จุดติดขัดวิกฤต (Critical Bottlenecks) | N4: คำแนะนำเชิงระบบ (Strategic Advice) | O4: Robotics Potential (/10) | P4: เหตุผลความเข้ากันได้ด้านหุ่นยนต์ (Robotics Engineering Rationale)
A5: 1 | B5: Solution-1 | C5: Recession Rate (dh/dt) Predictive Filtering for QRT Dispatch (Ann Arbor Case) | D5: ='Solution-1'!T9 | E5: ='Solution-1'!D17 | F5: ='Solution-1'!D18 | G5: ='Solution-1'!D19 | H5: ='Solution-1'!D20 | I5: ='Solution-1'!D21 | J5: ='Solution-1'!D22 | K5: ='Solution-1'!T12 | L5: ใช้สมการอนุพันธ์ชลศาสตร์คำนวณอัตราน้ำลด dh/dt เทียบกับเวลาเดินทาง 20-30 นาที ตัด Empty Cases ได้ 40-50% สมาชิกทั้ง 4 คนแบ่งงานชัดเจน ต้นทุนต่ำ (< 3,500 บ.) | M5: ต้องมีหลักฐาน Digital Evidence Card ประกอบการปิดงานบน Traffy Fondue และต้องล็อกสเปกฮาร์ดแวร์ก่อนสัปดาห์ที่ 9 | N5: พัฒนาโมดูลคำนวณ dh/dt บน Python/ROS 2 ร่วมกับ Screw Terminal Shield และออกรายงานกราฟดิจิทัลอัตโนมัติ | O5: 7.5 | P5: มีความเข้ากันได้สูงในแกนคณิตศาสตร์วิศวกรรม ทฤษฎีระบบควบคุม (Control Theory) และการประมวลผลสัญญาณ (Signal Processing & State Estimation) ของ JK แต่คะแนนอยู่ที่ 7.5 เนื่องจากขาด Physical Actuation และกลไกการเคลื่อนที่
A6: 2 | B6: Solution-2 | C6: 2-Factor Authentication Dispatch Filtering Layer (PUB Singapore CWOS) | D6: ='Solution-2'!T9 | E6: ='Solution-2'!D17 | F6: ='Solution-2'!D18 | G6: ='Solution-2'!D19 | H6: ='Solution-2'!D20 | I6: ='Solution-2'!D21 | J6: ='Solution-2'!D22 | K6: ='Solution-2'!T12 | L6: ใช้การตรวจสอบยืนยันร่วม 2 ปัจจัย (รายงานประชาชน + โทรมาตรระดับน้ำ/เรดาร์ฝน) ปลอดปัญหา PDPA 100% ต้นทุนต่ำ ตัด Empty Cases ได้มากกว่า 40-50% | M6: ขึ้นอยู่กับความหนาแน่นของจุดติดตั้งเซนเซอร์โทรมาตร และต้องมีระบบ Digital Evidence Card สำหรับระบบราชการ | N6: เชื่อมต่อ API เข้ากับ Traffy Fondue และจัดทำเทมเพลต Digital Evidence Card อัตโนมัติ พร้อมทั้งใช้เซนเซอร์ระดับน้ำ COTS แบบ Non-contact | O6: 5 | P6: สอดคล้องกับแกน Data Pipeline & Ingestion API ของ Kin แต่แก่นแท้เป็นงาน Software Engineering / IT Management ขาดองค์ประกอบหลักด้าน Mechatronics, Embedded Control และ Actuation ของวิศวกรรมหุ่นยนต์
A7: 3 | B7: Solution-3 | C7: Acoustic Sewer Measurement & Pre-Screening for Scheduled Maintenance (Case 3 UK/USA) | D7: ='Solution-3'!T9 | E7: ='Solution-3'!D17 | F7: ='Solution-3'!D18 | G7: ='Solution-3'!D19 | H7: ='Solution-3'!D20 | I7: ='Solution-3'!D21 | J7: ='Solution-3'!D22 | K7: ='Solution-3'!T12 | L7: เปลี่ยนจากการลอกท่อแบบสุ่มรอบปฏิทินมาเป็น Condition-Based Maintenance ด้วยการตรวจคัดกรองความสะอาดท่อ 3 ระดับ (Tier 1: Action, Tier 2: Queue, Tier 3: Clean) รวดเร็ว 3-5 นาทีต่อช่วงท่อ ประหยัดงบประมาณและทรัพยากรรถดูดโคลนได้มหาศาล | M7: ต้องหลีกเลี่ยงการจัดซื้ออุปกรณ์นำเข้าราคาแพง (SL-RAT) โดยหันมาสร้างต้นแบบจาก Transducer COTS และต้องประสานงานกับทีมงานเขตเพื่อความปลอดภัยบนผิวจราจร | N7: พัฒนาชุดก้านหย่อน Telescopic ร่วมกับ Transducer ความถี่กวาดและบอร์ดประมวลผล Time-of-Flight / Attenuation ทดสอบในท่อจำลองก่อนลงพื้นที่ร่วมกับฝ่ายระบายน้ำของเขตในฤดูแล้ง | O7: 8.5 | P7: เข้ากันได้สูงมากกับองค์ความรู้ Mechatronics, Acoustic Signal Processing, Instrument Design และ Field Robotics Payload ที่สามารถนำไปประกอบกับหุ่นยนต์มุดท่อระบายน้ำได้โดยตรง ตอบโจทย์วิศวกรรมหุ่นยนต์ภาคสนามอย่างยิ่ง
A8: 4 | B8: Solution-4 | C8: Smart Drainage Pipe Telemetry & Prioritized Flushing DSS (Jakarta Case Adaptation) | D8: ='Solution-4'!T9 | E8: ='Solution-4'!D17 | F8: ='Solution-4'!D18 | G8: ='Solution-4'!D19 | H8: ='Solution-4'!D20 | I8: ='Solution-4'!D21 | J8: ='Solution-4'!D22 | K8: ='Solution-4'!T12 | L8: มอนิเตอร์ระดับน้ำและอัตราการไหลในท่อแบบต่อเนื่องทั้งเมือง ชี้เป้าจุดวิกฤตระบายช้า และจัดลำดับการส่งรถดูดเลนได้อย่างมีข้อมูลเชิงประจักษ์รองรับ (Data-Driven Flushing DSS) | M8: สภาพแวดล้อมในท่อมีตะกอน คราบไขมัน และก๊าซกัดกร่อน H2S สูง และการติดตั้งต้องคำนึงถึงความปลอดภัยของเจ้าหน้าที่ | N8: ใช้เซนเซอร์วัดระดับน้ำและอัตราการไหลแบบ Non-contact ติดตั้งใต้ฝาท่อพักน้ำ พร้อมสายสลิงนิรภัยยึดสองชั้น และทดสอบในจุดเสี่ยงนำร่อง | O8: 6.5 | P8: สอดคล้องกับแกน Embedded Systems, Power Electronics & Custom PCB, และ Industrial Sensor Bus แต่ขาด Physical Actuation หรือแขนกล/กลไกการทำความสะอาดอัตโนมัติ (เน้นการเฝ้าระวังมากกว่าการกระทำ)
A9: 5 | B9: Solution-5 | C9: UHI Latent Heat Precision Road Cooling & Microclimate Water Dosing | D9: ='Solution-5'!T9 | E9: ='Solution-5'!D17 | F9: ='Solution-5'!D18 | G9: ='Solution-5'!D19 | H9: ='Solution-5'!D20 | I9: ='Solution-5'!D21 | J9: ='Solution-5'!D22 | K9: ='Solution-5'!T12 | L9: ใช้ประโยชน์จากความร้อนแฝงของการระเหย พ่นน้ำฟิล์มบางมาก (0.2-0.4 mm) ลด Peak Heat Flux ได้ 100-150 W/m² ไม่ลื่น ไม่เกิด Sauna Effect ประหยัดน้ำกว่ารถฉีดน้ำ 40-50% | M9: ลมกระโชกแรงอาจพัดละอองน้ำ และต้องมีระบบกรองน้ำป้องกันหัวพ่นหมอกอุดตัน รวมถึงการสร้างความเข้าใจแก่ประชาชนผู้ใช้ทาง | N9: ติดตั้งหัวฉีดละอองระดับต่ำขอบทางเท้า พร้อม Sauna Effect Guard และวาล์ว Micro-pulsing อัตโนมัติตามเซนเซอร์ IR | O9: 9 | P9: เป็นระบบ Cyber-Physical Mechatronic System สมบูรณ์แบบที่ผสานครบทั้ง 4 เสาหลักของหุ่นยนต์: Perception (Thermal Sensing), Control (Dynamic Closed-loop Model), Actuation (PWM Fluidic Valves & Pumps) และ Mechatronics Integration สอดคล้องกับวิชาการด้านหุ่นยนต์ของ FIBO อย่างเด่นชัดที่สุด

Sheet Solution-1
A1: เมทริกซ์ประเมินความเป็นไปได้เชิงระบบ TELOS+S: Recession Rate (dh/dt) Predictive Filtering for QRT Dispatch (Ann Arbor Case)
A2: ระบบคะแนนจำนวนเต็มเด็ดขาด: 1, 2, 3, 4, 5 เท่านั้น (ไม่มีจุดทศนิยม / ไม่มี 0.5) | โครงสร้างแบบ Transposed แนวนอน
A4: รหัสคำถาม (Question Code) | B4: T-01 | C4: T-02 | D4: T-03 | E4: T-04 | F4: E-01 | G4: E-02 | H4: E-03 | I4: L-01 | J4: L-02 | K4: O-01 | L4: O-02 | M4: O-03 | N4: S-01 | O4: S-02 | P4: S-03 | Q4: SDG-01 | R4: SDG-02 | S4: SDG-03 | T4: สรุปภาพรวม (SUMMARY)
A5: มิติการประเมิน (TELOS+S Pillar) | B5: ด้านเทคนิค (Technical 2.2) | C5: ด้านเทคนิค (Technical 2.2) | D5: ด้านเทคนิค (Technical 2.2) | E5: ด้านเทคนิค (Technical 2.2) | F5: ด้านเศรษฐศาสตร์ (Economic 2.3) | G5: ด้านเศรษฐศาสตร์ (Economic 2.3) | H5: ด้านเศรษฐศาสตร์ (Economic 2.3) | I5: ด้านกฎหมายและหน่วยงาน (Legal 2.4) | J5: ด้านกฎหมายและหน่วยงาน (Legal 2.4) | K5: ด้านการปฏิบัติการและผู้ใช้ (Operational 2.5) | L5: ด้านการปฏิบัติการและผู้ใช้ (Operational 2.5) | M5: ด้านการปฏิบัติการและผู้ใช้ (Operational 2.5) | N5: ด้านเวลาและแผนงาน (Schedule 2.6) | O5: ด้านเวลาและแผนงาน (Schedule 2.6) | P5: ด้านเวลาและแผนงาน (Schedule 2.6) | Q5: ด้านความยั่งยืน (SDGs 2.7) | R5: ด้านความยั่งยืน (SDGs 2.7) | S5: ด้านความยั่งยืน (SDGs 2.7) | T5: ผลรวมทุกมิติ (All Pillars)
A6: คำถามทดสอบความเสี่ยงจริง (Stress-Test Question) | B6: เมื่อพิจารณาความพร้อมด้านเครื่องจักรกลและทักษะของทีมงาน (Fifa เชี่ยวชาญการออกแบบส่งกำลังและประกอบกลไก, Due เชี่ยวชาญ 3D CAD) โครงสร้างทางกายภาพภายนอกของระบบสามารถออกแบบ ผลิต และประกอบขึ้นได้จริง โดยทนทานต่อสภาวะแวดล้อมหน้างานของ กทม. ได้อย่างสมบูรณ์หรือไม่? | C6: เมื่อพิจารณาศักยภาพของทีมงาน (Due มีทักษะ Custom PCB และระบบฝังตัว, JK เข้าใจฟิสิกส์ของเซนเซอร์, Fifa เชี่ยวชาญการปรับเทียบเซนเซอร์) สถาปัตยกรรมวงจรอิเล็กทรอนิกส์ การจ่ายพลังงาน และการเชื่อมต่อเซนเซอร์/ตัวกระตุ้น สามารถทำงานได้อย่างมีเสถียรภาพโดยปราศจากความร้อนสะสมหรือสัญญาณรบกวนหรือไม่? | D6: เมื่อพิจารณาทักษะด้านอัลกอริทึมของทีมงาน (JK เชี่ยวชาญคณิตศาสตร์วิศวกรรม/สมการอนุพันธ์/ROS 2, Kin เชี่ยวชาญการประมวลผลข้อมูล Time-series และ AI Pipeline) โมเดลหรือตรรกะการประมวลผลของระบบสามารถให้ผลลัพธ์ที่ถูกต้องแม่นยำได้ทันภายในกรอบเวลาตัดสินใจเชิงปฏิบัติการของระบบหรือไม่? | E6: ระบบมีความสามารถในการรักษาระดับความถูกต้องของสัญญาณตรวจวัด (Signal Integrity) และทนทานต่อสิ่งรบกวนในสภาพแวดล้อมจริงของ กทม. (เช่น คราบไขมัน ก๊าซกัดกร่อน ฝุ่นละออง คลื่นผิวน้ำ หรือลมกระโชก) โดยไม่เกิดความล้มเหลวหรือส่งข้อมูลหลอกหรือไม่? | F6: งบประมาณจัดซื้อวัสดุ อุปกรณ์เซนเซอร์ ตัวกระตุ้น และบอร์ดประมวลผล (BOM) สำหรับสร้างต้นแบบที่ทำงานได้จริง สามารถควบคุมให้อยู่ภายใต้เพดานงบประมาณโครงงานนักศึกษา (< 5,000 บาท) ได้อย่างแท้จริงหรือไม่? | G6: โครงการมีการจัดสรรงบประมาณสำรองสำหรับชิ้นส่วนอะไหล่ทดแทน (Scrap Allowance) อย่างน้อย 80-100% สำหรับเซนเซอร์และบอร์ดอิเล็กทรอนิกส์หลัก กรณีเกิดความเสียหายจากการทดสอบหน้างานจริงหรือไม่? | H6: เมื่อระบบถูกนำไปใช้งานจริง สามารถลดการสิ้นเปลืองทรัพยากรของภาครัฐ/เทศบาล (ค่าน้ำมันรถปฏิบัติการ ค่าน้ำ ค่าแรงลอกท่อ หรือค่าสึกหรอของยานพาหนะ) ได้คุ้มค่าเมื่อเทียบกับค่าใช้จ่ายในการบำรุงรักษาระบบ (OpEx) หรือไม่? | I6: การติดตั้งและปฏิบัติการของระบบ สอดคล้องกับกฎหมายคุ้มครองข้อมูลส่วนบุคคล (PDPA), พ.ร.บ. จราจรทางบก, และระเบียบความปลอดภัยในที่สาธารณะ โดยไม่ก่อให้เกิดความเสี่ยงต่อการถูกดำเนินคดีหรืออุบัติเหตุบนท้องถนนหรือไม่? | J6: เมื่อพิจารณาความพร้อมด้านการสื่อสารของทีมงาน (Due มีทักษะการถ่ายทอดเทคนิค, Fifa เชี่ยวชาญการคุยโจทย์เชิงพาณิชย์, JK ถนัดการคุยต่อหน้า) อุปกรณ์ไร้สายผ่านการรับรองจาก กสทช. และทีมงานมีความพร้อมในการเข้าพบประสานงานกับหน่วยงานรัฐ (สำนักงานเขต/กทม.) เพื่อขอพื้นที่ทดสอบจริงหรือไม่? | K6: ระบบสามารถสร้างหลักฐานเชิงประจักษ์ดิจิทัล (Digital Evidence / Audit Trail) เช่น กราฟแนวโน้ม, พิกัด GPS, การบันทึกเวลา และรายงานสรุปสถานะ เพื่อสนับสนุนการปิดงานหรือการตัดสินใจของหน่วยงานโดยไม่สร้างภาระงานซ้ำซ้อนหรือไม่? | L6: ความซับซ้อนในการติดตั้ง การบำรุงรักษา และการใช้งานโดยเจ้าหน้าที่หน้างาน อยู่ในระดับที่เหมาะสม ไม่สร้างภาระงานเพิ่มเติม และสอดคล้องกับพฤติกรรมการทำงานจริงของบุคลากรภาคสนามหรือไม่? | M6: ขั้นตอนการติดตั้ง การทดสอบ และการเก็บข้อมูลจริงหน้างาน สามารถกระทำได้อย่างปลอดภัย โดยไม่ก่อให้เกิดความเสี่ยงต่อชีวิตของผู้พัฒนา เจ้าหน้าที่ หรือประชาชนผู้สัญจรไปมาหรือไม่? | N6: เมื่อพิจารณาการกระจายงานในทีม 4 คน (Due, Fifa, Kin, JK) แผนงานและสถาปัตยกรรมระบบมีเวลาสำรอง (Buffer Time 3-4 สัปดาห์) เพียงพอที่จะดูดซับช่วงสอบกลางภาค/ปลายภาคของมหาวิทยาลัย โดยโครงการไม่ล่าช้ากว่ากำหนดหรือไม่? | O6: ความก้าวหน้าทางวิศวกรรมของทีม สามารถบรรลุเกณฑ์การทำงานร่วมกันได้จริงของฮาร์ดแวร์และซอฟต์แวร์ (Working Prototype) ภายในสัปดาห์ที่ 9 ก่อนการประเมินความก้าวหน้าหลักของภาคการศึกษาหรือไม่? | P6: ระยะเวลาในการสั่งซื้อและขนส่งชิ้นส่วน อุปกรณ์เซนเซอร์ และบอร์ดอิเล็กทรอนิกส์ทั้งหมด สอดคล้องกับกรอบเวลาของภาคการศึกษา โดยสามารถจัดส่งถึงมือได้ภายใน 14 วันหรือไม่? | Q6: ระบบส่งเสริมการลดความสูญเสียต่อชีวิต ทรัพย์สิน และโครงสร้างพื้นฐานของเมืองจากภัยพิบัติน้ำท่วมขังหรือความร้อนรุนแรง สอดคล้องกับเป้าหมาย SDG 11.5 และ SDG 13.1 อย่างเป็นรูปธรรมหรือไม่? | R6: อุปกรณ์และสาร/น้ำที่นำมาใช้ในระบบ ไม่ก่อให้เกิดมลพิษทางน้ำ ไม่เสี่ยงต่อการหลุดลอยกลายเป็นขยะอุดตันท่อระบายน้ำ และใช้วัสดุที่ทนทาน ปลอดสารอันตราย สอดคล้องกับ SDG 6.3 และ SDG 12.4 หรือไม่? | S6: ตรรกะการตัดสินใจ การคัดกรอง หรือการจัดสรรทรัพยากรของระบบ มีความโปร่งใส ตรวจสอบย้อนกลับได้ และให้บริการต่อประชาชนทุกกลุ่มอย่างเป็นธรรมโดยไม่เลือกปฏิบัติ สอดคล้องกับ SDG 10.2 และ SDG 16.6 หรือไม่? | T6: ประเมินคำถามทั้งสิ้น 18 ข้อ
A7: เหตุผลในการถาม & โหมดความล้มเหลวที่เฝ้าระวัง (Rationale) | B7: หากระบบบังคับต้องใช้เครื่องจักรกลึง/หล่อโลหะขนาดใหญ่ในโรงงานที่ทีมไม่มีสิทธิ์เข้าถึง โครงงานจะล้มเหลวตั้งแต่สัปดาห์แรก นอกจากนี้ อุปกรณ์ที่ติดตั้งกลางแจ้งหรือในระบบท่อต้องทนทานต่อแรงลมมรสุม ละอองน้ำ และแรงสั่นสะเทือน | C7: วงจรไฟฟ้าที่ขาดการป้องกันจะเสี่ยงต่อการลัดวงจรเมื่อเจอน้ำและความชื้น นอกจากนี้ อุปกรณ์ที่ต้องประมวลผลต่อเนื่องหรือจ่ายกระแสสูงกลางแจ้ง เสี่ยงต่อความร้อนสะสมจนชิปค้างหรือรีบูตตัวเองขณะปฏิบัติการ | D7: หัวใจของระบบอัตโนมัติคือการให้ผลการตัดสินใจที่ทันเวลาและถูกต้อง หากโมเดลซับซ้อนเกินไปจนรันไม่ทัน หรือขาดข้อมูลฝึกฝนจนผลลัพธ์เพี้ยน ระบบจะไม่สามารถสนับสนุนการทำงานจริงของเจ้าหน้าที่ได้ | E7: สภาพแวดล้อมจริงในเขตเมืองเต็มไปด้วยสิ่งรบกวน หากไม่มีเกราะกำบังทางกายภาพและตัวกรองสัญญาณเชิงสถิติ ข้อมูลจะกระโดดไปมา นำไปสู่การตัดสินใจที่ผิดพลาดและสร้างความเสียหายต่อกระบวนการทำงาน | F7: โครงงานนักศึกษาไม่มีงบประมาณสนับสนุนขนาดใหญ่จากภายนอก หากสถาปัตยกรรมบังคับใช้อุปกรณ์เกรดอุตสาหกรรมนำเข้าราคาหลายหมื่นบาท จะทำให้โครงงานหยุดชะงักจากปัญหางบประมาณบานปลาย | G7: การทดสอบหน้างานมีความเสี่ยงสูงต่อไฟกระชาก น้ำซึม หรืออุปกรณ์ตกหล่นเสียหาย หากไม่มีงบสำรองอะไหล่ทดแทนอย่างเพียงพอ ความเสียหายเพียงครั้งเดียวจะทำให้การทดลองหยุดชะงักอย่างยาวนาน | H7: โครงการด้านวิศวกรรมเมืองต้องพิสูจน์ความคุ้มค่าเชิงผลประโยชน์ต่อสาธารณะ หากค่าดูแลระบบแพงกว่าทรัพยากรที่ประหยัดได้ โครงการจะไม่สามารถนำไปขยายผลหรือใช้งานจริงในระยะยาวได้ | I7: การติดตั้งอุปกรณ์หรือปฏิบัติการบนถนนสาธารณะมักเสี่ยงต่อการละเมิดกฎหมาย การบันทึกภาพบุคคลผิด PDPA หรือการเปิดฝาท่อ/วางอุปกรณ์กีดขวางทางสัญจรโดยไม่ได้รับอนุญาต อาจนำไปสู่อุบัติเหตุและคดีความทันที | J7: เทคโนโลยีที่มีการเชื่อมต่อไร้สายต้องใช้คลื่นความถี่ที่ได้รับอนุญาต และการนำอุปกรณ์ไปทดสอบกับโครงสร้างพื้นฐานของเมืองจำเป็นต้องอาศัยการเข้าพบ ชี้แจง และขออนุญาตเป็นลายลักษณ์อักษรจากหน่วยงานผู้รับผิดชอบ | K7: ระเบียบปฏิบัติราชการและระบบเมืองจำเป็นต้องมีหลักฐานยืนยันผลการทำงาน หากระบบไม่สามารถสร้างหลักฐานที่น่าเชื่อถือได้ เจ้าหน้าที่จะยังคงถูกบังคับให้ต้องลงพื้นที่ไปตรวจสอบด้วยตนเองเหมือนเดิม | L7: ระบบวิศวกรรมที่ยอดเยี่ยมมักตายในหน้างานเพราะผู้ใช้ไม่ยอมรับ หากระบบมีขั้นตอนที่ยุ่งยาก ซับซ้อน หรือต้องใช้เวลาปรับเทียบนานเกินไป เจ้าหน้าที่จะปฏิเสธและหันกลับไปใช้วิธีเดิม | M7: ความปลอดภัยต่อชีวิตเป็นเกณฑ์ตัดสินเด็ดขาด (Fatal Gate) งานที่มีความเสี่ยงจากการตกท่อระบายน้ำลึก สัมผัสก๊าซพิษในที่อับอากาศ หรือถูกกระแสน้ำเชี่ยวพัดพา หากไม่มีมาตรการความปลอดภัยที่รัดกุม จะต้องถูกระงับทันที | N7: ปฏิทินการศึกษาของมหาวิทยาลัยมีช่วงสอบกลางภาคและปลายภาครวมกัน 4 สัปดาห์ หากแผนงานเป็นแบบ Linear Dependency และไม่มีการแบ่งงานขนาน โครงการจะล้มเหลวด้านเวลาทันที | O7: เกณฑ์ความก้าวหน้าสัปดาห์ที่ 9 เป็น Milestone สำคัญในการพิสูจน์ว่าแนวคิดทางวิศวกรรมสามารถทำงานร่วมกันได้จริง (Proof of Concept) หากไม่มีต้นแบบทำงานได้ จะไม่ผ่านเกณฑ์การประเมินวิชา | P7: การรอคอยชิ้นส่วนเป็นปัจจัยเสี่ยงอันดับต้น ๆ ของโครงการ หากออกแบบโดยใช้ชิ้นส่วนที่ต้องรอส่งจากต่างประเทศเกิน 4-6 สัปดาห์ จะทำให้ทีมงานไม่มีเวลาประกอบและทดสอบระบบ | Q7: นวัตกรรมเมืองต้องตอบสนองต่อเป้าหมายการพัฒนาที่ยั่งยืน ช่วยให้เมืองมีความยืดหยุ่น (Resilient Cities) และสามารถปรับตัวต่อผลกระทบของการเปลี่ยนแปลงสภาพภูมิอากาศได้อย่างมีประสิทธิภาพ | R7: ระบบที่นำไปติดตั้งในโครงสร้างพื้นฐานเมืองต้องไม่กลายเป็นผู้สร้างมลพิษรายใหม่ อุปกรณ์ต้องไม่หลุดลอยไปอุดตันท่อระบายน้ำ และต้องใช้วัสดุที่เป็นมิตรต่อสิ่งแวดล้อม | S7: ระบบอัตโนมัติหรือระบบคัดกรองของรัฐต้องไม่กลายเป็นกล่องดำ (Black Box) ที่เลือกปฏิบัติต่อชุมชนใดชุมชนหนึ่ง ต้องมีเกณฑ์การตัดสินใจที่โปร่งใส ตรวจสอบย้อนหลังได้ เพื่อสร้างความเชื่อมั่น | T7: สังเคราะห์จาก AI Agents Group 2
A8: เกณฑ์การให้คะแนน (Scoring Rubric Definition: ระดับ 1, 2, 3, 4, 5 ครบทุกระดับ) | B8: 1: บังคับต้องใช้เครื่องจักรกลึง/หล่อโลหะขนาดใหญ่ในโรงงานอุตสาหกรรมที่ทีมไม่มีสิทธิ์เข้าถึง (Fatal Flaw) 2: ต้องจ้างโรงกลึงภายนอกผลิตเกือบทั้งหมด งบประมาณไม่พอและเสี่ยงต่อความล่าช้า 3: ใช้โครงสร้าง 3D Print ร่วมกับการประกอบมือ ความแข็งแรงปานกลาง ต้องมีตัวกำบังเพิ่มเติม 4: ผสมผสานชิ้นส่วนสำเร็จรูป COTS ร่วมกับชิ้นงานกลไกที่ Fifa และ Due ออกแบบและประกอบเองได้ มีการทดสอบความแข็งแรง 5: ใช้โครงสร้างและกล่องสำเร็จรูปมาตรฐานอุตสาหกรรม (IP67/IP68) ร่วมกับระบบยึดจับมาตรฐาน (COTS Clamps/Mounts) แข็งแรง ทนทาน ไม่ต้องดัดแปลงซับซ้อน | C8: 1: ต้องพึ่งพาวงจรความถี่สูงหรือชิปเฉพาะทางที่ทีมไม่มีทักษะและเสี่ยงต่อการลัดวงจร/ความร้อนพังทลาย (Fatal Flaw) 2: อุปกรณ์ประมวลผลเกิดความร้อนสะสมสูงจัด หรือสัญญาณแอนะล็อกถูกคลื่นรบกวนจนอ่านค่าผิดพลาดบ่อย 3: ใช้วงจรประกอบมือบน Perfboard หรือสายไฟต่อแบบหลวม เสี่ยงต่อการหลุดเมื่อมีแรงสั่นสะเทือน 4: ใช้บอร์ดไมโครคอนโทรลเลอร์สำเร็จรูปเชื่อมต่อผ่าน Screw Terminal Shield หรือ Custom PCB ขนาดเล็กของ Due ที่มีระบบป้องกันไฟกระชาก 5: สถาปัตยกรรมวงจรมาตรฐานอุตสาหกรรม มีวงจรแยกสัญญาณรบกวน (Optocoupler/Filter) การจัดการพลังงานแบบ Low-Power โหมด และระบายความร้อนได้ดีเยี่ยม | D8: 1: ต้องพึ่งพาโมเดล AI มหาศาลที่ไม่มีชุดข้อมูล หรืออัลกอริทึมใช้เวลาประมวลผลนานเกินกว่ากรอบเวลาตัดสินใจหน้างานจนระบบไร้ประโยชน์ (Fatal Flaw) 2: อัลกอริทึมมีความซับซ้อนสูงแต่ขาดการปรับเทียบ (Calibration) ทำให้ผลการตัดสินใจคลาดเคลื่อนบ่อย 3: ใช้เกณฑ์แบบคงที่ (Static Threshold) ซึ่งปรับตัวตามสภาวะพลวัตของสภาพแวดล้อมจริงได้จำกัด 4: ใช้อัลกอริทึมประมวลผลสัญญาณหรือโมเดลน้ำหนักเบาที่ Kin และ JK พัฒนาขึ้น ประมวลผลเสร็จในระดับวินาที มีความแม่นยำสูง 5: ใช้สมการฟิสิกส์/คณิตศาสตร์เชิงประจักษ์ร่วมกับโมเดลการไหลของข้อมูลแบบเรียลไทม์ ประมวลผลเสร็จในระดับมิลลิวินาที พร้อมระบบตรวจสอบความถูกต้องในตัว | E8: 1: ระบบล้มเหลวโดยสิ้นเชิงเมื่อสัมผัสสภาพแวดล้อมจริง (เช่น สิ่งสกปรกบดบังหัววัดจนสัญญาณดับ หรือก๊าซกัดกร่อนเซนเซอร์พังทันที / Fatal Flaw) 2: เกิด False Alarm สูงเมื่อเจอสภาพอากาศแปรปรวน ต้องอาศัยมนุษย์คอยรีเซ็ตและปรับเทียบตลอดเวลา 3: ทนต่อสิ่งรบกวนได้ปานกลาง ต้องมีรอบการทำความสะอาดบ่อยครั้งเพื่อรักษาความแม่นยำ 4: มีการติดตั้งอุปกรณ์ป้องกันเชิงกายภาพ (Housing/Shield) ร่วมกับอัลกอริทึมกรองสัญญาณเชิงสถิติ (Statistical/Median Filter) 5: ออกแบบให้ตรวจวัดแบบไม่สัมผัสสิ่งรบกวนโดยตรง (Non-contact Sensing) พร้อมอัลกอริทึม Adaptive Filtering กรองสัญญาณรบกวนได้อย่างสมบูรณ์ | F8: 1: งบประมาณ BOM เกิน 20,000 บาท (เกินเพดาน 5,000 บาท ถึง 4 เท่าตัว / Fatal Flaw) 2: งบประมาณ BOM อยู่ระหว่าง 10,000 - 20,000 บาท ต้องขอทุนสนับสนุนภายนอก 3: งบประมาณ BOM อยู่ระหว่าง 5,000 - 10,000 บาท เกินงบส่วนตัวเล็กน้อย ต้องตัดทอนฟังก์ชัน 4: งบประมาณ BOM อยู่ระหว่าง 3,500 - 5,000 บาท พอดีกับเพดานงบประมาณของทีม 5: งบประมาณ BOM ต่ำกว่า 3,500 บาท ใช้อุปกรณ์ COTS ราคาประหยัด ควบคุมต้นทุนได้อย่างเด็ดขาด | G8: 1: ไม่มีงบสำรองอะไหล่เลย (0%) หากอุปกรณ์ช็อตหรือเสียหายชิ้นเดียว โครงการจะหยุดชะงักทันที (Fatal Flaw) 2: มีงบสำรองอะไหล่เพียง 10-20% ทดแทนได้เฉพาะอุปกรณ์พื้นฐานชิ้นเล็ก ๆ 3: มีงบสำรองอะไหล่ประมาณ 50% สามารถสำรองเซนเซอร์ได้แต่ไม่มีบอร์ดประมวลผลสำรอง 4: มีงบสำรองอะไหล่ 80-100% สำหรับเซนเซอร์หลักและโมดูลควบคุมสำคัญ 5: มีงบสำรองอะไหล่ 100% ครอบคลุมเซนเซอร์และบอร์ดหลักครบทุกชุด ภายใต้เพดานงบประมาณรวมของทีม | H8: 1: ค่าใช้จ่ายในการดูแลรักษาระบบ (OpEx) สูงกว่ามูลค่าทรัพยากรที่ประหยัดได้ กลายเป็นภาระงบประมาณของเมือง (Fatal Flaw) 2: ประหยัดทรัพยากรได้น้อยมาก ไม่คุ้มทุนภายในระยะเวลา 2 ปี 3: คืนทุนได้ในระยะปานกลาง (1-2 ปี) การประหยัดทรัพยากรขึ้นอยู่กับฤดูกาล 4: ประหยัดทรัพยากร ค่าน้ำมัน และค่าแรงเจ้าหน้าที่ได้อย่างชัดเจน คุ้มทุนภายในรอบการใช้งานปีแรก 5: ลดการสูญเปล่าของทรัพยากรเมืองได้มากกว่า 30-50% ประหยัดงบประมาณภาครัฐได้หลายแสนบาทต่อปี โดยระบบกินไฟต่ำมาก | I8: 1: มีการละเมิดกฎหมายอย่างร้ายแรง (เช่น ละเมิดสิทธิข้อมูลส่วนบุคคล PDPA ร้ายแรง หรือติดตั้งขวางทางจราจรเสี่ยงอุบัติเหตุรุนแรง / Fatal Flaw) 2: สุ่มเสี่ยงต่อการละเมิดกฎหมาย ต้องมีขั้นตอนทางเทคนิคที่ซับซ้อนเพื่อเลี่ยงข้อบังคับและยังไม่มีเอกสารยินยอม 3: ปฏิบัติตามกฎหมายได้บางส่วน แต่ต้องรอการอนุมัติข้อยกเว้นจากหน่วยงานอย่างเป็นทางการ 4: ปฏิบัติตามกฎหมายอย่างถูกต้อง ไม่มีการเก็บข้อมูลส่วนบุคคล และมีมาตรการความปลอดภัยบนผิวทางตามระเบียบ 5: ปลอดจากการละเมิดกฎหมาย 100% ไม่เก็บข้อมูลบุคคล (Zero PII) และติดตั้งในจุดปลอดภัยตามมาตรฐานวิศวกรรมสาธารณะ | J8: 1: อุปกรณ์สื่อสารไม่ผ่าน กสทช. และทีมงานไม่มีความพร้อม/ถูกปฏิเสธการติดต่อจากหน่วยงานรัฐอย่างสิ้นเชิง (Fatal Flaw) 2: โมดูลสื่อสารผ่าน กสทช. แต่ทีมงานขาดทักษะการเจรจากับราชการ ทำให้กระบวนการขออนุญาตล่าช้าเกิน 2 เดือน 3: มีหนังสือรับรองจากคณะวิศวกรรมศาสตร์ อยู่ระหว่างรอการประสานงานพื้นที่กับเจ้าหน้าที่ท้องถิ่น 4: โมดูลสื่อสารผ่าน กสทช. และทีมงานสามารถสื่อสาร ย่อยความซับซ้อน และประสานงานกับเจ้าหน้าที่เขตได้อย่างราบรื่น 5: โมดูลผ่าน กสทช. 100% และมีเครือข่ายความร่วมมือหรือหนังสืออนุญาตให้ทดสอบในพื้นที่จริงจากหน่วยงานผู้ดูแล | K8: 1: ไม่สามารถสร้างหลักฐานใด ๆ ได้ บังคับให้เจ้าหน้าที่ต้องลงพื้นที่ไปตรวจสอบซ้ำซ้อน 100% (Fatal Flaw) 2: แสดงได้เฉพาะตัวเลขดิบที่ยากต่อการแปลผล เจ้าหน้าที่หน้างานไม่สามารถนำไปใช้เป็นหลักฐานปิดงานได้ 3: สร้างรายงานสรุปได้แต่ยังต้องอาศัยการกรอกข้อมูลและรูปถ่ายจากเจ้าหน้าที่มายืนยันเพิ่มเติม 4: สร้างบัตรหลักฐานดิจิทัล (Digital Evidence Card / Report) ที่แสดงผลชัดเจน อ่านเข้าใจง่ายใน 5 วินาที 5: มีระบบบันทึก Audit Trail อัตโนมัติ พร้อมส่งออกรายงานหรือเชื่อมโยง API เข้าสู่ระบบของหน่วยงานได้อย่างสมบูรณ์ | L8: 1: ใช้งานยากมาก ต้องใช้วิศวกรหรือผู้เชี่ยวชาญคอยควบคุมตลอดเวลา ผู้ปฏิบัติงานปฏิเสธการใช้งาน (Fatal Flaw) 2: มีขั้นตอนการปรับเทียบ (Calibration) และบำรุงรักษาที่ยุ่งยากเกิน 30 นาทีต่อครั้ง 3: เจ้าหน้าที่ต้องผ่านการฝึกอบรม 1-2 วัน จึงจะสามารถใช้งานและบำรุงรักษาได้อย่างถูกต้อง 4: ใช้งานง่าย มีคู่มือปฏิบัติงานภาคสนามชัดเจน บำรุงรักษาได้ด้วยเครื่องมือช่างทั่วไป 5: ออกแบบตามหลักสรีรศาสตร์และ UX หน้างาน กดปุ่มเดียวทำงานอัตโนมัติ (Plug-and-Play) เจ้าหน้าที่ใช้งานได้ทันทีโดยไม่ต้องอบรมซับซ้อน | M8: 1: มีความเสี่ยงต่อชีวิตอย่างร้ายแรง (เช่น เสี่ยงตกท่อระบายน้ำลึก, สัมผัสก๊าซพิษสะสมในที่อับอากาศโดยไม่มีอุปกรณ์, หรือถูกกระแสน้ำดูด / Fatal Flaw) 2: สภาพแวดล้อมหน้างานมีความเสี่ยงสูง ต้องใช้อุปกรณ์ป้องกันภัยส่วนบุคคล (PPE) เต็มรูปแบบและต้องมีผู้ควบคุมความปลอดภัยมืออาชีพ 3: มีความปลอดภัยปานกลาง สามารถทดสอบได้เฉพาะจุดที่มีราวกั้นชัดเจนหรือบนทางเท้าที่มีการกั้นเขต 4: มีความปลอดภัยสูง ออกแบบให้ติดตั้งและทดสอบจากบนผิวทางเท้าหรือสะพาน โดยไม่มีการให้คนมุดลงในพื้นที่อับอากาศ 5: ปลอดภัย 100% ออกแบบให้ติดตั้งและทดสอบจากระยะไกล มีระบบตัดการทำงานฉุกเฉิน และปลอดจากจุดเสี่ยงอันตรายต่อชีวิตทุกประการ | N8: 1: แผนงานเป็นเส้นตรงที่พึ่งพากันทั้งหมด (Linear Dependency) หากติดสอบเพียง 1 สัปดาห์ โครงการจะพังทลายทันที (Fatal Flaw) 2: มีเวลาสำรองเพียง 3-5 วัน เสี่ยงต่อการส่งมอบงานล่าช้าอย่างมากเมื่อสมาชิกติดภารกิจการเรียน 3: มีเวลาสำรอง 1-2 สัปดาห์ สามารถเลื่อนงานได้บางส่วนแต่ต้องเร่งงานหนักหลังสอบ 4: มี Buffer Time 3-4 สัปดาห์ชัดเจน และแบ่งโมดูลฮาร์ดแวร์-ซอฟต์แวร์ให้สมาชิก 4 คนทำงานคู่ขนานกันได้ 5: สถาปัตยกรรมระบบเป็นอิสระต่อกันสูง ระบบหลักเสร็จสมบูรณ์ตั้งแต่ก่อนสัปดาห์สอบ มีเวลาทดสอบรวมมากกว่า 4-5 สัปดาห์ | O8: 1: มีความเสี่ยงสูงมากที่จะไม่มีระบบใด ๆ ทำงานได้จริงในสัปดาห์ที่ 9 (Fatal Flaw) 2: ในสัปดาห์ที่ 9 ได้เพียงการทดลองแยกส่วนบนโต๊ะแล็บ ยังไม่สามารถรวมระบบฮาร์ดแวร์และซอฟต์แวร์ได้ 3: ในสัปดาห์ที่ 9 ระบบทำงานร่วมกันได้บนโต๊ะแล็บ แต่อุปกรณ์ยังไม่พร้อมสำหรับการทดสอบในสภาวะจำลอง 4: ภายในสัปดาห์ที่ 9 มีต้นแบบฮาร์ดแวร์และซอฟต์แวร์ที่ผสานการทำงานสมบูรณ์ พร้อมทดสอบในสภาวะจำลองหน้างาน 5: ต้นแบบเสร็จสมบูรณ์ 100% และผ่านการทดสอบทำงานจริงได้เรียบร้อยแล้วตั้งแต่ก่อนสัปดาห์ที่ 9 | P8: 1: ต้องสั่งซื้อชิ้นส่วนพิเศษจากต่างประเทศที่ใช้เวลาส่งเกิน 4-6 สัปดาห์ เสี่ยงต่อการไม่มีอุปกรณ์ทำโครงงาน (Fatal Flaw) 2: มีชิ้นส่วนหลักบางรายการที่ต้องรอของ 3-4 สัปดาห์ ทำให้เริ่มงานฮาร์ดแวร์ได้ช้า 3: ชิ้นส่วนทั้งหมดใช้เวลาจัดส่ง 2-3 สัปดาห์ ต้องสั่งซื้อตั้งแต่วันแรกของโครงการ 4: ชิ้นส่วนเกือบทั้งหมดจัดซื้อได้จากตัวแทนจำหน่ายในประเทศ ได้รับของภายใน 7-10 วัน 5: ชิ้นส่วนทั้งหมด 100% มีจำหน่ายในประเทศและสามารถจัดส่งถึงมือได้ภายใน 2-4 วันทำการ | Q8: 1: โครงการไม่มีส่วนเกี่ยวข้องหรืออาจส่งผลกระทบเชิงลบต่อเป้าหมายความยั่งยืนของเมือง (Fatal Flaw) 2: สนับสนุนความยั่งยืนในทางอ้อมอย่างผิวเผิน แต่ไม่มีตัวชี้วัดผลกระทบที่ชัดเจน 3: ส่งเสริมการลดผลกระทบได้บางส่วน แต่จำกัดขอบเขตอยู่เฉพาะจุดทดลองขนาดเล็ก 4: สอดคล้องกับ SDG 11.5 และ SDG 13.1 ชัดเจน ช่วยลดระยะเวลาและผลกระทบของปัญหาบนถนนสายหลักของเมือง 5: สอดคล้องกับ SDG 11.5 และ SDG 13.1 อย่างเป็นรูปธรรม มีแบบจำลองแสดงการลดความสูญเสียทางเศรษฐกิจและความปลอดภัยของประชาชนในเมืองอย่างยั่งยืน | R8: 1: มีความเสี่ยงสูงที่อุปกรณ์จะหลุดลอยกลายเป็นขยะอุดตันท่อ หรือปล่อยสารเคมี/มลพิษลงสู่แหล่งน้ำสาธารณะ (Fatal Flaw) 2: อุปกรณ์ใช้วัสดุที่ชำรุดง่าย เสี่ยงต่อการตกค้างในสภาพแวดล้อมหากเกิดลมพายุหรือน้ำหลาก 3: ติดตั้งแข็งแรงปานกลาง มีโอกาสหลุดลอยหากเจอสภาวะวิกฤต ต้องมีการตรวจเช็กสม่ำเสมอ 4: ใช้วัสดุที่ไม่เป็นพิษต่อสิ่งแวดล้อม มีโครงสร้างยึดจับที่แน่นหนา ปลอดภัยต่อระบบระบายน้ำ 5: ปลอดภัยต่อระบบนิเวศน้ำ 100% ไม่มีส่วนประกอบที่หลุดลอยเป็นขยะ มีระบบสลิงนิรภัยสองชั้น และส่งเสริมการใช้น้ำอย่างมีประสิทธิภาพสูงสุด | S8: 1: ตรรกะของระบบเป็นกล่องดำ (Black Box) ไม่สามารถอธิบายเหตุผลได้ หรือมีอคติเลือกปฏิบัติตัดความช่วยเหลือชุมชนเปราะบาง (Fatal Flaw) 2: เกณฑ์การตัดสินใจไม่ชัดเจน อาจนำไปสู่ความเหลื่อมล้ำในการให้บริการของภาครัฐโดยไม่ตั้งใจ 3: ตรรกะตรวจสอบได้บางส่วน แต่ยังไม่มีกระบวนการอุทธรณ์หรือทบทวนจากเจ้าหน้าที่ 4: ตรรกะโปร่งใส ตัดสินใจตามเกณฑ์ข้อมูลเชิงประจักษ์อย่างเสมอภาค ให้ความช่วยเหลือตามระดับความจำเป็นจริง 5: โปร่งใส 100% มี Audit Trail บันทึกทุกการตัดสินใจ ตรวจสอบย้อนกลับได้ทุกเคส เสริมสร้างธรรมาภิบาลและความเชื่อมั่นของประชาชนต่อหน่วยงานรัฐ | T8: เกณฑ์รวม: >=80 ผ่านสูง, >=60 มีเงื่อนไข, <60 เสี่ยงสูง | หากมีข้อใดได้ 1 = VETOED ตกเกณฑ์ทันที
A9: คะแนนที่ได้รับ (ASSIGNED SCORE: 1, 2, 3, 4, 5 STRICT INTEGER) | B9: 5 | C9: 4 | D9: 5 | E9: 4 | F9: 5 | G9: 5 | H9: 5 | I9: 5 | J9: 4 | K9: 4 | L9: 4 | M9: 5 | N9: 4 | O9: 4 | P9: 5 | Q9: 5 | R9: 5 | S9: 5 | T9: =IF(T10>0, (T11/T10)*20, 0)
A10: ค่าน้ำหนัก (Weight %) | B10: 0.05 | C10: 0.05 | D10: 0.05 | E10: 0.05 | F10: 0.0667 | G10: 0.0667 | H10: 0.0666 | I10: 0.075 | J10: 0.075 | K10: 0.0667 | L10: 0.0667 | M10: 0.0666 | N10: 0.05 | O10: 0.05 | P10: 0.05 | Q10: 0.0333 | R10: 0.0333 | S10: 0.0334 | T10: =SUM(B10:S10)
A11: คะแนนถ่วงน้ำหนัก (=Score * Weight) | B11: =B9*B10 | C11: =C9*C10 | D11: =D9*D10 | E11: =E9*E10 | F11: =F9*F10 | G11: =G9*G10 | H11: =H9*H10 | I11: =I9*I10 | ... S11: =S9*S10 | T11: =SUM(B11:S11)
A12: คำอธิบาย & หลักฐานอ้างอิงจากไฟล์ Intake (Evidence Citation) | B12: อ้างอิง solution-1.md ข้อ Requirements: ติดตั้งเซนเซอร์วัดระดับน้ำและอัตราการไหล อ้างอิง team-skills/fifa.md และ due.md ที่เชี่ยวชาญการออกแบบ 3D CAD ขายึด และกล่อง COTS IP67 ยึดด้วยแคลมป์รัดท่อ | C12: อ้างอิง team-skills/due.md ที่มีประสบการณ์ Custom PCB และ ESP32 Low-power และ team-skills/jk.md ที่เข้าใจฟิสิกส์เซนเซอร์วัดระดับน้ำ วงจรกินไฟต่ำ ไม่มีปัญหาความร้อนสะสม | D12: อ้างอิง solution-1.md ข้อ Requirements a: คำนวณอัตราน้ำลด dh/dt เทียบกับเวลาเดินทาง 20-30 นาที อ้างอิง team-skills/jk.md เชี่ยวชาญสมการอนุพันธ์ (Differential Equations) และ Python/ROS 2 คำนวณเสร็จในระดับมิลลิวินาที | E12: อ้างอิง solution-1.md ข้อ Constraints a: มีปัญหาคลื่นน้ำและขยะลอย แก้ไขโดยใช้เซนเซอร์แบบไม่สัมผัสน้ำ (Non-contact Ultrasonic/Radar) พร้อมอัลกอริทึม Median Filter กรองสัญญาณหลอก | F12: อ้างอิงประมาณการ BOM ต้นแบบ: ESP32 (180 บ.), เซนเซอร์ Ultrasonic/Radar COTS (350-800 บ.), กล่องกันน้ำ IP67 (150 บ.), แบตเตอรี่ (800 บ.) รวม < 3,500 บาท อยู่ในเพดานงบประมาณ 5,000 บ. | G12: เนื่องจากต้นทุน BOM ต่ำ (~3,000 บ.) สามารถจัดสรรงบสำรองจัดซื้อเซนเซอร์และบอร์ด ESP32 สำรองได้ 100% ภายใต้งบ 5,000 บาท | H12: อ้างอิง solution-1.md ข้อ Leverage Point: ตัดเคสว่างเปล่า (Empty Cases) ได้ 40-50% ประหยัดค่าน้ำมันรถปฏิบัติการ QRT และค่าแรงเจ้าหน้าที่ได้หลายหมื่นบาทต่อฤดูมรสุม คุ้มค่าสูงมาก | I12: ระบบตรวจวัดระดับน้ำ ไม่มีการใช้กล้องบันทึกภาพบุคคล ปลอดจาก พ.ร.บ. PDPA 100% และการติดตั้งยึดกับราวสะพานหรือเสาไฟตามมาตรฐานความปลอดภัย | J12: โมดูล ESP32 และ 4G ผ่าน กสทช. อ้างอิง team-skills/due.md ในการสื่อสารเชิงเทคนิค และ jk.md ในการเข้าพบประสานงานกับฝ่ายระบายน้ำของเขต | K12: อ้างอิง solution-1.md ข้อ Constraints b: ต้องมีหลักฐานส่งคืนประชาชน ระบบสร้าง Digital Evidence Card พร้อมกราฟ dh/dt และเวลาที่น้ำลดสนิทเพื่อใช้ปิดงานบน Traffy Fondue อัตโนมัติ | L12: แดชบอร์ดสรุปสถานะการตัดสินใจ (Self-Clearing vs Critical) ด้วยรหัสสีเข้าใจง่าย เจ้าหน้าที่ศูนย์สั่งการตัดสินใจได้ใน 5 วินาที | M12: ติดตั้งเซนเซอร์จากบนราวสะพานคนข้ามหรือผิวทางเท้า ไม่มีการลงไปในน้ำหรือพื้นที่อับอากาศ ปลอดภัยต่อชีวิตผู้ปฏิบัติงาน 100% | N12: ทีมงาน 4 คนแบ่งงานชัดเจน: Fifa/Due ดูแลฮาร์ดแวร์, JK ดูแลคณิตศาสตร์ dh/dt, Kin ดูแลการทดสอบข้อมูล มีเวลาสำรอง 3-4 สัปดาห์ดูดซับช่วงสอบได้สบาย | O12: สามารถส่งมอบระบบจำลองการคำนวณ dh/dt พร้อมโหนดฮาร์ดแวร์ต้นแบบที่ส่งข้อมูลได้จริงก่อนสัปดาห์ที่ 9 | P12: ชิ้นส่วน COTS ทั้งหมดมีสต็อกพร้อมส่งในประเทศ ได้รับของภายใน 3-5 วันทำการ | Q12: สอดคล้องกับ SDG 11.5 ช่วยให้หน่วย QRT เข้าถึงพื้นที่วิกฤตน้ำท่วมจริงได้เร็วขึ้น ลดความสูญเสียทางเศรษฐกิจและการจราจรของเมือง | R12: อุปกรณ์ยึดแน่นเหนือผิวน้ำ มีสลิงนิรภัยสองชั้น ไม่ตกหล่นเป็นขยะอุดตันท่อระบายน้ำ | S12: เกณฑ์การตัดสินใจอิงตามสมการชลศาสตร์ที่เป็นวิทยาศาสตร์ โปร่งใส ตรวจสอบย้อนหลังได้ทุกเคส ไม่เลือกปฏิบัติ | T12: =IF(MIN(B9:S9)=1, "VETOED / ตกเกณฑ์ข้อบังคับวิกฤต (คะแนนระดับ 1)", IF(T9>=80, "ผ่านเกณฑ์ระดับสูง (HIGHLY VIABLE)", IF(T9>=60, "ผ่านแบบมีเงื่อนไข (CONDITIONALLY VIABLE)", "ความเสี่ยงสูง (HIGH RISK)")))
A13: แผนลดขอบเขตงาน & มาตรการลดความเสี่ยง (De-scoping Action) | B13: ใช้กล่องพักสายไฟมาตรฐาน IP67 พร้อมขายึดแคลมป์รัดท่อ COTS | C13: ใช้ Screw Terminal Expansion Shield ป้องกันไฟกระชาก | D13: ทดสอบสมการ dh/dt ด้วยข้อมูลจำลองน้ำฝนของ กทม. | E13: ใส่ฮูดกำบังเซนเซอร์และใช้ Median Filter กรองคลื่นผิวน้ำ | F13: ควบคุมการจัดซื้อเฉพาะอุปกรณ์ COTS มาตรฐาน | G13: จัดซื้อเซนเซอร์สำรอง 2 ชุดและบอร์ดสำรอง 1 ชุด | H13: คำนวณตัวเลขค่าน้ำมันที่ประหยัดได้ต่อเที่ยวรถ QRT | I13: ติดตั้งบนราวสะพานคนข้าม ปลอดภัย 100% | J13: ยื่นหนังสือรับรองจากมหาวิทยาลัยขออนุญาตติดตั้ง | K13: ส่งออกรายงานผลการลดระดับน้ำเป็นรูปภาพอัตโนมัติ | L13: ออกแบบ UI แดชบอร์ดแบบไฟเขียว/แดง | M13: ติดตั้งจากบนสะพานโดยไม่ต้องลงน้ำ | N13: จำลองข้อมูลระดับน้ำทดสอบระบบช่วงสัปดาห์สอบ | O13: ส่งมอบ Demo Scenario การคำนวณในสัปดาห์ที่ 9 | P13: สั่งซื้อจากร้านค้าอิเล็กทรอนิกส์ในประเทศ | Q13: ประเมินผลการลดเวลาตอบสนองของหน่วย QRT | R13: ใช้สายสลิงสแตนเลสยึดกล่องอุปกรณ์สองชั้น | S13: เปิดเผยตรรกะการคำนวณ dh/dt บนระบบเปิด | T13: ปฏิบัติตามแผนลดขอบเขตงาน (De-scoping Advisory)
A15: ตารางสรุปคะแนนแยกตามมิติ TELOS+S (Pillar Score Breakdown)
A16: มิติการประเมิน (TELOS+S Pillar) | B16: สัดส่วนน้ำหนัก (Weight %) | C16: คะแนนเต็มมิติ (Max Points) | D16: คะแนนที่ได้รับจริง (Earned Points) | E16: คะแนนเฉลี่ย (Score 1-5) | F16: ระดับความพร้อม (Readiness Level)
A17: T : ด้านเทคโนโลยีและวิศวกรรม (Technical) | B17: 0.2 | C17: 20 | D17: =SUM(B11:E11)*20 | E17: =IF(C17>0, (D17/C17)*5, 0) | F17: =IF(D17>=16.0, "พร้อมระดับสูง (High)", IF(D17>=12.0, "ปานกลาง (Medium)", "เสี่ยงวิกฤต (Critical)"))
A18: E : ด้านเศรษฐศาสตร์และความคุ้มค่า (Economic) | B18: 0.2 | C18: 20 | D18: =SUM(F11:H11)*20 | E18: =IF(C18>0, (D18/C18)*5, 0) | F18: =IF(D18>=16.0, "พร้อมระดับสูง (High)", IF(D18>=12.0, "ปานกลาง (Medium)", "เสี่ยงวิกฤต (Critical)"))
A19: L : ด้านกฎหมาย ระเบียบ และภาคประชาชน (Legal & Outreach) | B19: 0.15 | C19: 15 | D19: =SUM(I11:J11)*20 | E19: =IF(C19>0, (D19/C19)*5, 0) | F19: =IF(D19>=12.0, "พร้อมระดับสูง (High)", IF(D19>=9.0, "ปานกลาง (Medium)", "เสี่ยงวิกฤต (Critical)"))
A20: O : ด้านการปฏิบัติการและหน้างาน (Operational) | B20: 0.2 | C20: 20 | D20: =SUM(K11:M11)*20 | E20: =IF(C20>0, (D20/C20)*5, 0) | F20: =IF(D20>=16.0, "พร้อมระดับสูง (High)", IF(D20>=12.0, "ปานกลาง (Medium)", "เสี่ยงวิกฤต (Critical)"))
A21: S : ด้านแผนงานและเวลาส่งมอบ (Schedule) | B21: 0.15 | C21: 15 | D21: =SUM(N11:P11)*20 | E21: =IF(C21>0, (D21/C21)*5, 0) | F21: =IF(D21>=12.0, "พร้อมระดับสูง (High)", IF(D21>=9.0, "ปานกลาง (Medium)", "เสี่ยงวิกฤต (Critical)"))
A22: +S : ด้านความยั่งยืนและสิ่งแวดล้อม (Sustainability / SDG) | B22: 0.1 | C22: 10 | D22: =SUM(Q11:S11)*20 | E22: =IF(C22>0, (D22/C22)*5, 0) | F22: =IF(D22>=8.0, "พร้อมระดับสูง (High)", IF(D22>=6.0, "ปานกลาง (Medium)", "เสี่ยงวิกฤต (Critical)"))
A23: คะแนนรวมทุกมิติ (Total Feasibility Score) | B23: =SUM(B17:B22) | C23: =SUM(C17:C22) | D23: =SUM(D17:D22) | E23: =IF(C23>0, (D23/C23)*5, 0) | F23: =IF(D23>=80, "ผ่านเกณฑ์ระดับสูง (HIGHLY VIABLE)", IF(D23>=60, "ผ่านแบบมีเงื่อนไข (CONDITIONALLY VIABLE)", "ความเสี่ยงสูง (HIGH RISK)"))
A25: เมทริกซ์ประเมินความเข้ากันได้กับองค์ความรู้ด้านวิศวกรรมหุ่นยนต์ (Robotics Knowledge Compatibility)
A26: * หมายเหตุ: การประเมินส่วนนี้วัดศักยภาพในการประยุกต์ใช้องค์ความรู้ด้านวิศวกรรมหุ่นยนต์ (Perception, Control, Actuation, Mechatronics) เต็ม 10 คะแนน | เป็นเอกเทศ ไม่นับรวมในคะแนน TELOS+S 100 คะแนน
A27: มิติการประเมิน (Robotics Dimension) | B27: คะแนนศักยภาพ (/10) | C27: แกน Perception & Sensing (การรับรู้) | D27: แกน Control & Algorithms (การควบคุม) | E27: แกน Actuation & Mechanisms (กลไก) | F27: บทวิเคราะห์เชิงวิศวกรรมหุ่นยนต์ (FIBO Alignment Rationale)
A28: ศักยภาพการประยุกต์ใช้องค์ความรู้หุ่นยนต์และระบบอัตโนมัติ | B28: 7.5 | C28: เซนเซอร์วัดระดับน้ำและอัตราการไหล (Ultrasonic/Pressure) พร้อมอัลกอริทึมกรองสัญญาณคลื่นผิวน้ำ (Low-pass & Median Filter) | D28: โดดเด่นมากในวิชา Dynamic Systems & Control Theory: การแก้สมการอนุพันธ์ชลศาสตร์ dh/dt, Discrete Time Derivative, State Estimation และ Predictive Time Horizon (เทียบเวลาเดินทาง 20-30 นาที) | E28: ระดับต่ำ: ไม่มีระบบกลไกเคลื่อนที่ (Manipulator หรือ Mobile Chassis) เป็นระบบตัดสินใจแบบ Cyber-Physical Monitoring & Edge-DSS | F28: มีความเข้ากันได้สูงในแกนคณิตศาสตร์วิศวกรรม ทฤษฎีระบบควบคุม (Control Theory) และการประมวลผลสัญญาณ (Signal Processing & State Estimation) ของ JK แต่คะแนนอยู่ที่ 7.5 เนื่องจากขาด Physical Actuation และกลไกการเคลื่อนที่

Sheet Solution-2
A1: เมทริกซ์ประเมินความเป็นไปได้เชิงระบบ TELOS+S: 2-Factor Authentication Dispatch Filtering Layer (PUB Singapore CWOS)
A2: ระบบคะแนนจำนวนเต็มเด็ดขาด: 1, 2, 3, 4, 5 เท่านั้น (ไม่มีจุดทศนิยม / ไม่มี 0.5) | โครงสร้างแบบ Transposed แนวนอน
A4: รหัสคำถาม (Question Code) | B4: T-01 | C4: T-02 | D4: T-03 | E4: T-04 | F4: E-01 | G4: E-02 | H4: E-03 | I4: L-01 | J4: L-02 | K4: O-01 | L4: O-02 | M4: O-03 | N4: S-01 | O4: S-02 | P4: S-03 | Q4: SDG-01 | R4: SDG-02 | S4: SDG-03 | T4: สรุปภาพรวม (SUMMARY)
A5: มิติการประเมิน (TELOS+S Pillar) | B5: ด้านเทคนิค (Technical 2.2) | C5: ด้านเทคนิค (Technical 2.2) | D5: ด้านเทคนิค (Technical 2.2) | E5: ด้านเทคนิค (Technical 2.2) | F5: ด้านเศรษฐศาสตร์ (Economic 2.3) | G5: ด้านเศรษฐศาสตร์ (Economic 2.3) | H5: ด้านเศรษฐศาสตร์ (Economic 2.3) | I5: ด้านกฎหมายและหน่วยงาน (Legal 2.4) | J5: ด้านกฎหมายและหน่วยงาน (Legal 2.4) | K5: ด้านการปฏิบัติการและผู้ใช้ (Operational 2.5) | L5: ด้านการปฏิบัติการและผู้ใช้ (Operational 2.5) | M5: ด้านการปฏิบัติการและผู้ใช้ (Operational 2.5) | N5: ด้านเวลาและแผนงาน (Schedule 2.6) | O5: ด้านเวลาและแผนงาน (Schedule 2.6) | P5: ด้านเวลาและแผนงาน (Schedule 2.6) | Q5: ด้านความยั่งยืน (SDGs 2.7) | R5: ด้านความยั่งยืน (SDGs 2.7) | S5: ด้านความยั่งยืน (SDGs 2.7) | T5: ผลรวมทุกมิติ (All Pillars)
A6: คำถามทดสอบความเสี่ยงจริง (Stress-Test Question) | B6: เมื่อพิจารณาความพร้อมด้านเครื่องจักรกลและทักษะของทีมงาน (Fifa เชี่ยวชาญการออกแบบส่งกำลังและประกอบกลไก, Due เชี่ยวชาญ 3D CAD) โครงสร้างทางกายภาพภายนอกของระบบสามารถออกแบบ ผลิต และประกอบขึ้นได้จริง โดยทนทานต่อสภาวะแวดล้อมหน้างานของ กทม. ได้อย่างสมบูรณ์หรือไม่? | C6: เมื่อพิจารณาศักยภาพของทีมงาน (Due มีทักษะ Custom PCB และระบบฝังตัว, JK เข้าใจฟิสิกส์ของเซนเซอร์, Fifa เชี่ยวชาญการปรับเทียบเซนเซอร์) สถาปัตยกรรมวงจรอิเล็กทรอนิกส์ การจ่ายพลังงาน และการเชื่อมต่อเซนเซอร์/ตัวกระตุ้น สามารถทำงานได้อย่างมีเสถียรภาพโดยปราศจากความร้อนสะสมหรือสัญญาณรบกวนหรือไม่? | D6: เมื่อพิจารณาทักษะด้านอัลกอริทึมของทีมงาน (JK เชี่ยวชาญคณิตศาสตร์วิศวกรรม/สมการอนุพันธ์/ROS 2, Kin เชี่ยวชาญการประมวลผลข้อมูล Time-series และ AI Pipeline) โมเดลหรือตรรกะการประมวลผลของระบบสามารถให้ผลลัพธ์ที่ถูกต้องแม่นยำได้ทันภายในกรอบเวลาตัดสินใจเชิงปฏิบัติการของระบบหรือไม่? | E6: ระบบมีความสามารถในการรักษาระดับความถูกต้องของสัญญาณตรวจวัด (Signal Integrity) และทนทานต่อสิ่งรบกวนในสภาพแวดล้อมจริงของ กทม. (เช่น คราบไขมัน ก๊าซกัดกร่อน ฝุ่นละออง คลื่นผิวน้ำ หรือลมกระโชก) โดยไม่เกิดความล้มเหลวหรือส่งข้อมูลหลอกหรือไม่? | F6: งบประมาณจัดซื้อวัสดุ อุปกรณ์เซนเซอร์ ตัวกระตุ้น และบอร์ดประมวลผล (BOM) สำหรับสร้างต้นแบบที่ทำงานได้จริง สามารถควบคุมให้อยู่ภายใต้เพดานงบประมาณโครงงานนักศึกษา (< 5,000 บาท) ได้อย่างแท้จริงหรือไม่? | G6: โครงการมีการจัดสรรงบประมาณสำรองสำหรับชิ้นส่วนอะไหล่ทดแทน (Scrap Allowance) อย่างน้อย 80-100% สำหรับเซนเซอร์และบอร์ดอิเล็กทรอนิกส์หลัก กรณีเกิดความเสียหายจากการทดสอบหน้างานจริงหรือไม่? | H6: เมื่อระบบถูกนำไปใช้งานจริง สามารถลดการสิ้นเปลืองทรัพยากรของภาครัฐ/เทศบาล (ค่าน้ำมันรถปฏิบัติการ ค่าน้ำ ค่าแรงลอกท่อ หรือค่าสึกหรอของยานพาหนะ) ได้คุ้มค่าเมื่อเทียบกับค่าใช้จ่ายในการบำรุงรักษาระบบ (OpEx) หรือไม่? | I6: การติดตั้งและปฏิบัติการของระบบ สอดคล้องกับกฎหมายคุ้มครองข้อมูลส่วนบุคคล (PDPA), พ.ร.บ. จราจรทางบก, และระเบียบความปลอดภัยในที่สาธารณะ โดยไม่ก่อให้เกิดความเสี่ยงต่อการถูกดำเนินคดีหรืออุบัติเหตุบนท้องถนนหรือไม่? | J6: เมื่อพิจารณาความพร้อมด้านการสื่อสารของทีมงาน (Due มีทักษะการถ่ายทอดเทคนิค, Fifa เชี่ยวชาญการคุยโจทย์เชิงพาณิชย์, JK ถนัดการคุยต่อหน้า) อุปกรณ์ไร้สายผ่านการรับรองจาก กสทช. และทีมงานมีความพร้อมในการเข้าพบประสานงานกับหน่วยงานรัฐ (สำนักงานเขต/กทม.) เพื่อขอพื้นที่ทดสอบจริงหรือไม่? | K6: ระบบสามารถสร้างหลักฐานเชิงประจักษ์ดิจิทัล (Digital Evidence / Audit Trail) เช่น กราฟแนวโน้ม, พิกัด GPS, การบันทึกเวลา และรายงานสรุปสถานะ เพื่อสนับสนุนการปิดงานหรือการตัดสินใจของหน่วยงานโดยไม่สร้างภาระงานซ้ำซ้อนหรือไม่? | L6: ความซับซ้อนในการติดตั้ง การบำรุงรักษา และการใช้งานโดยเจ้าหน้าที่หน้างาน อยู่ในระดับที่เหมาะสม ไม่สร้างภาระงานเพิ่มเติม และสอดคล้องกับพฤติกรรมการทำงานจริงของบุคลากรภาคสนามหรือไม่? | M6: ขั้นตอนการติดตั้ง การทดสอบ และการเก็บข้อมูลจริงหน้างาน สามารถกระทำได้อย่างปลอดภัย โดยไม่ก่อให้เกิดความเสี่ยงต่อชีวิตของผู้พัฒนา เจ้าหน้าที่ หรือประชาชนผู้สัญจรไปมาหรือไม่? | N6: เมื่อพิจารณาการกระจายงานในทีม 4 คน (Due, Fifa, Kin, JK) แผนงานและสถาปัตยกรรมระบบมีเวลาสำรอง (Buffer Time 3-4 สัปดาห์) เพียงพอที่จะดูดซับช่วงสอบกลางภาค/ปลายภาคของมหาวิทยาลัย โดยโครงการไม่ล่าช้ากว่ากำหนดหรือไม่? | O6: ความก้าวหน้าทางวิศวกรรมของทีม สามารถบรรลุเกณฑ์การทำงานร่วมกันได้จริงของฮาร์ดแวร์และซอฟต์แวร์ (Working Prototype) ภายในสัปดาห์ที่ 9 ก่อนการประเมินความก้าวหน้าหลักของภาคการศึกษาหรือไม่? | P6: ระยะเวลาในการสั่งซื้อและขนส่งชิ้นส่วน อุปกรณ์เซนเซอร์ และบอร์ดอิเล็กทรอนิกส์ทั้งหมด สอดคล้องกับกรอบเวลาของภาคการศึกษา โดยสามารถจัดส่งถึงมือได้ภายใน 14 วันหรือไม่? | Q6: ระบบส่งเสริมการลดความสูญเสียต่อชีวิต ทรัพย์สิน และโครงสร้างพื้นฐานของเมืองจากภัยพิบัติน้ำท่วมขังหรือความร้อนรุนแรง สอดคล้องกับเป้าหมาย SDG 11.5 และ SDG 13.1 อย่างเป็นรูปธรรมหรือไม่? | R6: อุปกรณ์และสาร/น้ำที่นำมาใช้ในระบบ ไม่ก่อให้เกิดมลพิษทางน้ำ ไม่เสี่ยงต่อการหลุดลอยกลายเป็นขยะอุดตันท่อระบายน้ำ และใช้วัสดุที่ทนทาน ปลอดสารอันตราย สอดคล้องกับ SDG 6.3 และ SDG 12.4 หรือไม่? | S6: ตรรกะการตัดสินใจ การคัดกรอง หรือการจัดสรรทรัพยากรของระบบ มีความโปร่งใส ตรวจสอบย้อนกลับได้ และให้บริการต่อประชาชนทุกกลุ่มอย่างเป็นธรรมโดยไม่เลือกปฏิบัติ สอดคล้องกับ SDG 10.2 และ SDG 16.6 หรือไม่? | T6: ประเมินคำถามทั้งสิ้น 18 ข้อ
A7: เหตุผลในการถาม & โหมดความล้มเหลวที่เฝ้าระวัง (Rationale) | B7: หากระบบบังคับต้องใช้เครื่องจักรกลึง/หล่อโลหะขนาดใหญ่ในโรงงานที่ทีมไม่มีสิทธิ์เข้าถึง โครงงานจะล้มเหลวตั้งแต่สัปดาห์แรก นอกจากนี้ อุปกรณ์ที่ติดตั้งกลางแจ้งหรือในระบบท่อต้องทนทานต่อแรงลมมรสุม ละอองน้ำ และแรงสั่นสะเทือน | C7: วงจรไฟฟ้าที่ขาดการป้องกันจะเสี่ยงต่อการลัดวงจรเมื่อเจอน้ำและความชื้น นอกจากนี้ อุปกรณ์ที่ต้องประมวลผลต่อเนื่องหรือจ่ายกระแสสูงกลางแจ้ง เสี่ยงต่อความร้อนสะสมจนชิปค้างหรือรีบูตตัวเองขณะปฏิบัติการ | D7: หัวใจของระบบอัตโนมัติคือการให้ผลการตัดสินใจที่ทันเวลาและถูกต้อง หากโมเดลซับซ้อนเกินไปจนรันไม่ทัน หรือขาดข้อมูลฝึกฝนจนผลลัพธ์เพี้ยน ระบบจะไม่สามารถสนับสนุนการทำงานจริงของเจ้าหน้าที่ได้ | E7: สภาพแวดล้อมจริงในเขตเมืองเต็มไปด้วยสิ่งรบกวน หากไม่มีเกราะกำบังทางกายภาพและตัวกรองสัญญาณเชิงสถิติ ข้อมูลจะกระโดดไปมา นำไปสู่การตัดสินใจที่ผิดพลาดและสร้างความเสียหายต่อกระบวนการทำงาน | F7: โครงงานนักศึกษาไม่มีงบประมาณสนับสนุนขนาดใหญ่จากภายนอก หากสถาปัตยกรรมบังคับใช้อุปกรณ์เกรดอุตสาหกรรมนำเข้าราคาหลายหมื่นบาท จะทำให้โครงงานหยุดชะงักจากปัญหางบประมาณบานปลาย | G7: การทดสอบหน้างานมีความเสี่ยงสูงต่อไฟกระชาก น้ำซึม หรืออุปกรณ์ตกหล่นเสียหาย หากไม่มีงบสำรองอะไหล่ทดแทนอย่างเพียงพอ ความเสียหายเพียงครั้งเดียวจะทำให้การทดลองหยุดชะงักอย่างยาวนาน | H7: โครงการด้านวิศวกรรมเมืองต้องพิสูจน์ความคุ้มค่าเชิงผลประโยชน์ต่อสาธารณะ หากค่าดูแลระบบแพงกว่าทรัพยากรที่ประหยัดได้ โครงการจะไม่สามารถนำไปขยายผลหรือใช้งานจริงในระยะยาวได้ | I7: การติดตั้งอุปกรณ์หรือปฏิบัติการบนถนนสาธารณะมักเสี่ยงต่อการละเมิดกฎหมาย การบันทึกภาพบุคคลผิด PDPA หรือการเปิดฝาท่อ/วางอุปกรณ์กีดขวางทางสัญจรโดยไม่ได้รับอนุญาต อาจนำไปสู่อุบัติเหตุและคดีความทันที | J7: เทคโนโลยีที่มีการเชื่อมต่อไร้สายต้องใช้คลื่นความถี่ที่ได้รับอนุญาต และการนำอุปกรณ์ไปทดสอบกับโครงสร้างพื้นฐานของเมืองจำเป็นต้องอาศัยการเข้าพบ ชี้แจง และขออนุญาตเป็นลายลักษณ์อักษรจากหน่วยงานผู้รับผิดชอบ | K7: ระเบียบปฏิบัติราชการและระบบเมืองจำเป็นต้องมีหลักฐานยืนยันผลการทำงาน หากระบบไม่สามารถสร้างหลักฐานที่น่าเชื่อถือได้ เจ้าหน้าที่จะยังคงถูกบังคับให้ต้องลงพื้นที่ไปตรวจสอบด้วยตนเองเหมือนเดิม | L7: ระบบวิศวกรรมที่ยอดเยี่ยมมักตายในหน้างานเพราะผู้ใช้ไม่ยอมรับ หากระบบมีขั้นตอนที่ยุ่งยาก ซับซ้อน หรือต้องใช้เวลาปรับเทียบนานเกินไป เจ้าหน้าที่จะปฏิเสธและหันกลับไปใช้วิธีเดิม | M7: ความปลอดภัยต่อชีวิตเป็นเกณฑ์ตัดสินเด็ดขาด (Fatal Gate) งานที่มีความเสี่ยงจากการตกท่อระบายน้ำลึก สัมผัสก๊าซพิษในที่อับอากาศ หรือถูกกระแสน้ำเชี่ยวพัดพา หากไม่มีมาตรการความปลอดภัยที่รัดกุม จะต้องถูกระงับทันที | N7: ปฏิทินการศึกษาของมหาวิทยาลัยมีช่วงสอบกลางภาคและปลายภาครวมกัน 4 สัปดาห์ หากแผนงานเป็นแบบ Linear Dependency และไม่มีการแบ่งงานขนาน โครงการจะล้มเหลวด้านเวลาทันที | O7: เกณฑ์ความก้าวหน้าสัปดาห์ที่ 9 เป็น Milestone สำคัญในการพิสูจน์ว่าแนวคิดทางวิศวกรรมสามารถทำงานร่วมกันได้จริง (Proof of Concept) หากไม่มีต้นแบบทำงานได้ จะไม่ผ่านเกณฑ์การประเมินวิชา | P7: การรอคอยชิ้นส่วนเป็นปัจจัยเสี่ยงอันดับต้น ๆ ของโครงการ หากออกแบบโดยใช้ชิ้นส่วนที่ต้องรอส่งจากต่างประเทศเกิน 4-6 สัปดาห์ จะทำให้ทีมงานไม่มีเวลาประกอบและทดสอบระบบ | Q7: นวัตกรรมเมืองต้องตอบสนองต่อเป้าหมายการพัฒนาที่ยั่งยืน ช่วยให้เมืองมีความยืดหยุ่น (Resilient Cities) และสามารถปรับตัวต่อผลกระทบของการเปลี่ยนแปลงสภาพภูมิอากาศได้อย่างมีประสิทธิภาพ | R7: ระบบที่นำไปติดตั้งในโครงสร้างพื้นฐานเมืองต้องไม่กลายเป็นผู้สร้างมลพิษรายใหม่ อุปกรณ์ต้องไม่หลุดลอยไปอุดตันท่อระบายน้ำ และต้องใช้วัสดุที่เป็นมิตรต่อสิ่งแวดล้อม | S7: ระบบอัตโนมัติหรือระบบคัดกรองของรัฐต้องไม่กลายเป็นกล่องดำ (Black Box) ที่เลือกปฏิบัติต่อชุมชนใดชุมชนหนึ่ง ต้องมีเกณฑ์การตัดสินใจที่โปร่งใส ตรวจสอบย้อนหลังได้ เพื่อสร้างความเชื่อมั่น | T7: สังเคราะห์จาก AI Agents Group 2
A8: เกณฑ์การให้คะแนน (Scoring Rubric Definition: ระดับ 1, 2, 3, 4, 5 ครบทุกระดับ) | B8: 1: บังคับต้องใช้เครื่องจักรกลึง/หล่อโลหะขนาดใหญ่ในโรงงานอุตสาหกรรมที่ทีมไม่มีสิทธิ์เข้าถึง (Fatal Flaw) 2: ต้องจ้างโรงกลึงภายนอกผลิตเกือบทั้งหมด งบประมาณไม่พอและเสี่ยงต่อความล่าช้า 3: ใช้โครงสร้าง 3D Print ร่วมกับการประกอบมือ ความแข็งแรงปานกลาง ต้องมีตัวกำบังเพิ่มเติม 4: ผสมผสานชิ้นส่วนสำเร็จรูป COTS ร่วมกับชิ้นงานกลไกที่ Fifa และ Due ออกแบบและประกอบเองได้ มีการทดสอบความแข็งแรง 5: ใช้โครงสร้างและกล่องสำเร็จรูปมาตรฐานอุตสาหกรรม (IP67/IP68) ร่วมกับระบบยึดจับมาตรฐาน (COTS Clamps/Mounts) แข็งแรง ทนทาน ไม่ต้องดัดแปลงซับซ้อน | C8: 1: ต้องพึ่งพาวงจรความถี่สูงหรือชิปเฉพาะทางที่ทีมไม่มีทักษะและเสี่ยงต่อการลัดวงจร/ความร้อนพังทลาย (Fatal Flaw) 2: อุปกรณ์ประมวลผลเกิดความร้อนสะสมสูงจัด หรือสัญญาณแอนะล็อกถูกคลื่นรบกวนจนอ่านค่าผิดพลาดบ่อย 3: ใช้วงจรประกอบมือบน Perfboard หรือสายไฟต่อแบบหลวม เสี่ยงต่อการหลุดเมื่อมีแรงสั่นสะเทือน 4: ใช้บอร์ดไมโครคอนโทรลเลอร์สำเร็จรูปเชื่อมต่อผ่าน Screw Terminal Shield หรือ Custom PCB ขนาดเล็กของ Due ที่มีระบบป้องกันไฟกระชาก 5: สถาปัตยกรรมวงจรมาตรฐานอุตสาหกรรม มีวงจรแยกสัญญาณรบกวน (Optocoupler/Filter) การจัดการพลังงานแบบ Low-Power โหมด และระบายความร้อนได้ดีเยี่ยม | D8: 1: ต้องพึ่งพาโมเดล AI มหาศาลที่ไม่มีชุดข้อมูล หรืออัลกอริทึมใช้เวลาประมวลผลนานเกินกว่ากรอบเวลาตัดสินใจหน้างานจนระบบไร้ประโยชน์ (Fatal Flaw) 2: อัลกอริทึมมีความซับซ้อนสูงแต่ขาดการปรับเทียบ (Calibration) ทำให้ผลการตัดสินใจคลาดเคลื่อนบ่อย 3: ใช้เกณฑ์แบบคงที่ (Static Threshold) ซึ่งปรับตัวตามสภาวะพลวัตของสภาพแวดล้อมจริงได้จำกัด 4: ใช้อัลกอริทึมประมวลผลสัญญาณหรือโมเดลน้ำหนักเบาที่ Kin และ JK พัฒนาขึ้น ประมวลผลเสร็จในระดับวินาที มีความแม่นยำสูง 5: ใช้สมการฟิสิกส์/คณิตศาสตร์เชิงประจักษ์ร่วมกับโมเดลการไหลของข้อมูลแบบเรียลไทม์ ประมวลผลเสร็จในระดับมิลลิวินาที พร้อมระบบตรวจสอบความถูกต้องในตัว | E8: 1: ระบบล้มเหลวโดยสิ้นเชิงเมื่อสัมผัสสภาพแวดล้อมจริง (เช่น สิ่งสกปรกบดบังหัววัดจนสัญญาณดับ หรือก๊าซกัดกร่อนเซนเซอร์พังทันที / Fatal Flaw) 2: เกิด False Alarm สูงเมื่อเจอสภาพอากาศแปรปรวน ต้องอาศัยมนุษย์คอยรีเซ็ตและปรับเทียบตลอดเวลา 3: ทนต่อสิ่งรบกวนได้ปานกลาง ต้องมีรอบการทำความสะอาดบ่อยครั้งเพื่อรักษาความแม่นยำ 4: มีการติดตั้งอุปกรณ์ป้องกันเชิงกายภาพ (Housing/Shield) ร่วมกับอัลกอริทึมกรองสัญญาณเชิงสถิติ (Statistical/Median Filter) 5: ออกแบบให้ตรวจวัดแบบไม่สัมผัสสิ่งรบกวนโดยตรง (Non-contact Sensing) พร้อมอัลกอริทึม Adaptive Filtering กรองสัญญาณรบกวนได้อย่างสมบูรณ์ | F8: 1: งบประมาณ BOM เกิน 20,000 บาท (เกินเพดาน 5,000 บาท ถึง 4 เท่าตัว / Fatal Flaw) 2: งบประมาณ BOM อยู่ระหว่าง 10,000 - 20,000 บาท ต้องขอทุนสนับสนุนภายนอก 3: งบประมาณ BOM อยู่ระหว่าง 5,000 - 10,000 บาท เกินงบส่วนตัวเล็กน้อย ต้องตัดทอนฟังก์ชัน 4: งบประมาณ BOM อยู่ระหว่าง 3,500 - 5,000 บาท พอดีกับเพดานงบประมาณของทีม 5: งบประมาณ BOM ต่ำกว่า 3,500 บาท ใช้อุปกรณ์ COTS ราคาประหยัด ควบคุมต้นทุนได้อย่างเด็ดขาด | G8: 1: ไม่มีงบสำรองอะไหล่เลย (0%) หากอุปกรณ์ช็อตหรือเสียหายชิ้นเดียว โครงการจะหยุดชะงักทันที (Fatal Flaw) 2: มีงบสำรองอะไหล่เพียง 10-20% ทดแทนได้เฉพาะอุปกรณ์พื้นฐานชิ้นเล็ก ๆ 3: มีงบสำรองอะไหล่ประมาณ 50% สามารถสำรองเซนเซอร์ได้แต่ไม่มีบอร์ดประมวลผลสำรอง 4: มีงบสำรองอะไหล่ 80-100% สำหรับเซนเซอร์หลักและโมดูลควบคุมสำคัญ 5: มีงบสำรองอะไหล่ 100% ครอบคลุมเซนเซอร์และบอร์ดหลักครบทุกชุด ภายใต้เพดานงบประมาณรวมของทีม | H8: 1: ค่าใช้จ่ายในการดูแลรักษาระบบ (OpEx) สูงกว่ามูลค่าทรัพยากรที่ประหยัดได้ กลายเป็นภาระงบประมาณของเมือง (Fatal Flaw) 2: ประหยัดทรัพยากรได้น้อยมาก ไม่คุ้มทุนภายในระยะเวลา 2 ปี 3: คืนทุนได้ในระยะปานกลาง (1-2 ปี) การประหยัดทรัพยากรขึ้นอยู่กับฤดูกาล 4: ประหยัดทรัพยากร ค่าน้ำมัน และค่าแรงเจ้าหน้าที่ได้อย่างชัดเจน คุ้มทุนภายในรอบการใช้งานปีแรก 5: ลดการสูญเปล่าของทรัพยากรเมืองได้มากกว่า 30-50% ประหยัดงบประมาณภาครัฐได้หลายแสนบาทต่อปี โดยระบบกินไฟต่ำมาก | I8: 1: มีการละเมิดกฎหมายอย่างร้ายแรง (เช่น ละเมิดสิทธิข้อมูลส่วนบุคคล PDPA ร้ายแรง หรือติดตั้งขวางทางจราจรเสี่ยงอุบัติเหตุรุนแรง / Fatal Flaw) 2: สุ่มเสี่ยงต่อการละเมิดกฎหมาย ต้องมีขั้นตอนทางเทคนิคที่ซับซ้อนเพื่อเลี่ยงข้อบังคับและยังไม่มีเอกสารยินยอม 3: ปฏิบัติตามกฎหมายได้บางส่วน แต่ต้องรอการอนุมัติข้อยกเว้นจากหน่วยงานอย่างเป็นทางการ 4: ปฏิบัติตามกฎหมายอย่างถูกต้อง ไม่มีการเก็บข้อมูลส่วนบุคคล และมีมาตรการความปลอดภัยบนผิวทางตามระเบียบ 5: ปลอดจากการละเมิดกฎหมาย 100% ไม่เก็บข้อมูลบุคคล (Zero PII) และติดตั้งในจุดปลอดภัยตามมาตรฐานวิศวกรรมสาธารณะ | J8: 1: อุปกรณ์สื่อสารไม่ผ่าน กสทช. และทีมงานไม่มีความพร้อม/ถูกปฏิเสธการติดต่อจากหน่วยงานรัฐอย่างสิ้นเชิง (Fatal Flaw) 2: โมดูลสื่อสารผ่าน กสทช. แต่ทีมงานขาดทักษะการเจรจากับราชการ ทำให้กระบวนการขออนุญาตล่าช้าเกิน 2 เดือน 3: มีหนังสือรับรองจากคณะวิศวกรรมศาสตร์ อยู่ระหว่างรอการประสานงานพื้นที่กับเจ้าหน้าที่ท้องถิ่น 4: โมดูลสื่อสารผ่าน กสทช. และทีมงานสามารถสื่อสาร ย่อยความซับซ้อน และประสานงานกับเจ้าหน้าที่เขตได้อย่างราบรื่น 5: โมดูลผ่าน กสทช. 100% และมีเครือข่ายความร่วมมือหรือหนังสืออนุญาตให้ทดสอบในพื้นที่จริงจากหน่วยงานผู้ดูแล | K8: 1: ไม่สามารถสร้างหลักฐานใด ๆ ได้ บังคับให้เจ้าหน้าที่ต้องลงพื้นที่ไปตรวจสอบซ้ำซ้อน 100% (Fatal Flaw) 2: แสดงได้เฉพาะตัวเลขดิบที่ยากต่อการแปลผล เจ้าหน้าที่หน้างานไม่สามารถนำไปใช้เป็นหลักฐานปิดงานได้ 3: สร้างรายงานสรุปได้แต่ยังต้องอาศัยการกรอกข้อมูลและรูปถ่ายจากเจ้าหน้าที่มายืนยันเพิ่มเติม 4: สร้างบัตรหลักฐานดิจิทัล (Digital Evidence Card / Report) ที่แสดงผลชัดเจน อ่านเข้าใจง่ายใน 5 วินาที 5: มีระบบบันทึก Audit Trail อัตโนมัติ พร้อมส่งออกรายงานหรือเชื่อมโยง API เข้าสู่ระบบของหน่วยงานได้อย่างสมบูรณ์ | L8: 1: ใช้งานยากมาก ต้องใช้วิศวกรหรือผู้เชี่ยวชาญคอยควบคุมตลอดเวลา ผู้ปฏิบัติงานปฏิเสธการใช้งาน (Fatal Flaw) 2: มีขั้นตอนการปรับเทียบ (Calibration) และบำรุงรักษาที่ยุ่งยากเกิน 30 นาทีต่อครั้ง 3: เจ้าหน้าที่ต้องผ่านการฝึกอบรม 1-2 วัน จึงจะสามารถใช้งานและบำรุงรักษาได้อย่างถูกต้อง 4: ใช้งานง่าย มีคู่มือปฏิบัติงานภาคสนามชัดเจน บำรุงรักษาได้ด้วยเครื่องมือช่างทั่วไป 5: ออกแบบตามหลักสรีรศาสตร์และ UX หน้างาน กดปุ่มเดียวทำงานอัตโนมัติ (Plug-and-Play) เจ้าหน้าที่ใช้งานได้ทันทีโดยไม่ต้องอบรมซับซ้อน | M8: 1: มีความเสี่ยงต่อชีวิตอย่างร้ายแรง (เช่น เสี่ยงตกท่อระบายน้ำลึก, สัมผัสก๊าซพิษสะสมในที่อับอากาศโดยไม่มีอุปกรณ์, หรือถูกกระแสน้ำดูด / Fatal Flaw) 2: สภาพแวดล้อมหน้างานมีความเสี่ยงสูง ต้องใช้อุปกรณ์ป้องกันภัยส่วนบุคคล (PPE) เต็มรูปแบบและต้องมีผู้ควบคุมความปลอดภัยมืออาชีพ 3: มีความปลอดภัยปานกลาง สามารถทดสอบได้เฉพาะจุดที่มีราวกั้นชัดเจนหรือบนทางเท้าที่มีการกั้นเขต 4: มีความปลอดภัยสูง ออกแบบให้ติดตั้งและทดสอบจากบนผิวทางเท้าหรือสะพาน โดยไม่มีการให้คนมุดลงในพื้นที่อับอากาศ 5: ปลอดภัย 100% ออกแบบให้ติดตั้งและทดสอบจากระยะไกล มีระบบตัดการทำงานฉุกเฉิน และปลอดจากจุดเสี่ยงอันตรายต่อชีวิตทุกประการ | N8: 1: แผนงานเป็นเส้นตรงที่พึ่งพากันทั้งหมด (Linear Dependency) หากติดสอบเพียง 1 สัปดาห์ โครงการจะพังทลายทันที (Fatal Flaw) 2: มีเวลาสำรองเพียง 3-5 วัน เสี่ยงต่อการส่งมอบงานล่าช้าอย่างมากเมื่อสมาชิกติดภารกิจการเรียน 3: มีเวลาสำรอง 1-2 สัปดาห์ สามารถเลื่อนงานได้บางส่วนแต่ต้องเร่งงานหนักหลังสอบ 4: มี Buffer Time 3-4 สัปดาห์ชัดเจน และแบ่งโมดูลฮาร์ดแวร์-ซอฟต์แวร์ให้สมาชิก 4 คนทำงานคู่ขนานกันได้ 5: สถาปัตยกรรมระบบเป็นอิสระต่อกันสูง ระบบหลักเสร็จสมบูรณ์ตั้งแต่ก่อนสัปดาห์สอบ มีเวลาทดสอบรวมมากกว่า 4-5 สัปดาห์ | O8: 1: มีความเสี่ยงสูงมากที่จะไม่มีระบบใด ๆ ทำงานได้จริงในสัปดาห์ที่ 9 (Fatal Flaw) 2: ในสัปดาห์ที่ 9 ได้เพียงการทดลองแยกส่วนบนโต๊ะแล็บ ยังไม่สามารถรวมระบบฮาร์ดแวร์และซอฟต์แวร์ได้ 3: ในสัปดาห์ที่ 9 ระบบทำงานร่วมกันได้บนโต๊ะแล็บ แต่อุปกรณ์ยังไม่พร้อมสำหรับการทดสอบในสภาวะจำลอง 4: ภายในสัปดาห์ที่ 9 มีต้นแบบฮาร์ดแวร์และซอฟต์แวร์ที่ผสานการทำงานสมบูรณ์ พร้อมทดสอบในสภาวะจำลองหน้างาน 5: ต้นแบบเสร็จสมบูรณ์ 100% และผ่านการทดสอบทำงานจริงได้เรียบร้อยแล้วตั้งแต่ก่อนสัปดาห์ที่ 9 | P8: 1: ต้องสั่งซื้อชิ้นส่วนพิเศษจากต่างประเทศที่ใช้เวลาส่งเกิน 4-6 สัปดาห์ เสี่ยงต่อการไม่มีอุปกรณ์ทำโครงงาน (Fatal Flaw) 2: มีชิ้นส่วนหลักบางรายการที่ต้องรอของ 3-4 สัปดาห์ ทำให้เริ่มงานฮาร์ดแวร์ได้ช้า 3: ชิ้นส่วนทั้งหมดใช้เวลาจัดส่ง 2-3 สัปดาห์ ต้องสั่งซื้อตั้งแต่วันแรกของโครงการ 4: ชิ้นส่วนเกือบทั้งหมดจัดซื้อได้จากตัวแทนจำหน่ายในประเทศ ได้รับของภายใน 7-10 วัน 5: ชิ้นส่วนทั้งหมด 100% มีจำหน่ายในประเทศและสามารถจัดส่งถึงมือได้ภายใน 2-4 วันทำการ | Q8: 1: โครงการไม่มีส่วนเกี่ยวข้องหรืออาจส่งผลกระทบเชิงลบต่อเป้าหมายความยั่งยืนของเมือง (Fatal Flaw) 2: สนับสนุนความยั่งยืนในทางอ้อมอย่างผิวเผิน แต่ไม่มีตัวชี้วัดผลกระทบที่ชัดเจน 3: ส่งเสริมการลดผลกระทบได้บางส่วน แต่จำกัดขอบเขตอยู่เฉพาะจุดทดลองขนาดเล็ก 4: สอดคล้องกับ SDG 11.5 และ SDG 13.1 ชัดเจน ช่วยลดระยะเวลาและผลกระทบของปัญหาบนถนนสายหลักของเมือง 5: สอดคล้องกับ SDG 11.5 และ SDG 13.1 อย่างเป็นรูปธรรม มีแบบจำลองแสดงการลดความสูญเสียทางเศรษฐกิจและความปลอดภัยของประชาชนในเมืองอย่างยั่งยืน | R8: 1: มีความเสี่ยงสูงที่อุปกรณ์จะหลุดลอยกลายเป็นขยะอุดตันท่อ หรือปล่อยสารเคมี/มลพิษลงสู่แหล่งน้ำสาธารณะ (Fatal Flaw) 2: อุปกรณ์ใช้วัสดุที่ชำรุดง่าย เสี่ยงต่อการตกค้างในสภาพแวดล้อมหากเกิดลมพายุหรือน้ำหลาก 3: ติดตั้งแข็งแรงปานกลาง มีโอกาสหลุดลอยหากเจอสภาวะวิกฤต ต้องมีการตรวจเช็กสม่ำเสมอ 4: ใช้วัสดุที่ไม่เป็นพิษต่อสิ่งแวดล้อม มีโครงสร้างยึดจับที่แน่นหนา ปลอดภัยต่อระบบระบายน้ำ 5: ปลอดภัยต่อระบบนิเวศน้ำ 100% ไม่มีส่วนประกอบที่หลุดลอยเป็นขยะ มีระบบสลิงนิรภัยสองชั้น และส่งเสริมการใช้น้ำอย่างมีประสิทธิภาพสูงสุด | S8: 1: ตรรกะของระบบเป็นกล่องดำ (Black Box) ไม่สามารถอธิบายเหตุผลได้ หรือมีอคติเลือกปฏิบัติตัดความช่วยเหลือชุมชนเปราะบาง (Fatal Flaw) 2: เกณฑ์การตัดสินใจไม่ชัดเจน อาจนำไปสู่ความเหลื่อมล้ำในการให้บริการของภาครัฐโดยไม่ตั้งใจ 3: ตรรกะตรวจสอบได้บางส่วน แต่ยังไม่มีกระบวนการอุทธรณ์หรือทบทวนจากเจ้าหน้าที่ 4: ตรรกะโปร่งใส ตัดสินใจตามเกณฑ์ข้อมูลเชิงประจักษ์อย่างเสมอภาค ให้ความช่วยเหลือตามระดับความจำเป็นจริง 5: โปร่งใส 100% มี Audit Trail บันทึกทุกการตัดสินใจ ตรวจสอบย้อนกลับได้ทุกเคส เสริมสร้างธรรมาภิบาลและความเชื่อมั่นของประชาชนต่อหน่วยงานรัฐ | T8: เกณฑ์รวม: >=80 ผ่านสูง, >=60 มีเงื่อนไข, <60 เสี่ยงสูง | หากมีข้อใดได้ 1 = VETOED ตกเกณฑ์ทันที
A9: คะแนนที่ได้รับ (ASSIGNED SCORE: 1, 2, 3, 4, 5 STRICT INTEGER) | B9: 5 | C9: 4 | D9: 5 | E9: 5 | F9: 5 | G9: 5 | H9: 5 | I9: 5 | J9: 4 | K9: 5 | L9: 4 | M9: 5 | N9: 4 | O9: 4 | P9: 5 | Q9: 5 | R9: 5 | S9: 5 | T9: =IF(T10>0, (T11/T10)*20, 0)
A10: ค่าน้ำหนัก (Weight %) | B10: 0.05 | C10: 0.05 | D10: 0.05 | E10: 0.05 | F10: 0.0667 | G10: 0.0667 | H10: 0.0666 | I10: 0.075 | J10: 0.075 | K10: 0.0667 | L10: 0.0667 | M10: 0.0666 | N10: 0.05 | O10: 0.05 | P10: 0.05 | Q10: 0.0333 | R10: 0.0333 | S10: 0.0334 | T10: =SUM(B10:S10)
A11: คะแนนถ่วงน้ำหนัก (=Score * Weight) | B11: =B9*B10 | C11: =C9*C10 | D11: =D9*D10 | E11: =E9*E10 | F11: =F9*F10 | G11: =G9*G10 | H11: =H9*H10 | I11: =I9*I10 | ... S11: =S9*S10 | T11: =SUM(B11:S11)
A12: คำอธิบาย & หลักฐานอ้างอิงจากไฟล์ Intake (Evidence Citation) | B12: อ้างอิง solution-2.md ข้อ 3.a โครงสร้างโหนดโทรมาตรใช้กล่องกันน้ำ COTS IP67 อ้างอิง team-skills/due.md และ fifa.md ที่เชี่ยวชาญการออกแบบเคสและการติดตั้งภายนอก | C12: ใช้วงจร ESP32 ร่วมกับโมดูล LoRa/4G มีบอร์ด Screw Terminal ที่ Due และ Fifa ประกอบได้ มั่นคง แข็งแรง กินไฟต่ำมาก | D12: อ้างอิง solution-2.md ข้อ 3.b ตรรกะ 2-Factor Verification และ Holding Queue 15 นาที ประมวลผลแบบ Boolean/Confidence Scoring บนคลาวด์เสร็จในระดับมิลลิวินาที | E12: การยืนยันร่วม 2 ปัจจัยช่วยลดความผิดพลาดของเซนเซอร์เดี่ยวได้อย่างดีเยี่ยม หากเซนเซอร์อ่านเพี้ยนแต่ไม่มีแจ้งเหตุ หรือมีแจ้งเหตุแต่เซนเซอร์ปกติ ระบบจะหน่วงเวลาตรวจสอบซ้ำ 15 นาที | F12: ต้นทุนโหนดโทรมาตร COTS ระดับน้ำและเรดาร์ฝน API อยู่ที่ประมาณ 3,200 - 3,800 บาทต่อชุด อยู่ในงบ 5,000 บ. อย่างสมบูรณ์ | G12: ด้วยต้นทุนที่ต่ำ สามารถจัดซื้อเซนเซอร์และบอร์ดสำรองได้ 100% ภายใต้งบประมาณรวม | H12: ตัด Empty Cases จากการแจ้งเตือนเดี่ยวได้มากกว่า 40-50% ประหยัดค่าน้ำมันและกำลังพลของ กทม. ได้หลายหมื่นบาทต่อเดือน | I12: ปลอดจากปัญหา PDPA 100% เพราะไม่ใช้กล้อง CCTV ในการจับภาพบุคคล ใช้เพียงระดับน้ำและข้อมูลเรดาร์น้ำฝน | J12: โมดูลสื่อสารผ่าน กสทช. และสอดคล้องกับระบบตรวจวัดน้ำท่วมของ กทม. อ้างอิงความสามารถในการสื่อสารของ Due และ Fifa | K12: ออกบัตร Digital Evidence Card บันทึกกราฟระดับน้ำและเวลาปิดเคสอัตโนมัติ แนบในระบบ Traffy Fondue ได้ทันที | L12: แดชบอร์ดแสดงสถานะ 2-Factor (Confirmed vs Holding) ชัดเจน เจ้าหน้าที่หน้างานเข้าใจได้ใน 5 วินาที | M12: ติดตั้งบนราวสะพานหรือเสาไฟ ปลอดภัยต่อชีวิตผู้ปฏิบัติงาน 100% ไม่ต้องลงไปในทางน้ำ | N12: การแยกส่วนพัฒนา Rule Engine บนคลาวด์ (Kin, JK) และฮาร์ดแวร์ (Due, Fifa) ทำให้ดูดซับช่วงสอบได้สบาย | O12: สามารถส่งมอบระบบเชื่อมต่อ Webhook และเซนเซอร์ต้นแบบได้สมบูรณ์ก่อนสัปดาห์ที่ 9 | P12: อุปกรณ์ทั้งหมดเป็น COTS ในประเทศ จัดส่งได้ภายใน 2-3 วันทำการ | Q12: สนับสนุนการบริหารจัดการภัยพิบัติเมืองอย่างยืดหยุ่น (SDG 11.5) ลดการกระจายกำลังผิดจุด | R12: ติดตั้งเหนือผิวน้ำ ไม่สร้างขยะอุดตันท่อ และไม่มีมลพิษ | S12: เกณฑ์การตรวจสอบ 2 ปัจจัยโปร่งใส ตรวจสอบย้อนหลังได้ทุกเคส ไม่เลือกปฏิบัติ | T12: =IF(MIN(B9:S9)=1, "VETOED / ตกเกณฑ์ข้อบังคับวิกฤต (คะแนนระดับ 1)", IF(T9>=80, "ผ่านเกณฑ์ระดับสูง (HIGHLY VIABLE)", IF(T9>=60, "ผ่านแบบมีเงื่อนไข (CONDITIONALLY VIABLE)", "ความเสี่ยงสูง (HIGH RISK)")))
A13: แผนลดขอบเขตงาน & มาตรการลดความเสี่ยง (De-scoping Action) | B13: ใช้กล่องกันน้ำ COTS สำเร็จรูปพร้อมแคลมป์ยึดเสา | C13: ใช้ Screw Terminal Shield สำเร็จรูป | D13: เชื่อมต่อ Webhook บน Backend API แบบน้ำหนักเบา | E13: ใช้เซนเซอร์วัดระดับน้ำแบบไม่สัมผัสผิวน้ำ | F13: เลือกเซนเซอร์ระดับน้ำ COTS ราคาประหยัด | G13: ซื้ออะไหล่สำรองเซนเซอร์ 1 ชุด | H13: คำนวณอัตราการประหยัดน้ำมันเทียบกับรอบการปล่อยรถ | I13: ยึดอุปกรณ์บนโครงสร้างสะพานอย่างปลอดภัย | J13: ใช้เครือข่าย 4G/NB-IoT ที่ผ่าน กสทช. | K13: ส่งออกรายงานผลการตรวจสอบ 2 ปัจจุบันเป็น PDF | L13: ออกแบบ UI ให้มีสถานะสีเตือนชัดเจน | M13: ติดตั้งจากบนทางเท้า | N13: ทดสอบ Rule Engine ด้วย Mock Data ช่วงสอบ | O13: ส่งมอบ Demo Webhook ในสัปดาห์ที่ 9 | P13: จัดซื้อชิ้นส่วนในประเทศ 100% | Q13: ประเมินเวลาการลดเที่ยวรถว่างเปล่า | R13: ใช้สลิงนิรภัยยึดสองชั้น | S13: เปิดเผย Audit Log การยืนยันเหตุ | T13: ปฏิบัติตามแผนลดขอบเขตงาน (De-scoping Advisory)
A15: ตารางสรุปคะแนนแยกตามมิติ TELOS+S (Pillar Score Breakdown)
A16: มิติการประเมิน (TELOS+S Pillar) | B16: สัดส่วนน้ำหนัก (Weight %) | C16: คะแนนเต็มมิติ (Max Points) | D16: คะแนนที่ได้รับจริง (Earned Points) | E16: คะแนนเฉลี่ย (Score 1-5) | F16: ระดับความพร้อม (Readiness Level)
A17: T : ด้านเทคโนโลยีและวิศวกรรม (Technical) | B17: 0.2 | C17: 20 | D17: =SUM(B11:E11)*20 | E17: =IF(C17>0, (D17/C17)*5, 0) | F17: =IF(D17>=16.0, "พร้อมระดับสูง (High)", IF(D17>=12.0, "ปานกลาง (Medium)", "เสี่ยงวิกฤต (Critical)"))
A18: E : ด้านเศรษฐศาสตร์และความคุ้มค่า (Economic) | B18: 0.2 | C18: 20 | D18: =SUM(F11:H11)*20 | E18: =IF(C18>0, (D18/C18)*5, 0) | F18: =IF(D18>=16.0, "พร้อมระดับสูง (High)", IF(D18>=12.0, "ปานกลาง (Medium)", "เสี่ยงวิกฤต (Critical)"))
A19: L : ด้านกฎหมาย ระเบียบ และภาคประชาชน (Legal & Outreach) | B19: 0.15 | C19: 15 | D19: =SUM(I11:J11)*20 | E19: =IF(C19>0, (D19/C19)*5, 0) | F19: =IF(D19>=12.0, "พร้อมระดับสูง (High)", IF(D19>=9.0, "ปานกลาง (Medium)", "เสี่ยงวิกฤต (Critical)"))
A20: O : ด้านการปฏิบัติการและหน้างาน (Operational) | B20: 0.2 | C20: 20 | D20: =SUM(K11:M11)*20 | E20: =IF(C20>0, (D20/C20)*5, 0) | F20: =IF(D20>=16.0, "พร้อมระดับสูง (High)", IF(D20>=12.0, "ปานกลาง (Medium)", "เสี่ยงวิกฤต (Critical)"))
A21: S : ด้านแผนงานและเวลาส่งมอบ (Schedule) | B21: 0.15 | C21: 15 | D21: =SUM(N11:P11)*20 | E21: =IF(C21>0, (D21/C21)*5, 0) | F21: =IF(D21>=12.0, "พร้อมระดับสูง (High)", IF(D21>=9.0, "ปานกลาง (Medium)", "เสี่ยงวิกฤต (Critical)"))
A22: +S : ด้านความยั่งยืนและสิ่งแวดล้อม (Sustainability / SDG) | B22: 0.1 | C22: 10 | D22: =SUM(Q11:S11)*20 | E22: =IF(C22>0, (D22/C22)*5, 0) | F22: =IF(D22>=8.0, "พร้อมระดับสูง (High)", IF(D22>=6.0, "ปานกลาง (Medium)", "เสี่ยงวิกฤต (Critical)"))
A23: คะแนนรวมทุกมิติ (Total Feasibility Score) | B23: =SUM(B17:B22) | C23: =SUM(C17:C22) | D23: =SUM(D17:D22) | E23: =IF(C23>0, (D23/C23)*5, 0) | F23: =IF(D23>=80, "ผ่านเกณฑ์ระดับสูง (HIGHLY VIABLE)", IF(D23>=60, "ผ่านแบบมีเงื่อนไข (CONDITIONALLY VIABLE)", "ความเสี่ยงสูง (HIGH RISK)"))
A25: เมทริกซ์ประเมินความเข้ากันได้กับองค์ความรู้ด้านวิศวกรรมหุ่นยนต์ (Robotics Knowledge Compatibility)
A26: * หมายเหตุ: การประเมินส่วนนี้วัดศักยภาพในการประยุกต์ใช้องค์ความรู้ด้านวิศวกรรมหุ่นยนต์ (Perception, Control, Actuation, Mechatronics) เต็ม 10 คะแนน | เป็นเอกเทศ ไม่นับรวมในคะแนน TELOS+S 100 คะแนน
A27: มิติการประเมิน (Robotics Dimension) | B27: คะแนนศักยภาพ (/10) | C27: แกน Perception & Sensing (การรับรู้) | D27: แกน Control & Algorithms (การควบคุม) | E27: แกน Actuation & Mechanisms (กลไก) | F27: บทวิเคราะห์เชิงวิศวกรรมหุ่นยนต์ (FIBO Alignment Rationale)
A28: ศักยภาพการประยุกต์ใช้องค์ความรู้หุ่นยนต์และระบบอัตโนมัติ | B28: 5 | C28: การดึงข้อมูลจากระบบภายนอก (API เรดาร์ตรวจฝนและเกจระดับน้ำ) ขาดการเชื่อมต่อทางฟิสิกส์กับ Hardware Sensor โดยตรง | D28: ตรรกะแบบ Rule-based Decision Engine และ Cross-correlation สองปัจจัย (ไม่มีวงรอบปิด Closed-loop Feedback Control เชิงฟิสิกส์) | E28: ไม่มี: เป็นระบบ Pure Software / Cloud Dashboard / Webhook Dispatch | F28: สอดคล้องกับแกน Data Pipeline & Ingestion API ของ Kin แต่แก่นแท้เป็นงาน Software Engineering / IT Management ขาดองค์ประกอบหลักด้าน Mechatronics, Embedded Control และ Actuation ของวิศวกรรมหุ่นยนต์

Sheet Solution-3
A1: เมทริกซ์ประเมินความเป็นไปได้เชิงระบบ TELOS+S: Acoustic Sewer Measurement & Pre-Screening for Scheduled Maintenance (Case 3 UK/USA)
A2: ระบบคะแนนจำนวนเต็มเด็ดขาด: 1, 2, 3, 4, 5 เท่านั้น (ไม่มีจุดทศนิยม / ไม่มี 0.5) | โครงสร้างแบบ Transposed แนวนอน
A4: รหัสคำถาม (Question Code) | B4: T-01 | C4: T-02 | D4: T-03 | E4: T-04 | F4: E-01 | G4: E-02 | H4: E-03 | I4: L-01 | J4: L-02 | K4: O-01 | L4: O-02 | M4: O-03 | N4: S-01 | O4: S-02 | P4: S-03 | Q4: SDG-01 | R4: SDG-02 | S4: SDG-03 | T4: สรุปภาพรวม (SUMMARY)
A5: มิติการประเมิน (TELOS+S Pillar) | B5: ด้านเทคนิค (Technical 2.2) | C5: ด้านเทคนิค (Technical 2.2) | D5: ด้านเทคนิค (Technical 2.2) | E5: ด้านเทคนิค (Technical 2.2) | F5: ด้านเศรษฐศาสตร์ (Economic 2.3) | G5: ด้านเศรษฐศาสตร์ (Economic 2.3) | H5: ด้านเศรษฐศาสตร์ (Economic 2.3) | I5: ด้านกฎหมายและหน่วยงาน (Legal 2.4) | J5: ด้านกฎหมายและหน่วยงาน (Legal 2.4) | K5: ด้านการปฏิบัติการและผู้ใช้ (Operational 2.5) | L5: ด้านการปฏิบัติการและผู้ใช้ (Operational 2.5) | M5: ด้านการปฏิบัติการและผู้ใช้ (Operational 2.5) | N5: ด้านเวลาและแผนงาน (Schedule 2.6) | O5: ด้านเวลาและแผนงาน (Schedule 2.6) | P5: ด้านเวลาและแผนงาน (Schedule 2.6) | Q5: ด้านความยั่งยืน (SDGs 2.7) | R5: ด้านความยั่งยืน (SDGs 2.7) | S5: ด้านความยั่งยืน (SDGs 2.7) | T5: ผลรวมทุกมิติ (All Pillars)
