Workbook

Sheet เปรียบเทียบทุก Solution
A1: ตารางเปรียบเทียบความเป็นไปได้ของทุกข้อเสนอ (Multi-Solution Feasibility Summary)
A2: วิเคราะห์เปรียบเทียบเชิงระบบ (Systems-Thinking) ตามเกณฑ์ TELOS+S จาก AI Agents | รวมทุก Solution ในไฟล์เดียว
A4: ลำดับ | B4: รหัสข้อเสนอ (Solution ID) | C4: ชื่อแนวทางแก้ปัญหา (Title / Concept) | D4: คะแนนรวม (เต็ม 100) | E4: ผลการประเมิน (Verdict) | F4: จุดแข็งสำคัญ (Key Strengths) | G4: จุดติดขัดวิกฤต (Critical Bottlenecks) | H4: คำแนะนำเชิงระบบ (Strategic Advice)
A5: 1 | B5: Solution-1 | C5: คำนวณอัตราการลดระดับน้ำ (Recession Rate) กรอง Empty Cases สำหรับหน่วย QRT | D5: ='Solution-1'!T9 | E5: ='Solution-1'!T12 | F5: Leverage Point แม่นยำ, JK เชี่ยวชาญคณิตศาสตร์ควบคุมและ ROS2, ต้นทุนต่ำ (< 3,500 บ.), COTS 100% | G5: ระเบียบรูปถ่ายปิดเรื่องของ Traffy Fondue (O-01) และสัปดาห์สอบของมหาวิทยาลัย 4 สัปดาห์ (S-01) | H5: พัฒนาใบปิดงานดิจิทัล (Digital Evidence Card) พร้อมกราฟ dh/dt และล็อกสเปกฮาร์ดแวร์ก่อนสัปดาห์ที่ 9
A6: 2 | B6: Solution-2 | C6: 2-Factor Authentication Dispatch Filtering Layer (PUB Singapore CWOS) | D6: ='Solution-2'!T9 | E6: ='Solution-2'!T12 | F6: ใช้การยืนยันร่วม 2 ปัจจัยระหว่างรายงานประชาชนกับข้อมูลโทรมาตรระดับน้ำ/เรดาร์ ปลอดปัญหา PDPA 100% ต้นทุนต่ำ (< 3,800 บาท) ตัด Empty Cases ได้มากกว่า 40-50% | G6: ขึ้นอยู่กับความหนาแน่นของจุดติดตั้งเซนเซอร์โทรมาตร และต้องมีหลักฐาน Digital Evidence Card สำหรับระบบราชการ | H6: เชื่อมต่อ API กับ Traffy Fondue และจัดทำเทมเพลต Digital Evidence Card อัตโนมัติ พร้อมทั้งใช้เซนเซอร์ระดับน้ำ COTS แบบ Non-contact
A7: 3 | B7: Solution-3 | C7: Acoustic Sewer Measurement & Pre-Screening สำหรับการวางแผนบำรุงรักษาเชิงป้องกัน (Case 3 UK/USA) | D7: ='Solution-3'!T9 | E7: ='Solution-3'!T12 | F7: เปลี่ยนจากการลอกท่อแบบสุ่มตามรอบปฏิทินมาเป็น Condition-Based Maintenance ด้วยการตรวจคัดกรองความสะอาดท่อ 3 ระดับ (Tier 1: Action, Tier 2: Queue, Tier 3: Clean) รวดเร็ว 3-5 นาทีต่อช่วงท่อ ประหยัดงบประมาณและทรัพยากรรถดูดโคลนได้มหาศาล | G7: ต้องหลีกเลี่ยงการจัดซื้ออุปกรณ์นำเข้าราคาแพง (SL-RAT) โดยหันมาสร้างต้นแบบจาก Transducer COTS และต้องประสานงานกับทีมงานเขตเพื่อความปลอดภัยบนผิวจราจร | H7: พัฒนาชุดก้านหย่อน Telescopic ร่วมกับ Transducer ความถี่กวาดและบอร์ดประมวลผล Time-of-Flight / Attenuation ทดสอบในท่อจำลองก่อนลงพื้นที่ร่วมกับฝ่ายระบายน้ำของเขตในฤดูแล้ง
A8: 4 | B8: Solution-4 | C8: Smart Drainage Pipe Telemetry & Prioritized Flushing DSS (Jakarta Case Adaptation) | D8: ='Solution-4'!T9 | E8: ='Solution-4'!T12 | F8: มอนิเตอร์ระดับน้ำและอัตราการไหลในท่อแบบต่อเนื่องทั้งเมือง ชี้เป้าจุดวิกฤตระบายช้า และจัดลำดับการส่งรถดูดเลนได้อย่างมีข้อมูลเชิงประจักษ์รองรับ (Data-Driven Flushing DSS) | G8: สภาพแวดล้อมในท่อมีตะกอน คราบไขมัน และก๊าซกัดกร่อน H2S สูง และการติดตั้งต้องคำนึงถึงความปลอดภัยของเจ้าหน้าที่ | H8: ใช้เซนเซอร์วัดระดับน้ำและอัตราการไหลแบบ Non-contact ติดตั้งใต้ฝาท่อพักน้ำ พร้อมสายสลิงนิรภัยยึดสองชั้น และทดสอบในจุดเสี่ยงนำร่อง
A9: 5 | B9: Solution-5 | C9: UHI Latent Heat Precision Road Cooling & Microclimate Water Dosing | D9: ='Solution-5'!T9 | E9: ='Solution-5'!T12 | F9: ใช้ประโยชน์จากความร้อนแฝงของการระเหย พ่นน้ำฟิล์มบางมาก (0.2-0.4 mm) ลด Peak Heat Flux ได้ 100-150 W/m² ไม่ลื่น ไม่เกิด Sauna Effect ประหยัดน้ำกว่ารถฉีดน้ำ 40-50% | G9: ลมกระโชกแรงอาจพัดละอองน้ำ และต้องมีระบบกรองน้ำป้องกันหัวพ่นหมอกอุดตัน รวมถึงการสร้างความเข้าใจแก่ประชาชนผู้ใช้ทาง | H9: ติดตั้งหัวฉีดละอองระดับต่ำขอบทางเท้า พร้อม Sauna Effect Guard และวาล์ว Micro-pulsing อัตโนมัติตามเซนเซอร์ IR

Sheet Solution-1
A1: เมทริกซ์ประเมินความเป็นไปได้เชิงระบบ TELOS+S: คำนวณอัตราการลดระดับน้ำ (Recession Rate) กรอง Empty Cases สำหรับหน่วย QRT
A2: ระบบคะแนนจำนวนเต็มเด็ดขาด: 1, 2, 3, 4, 5 เท่านั้น (ไม่มีจุดทศนิยม / ไม่มี 0.5) | โครงสร้างแบบ Transposed แนวนอน
A4: รหัสคำถาม (Question Code) | B4: T-01 | C4: T-02 | D4: T-03 | E4: T-04 | F4: E-01 | G4: E-02 | H4: E-03 | I4: L-01 | J4: L-02 | K4: O-01 | L4: O-02 | M4: O-03 | N4: S-01 | O4: S-02 | P4: S-03 | Q4: SDG-01 | R4: SDG-02 | S4: SDG-03 | T4: สรุปภาพรวม (SUMMARY)
A5: มิติการประเมิน (TELOS+S Pillar) | B5: ด้านเทคนิค (Technical 2.2) | C5: ด้านเทคนิค (Technical 2.2) | D5: ด้านเทคนิค (Technical 2.2) | E5: ด้านเทคนิค (Technical 2.2) | F5: ด้านเศรษฐศาสตร์ (Economic 2.3) | G5: ด้านเศรษฐศาสตร์ (Economic 2.3) | H5: ด้านเศรษฐศาสตร์ (Economic 2.3) | I5: ด้านกฎหมายและหน่วยงาน (Legal 2.4) | J5: ด้านกฎหมายและหน่วยงาน (Legal 2.4) | K5: ด้านการปฏิบัติการ (Operational 2.5) | L5: ด้านการปฏิบัติการ (Operational 2.5) | M5: ด้านการปฏิบัติการ (Operational 2.5) | N5: ด้านตารางเวลา (Schedule 2.6) | O5: ด้านตารางเวลา (Schedule 2.6) | P5: ด้านตารางเวลา (Schedule 2.6) | Q5: เป้าหมายความยั่งยืน (SDGs 2.7) | R5: เป้าหมายความยั่งยืน (SDGs 2.7) | S5: เป้าหมายความยั่งยืน (SDGs 2.7) | T5: ผลรวมทุกมิติ (All Pillars)
A6: คำถามทดสอบความเสี่ยงจริง (Stress-Test Question) | B6: เมื่อพิจารณาว่าผู้พัฒนาไม่มีทักษะการกลึง/ตัดโลหะและไม่สามารถเข้าถึงโรงประลอง (Machine Shop) ได้ โครงสร้างฮาร์ดแวร์ภายนอกของระบบสามารถประกอบขึ้นจากอุปกรณ์สำเร็จรูปมาตรฐาน (COTS) เพื่อทนต่อสภาวะแวดล้อมน้ำท่วม/มรสุมของ กทม. ได้อย่างสมบูรณ์หรือไม่? | C6: เมื่อพิจารณาว่าผู้พัฒนาไม่มีทักษะการออกแบบ Custom PCB และมีทักษะการบัดกรีต่ำ สถาปัตยกรรมฮาร์ดแวร์อิเล็กทรอนิกส์และวงจรของระบบสามารถติดตั้งและทำงานได้อย่างมีเสถียรภาพโดยไม่เกิดความร้อนสะสมหรือวงจรล้มเหลวหรือไม่? | D6: ความสามารถและอัลกอริทึมในการตรวจวัดและทำนายระดับน้ำหรือการระบายน้ำ สามารถประมวลผลและให้ผลลัพธ์ที่แม่นยำได้ทันก่อนกรอบเวลาเดินทางของทีม QRT (20-30 นาที) หรือไม่? | E6: ระบบมีความแข็งแกร่ง (Robustness) ต่อปัจจัยรบกวนในสิ่งแวดล้อมจริงของ กทม. (เช่น คราบสิ่งสกปรก ขยะลอย ทัศนวิสัยต่ำตอนฝนตกหนัก น้ำทะเลหนุน) โดยไม่เกิดความล้มเหลวในการตรวจวัดหรือไม่? | F6: งบประมาณจัดซื้ออุปกรณ์ต้นแบบ (BOM) ทั้งหมด สามารถควบคุมให้อยู่ภายใต้เพดานงบประมาณโครงงานนักศึกษา (< 5,000 บาท) ได้อย่างแท้จริงหรือไม่? | G6: โครงการได้จัดสรรงบประมาณสำรองสำหรับอะไหล่ทดแทน 100% (Scrap Allowance) กรณีอุปกรณ์ลัดวงจรหรือเสียหายจากการทดสอบหน้างานจริงหรือไม่? | H6: ค่าใช้จ่ายในการบำรุงรักษาและทำความสะอาดอุปกรณ์ (OpEx) คุ้มค่าเมื่อเทียบกับต้นทุนค่าน้ำมันและกำลังพลที่ประหยัดได้จากการลดการปล่อยรถ QRT ไปเก้อหรือไม่? | I6: การติดตั้งและปฏิบัติการของระบบ สอดคล้องกับกฎหมายคุ้มครองข้อมูลส่วนบุคคล (PDPA), กฎหมายจราจร, และระเบียบความปลอดภัยในที่สาธารณะโดยไม่ละเมิดข้อบังคับหรือไม่? | J6: อุปกรณ์สื่อสารไร้สายได้รับการรับรองมาตรฐานจาก กสทช. (NBTC) และทีมงานมีความพร้อมในการประสานงานขอความร่วมมือจากหน่วยงานภาครัฐ (กทม./สำนักการระบายน้ำ) หรือไม่? | K6: ระบบสามารถสร้างหลักฐานยืนยันที่สอดคล้องกับระเบียบราชการ (เช่น ภาพถ่ายปิดเคสใน Traffy Fondue) เพื่อให้เจ้าหน้าที่ศูนย์สั่งการกล้าตัดสินใจยกเลิกหรือชะลอการปล่อยรถ QRT โดยไม่กลัวความผิดทางวินัยหรือไม่? | L6: ความซับซ้อนในการติดตั้ง การบำรุงรักษา และการใช้งานระบบ ไม่สร้างภาระงานส่วนเกินหรือต้องอาศัยการฝึกอบรมบุคลากรหน้างานอย่างซับซ้อนหรือไม่? | M6: การทดสอบและติดตั้งระบบจริงหน้างาน สามารถดำเนินการได้อย่างปลอดภัยโดยไม่นำพาผู้พัฒนาไปสู่สภาวะอันตรายถึงชีวิต (เช่น พื้นที่อับอากาศ/การจราจรหนาแน่น) หรือทำให้เกิดภาวะหมดไฟ (Burnout) หรือไม่? | N6: แผนงานและสถาปัตยกรรมระบบสามารถดูดซับช่วงเวลาหยุดนิ่งจากการสอบของมหาวิทยาลัย 4 สัปดาห์ (สัปดาห์ 10+1, 10+2, 15+1, 15+2) และส่งมอบต้นแบบได้ทันกรอบเวลา 16 สัปดาห์หรือไม่? | O6: ความก้าวหน้าทางวิศวกรรมสามารถบรรลุเกณฑ์ TRL ตามกำหนด (สัปดาห์ 9: TRL 2 Model, สัปดาห์ 13: TRL 3 PoC, สัปดาห์ 16: TRL 4 Lab Verification) ได้อย่างสมบูรณ์หรือไม่? | P6: ระยะเวลาในการสั่งซื้อและขนส่งอุปกรณ์ (Lead Time) มีการสำรองเวลา (Buffer) อย่างน้อย 2-3 สัปดาห์เพื่อการรวมระบบและแก้จุดบกพร่องก่อนส่งมอบจริงหรือไม่? | Q6: ระบบส่งเสริมการลดความสูญเสียจากภัยพิบัติน้ำท่วมเมือง (SDG 11.5) และยกระดับการเฝ้าระวังระบบระบายน้ำ (SDG 6.3) อย่างวัดผลได้จริงเชิงปฏิบัติการหรือไม่? | R6: อุปกรณ์ที่นำไปติดตั้ง ไม่เสี่ยงต่อการชะล้างสารพิษ การสร้างขยะอิเล็กทรอนิกส์ตกค้างในทางน้ำ (SDG 6/12) หรือการหลุดลอยไปอุดตันท่อระบายน้ำหรือไม่? | S6: ตรรกะการประเมินและการกรองเหตุร้องเรียน มีความเป็นธรรม ไม่สร้างความเหลื่อมล้ำในการตอบสนองระหว่างพื้นที่เมืองชั้นในที่มีการร้องเรียนหนาแน่น กับชุมชนชานเมืองหรือไม่? | T6: ประเมินคำถามทั้งสิ้น 18 ข้อ
A7: เหตุผลในการถาม & โหมดความล้มเหลวที่เฝ้าระวัง (Rationale) | B7: หากฝืนออกแบบโครงสร้างที่ต้องกลึงหรือเชื่อมโลหะเอง เมื่อไม่มีสิทธิ์เข้าใช้โรงประลอง (Machine Shop) งานฮาร์ดแวร์จะติดคอตันทันทีในสัปดาห์แรก ๆ นอกจากนี้ อุปกรณ์กลางแจ้งต้องทนลมพายุมรสุมและละอองน้ำขัง หากกล่องพิมพ์ 3D ซีลไม่ดี น้ำจะซึมเข้ากล่องทำให้วงจรลัดวงจร เซนเซอร์ดับกลางคัน และส่งข้อมูลหลอกศูนย์สั่งการ | C7: การสั่งผลิต Custom PCB ใช้เวลาแก้แบบและรอส่ง 2-3 สัปดาห์ต่อรอบ หากออกแบบลายวงจรผิดหรือบัดกรีพลาด จะทำให้โครงการล่มทันที นอกจากนี้ การนำบอร์ดประมวลผลสูงไปปิดผนึกในกล่องกันน้ำกลางแดด 40°C ของ กทม. เสี่ยงต่อการเกิดความร้อนสะสม (Thermal Throttling) จนชิปค้างหรือรีบูตตัวเองขณะฝนตกหนัก ซึ่งเป็นช่วงเวลาที่ต้องการข้อมูลมากที่สุด | D7: หัวใจเชิงระบบของโครงการนี้คือการแยกเคส 'น้ำท่วมชั่วคราวที่ระบายเองได้' ออกจากเคสวิกฤต หากอัลกอริทึมต้องพึ่งพา AI ข้อมูลมหาศาลที่ยังไม่มีชุดข้อมูล หรือประมวลผลช้าเกิน 20-30 นาที รถ QRT จะถูกส่งออกไปหน้างานและพบว่าน้ำแห้งแล้วก่อนที่ระบบจะคำนวณเสร็จ กลายเป็นระบบไร้ประโยชน์ที่แก้ปัญหาไม่ได้จริงในหน้างาน | E7: คลองและผิวจราจร กทม. เต็มไปด้วยขยะลอย ผักตบชวา คราบน้ำมัน และคลื่นผิวน้ำจากลมพายุ หากใช้เซนเซอร์ที่สัมผัสน้ำตรง ๆ ขยะจะพันติดจนเซนเซอร์พัง หรือถ้าใช้คลื่นสะท้อนโดยไม่มีตัวกรองเชิงสถิติกำจัดสัญญาณรบกวน ค่าระดับน้ำจะกระโดดไปมา นำไปสู่การประเมินอัตราน้ำลดผิดพลาดและสั่งยกเลิกรถผิดจังหวะ | F7: โครงงานนักศึกษาไม่มีงบจัดซื้อจากรัฐหรือสปอนเซอร์ภายนอก หากเลือกสถาปัตยกรรมที่ใช้อุปกรณ์อุตสาหกรรมราคาแพง (เช่น เซนเซอร์เสียงใต้ดินตัวละ 25,000 บาท หรือกล้อง AI เกรดราชการ) ผู้พัฒนาจะต้องควักเงินส่วนตัวจนเงินหมดก่อนได้ต้นแบบ หรือต้องยอมตัดทอนอุปกรณ์หลักจนระบบใช้งานไม่ได้ | G7: งานวิศวกรรมฮาร์ดแวร์และน้ำไม่เคยต่อครั้งเดียวแล้วติด การทดสอบหน้างานมีความเสี่ยงสูงที่จะทำบอร์ดไหม้ เซนเซอร์ช็อต หรืออุปกรณ์ตกน้ำสูญหาย หากตั้งงบไว้พอดีเป๊ะ 1x BOM โดยไม่มีงบอะไหล่สำรอง 100% ความเสียหายเพียงครั้งเดียวจะทำให้การทดลองหยุดชะงักและไม่มีเงินสั่งซื้อใหม่ | H7: ระบบต้องตอบคำถามความคุ้มค่าเชิงระบบได้ชัดเจน หากค่าซิม 4G รายเดือน ค่าไฟฟ้า และค่าแรงเจ้าหน้าที่ที่ต้องคอยปีนไปเช็ดกล้องหรือล้างเซนเซอร์สูงกว่าค่าน้ำมันรถ QRT ที่ประหยัดได้จากเคสว่างเปล่า โครงการนี้จะกลายเป็น 'ภาระทางงบประมาณ' ของ กทม. และถูกถอดทิ้งหลังจบการทดลอง | I7: การติดตั้งเทคโนโลยีในที่สาธารณะมักตายด้วยข้อกฎหมาย ไม่ใช่เทคโนโลยี การใช้กล้องส่องถนนจะติด พ.ร.บ. PDPA มาตรา 24 ทันทีที่มีใบหน้าคนหรือทะเบียนรถ หรือการเปิดฝาท่อบนผิวจราจรโดยไม่มีตำรวจกั้นทางจะผิด พ.ร.บ. ทางหลวงและเสี่ยงต่ออุบัติเหตุรถตกท่อ ซึ่งอาจนำไปสู่คดีความอาญาและคำสั่งระงับโครงการทันที | J7: แม้อุปกรณ์จะใช้ได้จริง แต่หากคลื่นวิทยุไม่ผ่าน กสทช. จะนำไปติดตั้งจริงไม่ได้ และที่สำคัญที่สุดคือ ระบบต้องไปแตะโครงสร้างสะพาน ท่อระบายน้ำ หรือเสาไฟของ กทม. หากทีมงานไม่มีคอนเนกชันเชิงสถาบันหรือหนังสือรับรองจากอาจารย์ที่ปรึกษาเพื่อขอเปิดพื้นที่ การลงหน้างานจะถูกเทศกิจสั่งรื้อถอนทันที | K7: จุดตายอันดับหนึ่งของระบบคัดกรองอัตโนมัติ เจ้าหน้าที่ศูนย์สั่งการ กทม. ต้องรับผิดชอบทางวินัยต่อเรื่องร้องเรียนของประชาชนใน Traffy Fondue หากระบบบอกว่า 'น้ำแห้งเองได้' แต่ไม่มีหลักฐานรูปภาพยืนยันปิดเคส เจ้าหน้าที่ก็ยังคง 'ต้องส่งรถออกไปถ่ายรูปอยู่ดี' เพื่อเอาตัวรอดจากข้อร้องเรียน ทำให้การลงทุนทำระบบกรองล้มเหลวโดยสิ้นเชิง | L7: อุปกรณ์ที่ออกแบบมาให้คนอื่นใช้ ถ้าติดตั้งยาก บำรุงรักษาซับซ้อน หรือต้องอบรมใช้งานหลายวัน จะถูกเจ้าหน้าที่หน้างานต่อต้านและปฏิเสธการใช้งาน เจ้าหน้าที่ระบายน้ำหน้างานต้องการเพียงกล่องที่ขันยึดเสร็จใน 10 นาที และแดชบอร์ดที่บอกชัดเจนว่า 'ส่งรถ' หรือ 'ไม่ต้องส่ง' โดยไม่ต้องแปลผลกราฟซับซ้อน | M7: ประเมินความปลอดภัยในชีวิตจริงของผู้พัฒนา การปล่อยให้นักศึกษาเดี่ยว (Solo Developer) ต้องลงไปเปิดฝาท่อระบายน้ำที่มีก๊าซไข่เน่าพิษ (H2S) ขาดอากาศหายใจ หรือยืนปรับมุมกล้องริมถนนใหญ่ที่มีรถวิ่งเร็ว เป็นการกระทำที่อันตรายถึงชีวิตและขัดต่อจรรยาบรรณวิศวกรรม หากผู้พัฒนาบาดเจ็บ โครงการจะยุติทันที | N7: โครงงานภาคการศึกษา 16 สัปดาห์ มีช่วงสอบกลางภาคและปลายภาคของมหาวิทยาลัยถึง 4 สัปดาห์เต็ม ซึ่งสมองและเวลาของนักศึกษาจะถูกดึงไปกับการสอบ 100% หากสถาปัตยกรรมระบบไม่แยกส่วนให้ชัดเจนและไม่ล็อกสเปกฮาร์ดแวร์ก่อนสอบ โครงการจะเกิดภาวะขวดโหลแตก (Schedule Collapse) และประกอบงานส่งไม่ทัน | O7: ป้องกันภาพลวงตาของการพัฒนา (Illusion of Progress) ที่นักศึกษาคิดว่าโปรเจกต์เดินหน้าแต่มีแค่สไลด์ เกณฑ์ TRL2 (สัปดาห์ 9) ต้องมีสมการคณิตศาสตร์ที่พิสูจน์ได้, TRL3 (สัปดาห์ 13) ต้องมีฮาร์ดแวร์วัดจริงในถังทดลอง, และ TRL4 (สัปดาห์ 16) ต้องทดสอบในแล็บ/คลองจริง หากวางแผนข้ามขั้นจะสอบตกการประเมินความก้าวหน้า | P7: การสั่งซื้อชิ้นส่วนพิเศษจากต่างประเทศ (AliExpress, JLCPCB, ยุโรป) มักเจอปัญหาติดด่านศุลกากร ขนส่งล่าช้า 3-6 สัปดาห์ หรือได้ของชำรุด หากไม่มี Buffer รวมระบบอย่างน้อย 2-3 สัปดาห์ก่อนส่งงาน การที่ของมาถึงในสัปดาห์ที่ 15 จะทำให้ไม่มีเวลาแก้บักและระบบจะพังต่อหน้ากรรมการในวันสอบ Final | Q7: ประเมินว่าโครงการแก้ปัญหาที่ Pain Point จริงของเมืองหรือไม่ การลด Empty Cases ไม่ใช่แค่การเขียนโค้ดเล่น แต่เป็นการปลดล็อกรถดูดน้ำและหน่วยเคลื่อนที่เร็วให้สามารถวิ่งไปช่วยชุมชนที่น้ำท่วมขังวิกฤตจริงได้เร็วขึ้น 15-20 นาที ลดความเสียหายต่อทรัพย์สินและบ้านเรือนของประชาชนตามเป้าหมาย SDG 11.5 | R7: วิศวกรต้องไม่สร้างปัญหาใหม่ทับซ้อนปัญหาเดิม กล่องเซนเซอร์หรืออุปกรณ์ที่ติดตั้งในทางระบายน้ำ หากยึดไม่แน่นหนาแล้วหลุดลอยไปในคลอง ตัวกล่องและแบตเตอรี่จะกลายเป็นขยะอิเล็กทรอนิกส์มีพิษ (E-Waste) ที่ไปอุดตันเครื่องสูบน้ำของ กทม. ทำให้เกิดน้ำท่วมหนักกว่าเดิม | S7: แอปพลิเคชันอย่าง Traffy Fondue มีอคติเชิงพื้นที่ (Geospatial Bias) สูงมาก เพราะคนในย่านธุรกิจใจกลางเมืองจะแจ้งเรื่องบ่อยและส่งเสียงดังกว่าชุมชนชานเมือง หากระบบใช้อัลกอริทึมที่อิงตามความถี่การแจ้งเรื่อง ชุมชนยากจนจะถูกละเลย ระบบจึงต้องใช้ฟิสิกส์อัตราการระบายน้ำที่เป็นกลางในการตัดสินใจอย่างเท่าเทียม | T7: สังเคราะห์จาก AI Agents Group 2
A8: เกณฑ์การให้คะแนน (Scoring Rubric Definition: ระดับ 1, 2, 3, 4, 5 ครบทุกระดับ) | B8: 1: บังคับต้องกลึงหรือตัดขึ้นรูปชิ้นงานโลหะ custom เองทั้งหมดโดยไม่มีเครื่องจักร (Fatal Flaw / ไม่ผ่านเกณฑ์) 2: ต้องจ้างโรงกลึงภายนอกผลิตชิ้นงานเฉพาะจุดโดยไม่มีงบประมาณและเสี่ยงต่อความล่าช้า 3: ใช้ชิ้นงานพิมพ์ 3D PETG ซีลกันน้ำด้วยซิลิโคนมือ ทนทานปานกลางต่อแรงลมมรสุม 4: ใช้กล่องกันน้ำ COTS ร่วมกับขายึดดัดแปลงเล็กน้อย มีการทดสอบการรั่วซึมเบื้องต้น 5: ใช้กล่องกันน้ำสำเร็จรูปมาตรฐาน IP67/68 ร่วมกับแคลมป์รัดท่อ/เสามาตรฐานอุตสาหกรรมที่มีขายทั่วไป ไม่ต้องดัดแปลง | C8: 1: บังคับต้องออกแบบและผลิต Custom PCB หลายชั้นเองโดยไม่มีทักษะและเวลาไม่พอ (Fatal Flaw) 2: อุปกรณ์ประมวลผลเกิดความร้อนสะสมสูงจัด (เช่น ชิป GPU รันกลางแดด 40°C) เสี่ยงต่อการดับตัวเอง 3: บัดกรีด้วยมือบนแผ่นไข่ปลา (Perfboard) วงจรทนต่อแรงสั่นสะเทือนได้จำกัด 4: ใช้บอร์ดไมโครคอนโทรลเลอร์สำเร็จรูปเชื่อมต่อสายไฟแบบขันสกรู มีการป้องกันสัญญาณรบกวนเบื้องต้น 5: ใช้ Industrial Screw Terminal Shield สำเร็จรูปมาตรฐานอุตสาหกรรม มีวงจรป้องกันไฟกระชากและระบายความร้อนได้ดีเยี่ยม | D8: 1: ต้องพึ่งพาโมเดล AI ข้อมูลมหาศาลที่ยังไม่มีชุดข้อมูล หรืออัลกอริทึมประมวลผลช้าเกินกว่ากรอบเวลา 30 นาที (Fatal Flaw) 2: ใช้อัลกอริทึมที่ซับซ้อนเกินไปจนไม่สามารถรันบนฮาร์ดแวร์จริงได้ทันเวลาเดินทางของ QRT 3: ใช้เกณฑ์ระดับน้ำแบบคงที่ (Static Threshold) ซึ่งแยกเคสฝนตกหนักชั่วคราวไม่ออก 4: ใช้อัลกอริทึมวิเคราะห์อัตราการเปลี่ยนแปลงหรือโมเดลน้ำหนักเบา ประมวลผลได้ภายในไม่กี่วินาที 5: ใช้สมการอนุพันธ์ชลศาสตร์ (dh/dt) คำนวณเทียบเวลาระบายจริง ประมวลผลเสร็จในระดับมิลลิวินาที แม่นยำสูง | E8: 1: ระบบล้มเหลวโดยสิ้นเชิงเมื่อเจอสภาวะแวดล้อมจริง (เช่น ขยะลอย น้ำขุ่น ฝนตกหนัก หรือก๊าซในท่อ) (Fatal Flaw) 2: เซนเซอร์อ่านค่าผิดพลาดบ่อยครั้งเมื่อทัศนวิสัยต่ำหรือมีสิ่งสกปรกเกาะ ต้องอาศัยการรีเซ็ตด้วยมือ 3: ทนต่อสิ่งรบกวนได้ปานกลาง แต่อาจเกิด False Positive ชั่วคราวเมื่อมีฝนตกหนักจัด 4: มีการติดตั้งฮูดกำบัง และใส่อัลกอริทึมกรองสัญญาณรบกวนเชิงสถิติ (Statistical Filter) 5: เซนเซอร์ติดตั้งแบบไม่สัมผัสสิ่งรบกวน พร้อมอัลกอริทึม Median Filter กรองสัญญาณสะท้อนหลอกจากขยะและคลื่นผิวน้ำได้อย่างสมบูรณ์ | F8: 1: งบประมาณ BOM เกิน 20,000 บาท (เกินเพดาน 5,000 บาทของนักศึกษาถึง 4-5 เท่าตัว / Fatal Flaw) 2: งบประมาณ BOM อยู่ระหว่าง 10,000 - 20,000 บาท ต้องจัดหาทุนสนับสนุนภายนอก 3: งบประมาณ BOM อยู่ระหว่าง 5,000 - 10,000 บาท เกินงบส่วนตัวเล็กน้อย ต้องตัดทอนอุปกรณ์ 4: งบประมาณ BOM รวมอยู่ระหว่าง 3,500 - 5,000 บาท พอดีกับเพดานงบประมาณ 5: งบประมาณ BOM รวมต่ำกว่า 3,500 บาท ใช้อุปกรณ์ COTS ราคาประหยัด ควบคุมค่าใช้จ่ายได้อย่างเด็ดขาด | G8: 1: ไม่มีงบสำรองอะไหล่เลย (0%) หากชิ้นส่วนเสียหายชิ้นเดียว โครงการหยุดชะงักทันที (Fatal Flaw) 2: มีงบสำรองอะไหล่เพียง 10-20% ซื้ออะไหล่ทดแทนได้เฉพาะชิ้นส่วนเล็ก ๆ 3: มีงบสำรองอะไหล่ประมาณ 50% สามารถสำรองเซนเซอร์ได้แต่ไม่มีบอร์ดหลักสำรอง 4: มีงบสำรองอะไหล่ 80-100% สำหรับเซนเซอร์และบอร์ดหลักบางส่วน 5: มีงบสำรองอะไหล่ 100% ครอบคลุมเซนเซอร์ 3 ชุด และบอร์ดประมวลผล 2 ชุด ภายใต้งบรวมไม่เกิน 5,000 บาท | H8: 1: ค่าใช้จ่ายในการดำเนินงานและบำรุงรักษา (OpEx) สูงกว่ามูลค่าทรัพยากรที่ประหยัดได้ ไม่คุ้มทุนทางเศรษฐศาสตร์ (Fatal Flaw) 2: ประหยัดทรัพยากรได้น้อยมากเมื่อหักลบค่าซิมการ์ด ค่าไฟฟ้า และค่าแรงบำรุงรักษา 3: จุดคุ้มทุนปานกลาง ใช้เวลามากกว่า 1-2 ปีในการคืนทุนค่าน้ำมันรถ 4: ประหยัดค่าน้ำมันและค่าเบี้ยเลี้ยงเจ้าหน้าที่ได้ชัดเจน คุ้มทุนภายในฤดูมรสุมเดียว 5: ลดการปล่อยรถเก้อได้ 30-40% ประหยัดงบประมาณค่าน้ำมันและค่าสึกหรอของเมืองได้หลายหมื่นบาทต่อปี โดยระบบกินไฟต่ำมาก | I8: 1: ละเมิดกฎหมายอย่างร้ายแรง (เช่น บันทึกภาพบุคคลผิด PDPA หรือเปิดฝาท่อบนทางหลวงโดยไม่ได้รับอนุญาต / Fatal Flaw) 2: สุ่มเสี่ยงต่อการละเมิดกฎหมาย ต้องใช้กระบวนการทางเทคนิคที่ซับซ้อนช่วยลดทอนและยังไม่มีเอกสารยินยอม 3: มีข้อตกลงเบื้องต้นหรือใช้วิธีเบลอภาพอัตโนมัติ แต่ยังต้องรอการอนุมัติระเบียบอย่างเป็นทางการ 4: ปฏิบัติตามกฎหมายอย่างถูกต้อง มีการขออนุญาตติดตั้งตามระเบียบองค์กร และไม่มีการเก็บข้อมูลส่วนบุคคลที่เป็นอันตราย 5: ปลอดจากการละเมิดกฎหมาย 100% ไม่เก็บข้อมูลระบุตัวตน (No PII) และติดตั้งบนโครงสร้างสะพานอย่างปลอดภัยตามระเบียบ | J8: 1: ใช้อุปกรณ์ส่งคลื่นวิทยุผิดกฎหมาย กสทช. หรือไม่มีช่องทางติดต่อประสานงานหน่วยงานรัฐเลยแม้แต่น้อย (Fatal Flaw) 2: อุปกรณ์ไม่ได้รับการรับรอง และการประสานงานอาศัยเพียงจดหมายทางการที่ไม่มีการตอบรับ 3: อุปกรณ์ได้รับรอง แต่การขออนุญาตเข้าพื้นที่สาธารณะต้องผ่านกระบวนการทำ MoU ล่าช้า 4: ใช้โมดูลสื่อสารที่ได้รับใบรับรอง กสทช. ถูกต้อง และมีอาจารย์ที่ปรึกษาช่วยเปิดช่องทางประสานงาน 5: โมดูลสื่อสารผ่านมาตรฐาน กสทช. 100% และมีเครือข่ายความร่วมมือทางวิชาการกับสำนักการระบายน้ำ กทม. ดำเนินการได้อย่างรวดเร็ว | K8: 1: ระบบให้เพียงตัวเลขที่ไม่มีหลักฐานเชิงประจักษ์ เจ้าหน้าที่ไม่กล้าใช้ตัดสินใจเพราะกลัวถูกสอบวินัย (Fatal Flaw) 2: เจ้าหน้าที่ปฏิเสธการใช้งานเนื่องจากไม่สอดคล้องกับขั้นตอนการทำงานปกติ 3: เจ้าหน้าที่ยอมรับเฉพาะบางกรณี และยังคงต้องส่งรถออกไปถ่ายรูปปิดเคสหน้างานอยู่ดี 4: ระบบสร้างรายงานดิจิทัลพร้อมหลักฐานชัดเจนที่หัวหน้างานให้การยอมรับในการชะลอการปล่อยรถ 5: ระบบสร้างใบปิดงานดิจิทัล (Digital Evidence Card) ที่ระบุค่า dh/dt พิกัด และเวลา ที่ กทม. ยอมรับเป็นรูปภาพปิดเคสใน Traffy Fondue ได้ทันที | L8: 1: ใช้งานยากมาก สร้างภาระงานหนักแก่เจ้าหน้าที่ และต้องใช้ช่างผู้เชี่ยวชาญดูแลรายวัน (Fatal Flaw) 2: ต้องฝึกอบรมเจ้าหน้าที่หลายวันและมีขั้นตอนการบำรุงรักษาที่ยุ่งยากซับซ้อน 3: ต้องมีการฝึกอบรมเจ้าหน้าที่ 1-2 ชั่วโมง และต้องคอยเช็ดทำความสะอาดระบบทุกเดือน 4: เจ้าหน้าที่เข้าใจได้ง่ายภายใน 15 นาที การติดตั้งสะดวกรวดเร็ว 5: ติดตั้งเสร็จใน 10 นาทีด้วยแคลมป์รัด ไม่ต้องเจาะทำลายสะพาน แดชบอร์ดแสดงสถานะ ชะลอ/ปล่อยรถ ชัดเจน ไม่ต้องอบรม | M8: 1: ต้องลงไปปฏิบัติงานในพื้นที่อันตรายถึงชีวิต (เช่น ท่อระบายน้ำอับอากาศ หรือช่องจราจรความเร็วสูง) เพียงลำพัง (Fatal Flaw) 2: ปฏิบัติงานในพื้นที่เสี่ยงสูงโดยไม่มีอุปกรณ์คุ้มครองความปลอดภัยส่วนบุคคลที่เพียงพอ 3: ปฏิบัติงานริมถนนสาธารณะที่มีความเสี่ยงปานกลาง ต้องมีเพื่อนร่วมงานคอยดูแลความปลอดภัยตลอดเวลา 4: ปฏิบัติงานบนทางเท้าหรือสะพานลอยคนข้ามที่มีรั้วกั้นปลอดภัย สวมใส่อุปกรณ์สะท้อนแสง 5: ติดตั้งบนราวสะพานคนข้ามที่ปลอดภัย 100% และสามารถทดสอบระบบจำลองบนโต๊ะแล็บได้เกือบทั้งหมดก่อนลงพื้นที่จริง | N8: 1: โครงการหยุดชะงักอย่างสิ้นเชิงจากช่วงสอบ 4 สัปดาห์ และไม่สามารถส่งมอบงานได้ทันสัปดาห์ที่ 16 (Fatal Flaw) 2: ติดสอบจนงานล่าช้ากว่ากำหนดมากกว่า 3 สัปดาห์ และต้องตัดทอนระบบสำคัญออก 3: งานล่าช้าเล็กน้อยและต้องเร่งทำงานอย่างหนักหลังสอบเสร็จ ไม่มีเวลาทดสอบรวมระบบ 4: แผนงานจัดสรรเวลาได้ดี สามารถหยุดอ่านหนังสือสอบได้โดยโครงการยังอยู่ในกรอบเวลา 5: สถาปัตยกรรมแยกส่วนชัดเจน โค้ดหลักเสร็จก่อนสอบกลางภาค และฮาร์ดแวร์ COTS ประกอบเสร็จทันทีหลังสอบ มีเวลาเหลือเฟือ | O8: 1: ไม่สามารถบรรลุเกณฑ์ TRL ขั้นต่ำ (TRL 2 ภายในสัปดาห์ที่ 9) ได้เลย (Fatal Flaw) 2: บรรลุเกณฑ์ TRL ได้ล่าช้ากว่ากำหนดมากกว่า 2 สัปดาห์ 3: บรรลุ TRL 2 ได้ทัน แต่ TRL 3 และ TRL 4 ต้องลดทอนข้อกำหนดลงอย่างมาก 4: บรรลุเกณฑ์ TRL 2, TRL 3, และ TRL 4 ได้ตามกรอบเวลาของรายวิชาเกือบครบถ้วน 5: บรรลุ TRL 2 ในสัปดาห์ 9 (Mathematical Model), TRL 3 ในสัปดาห์ 13 (Bench PoC), และ TRL 4 ในสัปดาห์ 16 (Canal/Lab) ได้อย่างสมบูรณ์แบบ | P8: 1: อุปกรณ์ต้องนำเข้าต่างประเทศใช้เวลาขนส่ง 4-6 สัปดาห์ ทำลายเส้นทางวิกฤตของโปรเจกต์ 16 สัปดาห์ (Fatal Flaw) 2: อุปกรณ์จัดส่งล่าช้า 2-3 สัปดาห์ ทำให้ไม่มีเวลาสำหรับการทดสอบและแก้ไขจุดบกพร่อง 3: มี Buffer เวลาสำหรับการทดสอบรวมระบบเพียง 1 สัปดาห์ เสี่ยงต่อการส่งงานไม่ทันหากมีข้อผิดพลาด 4: อุปกรณ์จัดส่งภายใน 5-7 วัน มี Buffer สำหรับการรวมระบบและแก้บักอย่างน้อย 2 สัปดาห์ 5: อุปกรณ์ทุกชิ้นมีสต็อกในประเทศ จัดส่งถึงภายใน 2-3 วันทำการ มี Buffer รวมระบบก่อนส่งมอบมากกว่า 3 สัปดาห์ | Q8: 1: ไม่สอดคล้องกับเป้าหมายความยั่งยืนใด ๆ หรือสร้างผลกระทบเชิงลบต่อการจัดการภัยพิบัติ (Fatal Flaw) 2: สอดคล้องในเชิงทฤษฎีเท่านั้น แต่ไม่มีผลลัพธ์หรือตัวชี้วัดที่จับต้องได้ในทางปฏิบัติ 3: ส่งเสริมการเฝ้าระวังทางอ้อม แต่ไม่สามารถวัดผลการลดความสูญเสียได้อย่างชัดเจน 4: ช่วยลดเวลาในการเข้าถึงพื้นที่น้ำท่วมขัง และมีตัวชี้วัดความสำเร็จที่สอดคล้องกับ SDG 11.5 5: ตอบโจทย์ SDG 11.5 (ลดความสูญเสียทางเศรษฐกิจ) และ SDG 6.3 (เฝ้าระวังระบบระบายน้ำ) อย่างชัดเจน ปลดล็อกกำลังพลช่วยเหลือพื้นที่วิกฤตได้เร็วขึ้น | R8: 1: ใช้วัสดุที่ชะสารพิษลงน้ำ หรืออุปกรณ์เสี่ยงหลุดลอยไปอุดตันท่อระบายน้ำกลายเป็นมลพิษ (Fatal Flaw) 2: มีความเสี่ยงที่อุปกรณ์จะเสื่อมสภาพและปล่อยไมโครพลาสติกหรือสารเคมีลงสู่แหล่งน้ำ 3: อุปกรณ์ปลอดภัยในสภาวะปกติ แต่อาจชำรุดเสียหายหากเกิดกระแสน้ำหลากฉับพลัน 4: อุปกรณ์ติดตั้งเหนือน้ำ กล่องกันน้ำมิดชิด มีการป้องกันการหลุดร่วงอย่างเหมาะสม 5: ตัวกล่องมาตรฐาน IP67 ไม่สัมผัสน้ำ มีสลิงนิรภัยสแตนเลสยึดสองชั้น และใช้แบตเตอรี่แห้งปลอดภัยที่ไม่ปล่อยสารเคมี 100% | S8: 1: อัลกอริทึมเลือกปฏิบัติต่อพื้นที่ หรือตัดการให้บริการแก่ชุมชนยากจนอย่างไม่เป็นธรรม (Fatal Flaw) 2: มีความเหลื่อมล้ำเชิงพื้นที่สูง ระบบทำงานได้เฉพาะเขตเมืองชั้นในที่ร่ำรวย ละเลยชุมชนชานเมือง 3: มีความเหลื่อมล้ำเล็กน้อยตามปริมาณข้อมูลหรือสัญญาณเครือข่าย แต่ไม่ได้เลือกปฏิบัติโดยเจตนา 4: ระบบกระจายการให้บริการอย่างทั่วถึง และมีกลไกชดเชยสำหรับพื้นที่ที่มีข้อมูลน้อย 5: ใช้อัตราการลดระดับน้ำตามกฎฟิสิกส์ชลศาสตร์เป็นเกณฑ์สากลอย่างเสมอภาคเท่าเทียม ไม่ขึ้นกับฐานะทางเศรษฐกิจหรือเสียงร้องเรียน | T8: เกณฑ์รวม: >=80 ผ่านสูง, >=60 มีเงื่อนไข, <60 เสี่ยงสูง | หากมีข้อใดได้ 1 = VETOED ตกเกณฑ์ทันที
A9: คะแนนที่ได้รับ (ASSIGNED SCORE: 1, 2, 3, 4, 5 STRICT INTEGER) | B9: 4 | C9: 4 | D9: 5 | E9: 4 | F9: 5 | G9: 5 | H9: 4 | I9: 5 | J9: 4 | K9: 3 | L9: 4 | M9: 4 | N9: 4 | O9: 5 | P9: 5 | Q9: 5 | R9: 5 | S9: 5 | T9: =IF(T10>0, (T11/T10)*20, 0)
A10: ค่าน้ำหนัก (Weight %) | B10: 0.05 | C10: 0.05 | D10: 0.05 | E10: 0.05 | F10: 0.0667 | G10: 0.0667 | H10: 0.0666 | I10: 0.075 | J10: 0.075 | K10: 0.0667 | L10: 0.0667 | M10: 0.0666 | N10: 0.05 | O10: 0.05 | P10: 0.05 | Q10: 0.0333 | R10: 0.0333 | S10: 0.0334 | T10: =SUM(B10:S10)
A11: คะแนนถ่วงน้ำหนัก (=Score * Weight) | B11: =B9*B10 | C11: =C9*C10 | D11: =D9*D10 | E11: =E9*E10 | F11: =F9*F10 | G11: =G9*G10 | H11: =H9*H10 | I11: =I9*I10 | ... S11: =S9*S10 | T11: =SUM(B11:S11)
A12: คำอธิบาย & หลักฐานอ้างอิงจากไฟล์ Intake (Evidence Citation) | B12: อ้างอิง solution-1.md ข้อจำกัดทางกายภาพ: ต้องทนฝนและน้ำขัง อ้างอิง team-skills/jk.md หัวข้อ Mechanic: ใช้ SOLIDWORKS ได้แต่ไม่สามารถเข้าถึง Machine Shop ได้ จึงแก้ปัญหาด้วยกล่องสำเร็จรูป COTS | C12: อ้างอิง solution-1.md ข้อ Requirements b: ใช้เซนเซอร์วัดระดับน้ำและวัดการไหล อ้างอิง team-skills/jk.md หัวข้อ Electronics: ไม่เคยออกแบบ PCB และบัดกรีไม่เก่ง แต่เข้าใจการต่อวงจร IC และใช้บอร์ดสำเร็จรูปได้ กินไฟต่ำ ไม่มีความร้อนสะสม | D12: อ้างอิง solution-1.md ข้อ Requirements a: คำนวณ dh/dt เทียบกับเวลาเดินทาง QRT 20-30 นาที อ้างอิง team-skills/jk.md หัวข้อ Programming: JK เชี่ยวชาญ Python, C++, ROS2, Linear Algebra และ Differential Equations ขั้นสูง | E12: อ้างอิง solution-1.md ข้อ Constraints a: เซนเซอร์อาจประเมินค่าผิดพลาดจากขยะลอยและคลื่นผิวน้ำ แต่แก้ไขได้ด้วยการติดตั้งเซนเซอร์แบบไม่สัมผัสน้ำ (Non-contact) และใช้ตัวกรองเชิงสถิติ | F12: อ้างอิง solution-1.md ข้อ Requirements: ใช้อุปกรณ์ COTS ทั่วไป คำนวณงบประมาณต้นแบบบนโต๊ะทดลองไม่เกิน 3,500 บาท (JSN-SR04T ~120 บ., ESP32 ~150 บ., โมเด็ม 4G ~800 บ., กล่อง IP67 ~150 บ.) | G12: ราคาต่อหน่วยของอุปกรณ์ COTS ต่ำมาก ทำให้สามารถซื้อบอร์ดสำรอง 2 ชุดและเซนเซอร์สำรอง 3 ชุดได้โดยอยู่ในงบสำรอง 1,500 บาท รวมงบประมาณทั้งสิ้น 5,000 บาทพอดี | H12: อ้างอิง solution-1.md ข้อ Leverage Point: มุ่งลดการสะสมของ False Flags และลดการเสียเวลาและทรัพยากรของเจ้าหน้าที่หน้างาน โดยอุปกรณ์ใช้แบตเตอรี่ LiFePO4 อยู่ได้นานหลายเดือน | I12: อ้างอิง solution-1.md ข้อ Requirements c: ตัดสินใจใช้ Local Ultrasonic Sensors วัดเฉพาะระยะห่างผิวน้ำ ปลอดจากข้อมูลระบุตัวตน (No PII) 100% จึงไม่มีความเสี่ยงต่อ พ.ร.บ. PDPA และติดตั้งบนราวสะพานไม่กีดขวางทางสัญจร | J12: เลือกใช้โมดูล 4G LTE มาตรฐานอุตสาหกรรม (เช่น SIM7600) ที่ได้รับใบรับรองจาก กสทช. ถูกต้อง และอ้างอิง team-skills/jk.md ที่มีอาจารย์ที่ปรึกษามีเครือข่ายความร่วมมือทางวิชาการกับสำนักการระบายน้ำ กทม. | K12: อ้างอิง solution-1.md ข้อ Constraints b: ขั้นตอนการดำเนินงานต้องมี Evidences ส่งคืนประชาชน ทำให้เกิดการบังคับให้เจ้าหน้าที่ต้องลงหน้างานเพื่อถ่ายรูปปิดเคสใน Traffy Fondue | L12: การออกแบบเน้นกล่อง COTS ที่มีแคลมป์รัดท่อแบบ Universal ไม่ต้องเจาะทำลายสะพาน และส่งข้อมูลผ่านสัญญาณมือถือขึ้น Web Dashboard แบบ Standalone โดยตรง | M12: อ้างอิง team-skills/jk.md เป็นนักศึกษาทำงานเดี่ยว (Solo Developer). ตำแหน่งติดตั้งเซนเซอร์อัลตราโซนิกอยู่บนราวสะพานข้ามคลอง ผู้พัฒนาสามารถยืนติดตั้งจากบนสะพานได้อย่างปลอดภัย ไม่ต้องลงน้ำหรือลงผิวจราจร | N12: อ้างอิง schedule-details/schedule.md ระบุชัดเจนว่ามีช่วงสอบกลางภาคและปลายภาครวม 4 สัปดาห์. โครงสร้างซอฟต์แวร์ของ Solution 1 สามารถทดสอบล่วงหน้าบนคอมพิวเตอร์ด้วยข้อมูลจำลองได้ ทำให้ไม่สะดุดช่วงสอบ | O12: อ้างอิง schedule-details/schedule.md: สัปดาห์ 9 ส่งสมการ Recession Rate (TRL 2), สัปดาห์ 13 ประกอบเซนเซอร์ทดสอบกับถังน้ำบนโต๊ะ (TRL 3), สัปดาห์ 16 ทดสอบกับคลองมหาวิทยาลัย (TRL 4) สอดคล้องกับทักษะของ JK | P12: อุปกรณ์ทุกชิ้น (ESP32, JSN-SR04T, กล่อง IP67, โมเด็ม 4G) มีสต็อกพร้อมส่งในประเทศไทย จัดส่งถึงภายใน 2-3 วันทำการ ทำให้มี Buffer รวมระบบมากกว่า 3 สัปดาห์ | Q12: อ้างอิง sdg-rulebook/goals/goal-11.md ตัวชี้วัด 11.5.2 และ goal-06.md ตัวชี้วัด 6.3.2: การกรอง Empty Cases ช่วยปลดล็อกกำลังพลของ QRT ให้สามารถเข้าช่วยเหลือจุดวิกฤตน้ำท่วมขังรุนแรงได้อย่างทันท่วงที | R12: อ้างอิง sdg-rulebook/goals/goal-06.md ตัวชี้วัด 6.3.2: อุปกรณ์ติดตั้งเหนือน้ำ ไม่สัมผัสน้ำโดยตรง กล่องปิดสนิท และมีสลิงนิรภัยสแตนเลสยึดกับโครงสร้างสะพานป้องกันตัวเครื่องหลุดลอยยามน้ำหลาก | S12: อ้างอิง sdg-rulebook/goals/goal-10.md: การตัดสินใจใช้สมการชลศาสตร์ทางกายภาพเป็นเกณฑ์เดียวกันทุกพื้นที่ ทำให้ทุกชุมชนได้รับการประเมินตามสภาพน้ำท่วมจริงอย่างเสมอภาค ไม่ถูกเลือกปฏิบัติ | T12: =IF(MIN(B9:S9)=1, "VETOED / ตกเกณฑ์ข้อบังคับวิกฤต (คะแนนระดับ 1)", IF(T9>=80, "ผ่านเกณฑ์ระดับสูง (HIGHLY VIABLE)", IF(T9>=60, "ผ่านแบบมีเงื่อนไข (CONDITIONALLY VIABLE)", "ความเสี่ยงสูง (HIGH RISK)")))
A13: แผนลดขอบเขตงาน & มาตรการลดความเสี่ยง (De-scoping Action) | B13: จัดซื้อกล่องพักสายไฟกันน้ำมาตรฐาน IP67 (~150 บาท) และแคลมป์รัดเสาสำเร็จรูป จำกัดการพิมพ์ 3D ไว้เฉพาะตัวยึดภายในกล่องเท่านั้น | C13: ห้ามออกแบบ Custom PCB เด็ดขาด ให้ใช้ Screw Terminal Expansion Shield สำเร็จรูปที่มีระบบป้องกันไฟกระชากในตัว | D13: พัฒนาเป็นโมดูลคำนวณอัตราการลดระดับน้ำด้วย Python/ROS2 พร้อมชุดทดสอบ Unit Test จำลองกราฟการระบายน้ำของ กทม. | E13: นำแบบจำลองการระบายน้ำของ Ann Arbor มาปรับใช้ร่วมกับการกำหนดค่าเผื่อความปลอดภัย (Safety Margin) ที่รัดกุม | F13: สั่งซื้ออุปกรณ์อิเล็กทรอนิกส์ทั้งหมดจากผู้จัดจำหน่ายในไทยเพื่อตัดค่าขนส่งระหว่างประเทศและควบคุมงบประมาณอย่างเด็ดขาด | G13: จัดซื้อเซนเซอร์และตัวแปลงไฟสำรองตั้งแต่สัปดาห์แรกของการเริ่มโครงการ เพื่อป้องกันความล่าช้ากรณีชิ้นส่วนเสียหาย | H13: คำนวณตัวเลขค่าน้ำมันและชั่วโมงการทำงานของเจ้าหน้าที่ที่ประหยัดได้ต่อปีเพื่อนำเสนอในเล่มรายงาน Final | I13: ระบุในเอกสารข้อกำหนดระบบอย่างเป็นทางการว่าไม่มีการเก็บภาพถ่ายหรือข้อมูลส่วนบุคคล เพื่อหลีกเลี่ยงกระบวนการขออนุญาต PDPA | J13: ให้อาจารย์ที่ปรึกษาออกหนังสือนำทางวิชาการสำหรับการขอทดสอบติดตั้งอุปกรณ์บนสะพานคลองในเขตมหาวิทยาลัยก่อน | K13: พัฒนาฟังก์ชันสร้าง Digital Evidence Card แนบกราฟอัตราน้ำลดลงส่งเข้าสู่ระบบ Traffy Fondue โดยตรง และนัดประชุมชี้แจงหัวหน้าฝ่ายระบายน้ำเพื่อขออนุมัติระเบียบการปิดเคสดิจิทัล | L13: ออกแบบ Web UI ให้เรียบง่ายที่สุด โดยแสดงแถบสถานะสีเขียว (แห้งเองได้) และสีแดง (ต้องส่งรถ) พร้อมปุ่มกดคัดลอกข้อความสรุปเหตุการณ์ | M13: ดำเนินการทดสอบระบบบนโต๊ะทดลองและคลองทดสอบภายในมหาวิทยาลัยให้สมบูรณ์ 100% ก่อน และสวมเสื้อสะท้อนแสงทุกครั้งที่ลงพื้นที่จริง | N13: เร่งรัดการล็อกสเปกฮาร์ดแวร์และเขียนโค้ดอัลกอริทึม dh/dt ให้เสร็จสมบูรณ์ 100% ก่อนเข้าสู่สัปดาห์สอบกลางภาค (สัปดาห์ที่ 9) | O13: กำหนดให้เกณฑ์ผ่าน TRL 3 เป็นการทดสอบในถังน้ำในห้องแล็บ เพื่อรับประกันว่าจะผ่านเกณฑ์ได้โดยไม่ต้องพึ่งพาสภาพฝนตกจริง | P13: จัดซื้ออุปกรณ์ทั้งหมดจากร้านค้าออนไลน์ในไทยในสัปดาห์แรก และปฏิเสธการสั่งซื้อชิ้นส่วนนำเข้าจากต่างประเทศทุกกรณี | Q13: รวบรวมสถิติการลดเวลาเดินทางและจำนวนเคสที่ได้รับการแก้ไขเร็วขึ้นเพื่อใช้เป็นตัวชี้วัดความสำเร็จตาม SDG 11.5 ในรายงานขั้นสุดท้าย | R13: ติดตั้งสายสลิงนิรภัยสองชั้น (Dual Safety Tether) และใช้แบตเตอรี่ LiFePO4 ที่มีความปลอดภัยสูงและไม่มีสารพิษรั่วไหล | S13: กำหนดให้อัลกอริทึมใช้พารามิเตอร์ทางชลศาสตร์มาตรฐานเดียวกันทุกจุดติดตั้ง เพื่อรักษาความเสมอภาคตาม SDG 10 | T13: ปฏิบัติตามแผนลดขอบเขตงาน (De-scoping Advisory)

Sheet Solution-2
A1: เมทริกซ์ประเมินความเป็นไปได้เชิงระบบ TELOS+S: 2-Factor Authentication Dispatch Filtering Layer (PUB Singapore CWOS)
A2: ระบบคะแนนจำนวนเต็มเด็ดขาด: 1, 2, 3, 4, 5 เท่านั้น (ไม่มีจุดทศนิยม / ไม่มี 0.5) | โครงสร้างแบบ Transposed แนวนอน
A4: รหัสคำถาม (Question Code) | B4: T-01 | C4: T-02 | D4: T-03 | E4: T-04 | F4: E-01 | G4: E-02 | H4: E-03 | I4: L-01 | J4: L-02 | K4: O-01 | L4: O-02 | M4: O-03 | N4: S-01 | O4: S-02 | P4: S-03 | Q4: SDG-01 | R4: SDG-02 | S4: SDG-03 | T4: สรุปภาพรวม (SUMMARY)
A5: มิติการประเมิน (TELOS+S Pillar) | B5: ด้านเทคนิค (Technical 2.2) | C5: ด้านเทคนิค (Technical 2.2) | D5: ด้านเทคนิค (Technical 2.2) | E5: ด้านเทคนิค (Technical 2.2) | F5: ด้านเศรษฐศาสตร์ (Economic 2.3) | G5: ด้านเศรษฐศาสตร์ (Economic 2.3) | H5: ด้านเศรษฐศาสตร์ (Economic 2.3) | I5: ด้านกฎหมายและหน่วยงาน (Legal 2.4) | J5: ด้านกฎหมายและหน่วยงาน (Legal 2.4) | K5: ด้านการปฏิบัติการและผู้ใช้ (Operational 2.5) | L5: ด้านการปฏิบัติการและผู้ใช้ (Operational 2.5) | M5: ด้านการปฏิบัติการและผู้ใช้ (Operational 2.5) | N5: ด้านเวลาและแผนงาน (Schedule 2.6) | O5: ด้านเวลาและแผนงาน (Schedule 2.6) | P5: ด้านเวลาและแผนงาน (Schedule 2.6) | Q5: ด้านความยั่งยืน (SDGs 2.7) | R5: ด้านความยั่งยืน (SDGs 2.7) | S5: ด้านความยั่งยืน (SDGs 2.7) | T5: ผลรวมทุกมิติ (All Pillars)
A6: คำถามทดสอบความเสี่ยงจริง (Stress-Test Question) | B6: เมื่อพิจารณาว่าผู้พัฒนาไม่มีทักษะการกลึง/ตัดโลหะและไม่สามารถเข้าถึงโรงประลอง (Machine Shop) ได้ โครงสร้างฮาร์ดแวร์ภายนอกของระบบสามารถประกอบขึ้นจากอุปกรณ์สำเร็จรูปมาตรฐาน (COTS) เพื่อทนต่อสภาวะแวดล้อมน้ำท่วม/มรสุมของ กทม. ได้อย่างสมบูรณ์หรือไม่? | C6: เมื่อพิจารณาว่าผู้พัฒนาไม่มีทักษะการออกแบบ Custom PCB และมีทักษะการบัดกรีต่ำ สถาปัตยกรรมฮาร์ดแวร์อิเล็กทรอนิกส์และวงจรของระบบสามารถติดตั้งและทำงานได้อย่างมีเสถียรภาพโดยไม่เกิดความร้อนสะสมหรือวงจรล้มเหลวหรือไม่? | D6: ความสามารถและอัลกอริทึมในการตรวจวัดและทำนายระดับน้ำหรือการระบายน้ำ สามารถประมวลผลและให้ผลลัพธ์ที่แม่นยำได้ทันก่อนกรอบเวลาเดินทางของทีม QRT (20-30 นาที) หรือไม่? | E6: ระบบมีความแข็งแกร่ง (Robustness) ต่อปัจจัยรบกวนในสิ่งแวดล้อมจริงของ กทม. (เช่น คราบสิ่งสกปรก ขยะลอย ทัศนวิสัยต่ำตอนฝนตกหนัก น้ำทะเลหนุน) โดยไม่เกิดความล้มเหลวในการตรวจวัดหรือไม่? | F6: งบประมาณจัดซื้ออุปกรณ์ต้นแบบ (BOM) ทั้งหมด สามารถควบคุมให้อยู่ภายใต้เพดานงบประมาณโครงงานนักศึกษา (< 5,000 บาท) ได้อย่างแท้จริงหรือไม่? | G6: โครงการได้จัดสรรงบประมาณสำรองสำหรับอะไหล่ทดแทน 100% (Scrap Allowance) กรณีอุปกรณ์ลัดวงจรหรือเสียหายจากการทดสอบหน้างานจริงหรือไม่? | H6: ค่าใช้จ่ายในการบำรุงรักษาและทำความสะอาดอุปกรณ์ (OpEx) คุ้มค่าเมื่อเทียบกับต้นทุนค่าน้ำมันและกำลังพลที่ประหยัดได้จากการลดการปล่อยรถ QRT ไปเก้อหรือไม่? | I6: การติดตั้งและปฏิบัติการของระบบ สอดคล้องกับกฎหมายคุ้มครองข้อมูลส่วนบุคคล (PDPA), กฎหมายจราจร, และระเบียบความปลอดภัยในที่สาธารณะโดยไม่ละเมิดข้อบังคับหรือไม่? | J6: อุปกรณ์สื่อสารไร้สายได้รับการรับรองมาตรฐานจาก กสทช. (NBTC) และทีมงานมีความพร้อมในการประสานงานขอความร่วมมือจากหน่วยงานภาครัฐ (กทม./สำนักการระบายน้ำ) หรือไม่? | K6: ระบบสามารถสร้างหลักฐานยืนยันที่สอดคล้องกับระเบียบการปิดงาน (Proof of Work) ของ กทม./Traffy Fondue โดยไม่ต้องบังคับให้เจ้าหน้าที่ต้องเดินทางไปถ่ายรูปซ้ำซ้อนหรือไม่? | L6: ความซับซ้อนในการติดตั้ง การบำรุงรักษา และการใช้งานโดยเจ้าหน้าที่หน้างาน (Usability & Maintainability) อยู่ในระดับที่เหมาะสมและไม่สร้างภาระงานเพิ่มเติมหรือไม่? | M6: การทดสอบและติดตั้งระบบจริงหน้างาน สามารถกระทำได้อย่างปลอดภัยโดยไม่เสี่ยงต่อชีวิตของผู้พัฒนาหรือประชาชนผู้ใช้ทางหรือไม่? | N6: แผนงานและสถาปัตยกรรมระบบสามารถดูดซับช่วงสอบกลางภาค/ปลายภาคของมหาวิทยาลัย (Buffer Time 4 สัปดาห์) โดยโครงการไม่ล่าช้ากว่ากำหนดหรือไม่? | O6: ความก้าวหน้าทางวิศวกรรมสามารถบรรลุเกณฑ์การทำงานได้จริง (Working Prototype) ภายในสัปดาห์ที่ 9 ก่อนการประเมินความก้าวหน้าหลักหรือไม่? | P6: ระยะเวลาในการสั่งซื้อและขนส่งอุปกรณ์ (Lead Time) สอดคล้องกับกรอบเวลาของภาคการศึกษา โดยชิ้นส่วนหลักทั้งหมดมาถึงภายใน 14 วันหรือไม่? | Q6: ระบบส่งเสริมการลดความสูญเสียจากภัยพิบัติและสนับสนุนเมืองที่มีความยืดหยุ่นและยั่งยืน (สอดคล้องกับ SDG 11.5 และ SDG 13.1) หรือไม่? | R6: อุปกรณ์ที่นำไปติดตั้ง ไม่เสี่ยงต่อการชะล้างกลายเป็นขยะในท่อระบายน้ำ และใช้วัสดุที่ทนทาน ปลอดสารอันตราย และเป็นมิตรต่อสิ่งแวดล้อม (สอดคล้องกับ SDG 6.3 และ SDG 12.4/12.5) หรือไม่? | S6: ตรรกะการประเมินและการกรองเหตุร้องเรียน มีความโปร่งใส ตรวจสอบย้อนกลับได้ และไม่สร้างความเหลื่อมล้ำในการให้บริการของรัฐต่อประชาชนทุกกลุ่มอย่างเป็นธรรม (สอดคล้องกับ SDG 10.2 และ SDG 16.6) หรือไม่? | T6: ประเมินคำถามทั้งสิ้น 18 ข้อ
A7: เหตุผลในการถาม & โหมดความล้มเหลวที่เฝ้าระวัง (Rationale) | B7: เซนเซอร์โทรมาตรวัดระดับน้ำและเรดาร์น้ำฝนสำหรับปัจจัยที่สอง (Factor 2) สามารถติดตั้งในกล่องกันน้ำ COTS มาตรฐาน IP67 ยึดด้วยแคลมป์รัดเสามาตรฐานอุตสาหกรรม ไม่ต้องพึ่งพาโรงกลึงโลหะ | C7: โหนดตรวจวัดโทรมาตรใช้บอร์ดไมโครคอนโทรลเลอร์ ESP32 สำเร็จรูปพร้อม Screw Terminal Shield สำหรับการต่อสายเซนเซอร์ กินไฟต่ำและไม่มีความร้อนสะสม | D7: ตรรกะการตรวจสอบ 2-Factor Authentication และการจับคู่พิกัด GPS ระหว่างเคส Traffy Fondue กับเซนเซอร์โทรมาตรประมวลผลเสร็จในระดับวินาที รวดเร็วกว่ากรอบเวลาเดินทาง 20-30 นาทีอย่างมาก | E7: การใช้หลักการ 2-Factor Cross-Validation ช่วยลดปัญหา False Alarm จากสัญญาณรบกวนของเซนเซอร์เดี่ยวได้อย่างมีนัยสำคัญ หากเซนเซอร์อ่านค่าผิดแต่ไม่มีประชาชนแจ้ง หรือมีประชาชนแจ้งแต่เซนเซอร์วัดได้ปกติ ระบบจะตั้งเวลาตรวจสอบซ้ำ 15 นาที | F7: ต้นทุนอุปกรณ์โหนดตรวจวัดโทรมาตร COTS (ESP32 + Ultrasonic/Radar + กล่อง IP67 + แบตเตอรี่) อยู่ที่ประมาณ 3,200 - 3,800 บาทต่อชุด อยู่ภายใต้เพดานงบประมาณอย่างสมบูรณ์ | G7: ด้วยต้นทุนต่อชุดที่ต่ำ (~3,500 บาท) งบประมาณที่เหลือสามารถจัดซื้อเซนเซอร์และบอร์ดไมโครคอนโทรลเลอร์สำรองได้ 100% | H7: การลดการปล่อยรถ QRT ไปเก้อได้ 40-50% ช่วยประหยัดค่าน้ำมันรถปฏิบัติการและค่าสึกหรอของ กทม. ได้หลายหมื่นบาทต่อเดือน โดยที่ระบบมีค่าใช้จ่ายซิมข้อมูลเพียง 150-200 บาทต่อเดือน | I7: ระบบประมวลผลเฉพาะระดับน้ำและข้อมูลโทรมาตร ไม่มีการติดตั้งกล้องบันทึกภาพใบหน้าหรือทะเบียนรถ จึงปลอดจากข้อกำหนด PDPA 100% และการติดตั้งโหนดบนราวสะพานหรือเสาสาธารณะทำตามขั้นตอนขออนุญาตหน่วยงาน | J7: ใช้โมดูลสื่อสารที่ผ่านการรับรองจาก กสทช. (NBTC Approved) และการเชื่อมต่อข้อมูลช่วยสนับสนุนการทำงานของศูนย์ควบคุมระบบป้องกันน้ำท่วม กทม. โดยตรง | K7: ระบบสร้าง Digital Evidence Card แสดงกราฟระดับน้ำ เปรียบเทียบกับภาพถ่ายเรื่องร้องเรียน และบันทึกเวลาที่ระดับน้ำลดลงสู่ระดับปกติ เพื่อใช้เป็นหลักฐานปิดเคสบน Traffy Fondue ได้อย่างเป็นทางการ | L7: หน้าจอแสดงผลออกแบบให้แสดงสถานะการยืนยัน 2-Factor แบบชัดเจน (Confirmed vs Holding) เจ้าหน้าที่ศูนย์สั่งการสามารถตัดสินใจได้ทันทีใน 5 วินาทีโดยไม่ต้องตีความข้อมูลทางเทคนิคที่ซับซ้อน | M7: การติดตั้งเซนเซอร์โทรมาตรทำจากบนราวสะพานหรือทางเท้า ไม่ต้องสัมผัสน้ำหรือเปิดฝาท่อบนผิวถนน จึงมีความปลอดภัยสูงมาก ไม่มีความเสี่ยงต่อชีวิตของผู้ปฏิบัติงาน | N7: งานส่วนใหญ่เป็นการพัฒนาระบบซอฟต์แวร์เชื่อมโยง API และกฎการคัดกรอง 2-Factor ซึ่งสามารถทำงานคู่ขนานและทดสอบด้วยข้อมูลจำลอง (Mock Telemetry) ในช่วงสัปดาห์สอบได้ | O7: สามารถส่งมอบระบบต้นแบบที่เชื่อมต่อ Webhook ของ Traffy Fondue กับเซนเซอร์วัดระดับน้ำจำลองและออกผลการคัดกรองได้เสร็จสิ้นก่อนสัปดาห์ที่ 9 | P7: ชิ้นส่วนทั้งหมดเป็นอุปกรณ์อิเล็กทรอนิกส์ COTS ทั่วไปที่มีสต็อกจำหน่ายในประเทศไทย สามารถจัดส่งถึงมือได้ภายใน 2-3 วันทำการ | Q7: การเพิ่มความแม่นยำในการส่งหน่วยเคลื่อนที่เร็ว ช่วยให้เจ้าหน้าที่เข้าถึงจุดวิกฤตจริงได้เร็วขึ้น ลดความเสียหายต่อชีวิตและทรัพย์สินของประชาชนในเขตเมืองจากน้ำท่วมฉับพลัน | R7: อุปกรณ์ติดตั้งเหนือผิวน้ำบนราวสะพานหรือเสาไฟ ไม่ได้อยู่ในทางน้ำ จึงไม่มีความเสี่ยงต่อการหลุดลอยไปอุดตันท่อระบายน้ำ | S7: การใช้เกณฑ์ทางฟิสิกส์ 2 ปัจจัยช่วยขจัดความลำเอียงในการจัดสรรทรัพยากรภาครัฐ ประชาชนทุกกลุ่มได้รับความช่วยเหลือตามระดับความรุนแรงจริงอย่างเสมอภาคและตรวจสอบย้อนหลังได้ | T7: สังเคราะห์จาก AI Agents Group 2
A8: เกณฑ์การให้คะแนน (Scoring Rubric Definition: ระดับ 1, 2, 3, 4, 5 ครบทุกระดับ) | B8: 1: บังคับต้องกลึงหรือตัดขึ้นรูปชิ้นงานโลหะ custom เองทั้งหมดโดยไม่มีเครื่องจักร (Fatal Flaw / ไม่ผ่านเกณฑ์) 2: ต้องจ้างโรงกลึงภายนอกผลิตชิ้นงานเฉพาะจุดโดยไม่มีงบประมาณและเสี่ยงต่อความล่าช้า 3: ใช้ชิ้นงานพิมพ์ 3D PETG ซีลกันน้ำด้วยซิลิโคนมือ ทนทานปานกลางต่อแรงลมมรสุม 4: ใช้กล่องกันน้ำ COTS ร่วมกับขายึดดัดแปลงเล็กน้อย มีการทดสอบการรั่วซึมเบื้องต้น 5: ใช้กล่องกันน้ำสำเร็จรูปมาตรฐาน IP67/68 ร่วมกับแคลมป์รัดท่อ/เสามาตรฐานอุตสาหกรรมที่มีขายทั่วไป ไม่ต้องดัดแปลง | C8: 1: บังคับต้องออกแบบและผลิต Custom PCB หลายชั้นเองโดยไม่มีทักษะและเวลาไม่พอ (Fatal Flaw) 2: อุปกรณ์ประมวลผลเกิดความร้อนสะสมสูงจัด (เช่น ชิป GPU รันกลางแดด 40°C) เสี่ยงต่อการดับตัวเอง 3: บัดกรีด้วยมือบนแผ่นไข่ปลา (Perfboard) วงจรทนต่อแรงสั่นสะเทือนได้จำกัด 4: ใช้บอร์ดไมโครคอนโทรลเลอร์สำเร็จรูปเชื่อมต่อสายไฟแบบขันสกรู มีการป้องกันสัญญาณรบกวนเบื้องต้น 5: ใช้ Industrial Screw Terminal Shield สำเร็จรูปมาตรฐานอุตสาหกรรม มีวงจรป้องกันไฟกระชากและระบายความร้อนได้ดีเยี่ยม | D8: 1: ต้องพึ่งพาโมเดล AI ข้อมูลมหาศาลที่ยังไม่มีชุดข้อมูล หรืออัลกอริทึมประมวลผลช้าเกินกว่ากรอบเวลา 30 นาที (Fatal Flaw) 2: ใช้อัลกอริทึมที่ซับซ้อนเกินไปจนไม่สามารถรันบนฮาร์ดแวร์จริงได้ทันเวลาเดินทางของ QRT 3: ใช้เกณฑ์ระดับน้ำแบบคงที่ (Static Threshold) ซึ่งแยกเคสฝนตกหนักชั่วคราวไม่ออก 4: ใช้อัลกอริทึมวิเคราะห์อัตราการเปลี่ยนแปลงหรือโมเดลน้ำหนักเบา ประมวลผลได้ภายในไม่กี่วินาที 5: ใช้สมการอนุพันธ์ชลศาสตร์ (dh/dt) คำนวณเทียบเวลาระบายจริง ประมวลผลเสร็จในระดับมิลลิวินาที แม่นยำสูง | E8: 1: ระบบล้มเหลวโดยสิ้นเชิงเมื่อเจอสภาวะแวดล้อมจริง (เช่น ขยะลอย น้ำขุ่น ฝนตกหนัก หรือก๊าซในท่อ) (Fatal Flaw) 2: เซนเซอร์อ่านค่าผิดพลาดบ่อยครั้งเมื่อทัศนวิสัยต่ำหรือมีสิ่งสกปรกเกาะ ต้องอาศัยการรีเซ็ตด้วยมือ 3: ทนต่อสิ่งรบกวนได้ปานกลาง แต่อาจเกิด False Positive ชั่วคราวเมื่อมีฝนตกหนักจัด 4: มีการติดตั้งฮูดกำบัง และใส่อัลกอริทึมกรองสัญญาณรบกวนเชิงสถิติ (Statistical Filter) 5: เซนเซอร์ติดตั้งแบบไม่สัมผัสสิ่งรบกวน พร้อมอัลกอริทึม Median Filter กรองสัญญาณสะท้อนหลอกจากขยะและคลื่นผิวน้ำได้อย่างสมบูรณ์ | F8: 1: งบประมาณ BOM เกิน 20,000 บาท (เกินเพดาน 5,000 บาทของนักศึกษาถึง 4-5 เท่าตัว / Fatal Flaw) 2: งบประมาณ BOM อยู่ระหว่าง 10,000 - 20,000 บาท ต้องจัดหาทุนสนับสนุนภายนอก 3: งบประมาณ BOM อยู่ระหว่าง 5,000 - 10,000 บาท เกินงบส่วนตัวเล็กน้อย ต้องตัดทอนอุปกรณ์ 4: งบประมาณ BOM รวมอยู่ระหว่าง 3,500 - 5,000 บาท พอดีกับเพดานงบประมาณ 5: งบประมาณ BOM รวมต่ำกว่า 3,500 บาท ใช้อุปกรณ์ COTS ราคาประหยัด ควบคุมค่าใช้จ่ายได้อย่างเด็ดขาด | G8: 1: ไม่มีงบสำรองอะไหล่เลย (0%) หากชิ้นส่วนเสียหายชิ้นเดียว โครงการหยุดชะงักทันที (Fatal Flaw) 2: มีงบสำรองอะไหล่เพียง 10-20% ซื้ออะไหล่ทดแทนได้เฉพาะชิ้นส่วนเล็ก ๆ 3: มีงบสำรองอะไหล่ประมาณ 50% สามารถสำรองเซนเซอร์ได้แต่ไม่มีบอร์ดหลักสำรอง 4: มีงบสำรองอะไหล่ 80-100% สำหรับเซนเซอร์และบอร์ดหลักบางส่วน 5: มีงบสำรองอะไหล่ 100% ครอบคลุมเซนเซอร์ 3 ชุด และบอร์ดประมวลผล 2 ชุด ภายใต้งบรวมไม่เกิน 5,000 บาท | H8: 1: ค่าใช้จ่ายในการดำเนินงานและบำรุงรักษา (OpEx) สูงกว่ามูลค่าทรัพยากรที่ประหยัดได้ ไม่คุ้มทุนทางเศรษฐศาสตร์ (Fatal Flaw) 2: ประหยัดทรัพยากรได้น้อยมากเมื่อหักลบค่าซิมการ์ด ค่าไฟฟ้า และค่าแรงบำรุงรักษา 3: จุดคุ้มทุนปานกลาง ใช้เวลามากกว่า 1-2 ปีในการคืนทุนค่าน้ำมันรถ 4: ประหยัดค่าน้ำมันและค่าเบี้ยเลี้ยงเจ้าหน้าที่ได้ชัดเจน คุ้มทุนภายในฤดูมรสุมเดียว 5: ลดการปล่อยรถเก้อได้ 30-40% ประหยัดงบประมาณค่าน้ำมันและค่าสึกหรอของเมืองได้หลายหมื่นบาทต่อปี โดยระบบกินไฟต่ำมาก | I8: 1: ละเมิดกฎหมายอย่างร้ายแรง (เช่น บันทึกภาพบุคคลผิด PDPA หรือเปิดฝาท่อบนทางหลวงโดยไม่ได้รับอนุญาต / Fatal Flaw) 2: สุ่มเสี่ยงต่อการละเมิดกฎหมาย ต้องใช้กระบวนการทางเทคนิคที่ซับซ้อนช่วยลดทอนและยังไม่มีเอกสารยินยอม 3: มีข้อตกลงเบื้องต้นหรือใช้วิธีเบลอภาพอัตโนมัติ แต่ยังต้องรอการอนุมัติระเบียบอย่างเป็นทางการ 4: ปฏิบัติตามกฎหมายอย่างถูกต้อง มีการขออนุญาตติดตั้งตามระเบียบองค์กร และไม่มีการเก็บข้อมูลส่วนบุคคลที่เป็นอันตราย 5: ปลอดจากการละเมิดกฎหมาย 100% ไม่เก็บข้อมูลระบุตัวตน (No PII) และติดตั้งบนโครงสร้างสะพานอย่างปลอดภัยตามระเบียบ | J8: 1: คลื่นวิทยุไม่ผ่าน กสทช. และไม่มีช่องทางติดต่อหน่วยงานรัฐ ถูกสั่งระงับแน่นอน (Fatal Flaw) 2: คลื่นวิทยุผ่านเกณฑ์ แต่การประสานงานราชการมีความล่าช้าสูงเกิน 2 เดือน 3: มีหนังสือรับรองจากมหาวิทยาลัย อยู่ระหว่างการยื่นขออนุญาตใช้พื้นที่ติดตั้ง 4: โมดูลสื่อสารผ่าน กสทช. และมีเครือข่ายความร่วมมือกับเจ้าหน้าที่เขตในระดับปฏิบัติการ 5: โมดูลผ่าน กสทช. 100% และได้รับอนุญาตเป็นลายลักษณ์อักษรจากสำนักการระบายน้ำ กทม. ให้ทดสอบระบบ | K8: 1: ไม่สามารถสร้างหลักฐานใด ๆ ได้ บังคับให้คนต้องลงไปดูหน้างานเหมือนเดิม 100% (Fatal Flaw) 2: สร้างได้เฉพาะตัวเลขดิบที่เจ้าหน้าที่หน้างานอ่านไม่เข้าใจ ต้องแปลผลด้วยผู้เชี่ยวชาญ 3: สร้างรายงานสรุปได้แต่ยังต้องอาศัยรูปถ่ายจากกล้องมือถือของเจ้าหน้าที่ยืนยันซ้ำ 4: ส่งออกบัตรหลักฐานดิจิทัล (Digital Evidence Card) พร้อมระดับความเสี่ยงที่อ่านเข้าใจง่ายใน 3 วินาที 5: เชื่อมต่อ API ปิดเรื่องอัตโนมัติ พร้อมภาพถ่ายกราฟวิเคราะห์และพิกัด GPS ที่ระเบียบราชการยอมรับ | L8: 1: ใช้งานยากมาก ต้องใช้ผู้เชี่ยวชาญระดับปริญญาโทคอยควบคุมตลอดเวลา (Fatal Flaw) 2: มีขั้นตอนการปรับเทียบ (Calibration) หน้างานซับซ้อนเกิน 30 นาทีต่อครั้ง 3: เจ้าหน้าที่ต้องผ่านการอบรมอย่างน้อย 1-2 วันจึงจะใช้งานและบำรุงรักษาได้ 4: ใช้งานง่าย มีคู่มือปฏิบัติการหน้างานชัดเจน บำรุงรักษาได้ด้วยเครื่องมือช่างทั่วไป 5: ทำงานแบบ Plug-and-Play กดปุ่มเดียวทำงานอัตโนมัติ เจ้าหน้าที่หน้างานใช้งานได้ทันทีโดยไม่ต้องอบรมซับซ้อน | M8: 1: มีความเสี่ยงต่อชีวิตอย่างร้ายแรง (เช่น ต้องลุยน้ำเชี่ยวกลางพายุ หรือเปิดฝาท่อบนถนนโดยไม่มีการกั้นทาง / Fatal Flaw) 2: สภาพแวดล้อมหน้างานมีความเสี่ยงปานกลาง ต้องมีอุปกรณ์ป้องกันภัยส่วนบุคคล (PPE) ครบชุดและมีพี่เลี้ยงคุม 3: มีความปลอดภัยปานกลาง ทดสอบได้เฉพาะริมตลิ่งหรือจุดที่มีราวกั้นชัดเจน 4: ปลอดภัยสูง ติดตั้งจากบนสะพานคนเดินหรือผิวทางเท้าโดยไม่ต้องสัมผัสน้ำตรง ๆ 5: ปลอดภัย 100% ออกแบบให้ติดตั้งและทดสอบได้จากระยะไกล มีระบบตัดไฟอัตโนมัติเมื่อเกิดเหตุฉุกเฉิน | N8: 1: แผนงานแน่นเอี้ยดแบบเส้นตรง (Linear Dependency) หากติดสอบเพียง 1 สัปดาห์ โครงการจะพังทันที (Fatal Flaw) 2: มีเวลาสำรองเพียง 3-5 วัน เสี่ยงต่อการส่งมอบงานช้าเมื่อติดภารกิจการเรียน 3: มีเวลาสำรอง 1-2 สัปดาห์ สามารถเลื่อนแผนงานได้บางส่วนแต่ต้องเร่งงานหลังสอบ 4: มี Buffer Time ชัดเจน 3-4 สัปดาห์ และแบ่งงานเป็นโมดูลอิสระที่ทำคู่ขนานกันได้ 5: สถาปัตยกรรมระบบเสร็จสมบูรณ์ตั้งแต่สัปดาห์ที่ 8 มีเวลาทดสอบและปรับปรุงหน้างานมากกว่า 5 สัปดาห์ | O8: 1: มีความเสี่ยงสูงมากที่จะยังไม่มีอุปกรณ์ใด ๆ ทำงานได้ในสัปดาห์ที่ 9 (Fatal Flaw) 2: ในสัปดาห์ที่ 9 ได้เพียงแค่การทดลองบนโต๊ะแล็บแบบแยกส่วน ยังไม่สามารถรวมระบบได้ 3: ในสัปดาห์ที่ 9 ระบบสามารถทำงานร่วมกันได้บนโต๊ะแล็บ แต่อุปกรณ์ยังไม่พร้อมลงน้ำจริง 4: ภายในสัปดาห์ที่ 9 มีต้นแบบฮาร์ดแวร์และซอฟต์แวร์ที่พร้อมนำไปทดสอบในสภาพแวดล้อมจริง 5: ต้นแบบเสร็จสมบูรณ์และผ่านการทดสอบภาคสนามเบื้องต้นเรียบร้อยแล้วตั้งแต่ก่อนสัปดาห์ที่ 9 | P8: 1: ต้องสั่งซื้อชิ้นส่วนพิเศษจากต่างประเทศที่ใช้เวลาส่งเกิน 4-6 สัปดาห์ เสี่ยงต่อการไม่มีของทำโครงงาน (Fatal Flaw) 2: มีชิ้นส่วนหลักบางชิ้นที่ต้องรอของ 3-4 สัปดาห์ ทำให้เริ่มงานฮาร์ดแวร์ได้ช้า 3: ชิ้นส่วนทั้งหมดใช้เวลาจัดส่ง 2-3 สัปดาห์ ต้องเริ่มสั่งซื้อตั้งแต่วันแรกของโครงการ 4: ชิ้นส่วนเกือบทั้งหมดสามารถจัดซื้อในประเทศได้ ได้รับของภายใน 7-10 วัน 5: ชิ้นส่วนทั้งหมด 100% มีจำหน่ายในประเทศและสามารถจัดส่งถึงมือได้ภายใน 2-3 วัน | Q8: 1: โครงการไม่มีส่วนเกี่ยวข้องหรืออาจส่งผลเสียต่อเป้าหมายความยั่งยืน (Fatal Flaw) 2: สนับสนุนความยั่งยืนในทางอ้อมอย่างผิวเผิน แต่ไม่มีตัวชี้วัดที่ชัดเจน 3: ส่งเสริมการลดผลกระทบน้ำท่วมได้บางส่วน แต่จำกัดเฉพาะจุดติดตั้งขนาดเล็ก 4: สอดคล้องกับ SDG 11.5 ชัดเจน ช่วยลดเวลาและพื้นที่น้ำท่วมขังบนถนนสายสำคัญ 5: สอดคล้องกับ SDG 11.5 และ SDG 13.1 อย่างเป็นรูปธรรม มีโมเดลการประเมินลดความสูญเสียทางเศรษฐกิจและภัยพิบัติของเมืองอย่างยั่งยืน | R8: 1: มีความเสี่ยงสูงที่อุปกรณ์จะหลุดลอยกลายเป็นขยะอุดตันท่อระบายน้ำ หรือใช้วัสดุเป็นพิษต่อระบบนิเวศ (Fatal Flaw) 2: อุปกรณ์ใช้วัสดุที่ไม่ทนต่อการกัดกร่อน อาจเกิดการชำรุดและตกค้างในสิ่งแวดล้อม 3: ติดตั้งแข็งแรงปานกลาง มีโอกาสหลุดลอยหากเจอน้ำหลากระดับรุนแรง 4: ใช้วัสดุไม่เป็นพิษ ตัวกล่องปิดมิดชิด มีระบบยึดเหนี่ยวที่แข็งแรงทนทานต่อกระแสน้ำ 5: อุปกรณ์หย่อนชั่วคราวและดึงกลับ 100% พร้อมสายสลิงนิรภัยสองชั้น ปลอดภัยต่อระบบนิเวศน้ำและไม่สร้างขยะในท่อ | S8: 1: ตรรกะของระบบเป็นกล่องดำ (Black Box) หรือลำเอียงตัดการช่วยเหลือในพื้นที่เปราะบาง (Fatal Flaw) 2: เกณฑ์การตัดสินใจไม่ชัดเจน อาจนำไปสู่การเลือกปฏิบัติต่อบางชุมชนโดยไม่ตั้งใจ 3: ตรรกะตรวจสอบได้บางส่วน แต่ยังไม่มีกระบวนการอุทธรณ์หรือทบทวนจากมนุษย์ 4: ตรรกะโปร่งใส มีเกณฑ์คะแนนชัดเจน ให้ความสำคัญกับทุกพื้นที่อย่างเท่าเทียมตามระดับความรุนแรง 5: โปร่งใส 100% ตรวจสอบย้อนกลับได้ทุกการตัดสินใจ สอดคล้องกับ SDG 10.2 และ SDG 16.6 เสริมสร้างธรรมาภิบาลภาครัฐ | T8: เกณฑ์รวม: >=80 ผ่านสูง, >=60 มีเงื่อนไข, <60 เสี่ยงสูง | หากมีข้อใดได้ 1 = VETOED ตกเกณฑ์ทันที
A9: คะแนนที่ได้รับ (ASSIGNED SCORE: 1, 2, 3, 4, 5 STRICT INTEGER) | B9: 4 | C9: 4 | D9: 4 | E9: 4 | F9: 5 | G9: 4 | H9: 5 | I9: 5 | J9: 4 | K9: 4 | L9: 4 | M9: 4 | N9: 4 | O9: 4 | P9: 5 | Q9: 5 | R9: 5 | S9: 5 | T9: =IF(T10>0, (T11/T10)*20, 0)
A10: ค่าน้ำหนัก (Weight %) | B10: 0.05 | C10: 0.05 | D10: 0.05 | E10: 0.05 | F10: 0.0667 | G10: 0.0667 | H10: 0.0666 | I10: 0.075 | J10: 0.075 | K10: 0.0667 | L10: 0.0667 | M10: 0.0666 | N10: 0.05 | O10: 0.05 | P10: 0.05 | Q10: 0.0333 | R10: 0.0333 | S10: 0.0334 | T10: =SUM(B10:S10)
A11: คะแนนถ่วงน้ำหนัก (=Score * Weight) | B11: =B9*B10 | C11: =C9*C10 | D11: =D9*D10 | E11: =E9*E10 | F11: =F9*F10 | G11: =G9*G10 | H11: =H9*H10 | I11: =I9*I10 | ... S11: =S9*S10 | T11: =SUM(B11:S11)
A12: คำอธิบาย & หลักฐานอ้างอิงจากไฟล์ Intake (Evidence Citation) | B12: อ้างอิง solution-2.md ข้อ 3.a ใช้อุปกรณ์ COTS กล่องกันน้ำมาตรฐาน และ team-skills/due.md ที่เชี่ยวชาญการออกแบบเคสและการติดตั้งภายนอก | C12: อ้างอิง team-skills/jk.md และ due.md ที่เชี่ยวชาญ ESP32 เฟิร์มแวร์ และการต่อสายไฟ IC แบบ Screw Terminal | D12: อ้างอิง solution-2.md ข้อ 3.b ระบบประมวลผลคัดกรองแบบ 2 ปัจจัย และ holding 15 นาที | E12: อ้างอิง solution-2.md ข้อ 2 และ 3.a การยืนยันร่วมระหว่างสองแหล่งข้อมูลอิสระ | F12: อ้างอิง BOM ประมาณการ: ESP32 (180 บาท), Ultrasonic Sensor กันน้ำ (350 บาท), กล่อง IP67 (150 บาท), แบตเตอรี่และระบบจ่ายไฟ (800 บาท) | G12: อุปกรณ์ COTS มีราคาถูก สามารถซื้อเซนเซอร์สำรอง 2 ตัว และบอร์ด ESP32 สำรอง 1 ตัวได้ในงบ | H12: อ้างอิง solution-2.md ข้อ 2 การลด Empty Cases ส่งผลตรงต่อการประหยัดน้ำมันเชื้อเพลิงของรถ QRT | I12: อ้างอิง solution-2.md ปลอดจากปัญหา PDPA 100% เพราะไม่ใช้กล้อง CCTV ในการจับภาพบุคคล | J12: โมดูล ESP32 และโมดูล 4G LTE/NB-IoT ได้รับการรับรอง กสทช. สำหรับจำหน่ายในไทย | K12: อ้างอิง solution-2.md ข้อ 4.b การสร้าง Digital Evidence Card เพื่อลดภาระการลงพื้นที่ถ่ายรูปซ้ำซ้อน | L12: อ้างอิง solution-2.md ข้อ 3.c Automated Dispatch Filtering Interface สำหรับเจ้าหน้าที่ | M12: ติดตั้งแบบ Non-contact เหนือผิวน้ำจากโครงสร้างสะพาน ปลอดภัยต่อผู้ติดตั้ง 100% | N12: การแยกส่วนซอฟต์แวร์ Rule Engine และตัวรับส่งข้อมูล ทำให้ทีมงานปรับแผนงานได้ยืดหยุ่น | O12: ต้นแบบฮาร์ดแวร์วัดระดับน้ำ ESP32 เสร็จสิ้นและสื่อสารผ่าน MQTT เข้า Dashboard ได้ก่อนสัปดาห์ที่ 9 | P12: ชิ้นส่วนทุกชิ้นจัดซื้อจากร้านค้าอิเล็กทรอนิกส์ในไทย 100% | Q12: อ้างอิง sdg-rulebook goal-11 ข้อ 11.5 สนับสนุนการบริหารจัดการภัยพิบัติในเมืองอย่างยืดหยุ่น | R12: การติดตั้งแบบ Non-contact เหนือผิวน้ำ มีการยึดจับสองชั้นด้วยสแตนเลส ไม่ตกหล่นในน้ำ | S12: อ้างอิง solution-2.md ตรรกะการยืนยัน 2 ปัจจัยโปร่งใส ตรวจสอบบันทึกข้อมูลย้อนหลังได้ทุกเคส | T12: =IF(MIN(B9:S9)=1, "VETOED / ตกเกณฑ์ข้อบังคับวิกฤต (คะแนนระดับ 1)", IF(T9>=80, "ผ่านเกณฑ์ระดับสูง (HIGHLY VIABLE)", IF(T9>=60, "ผ่านแบบมีเงื่อนไข (CONDITIONALLY VIABLE)", "ความเสี่ยงสูง (HIGH RISK)")))
A13: แผนลดขอบเขตงาน & มาตรการลดความเสี่ยง (De-scoping Action) | B13: ใช้กล่องพักสายไฟมาตรฐาน IP67 และแคลมป์รัดท่อสำเร็จรูปที่มีจำหน่ายทั่วไป | C13: ใช้ Screw Terminal Expansion Shield มาตรฐานสำหรับบอร์ด ESP32 ไม่ทำ Custom PCB | D13: พัฒนาอัลกอริทึม Cross-validation ด้วย Python Backend เชื่อมต่อ Webhook | E13: ใช้เซนเซอร์วัดระดับน้ำแบบไม่สัมผัสน้ำ (Ultrasonic/Radar) พร้อม Median Filter | F13: ใช้เซนเซอร์อัลตราโซนิกกันน้ำมาตรฐาน COTS และใช้ Wi-Fi/4G Hotspot ในการทดสอบ | G13: จัดซื้ออะไหล่เซนเซอร์ระดับน้ำสำรอง 1 ชุดเตรียมไว้ล่วงหน้า | H13: ใช้ SIM IoT รายปีราคาประหยัดสำหรับการส่งข้อมูลโทรมาตร | I13: ติดตั้งบนราวสะพานคนข้ามหรือขอบคลองสาธารณะโดยยึดด้วยแคลมป์ที่ไม่ทำลายโครงสร้าง | J13: ใช้ช่องสัญญาณ 4G Cellular และ Wi-Fi สาธารณะของ กทม. | K13: พัฒนาระบบออกรายงานกราฟสรุปสถานการณ์น้ำระดับจุดพิกัดในรูปแบบรูปภาพอัตโนมัติ | L13: ออกแบบ UI ให้มีสัญญาณไฟสีเขียว/แดง แสดงผลชัดเจนว่าควรปล่อยรถหรือไม่ | M13: เลือกจุดติดตั้งนำร่องบนสะพานคนเดินข้ามคลองในพื้นที่มหาวิทยาลัย | N13: ทดสอบระบบตรรกะคัดกรองด้วยข้อมูลย้อนหลัง (Historical Data) ในช่วงสัปดาห์สอบ | O13: จัดทำ Demo Scenario แสดงการคัดกรองเคสจริง 3 รูปแบบสำหรับส่งมอบในสัปดาห์ที่ 9 | P13: สั่งซื้ออุปกรณ์ผ่านร้านค้าในประเทศที่มีการรับประกันเปลี่ยนสินค้าทันที | Q13: ประเมินตัวเลขการลดเวลาตอบสนองต่อเหตุน้ำท่วมในจุดวิกฤต | R13: ใช้แคลมป์รัดสแตนเลสเกรด 304 ยึดอุปกรณ์กับโครงสร้างถาวร | S13: จัดทำ Audit Log บันทึกค่าระดับน้ำและเหตุผลการปล่อย/ระงับรถทุกครั้ง | T13: ปฏิบัติตามแผนลดขอบเขตงาน (De-scoping Advisory)

Sheet Solution-3
A1: เมทริกซ์ประเมินความเป็นไปได้เชิงระบบ TELOS+S: Acoustic Sewer Measurement & Pre-Screening สำหรับการวางแผนบำรุงรักษาเชิงป้องกัน (Case 3 UK/USA)
A2: ระบบคะแนนจำนวนเต็มเด็ดขาด: 1, 2, 3, 4, 5 เท่านั้น (ไม่มีจุดทศนิยม / ไม่มี 0.5) | โครงสร้างแบบ Transposed แนวนอน
A4: รหัสคำถาม (Question Code) | B4: T-01 | C4: T-02 | D4: T-03 | E4: T-04 | F4: E-01 | G4: E-02 | H4: E-03 | I4: L-01 | J4: L-02 | K4: O-01 | L4: O-02 | M4: O-03 | N4: S-01 | O4: S-02 | P4: S-03 | Q4: SDG-01 | R4: SDG-02 | S4: SDG-03 | T4: สรุปภาพรวม (SUMMARY)
A5: มิติการประเมิน (TELOS+S Pillar) | B5: ด้านเทคนิค (Technical 2.2) | C5: ด้านเทคนิค (Technical 2.2) | D5: ด้านเทคนิค (Technical 2.2) | E5: ด้านเทคนิค (Technical 2.2) | F5: ด้านเศรษฐศาสตร์ (Economic 2.3) | G5: ด้านเศรษฐศาสตร์ (Economic 2.3) | H5: ด้านเศรษฐศาสตร์ (Economic 2.3) | I5: ด้านกฎหมายและหน่วยงาน (Legal 2.4) | J5: ด้านกฎหมายและหน่วยงาน (Legal 2.4) | K5: ด้านการปฏิบัติการและผู้ใช้ (Operational 2.5) | L5: ด้านการปฏิบัติการและผู้ใช้ (Operational 2.5) | M5: ด้านการปฏิบัติการและผู้ใช้ (Operational 2.5) | N5: ด้านเวลาและแผนงาน (Schedule 2.6) | O5: ด้านเวลาและแผนงาน (Schedule 2.6) | P5: ด้านเวลาและแผนงาน (Schedule 2.6) | Q5: ด้านความยั่งยืน (SDGs 2.7) | R5: ด้านความยั่งยืน (SDGs 2.7) | S5: ด้านความยั่งยืน (SDGs 2.7) | T5: ผลรวมทุกมิติ (All Pillars)
A6: คำถามทดสอบความเสี่ยงจริง (Stress-Test Question) | B6: เมื่อพิจารณาว่าผู้พัฒนาไม่มีทักษะการกลึง/ตัดโลหะและไม่สามารถเข้าถึงโรงประลอง (Machine Shop) ได้ โครงสร้างฮาร์ดแวร์ภายนอกของระบบสามารถประกอบขึ้นจากอุปกรณ์สำเร็จรูปมาตรฐาน (COTS) เพื่อทนต่อสภาวะแวดล้อมน้ำท่วม/มรสุมของ กทม. ได้อย่างสมบูรณ์หรือไม่? | C6: เมื่อพิจารณาว่าผู้พัฒนาไม่มีทักษะการออกแบบ Custom PCB และมีทักษะการบัดกรีต่ำ สถาปัตยกรรมฮาร์ดแวร์อิเล็กทรอนิกส์และวงจรของระบบสามารถติดตั้งและทำงานได้อย่างมีเสถียรภาพโดยไม่เกิดความร้อนสะสมหรือวงจรล้มเหลวหรือไม่? | D6: ความสามารถและอัลกอริทึมในการตรวจวัดและทำนายระดับน้ำหรือการระบายน้ำ สามารถประมวลผลและให้ผลลัพธ์ที่แม่นยำได้ทันก่อนกรอบเวลาเดินทางของทีม QRT (20-30 นาที) หรือไม่? | E6: ระบบมีความแข็งแกร่ง (Robustness) ต่อปัจจัยรบกวนในสิ่งแวดล้อมจริงของ กทม. (เช่น คราบสิ่งสกปรก ขยะลอย ทัศนวิสัยต่ำตอนฝนตกหนัก น้ำทะเลหนุน) โดยไม่เกิดความล้มเหลวในการตรวจวัดหรือไม่? | F6: งบประมาณจัดซื้ออุปกรณ์ต้นแบบ (BOM) ทั้งหมด สามารถควบคุมให้อยู่ภายใต้เพดานงบประมาณโครงงานนักศึกษา (< 5,000 บาท) ได้อย่างแท้จริงหรือไม่? | G6: โครงการได้จัดสรรงบประมาณสำรองสำหรับอะไหล่ทดแทน 100% (Scrap Allowance) กรณีอุปกรณ์ลัดวงจรหรือเสียหายจากการทดสอบหน้างานจริงหรือไม่? | H6: ค่าใช้จ่ายในการบำรุงรักษาและทำความสะอาดอุปกรณ์ (OpEx) คุ้มค่าเมื่อเทียบกับต้นทุนค่าน้ำมันและกำลังพลที่ประหยัดได้จากการลดการปล่อยรถ QRT ไปเก้อหรือไม่? | I6: การติดตั้งและปฏิบัติการของระบบ สอดคล้องกับกฎหมายคุ้มครองข้อมูลส่วนบุคคล (PDPA), กฎหมายจราจร, และระเบียบความปลอดภัยในที่สาธารณะโดยไม่ละเมิดข้อบังคับหรือไม่? | J6: อุปกรณ์สื่อสารไร้สายได้รับการรับรองมาตรฐานจาก กสทช. (NBTC) และทีมงานมีความพร้อมในการประสานงานขอความร่วมมือจากหน่วยงานภาครัฐ (กทม./สำนักการระบายน้ำ) หรือไม่? | K6: ระบบสามารถสร้างหลักฐานยืนยันที่สอดคล้องกับระเบียบการปิดงาน (Proof of Work) ของ กทม./Traffy Fondue โดยไม่ต้องบังคับให้เจ้าหน้าที่ต้องเดินทางไปถ่ายรูปซ้ำซ้อนหรือไม่? | L6: ความซับซ้อนในการติดตั้ง การบำรุงรักษา และการใช้งานโดยเจ้าหน้าที่หน้างาน (Usability & Maintainability) อยู่ในระดับที่เหมาะสมและไม่สร้างภาระงานเพิ่มเติมหรือไม่? | M6: การทดสอบและติดตั้งระบบจริงหน้างาน สามารถกระทำได้อย่างปลอดภัยโดยไม่เสี่ยงต่อชีวิตของผู้พัฒนาหรือประชาชนผู้ใช้ทางหรือไม่? | N6: แผนงานและสถาปัตยกรรมระบบสามารถดูดซับช่วงสอบกลางภาค/ปลายภาคของมหาวิทยาลัย (Buffer Time 4 สัปดาห์) โดยโครงการไม่ล่าช้ากว่ากำหนดหรือไม่? | O6: ความก้าวหน้าทางวิศวกรรมสามารถบรรลุเกณฑ์การทำงานได้จริง (Working Prototype) ภายในสัปดาห์ที่ 9 ก่อนการประเมินความก้าวหน้าหลักหรือไม่? | P6: ระยะเวลาในการสั่งซื้อและขนส่งอุปกรณ์ (Lead Time) สอดคล้องกับกรอบเวลาของภาคการศึกษา โดยชิ้นส่วนหลักทั้งหมดมาถึงภายใน 14 วันหรือไม่? | Q6: ระบบส่งเสริมการลดความสูญเสียจากภัยพิบัติและสนับสนุนเมืองที่มีความยืดหยุ่นและยั่งยืน (สอดคล้องกับ SDG 11.5 และ SDG 13.1) หรือไม่? | R6: อุปกรณ์ที่นำไปติดตั้ง ไม่เสี่ยงต่อการชะล้างกลายเป็นขยะในท่อระบายน้ำ และใช้วัสดุที่ทนทาน ปลอดสารอันตราย และเป็นมิตรต่อสิ่งแวดล้อม (สอดคล้องกับ SDG 6.3 และ SDG 12.4/12.5) หรือไม่? | S6: ตรรกะการประเมินและการกรองเหตุร้องเรียน มีความโปร่งใส ตรวจสอบย้อนกลับได้ และไม่สร้างความเหลื่อมล้ำในการให้บริการของรัฐต่อประชาชนทุกกลุ่มอย่างเป็นธรรม (สอดคล้องกับ SDG 10.2 และ SDG 16.6) หรือไม่? | T6: ประเมินคำถามทั้งสิ้น 18 ข้อ
A7: เหตุผลในการถาม & โหมดความล้มเหลวที่เฝ้าระวัง (Rationale) | B7: ก้านหย่อนและหัวยึดเซนเซอร์เสียงลงในบ่อพักน้ำสามารถประกอบขึ้นจากก้านยืดหด (Telescopic Pole) สำเร็จรูป และกล่องกันน้ำ COTS มาตรฐาน IP67 ร่วมกับชิ้นส่วนพิมพ์ 3D PETG โดยไม่ต้องใช้เครื่องจักรกลึงเชื่อมโลหะใน Machine Shop | C7: ระบบสามารถใช้วงจรขยายสัญญาณเสียงสำเร็จรูปและบอร์ดไมโครคอนโทรลเลอร์ที่มี Screw Terminal Shield โดยไม่ต้องออกแบบ Custom PCB และใช้งานเฉพาะช่วงตรวจวัด 3-5 นาที จึงไม่มีปัญหาความร้อนสะสม | D7: ในบริบทงานซ่อมบำรุงเชิงป้องกัน (Maintenance Planning) ระบบเน้นความเร็วในการคัดกรอง 3-5 นาทีต่อช่วงท่อ ซึ่งอัลกอริทึมคำนวณ Time-of-Flight และ Spectral Attenuation ประมวลผลเสร็จสิ้นภายในไม่กี่วินาทีบนไมโครคอนโทรลเลอร์ | E7: การใช้งานเฉพาะช่วงฤดูแล้งที่น้ำไหลเอื่อย ทำให้ไม่มีเสียงฝนตกหนักหรือคลื่นน้ำรบกวนสัญญาณเสียง และอุปกรณ์หย่อนลงไปเพียงชั่วคราวแล้วดึงขึ้นมาเช็ดทำความสะอาดได้ทันที | F7: หากหลีกเลี่ยงเครื่อง SL-RAT สำเร็จรูปราคาหลักล้าน และสร้างต้นแบบด้วยทรานสดิวเซอร์เสียง COTS ร่วมกับไมโครคอนโทรลเลอร์และก้านยืดหด งบประมาณ BOM ต้นแบบจะอยู่ที่ประมาณ 4,200 - 4,800 บาท ควบคุมให้อยู่ในงบได้ | G7: เมื่อคุมต้นทุนต่อชุดให้อยู่ในระดับ ~2,000-2,500 บาทสำหรับหัววัด สามารถจัดเตรียมหัวทรานสดิวเซอร์สำรองได้ 1 ชุดเพื่อรองรับกรณีเกิดความเสียหาย | H7: ความคุ้มค่าเชิงระบบสูงมาก การคัดกรองท่อสะอาดล่วงหน้าช่วยให้เทศบาลไม่ต้องส่งรถดูดโคลนไปลอกท่อที่ไม่มีการอุดตัน ประหยัดค่าน้ำมันรถดูดโคลนและค่าแรงได้หลายหมื่นบาทต่อเดือน | I7: การเปิดฝาท่อพักน้ำเพื่อหย่อนอุปกรณ์ตรวจวัดในฤดูแล้งกระทำร่วมกับทีมงานเทศบาล/กทม. โดยมีกรวยจราจรและป้ายเตือนตาม พ.ร.บ. จราจรทางบก และเป็นการหย่อนจากผิวถนนโดยไม่มีการให้คนมุดลงในที่อับอากาศ (Zero Confined Space Entry) | J7: อุปกรณ์ใช้โมดูล Wi-Fi/Bluetooth ที่ผ่านการรับรอง กสทช. และการทำแผนที่สุขภาพท่อระบายน้ำตรงกับภารกิจของฝ่ายโยธา/ระบายน้ำ สำนักงานเขต ทำให้การประสานงานขอความร่วมมือมีความเป็นไปได้สูง | K7: ระบบสามารถออกรายงานผลการตรวจคัดกรองความสะอาดท่อ (Pipe Cleanliness Certificate) พร้อมคะแนน Tier และกราฟการสะท้อน เพื่อใช้เป็นหลักฐานประกอบแผนงานบำรุงรักษาของสำนักงานเขตได้อย่างสมบูรณ์ | L7: การใช้งานหน้างานไม่ซับซ้อน เพียงวางก้านหย่อนลงในบ่อพักน้ำ กดปุ่มวัดค่า และรอผล 3 นาที เจ้าหน้าที่ภาคสนามสามารถเรียนรู้การใช้งานได้ภายในเวลา 15 นาที | M7: การทดสอบทำในช่วงฤดูแล้ง ไม่มีกระแสน้ำเชี่ยวหรืออันตรายจากน้ำท่วมหลาก และใช้วิธีหย่อนจากขอบบ่อพักน้ำพร้อมกรวยกั้นจราจร ทำให้มีความปลอดภัยสูง | N7: งานพัฒนาซอฟต์แวร์ประมวลผลเสียงและฮาร์ดแวร์ก้านหย่อนสามารถแบ่งโมดูลทดสอบบนโต๊ะแล็บได้ ทำให้ตารางงานมีความยืดหยุ่นและรองรับช่วงสอบได้ดี | O7: สามารถสร้างต้นแบบก้านหย่อนพร้อมชุดตรวจวัดและทดสอบความแม่นยำในท่อ PVC จำลองของมหาวิทยาลัยได้เสร็จสิ้นก่อนสัปดาห์ที่ 9 | P7: ชิ้นส่วนก้าน Telescopic, ทรานสดิวเซอร์ COTS และบอร์ด ESP32 สามารถจัดซื้อได้จากร้านค้าในประเทศ มีระยะเวลาขนส่งไม่เกิน 3-7 วัน | Q7: การคัดกรองและลอกท่อระบายน้ำเชิงรุกก่อนฤดูฝน ช่วยป้องกันปัญหาน้ำท่วมขังฉับพลันในเขตเมือง ลดความเสียหายต่อทรัพย์สินของประชาชนและการจราจรอย่างยั่งยืน | R7: อุปกรณ์เป็นแบบหย่อนตรวจวัดชั่วคราวแล้วนำกลับ (No Permanent In-Pipe Installation) และมีสายคล้องนิรภัยป้องกันการหลุด จึงไม่มีความเสี่ยงที่จะหลุดไปอุดตันท่อระบายน้ำ | S7: การจัดสรรคิวรถดูดโคลนและแรงงานลอกท่อระบายน้ำขึ้นอยู่กับเกณฑ์คะแนนความสะอาดที่เป็นวิทยาศาสตร์ (Data-Driven Cleanliness Tiering) ไม่เลือกปฏิบัติและโปร่งใสตรวจสอบได้ | T7: สังเคราะห์จาก AI Agents Group 2
