Workbook

Sheet เปรียบเทียบทุก Solution
A1: ตารางเปรียบเทียบความเป็นไปได้ของทุกข้อเสนอ (Multi-Solution Feasibility Summary)
A2: วิเคราะห์เปรียบเทียบเชิงระบบตามเกณฑ์ TELOS+S (เต็ม 100) และเมทริกซ์ศักยภาพด้านวิศวกรรมหุ่นยนต์ (เต็ม 10 แยกอิสระ)
A4: ลำดับ | B4: รหัสข้อเสนอ (Solution ID) | C4: ชื่อแนวทางแก้ปัญหา (Title / Concept) | D4: คะแนนรวม (เต็ม 100) | E4: T: เทคนิค (/20) | F4: E: เศรษฐศาสตร์ (/20) | G4: L: กฎหมาย (/15) | H4: O: ปฏิบัติการ (/20) | I4: S: แผนงาน (/15) | J4: +S: ยั่งยืน (/10) | K4: ผลการประเมิน (Verdict) | L4: จุดแข็งสำคัญ (Key Strengths) | M4: จุดติดขัดวิกฤต (Critical Bottlenecks) | N4: คำแนะนำเชิงระบบ (Strategic Advice) | O4: Robotics Potential (/10) | P4: เหตุผลความเข้ากันได้ด้านหุ่นยนต์ (Robotics Engineering Rationale)
A5: 1 | B5: Solution-1 | C5: CCTV on the road (Visual water flow) + ultrasonic to measure the flow rate of the canal + alarm | D5: ='Solution-1'!T9 | E5: ='Solution-1'!D17 | F5: ='Solution-1'!D18 | G5: ='Solution-1'!D19 | H5: ='Solution-1'!D20 | I5: ='Solution-1'!D21 | J5: ='Solution-1'!D22 | K5: ='Solution-1'!T12 | L5: ใช้ประโยชน์จากเซนเซอร์อัลตราโซนิกคลองเดิมและกล้อง CCTV จราจรที่มีอยู่แล้ว ช่วยวิเคราะห์แยกว่าน้ำท่วมเกิดจากฝนตกหนักหรือท่อตันได้โดยตรง | M5: อัลกอริทึม Optical Flow/PTV บนกล้อง CCTV มีข้อจำกัดสูงเรื่องแสงกลางแจ้ง แสงสะท้อนผิวน้ำ และใช้ไม่ได้ในเวลากลางคืนหรือจุดที่กล้องส่องไม่ถึง | N5: ติดตั้งไฟส่องสว่างอินฟราเรดเฉพาะจุด หรือผสานข้อมูลเรดาร์ฝนเพื่อชดเชยช่วงเวลาที่ CCTV ไม่สามารถประเมิน Optical Flow ได้ | O5: 4 | P5: Solution 1 functions as a municipal IoT telemetry and computer vision monitoring system rather than a robotic system. The operational loop breaks at actuation because output is strictly restricted to alerting human operators. It heavily neglects the core mechanical design, power transmission, and physical control capabilities of the team.
A6: 2 | B6: Solution-2 | C6: Sewer Inspection by transmitter and receiver. Mapping Sewer profile | D6: ='Solution-2'!T9 | E6: ='Solution-2'!D17 | F6: ='Solution-2'!D18 | G6: ='Solution-2'!D19 | H6: ='Solution-2'!D20 | I6: ='Solution-2'!D21 | J6: ='Solution-2'!D22 | K6: ='Solution-2'!T12 | L6: ตรวจคัดกรองความสะอาดท่อระบายน้ำด้วยคลื่นเสียงสะท้อน (Acoustic Reflectometry) ได้รวดเร็ว สร้างภาพตัดขวาง 2D ช่วยจัดคิวลอกท่อได้ตรงจุด | M6: จุดอ่อนวิกฤตระบุชัดเจนว่า 'Can’t use in water in pipe situation' ซึ่งท่อระบายน้ำ กทม. มีน้ำขังเกือบตลอดเวลา และการสะท้อนของเสียงมีความซับซ้อนสูง | N6: จำกัดการใช้งานเฉพาะช่วงฤดูแล้งที่น้ำในท่อลดระดับลงต่ำสุด และใช้ร่วมกับก้านวัดระดับตะกอนแบบกายภาพเพื่อยืนยันผล | O6: 3.5 | P6: Solution 2 is an acoustic Non-Destructive Testing (NDT) diagnostic instrument rather than an autonomous robotic system. While technically grounded in sensor wave physics, it operates in an open loop terminating at human-interpreted cross-section imagery. It lacks any automated locomotion or physical actuation, underutilizing mechanical and control engineering competencies.
A7: 3 | B7: Solution-3 | C7: ระบบปล่อยน้ำแบบ Adaptive เพื่อระบายความร้อนบนทางเดินเท้าและตรอกซอยอย่างมีประสิทธิภาพสูงสุด | D7: ='Solution-3'!T9 | E7: ='Solution-3'!D17 | F7: ='Solution-3'!D18 | G7: ='Solution-3'!D19 | H7: ='Solution-3'!D20 | I7: ='Solution-3'!D21 | J7: ='Solution-3'!D22 | K7: ='Solution-3'!T12 | L7: ใช้เซนเซอร์ IR ตรวจวัดอุณหภูมิผิวทางเดินเท้าแบบเรียลไทม์ และเปิดพ่นละอองน้ำเฉพาะเมื่อเกิน 45 °C ในช่วง 11:00–14:00 น. ไม่สูญเสียน้ำไปกับ Runoff | M7: จุดอ่อนระบุชัดว่า 'ในซอยไม่มีแหล่งน้ำสะอาด ต้องต่อท่อน้ำจากอาคาร' เสี่ยงต่อข้อพิพาทสิทธิ์การใช้น้ำ และต้องใช้พื้นที่มากแต่ให้ผลลดความร้อนเฉพาะจุด | N7: เปลี่ยนกลุ่มเป้าหมายจากการติดตั้งตามตรอกซอยส่วนบุคคล มาเป็นการติดตั้งในสวนสาธารณะ ทางเดินลอยฟ้า (Skywalk) หรือลานกิจกรรมของรัฐ | O7: 7.3 | P7: Solution 3 successfully completes the closed-loop robotic triad (Sense -> Think -> Act -> Feedback) by measuring environmental thermal state, computing dynamic cooling requirements, and physically actuating fluid valves to alter surface temperature. It provides 100% utilization of the team's multidisciplinary skills (CAD/FEA mechanics, custom PCB electronics, feedback control firmware, and telemetry analytics). It scores 7.3 rather than 10.0 due to being a stationary cyber-physical mechatronic system lacking multi-DOF kinematics or mobile locomotion.

Sheet Solution-1
A1: เมทริกซ์ประเมินความเป็นไปได้เชิงระบบ TELOS+S: CCTV on the road (Visual water flow) + ultrasonic to measure the flow rate of the canal + alarm
A2: ระบบคะแนนจำนวนเต็มเด็ดขาด: 1, 2, 3, 4, 5 เท่านั้น (ไม่มีจุดทศนิยม / ไม่มี 0.5) | โครงสร้างแบบ Transposed แนวนอน
A4: รหัสคำถาม (Question Code) | B4: T-01 | C4: T-02 | D4: T-03 | E4: T-04 | F4: T-05 | G4: E-01 | H4: E-02 | I4: E-03 | J4: L-01 | K4: L-02 | L4: O-01 | M4: O-02 | N4: O-03 | O4: O-04 | P4: S-01 | Q4: SDG-01 | R4: SDG-02 | S4: SDG-03 | T4: สรุปภาพรวม (SUMMARY)
A5: มิติการประเมิน (TELOS+S Pillar) | B5: ด้านเทคโนโลยีและวิศวกรรม (Technical Feasibility) | C5: ด้านเทคโนโลยีและวิศวกรรม (Technical Feasibility) | D5: ด้านเทคโนโลยีและวิศวกรรม (Technical Feasibility) | E5: ด้านเทคโนโลยีและวิศวกรรม (Technical Feasibility) | F5: ด้านเทคโนโลยีและวิศวกรรม (Technical Feasibility) | G5: ด้านเศรษฐศาสตร์ (Economic Feasibility) | H5: ด้านเศรษฐศาสตร์ (Economic Feasibility) | I5: ด้านเศรษฐศาสตร์ (Economic Feasibility) | J5: ด้านกฎหมายและสถาบัน (Legal & Institutional Feasibility) | K5: ด้านกฎหมายและสถาบัน (Legal & Institutional Feasibility) | L5: ด้านการปฏิบัติการ (Operational Feasibility) | M5: ด้านการปฏิบัติการ (Operational Feasibility) | N5: ด้านการปฏิบัติการ (Operational Feasibility) | O5: ด้านการปฏิบัติการ (Operational Feasibility) | P5: ด้านแผนงานและเวลา (Schedule Feasibility) | Q5: +S ด้านความยั่งยืน (Sustainable Feasibility) | R5: +S ด้านความยั่งยืน (Sustainable Feasibility) | S5: +S ด้านความยั่งยืน (Sustainable Feasibility) | T5: ผลรวมทุกมิติ (All Pillars)
A6: คำถามทดสอบความเสี่ยงจริง (Stress-Test Question) | B6: Implementation (Build vs. Buy Burden): ภาระการสร้างเองกับการเลือกซื้ออุปกรณ์สำเร็จรูป (COTS) | C6: Access (Tech Stack & Ecosystem Permissions): สิทธิ์และการเข้าถึงสแตกเทคโนโลยีและระบบนิเวศน์ | D6: Base Performance (Technology Readiness Level - TRL): ระดับความพร้อมและความเสถียรของเทคโนโลยีฐาน | E6: Team Compatibility (Manpower & Skill Redundancy): ความเข้ากันได้ของทักษะทีมและความพร้อมทดแทน (SPOF) | F6: Learning Curve ("How much do we have to learn?"): เส้นทางการเรียนรู้และระยะเวลาปรับตัวของทีม | G6: ROI (Payback Period / Value Horizon): ระยะเวลาคืนทุนและกรอบความคุ้มค่าทางการเงิน | H6: Dependency of Component (Vendor Lock-in & Reliability): การพึ่งพาผู้ขายภายนอกและความเสี่ยงการผูกขาด | I6: Scrap Margin (Safety Allowance for Blown ICs & Iterations): สัดส่วนงบสำรองสำหรับความเสียหายและการทดลองซ้ำ | J6: Felony and Civil Law (Regulatory, Traffic & Public Safety Compliance): ความสอดคล้องตามกฎหมายอาญา แพ่ง ระเบียบจราจร และความปลอดภัยสาธารณะ | K6: IP and Licensing: สิทธิ์ในทรัพย์สินทางปัญญาและการอนุญาตใช้งานซอฟต์แวร์/ฮาร์ดแวร์ | L6: User — Failure Impact ("If it fails, how severe is the effect?"): ความรุนแรงของผลกระทบเมื่อระบบขัดข้องต่อผู้ใช้และสาธารณะ | M6: User — Behavior & Problem-Solution Fit: ความสอดคล้องกับพฤติกรรมผู้ใช้และกระบวนการทำงานเดิม | N6: Developer — Contribution Dependency (Administrative & Lab Gatekeeping): การพึ่งพาการอนุมัติและอุปสรรคการเข้าถึงห้องปฏิบัติการ/เครื่องมือ | O6: Developer — Complexity (Step Count & Pipeline Friction): ความซับซ้อนของขั้นตอนการประกอบ ติดตั้ง และบิวด์ระบบ | P6: Production Time (Engineering Design Maturity by 5 Business Weeks): วุฒิภาวะของแบบทางวิศวกรรมและความพร้อมผลิตใน 5 สัปดาห์ทำการ | Q6: SDG-01: Public Impact vs. Academic Greenwashing (SDG 11.5 / 13.1): ผลกระทบเชิงประจักษ์ต่อสาธารณะกับการฟอกเขียวทางวิชาการ | R6: SDG-02: Environmental Footprint & E-Waste ("Do No Harm" — SDG 6.3 / 12.4): ภาระสิ่งแวดล้อมและขยะอิเล็กทรอนิกส์ตามหลักไม่สร้างผลเสียซ้ำซ้อน | S6: SDG-03: Algorithmic Equity & Decision Transparency (SDG 10.2 / 16.6): ความเป็นธรรมของอัลกอริทึมและความโปร่งใสในการตัดสินใจ | T6: ประเมินคำถามทั้งสิ้น 18 ข้อ
A7: เหตุผลในการถาม & โหมดความล้มเหลวที่เฝ้าระวัง (Rationale) | B7: ประเมินภาระงานวิจัยและพัฒนาชิ้นส่วนฮาร์ดแวร์/เฟิร์มแวร์ว่าต้องสร้างขึ้นใหม่ตั้งแต่ศูนย์หรือใช้อุปกรณ์สำเร็จรูปมาตรฐาน เพื่อควบคุมความเสี่ยงด้านความผิดพลาดและระยะเวลาพัฒนา | C7: ประเมินข้อจำกัดในการเข้าถึงซอร์สโค้ด สิทธิ์การพัฒนา สิทธิ์การเชื่อมต่อระบบคลาวด์ และสิทธิ์ผู้ดูแลระบบ เพื่อป้องกันปัญหาติดล็อกระบบปิด (Walled Garden) | D7: ประเมินระดับความพร้อมของเทคโนโลยีต้นแบบ (TRL) ว่าอยู่ในระดับแล็บหรือผ่านการทดสอบภาคสนามจริงมาแล้ว เพื่อลดความเสี่ยงจากการนำเทคโนโลยีที่ยังไม่เสถียรมาใช้งาน | E7: ประเมินการกระจายทักษะทางเทคนิคและความเสี่ยงจากการมีผู้เชี่ยวชาญเพียงคนเดียว (Single Point of Failure: SPOF) หากสมาชิกหลักไม่อยู่ โครงการจะหยุดชะงักหรือไม่ | F7: ประเมินช่องว่างทางความรู้และทักษะที่ทีมต้องเรียนรู้เพิ่มขึ้นเมื่อเทียบกับประสบการณ์เดิม ป้องกันปัญหางานสะดุดจากการติดขัดช่วงเริ่มต้นการเรียนรู้เทคโนโลยีใหม่ | G7: ประเมินระยะเวลาในการคืนทุนและมูลค่าทางเศรษฐกิจที่ได้กลับคืนจากการลดความสูญเสียเมื่อเทียบกับเงินลงทุนเริ่มต้น (CapEx) และค่าใช้จ่ายดำเนินงาน (OpEx) | H7: ประเมินความเสี่ยงจากการพึ่งพาระบบคลาวด์เฉพาะ อะไหล่ผูกขาด หรือค่าธรรมเนียมรายปีที่ส่งผลกระทบต่องบประมาณระยะยาวและความยืดหยั่งของระบบ | I7: ประเมินความเพียงพอของงบประมาณสำรองสำหรับชิ้นส่วนที่อาจเสียหายระหว่างการทดสอบ (Burn-in/Debugging) ป้องกันโครงการหยุดชะงักเมื่ออุปกรณ์เสียหาย | J7: ประเมินความเสี่ยงต่อการละเมิดกฎหมาย พ.ร.บ. คุ้มครองข้อมูลส่วนบุคคล (PDPA) การรบกวนสัญญาณคลื่นวิทยุ (กสทช.) หรือการติดตั้งที่กีดขวางทางสัญจรและเสี่ยงต่ออันตรายสาธารณะ | K7: ประเมินข้อกำหนดด้านสัญญาอนุญาตสิทธิ์ (Software/Hardware Licenses) และความเสี่ยงต่อการละเมิดสิทธิบัตรหรือข้อจำกัดแบบไวรัสลิขสิทธิ์ (Viral Copyleft) | L7: ประเมินความรุนแรงของผลกระทบกรณีระบบล้มเหลว (System Failure) ต่อชีวิต ทรัพย์สิน และการปฏิบัติการฉุกเฉินของเจ้าหน้าที่ เพื่อป้องกันโหมดความล้มเหลวขั้นวิกฤต | M7: ประเมินแรงต้านทานในการเปลี่ยนแปลงขั้นตอนการทำงานของผู้ปฏิบัติงาน (Operational Resistance) และภาระงานเอกสารหรือการฝึกอบรมที่เพิ่มขึ้น | N7: ประเมินขั้นตอนความยุ่งยากทางธุรการ การขออนุญาตเข้าใช้สถานที่ และการเข้าถึงอุปกรณ์เครื่องมือในการพัฒนาว่ามีความคล่องตัวหรือถูกปิดกั้น | O7: ประเมินจำนวนขั้นตอนและความเปราะบางของกระบวนการบิวด์ ติดตั้ง และทดสอบระบบ เพื่อลดโอกาสเกิดข้อผิดพลาดจากมนุษย์ (Human Error) | P7: ประเมินความสมบูรณ์ของแบบวิศวกรรม (CAD, Schematics, PCB Gerber, Firmware) เทียบกับกรอบเวลา 5 สัปดาห์ทำการก่อนช่วงสอบและการส่งมอบชิ้นงาน | Q7: ประเมินว่าโครงการสร้างผลกระทบที่วัดผลได้จริงในการลดความสูญเสียจากภัยพิบัติหรือฟื้นฟูเมือง หรือเป็นเพียงข้ออ้างด้านความยั่งยืนเชิงสัญลักษณ์ | R7: ประเมินวงจรชีวิตของอุปกรณ์ การปลดปล่อยสารพิษ ปัญหาขยะอิเล็กทรอนิกส์ (E-Waste) และการหลุดรอดของสารเคมีลงสู่แหล่งน้ำสาธารณะ | S7: ประเมินความโปร่งใสของตรรกะการตัดสินใจและเกณฑ์การตัดคัดกรองเคส เพื่อป้องกันการเลือกปฏิบัติหรือการเพิกเฉยต่อพื้นที่ชุมชนเปราะบาง | T7: สังเคราะห์จาก AI Agents Group 2
A8: เกณฑ์การให้คะแนน (Scoring Rubric Definition: ระดับ 1, 2, 3, 4, 5 ครบทุกระดับ) | B8: 1: Build from Scratch (100% custom R&D required; custom mechanism, bare-metal schematics, custom algorithm derivation; no reference designs or libraries exist) 2: Heavy Customization (Core components exist, but requires extensive custom adaptation, structural machining, and custom wrapper code) 3: Hybrid / COTS Integration (Standard off-the-shelf breakout boards and modules assembled with custom brackets, intermediate wiring, and glue code) 4: Modular COTS Assembly (Pre-engineered building blocks with standard mounting and standard communication buses e.g. DIN-rail modules, I2C/CAN shields; minimal custom fabrication) 5: Buy and Use / COTS (Buy and deploy directly out of the box / Plug-and-Play; zero mechanical or electrical fabrication required) | C8: 1: Strictly Restricted (Proprietary stack under NDA, locked enterprise firewalls, or unavailable developer licenses) 2: Limited Access (Closed binary blobs or third-party proprietary firmware; black-box operation with zero telemetry or source code) 3: Request-Based Access (Educational/evaluation tier with strict rate limits or quotas; requires formal request or approval delays) 4: Open Developer Access (Free public SDKs, full documentation, and open developer APIs, but core low-level architecture cannot be modified) 5: Full-Stack Access (Fully open source with permissive license and open hardware; team has root/admin rights to inspect, modify, and deploy as both user and developer) | D8: 1: Proof of Concept (TRL 2–3: Bench breadboard, simulation, or pure mathematical model; verified only in controlled laboratory conditions) 2: Functional Breadboard (TRL 4: Integrated components working together in a lab; fragile wiring, uncalibrated for harsh field environments) 3: Alpha Prototype (TRL 5–6: Enclosed prototype tested in a relevant simulated environment; operational, but requires human supervision) 4: Beta / Field-Proven (TRL 7: Pre-production hardware operating reliably in the actual operating environment under real-world stress) 5: Commercial Product (TRL 8–9: Fully certified, production-grade commercial product with documented MTBF and mass field reliability) | E8: 1: Single Point of Failure / SPOF (Only 1 person has the required skill; if they are unavailable, subsystem development halts 100%) 2: Solo Lead with Minimal Backup (1 core developer; 1 teammate understands basic concepts but cannot debug code or fix hardware alone) 3: Primary + Secondary Pair (1 primary lead and 1 competent secondary backup who can maintain, troubleshoot, and push updates) 4: Broad Competence (3+ teammates can actively design, assemble, and debug the subsystem with minimal ramp-up time) 5: Full Team Redundancy (All team members are fully proficient; tasks can be swapped across anyone with zero friction or velocity loss) | F8: 1: Total Reset (Every step requires learning completely unfamiliar tools, languages, and hardware from scratch with zero prior baseline) 2: Steep Learning Curve (High theoretical understanding, but zero hands-on experience; debugging basic syntax or wiring stalls progress) 3: Moderate Ramp-up (Proven adjacent mastery e.g. Arduino/ESP32 moving to STM32, or SolidWorks to Fusion 360; manageable 1-week curve) 4: Minor Adaptation (Familiar tech stack; only requires learning a specific minor library, sensor API, or configuration syntax) 5: Zero Learning Curve (Team can deploy verified past code, existing toolchains, and established muscle memory directly; no new learning required) | G8: 1: Long Payback (>= 10 Years: High initial CapEx with minimal recurring savings; economically non-viable for rapid deployment) 2: Slow Return (6–9 Years: Substantial capital investment with a long break-even horizon; requires long-term subsidization) 3: Moderate Return (3–5 Years: Reasonable public infrastructure payback; offsets costs across multi-year operational cycles) 4: Fast Return (2–3 Years: Strong operational cost reduction in fuel, labor, scrap; breaks even within normal equipment lifecycle) 5: Immediate Payback (<= 1–2 Years: Rapid break-even; eliminates major recurring operational losses within the first operating season) | H8: 1: Total Vendor Lock-in (100% dependent on proprietary cloud backend, encrypted telemetry, and single-source proprietary connectors) 2: High Dependency (Hardware requires vendor-licensed diagnostic tools or annual subscription fees to maintain operation) 3: Semi-Independent (Core hardware relies on proprietary firmware, but allows open API export and standard electrical interfaces) 4: High Autonomy (Uses standard open communication protocols e.g. Modbus, MQTT, CAN; parts can be serviced using generic tools) 5: Complete Independence (100% open architecture; hardware is interchangeable with generic substitutes; self-serviceable by any engineer) | I8: 1: Zero Buffer (0%: Exactly 1x BOM purchased; any fried chip, cracked bracket, or wiring mistake halts the project) 2: Fragile Buffer (20–30%: Spares only for passive components; no backup microcontrollers or expensive sensors) 3: Moderate Buffer (50%: Spares for all critical passive parts and 1 spare for the primary controller board) 4: High Buffer (80%: Spares for nearly every active component and sensor; can sustain multiple prototype burn-ins) 5: Full Redundancy (>= 100%: Complete 2x BOM budget on hand; can build two complete working units simultaneously) | J8: 1: Severe Violation / No Privilege (Direct breach of statutory law e.g. unconsented public surveillance/PDPA, hazardous road blockage, illegal RF transmission) 2: High Legal Exposure (Ambiguous legal zone; high risk of civic complaints or traffic disruption; requires complex technical waivers) 3: Conditional / Requires Permit (Permitted strictly under formal written approval, official agency MoU, or municipal permits) 4: Low Legal Friction (Operates within standard public engineering exemptions; simple standard notification/safety compliance needed) 5: 100% Free Domain (Fully exempt from statutory licensing; zero public safety risk, zero personal data/Zero PII, fully unrestricted) | K8: 1: Closed Commercial Barrier (Proprietary commercial license; cannot compile, flash, or operate without paying expensive commercial seat licenses) 2: Ambiguous / Gray IP (Unclear licensing terms or unlicensed public repos; risk of copyright strike or IP dispute upon public demonstration) 3: Restrictive Open Source / Copyleft (Permitted for educational use, but viral licenses e.g. GPLv3 force your entire codebase to be made public if distributed) 4: Permissive Open Source (Open source with minimal conditions e.g. LGPL, CC-BY; allows proprietary wrapping with simple attribution) 5: Completely Permissive / Public Domain (Permissive open source e.g. MIT, Apache 2.0, BSD or Public Domain; unrestricted freedom to commercialize, modify, and contribute) | L8: 1: Life-Threatening (Failure causes electrocution, fire, traffic collisions, toxic chemical exposure, or structural collapse) 2: Severe Physical Hazard (Equipment destroys itself, causes acute environmental contamination, or halts major emergency infrastructure) 3: Chaotic Response from User (Panic, operational deadlock, conflicting manual dispatches, and severe operational confusion) 4: Minor Operational Delay (System trips safely; requires a manual reboot or standard fallback procedure; no safety risk or chaos) 5: Benign Budget Loss Only (Failure causes zero human or operational harm; results only in minor, easily absorbed component/battery replacement costs) | M8: 1: Disruptive Overhaul (Forces operators to abandon existing standard procedures, adds 5+ extra tedious forms, and faces active user rejection) 2: High Friction (Adds notable extra documentation or redundant verification steps; operators will actively look for ways to bypass it) 3: Moderate Adaptation (Modifies daily routines slightly; requires 1–2 training sessions, but delivers clear operational trade-offs) 4: Low Friction (Integrates directly into existing tools e.g. sends alerts to existing LINE/Telegram or ticketing dashboard; minimal habit changes) 5: Smooth Transient Operation (Zero workflow disruption; runs transparently in the background and automates existing manual paperwork seamlessly) | N8: 1: Heavy Gatekeeping (Blocked by supervisor approvals, locked lab cabinets, NDA signatures, purchasing bureaucracy, and restricted git branches) 2: Moderate Bureaucracy (Requires departmental request forms, tool booking queues, and waiting 3–5 days for administrative sign-offs) 3: Standard Campus Access (Workable access during university open hours; minor approval delays for specialized equipment or lab keys) 4: High Autonomy (Team has full repository write access, open 24/7 lab entry, and pre-approved discretionary stipends for rapid purchases) 5: Frictionless Contribution (Complete autonomy; decentralized cloud CI/CD, local prototyping tools at home/bench, zero administrative blockers) | O8: 1: Highly Convoluted (Dozens of fragile build steps, complex toolchain dependencies, and high probability of human error during setup) 2: High Complexity (Multi-stage manual toolchains; frequent dependency conflicts and difficult multi-board flashing procedures) 3: Moderate Complexity (Standard multi-step build/assembly pipeline; manageable and repeatable when following a documented checklist) 4: Low Complexity (Straightforward workflow using automated build scripts, standard IDEs, or single-command flashing) 5: Simple & Direct (Plug-and-play, 1-step linear workflow; idiot-proof setup requiring zero multi-stage manual configuration) | P8: 1: Concept Only (0% Design: Napkin sketches and verbal ideas; 0% CAD models, 0% schematics, 0% firmware written) 2: Rough Drafts (25% Design: Preliminary block diagrams, hand-drawn schematics, unverified parts list, rough 3D bounding boxes) 3: Intermediate Maturity (50% Design: Complete CAD assembly with untested clearances, schematic capture complete, draft firmware architecture mapped) 4: Pre-Production (75–80% Design: Detailed 3D CAD ready for 3D print/CNC, routed PCB Gerber files verified with DRC, pinouts locked down) 5: Fully Engineered Design (100% Production Ready: Complete manufacturing package: verified Gerbers, mechanical tolerance drawings, locked BOM, and flashing scripts ready) | Q8: 1: Pure Buzzword / Greenwashing (Claims sustainability benefits with zero data, zero measurable effect, and solves no real municipal problem) 2: Superficial Correlation (Indirect impact; functions only as an isolated school demo with no realistic way to measure damage prevention) 3: Localized Proof (Delivers a measurable, verified benefit e.g. cuts response time or drops localized temperature on a single test strip, but lacks a scaling model) 4: District-Level Viability (Clear pathway to protect municipal infrastructure or reduce public losses across multiple roads/alleys during extreme weather) 5: Systemic City Resilience (Backed by concrete empirical data showing significant reduction in public economic losses, vehicle damage, or human hazard) | R8: 1: Toxic Field Hazard (Enclosure degrades under UV, or unsealed batteries leak toxic chemicals and detach into the urban drainage network as marine litter) 2: Fragile Disposable Tech (Short operational lifespan; sensors foul or corrode within 2–3 weeks and are abandoned because retrieval is impractical) 3: Standard Field Footprint (Requires periodic battery replacement and creates standard electronic scrap, but uses basic tethering to prevent total hardware loss) 4: Low-Impact Enclosure (Solar-trickle or long-life low-power architecture; uses recyclable casing and redundant physical tethers e.g. dual stainless lanyards) 5: Fully Circular & Zero Footprint (100% fail-safe retrieval design; uses non-toxic materials, consumes minimal public resources, and leaves zero field trace) | S8: 1: Opaque Black Box (Proprietary or unexplained threshold that cancels dispatches or alters public services with zero explanation, risking neglect of vulnerable areas) 2: Ambiguous Logic (Decision rules are buried in messy heuristic code; field operators cannot explain to a citizen why an alert was triggered or suppressed) 3: Documented Internal Rules (Logic is documented on paper for engineers, but has no public audit trail or clear appeal mechanism if the sensor misreads) 4: Open Empirical Standards (Decisions are driven by transparent physical equations applied equally across all city zones) 5: 100% Auditable & Equitable (Full tamper-evident digital audit trail; open logic accessible to officials and citizens, guaranteeing equal public protection regardless of district wealth) | T8: เกณฑ์รวม: >=80 ผ่านสูง, >=60 มีเงื่อนไข, <60 เสี่ยงสูง | หากมีข้อใดได้ 1 = VETOED ตกเกณฑ์ทันที
A9: คะแนนที่ได้รับ (ASSIGNED SCORE: 1, 2, 3, 4, 5 STRICT INTEGER) | B9: 4 | C9: 3 | D9: 2 | E9: 4 | F9: 2 | G9: 4 | H9: 3 | I9: 5 | J9: 3 | K9: 5 | L9: 4 | M9: 4 | N9: 3 | O9: 3 | P9: 3 | Q9: 4 | R9: 5 | S9: 4 | T9: =IF(T10>0, (T11/T10)*20, 0)
A10: ค่าน้ำหนัก (Weight %) | B10: 0.04 | C10: 0.04 | D10: 0.04 | E10: 0.04 | F10: 0.04 | G10: 0.0667 | H10: 0.0667 | I10: 0.0666 | J10: 0.075 | K10: 0.075 | L10: 0.05 | M10: 0.05 | N10: 0.05 | O10: 0.05 | P10: 0.15 | Q10: 0.0333 | R10: 0.0333 | S10: 0.0334 | T10: =SUM(B10:S10)
A11: คะแนนถ่วงน้ำหนัก (=Score * Weight) | B11: =B9*B10 | C11: =C9*C10 | D11: =D9*D10 | E11: =E9*E10 | F11: =F9*F10 | G11: =G9*G10 | H11: =H9*H10 | I11: =I9*I10 | ... S11: =S9*S10 | T11: =SUM(B11:S11)
A12: คำอธิบาย & หลักฐานอ้างอิงจากไฟล์ Intake (Evidence Citation) | B12: solution-1.md หน้าที่ 1-2 ระบุการใช้กล้อง CCTV เดิมและดึงข้อมูล ultrasonic เซนเซอร์คลองเดิม เป็นสถาปัตยกรรม Modular COTS ซอฟต์แวร์ | C12: solution-1.md ระบุการดึงข้อมูลจาก CCTV จราจรและเซนเซอร์คลองของ กทม. ซึ่งต้องทำเรื่องขอสิทธิ์เข้าถึงสตรีมวิดีโอ (Request-Based Access) | D12: solution-1.md Weak point ระบุว่า 'ดู flow ได้เฉพาะช่วงที่มีแสง' และ PIV/PTV บนผิวน้ำกลางแจ้งมีความแปรปรวนสูง อยู่ในระดับ Functional Breadboard (TRL 4) | E12: jk.md (OpenCV, Python), kin.md (Telemetry Ingestion, Data Analysis), due.md (API, Web) มีทักษะสอดคล้องมากกว่า 3 คน | F12: solution-1.md Tech stack ใช้ Particle Tracking Velocimetry (PTV) และ PIV ซึ่งเป็นอัลกอริทึมชลศาสตร์ขั้นสูงที่ทีมยังไม่มีประสบการณ์ตรง (Steep Curve) | G12: solution-1.md ส่วน Function ช่วยวิเคราะห์จัดคิวลอกท่อและแจ้งเตือน QRT ตรงจุด โดยไม่ต้องติดตั้งฮาร์ดแวร์แพง คืนทุนรวดเร็วใน 2-3 ปี | H12: solution-1.md พึ่งพาข้อมูลสตรีมวิดีโอจากกล้อง CCTV ของหน่วยงานรัฐ หากกล้องเสียหรือมุมกล้องเปลี่ยนระบบจะคำนวณไม่ได้ | I12: solution-1.md เป็นระบบประมวลผลซอฟต์แวร์จากเซนเซอร์ที่มีอยู่แล้ว งบประมาณการทดสอบฮาร์ดแวร์มีสำรองเกิน 100% | J12: solution-1.md การดึงภาพวิดีโอจาก CCTV บนถนนสาธารณะติดภาพบุคคลและยานพาหนะ ต้องขออนุญาตและมีระบบเบลอภาพตาม พ.ร.บ. PDPA | K12: solution-1.md ใช้งาน OpenCV และอัลกอริทึม Optical Flow โอเพนซอร์ส ปราศจากสิทธิบัตรปิดกั้น | L12: solution-1.md หากระบบ Optical Flow วิเคราะห์ผิดพลาด เป็นเพียงการแจ้งเตือนล่าช้า เจ้าหน้าที่สามารถสลับไปดูภาพสดได้ ไม่เกิดอันตรายร้ายแรง | M12: solution-1.md แจ้ง alert เข้าหน่วยงานที่เกี่ยวข้องและจัดคิวลอกท่อ สอดคล้องกับกระบวนการทำงานของหน่วย QRT และฝ่ายซ่อมบำรุง | N12: solution-1.md ต้องขอไฟล์วิดีโอบันทึกย้อนหลังจากกล้อง CCTV ของมหาวิทยาลัยหรือ กทม. เพื่อนำมาใช้เทรนและทดสอบระบบ | O12: solution-1.md การเชื่อมต่อสตรีมวิดีโอแบบเรียลไทม์ร่วมกับการคำนวณ Optical Flow ทีละเฟรม มีขั้นตอนการบิวด์และปรับแต่งปานกลาง | P12: schedule.md ระบุ TRL 3 ในสัปดาห์ที่ 13 โดย Solution 1 สามารถสร้างระบบต้นแบบวิเคราะห์วิดีโอบน Bench ได้ทันกำหนด (50% Design) | Q12: solution-1.md ช่วยชี้เป้าว่าน้ำท่วมเกิดจากท่อตันหรือฝนตกหนัก สนับสนุนการลอกท่อระดับเขตตาม SDG 11.5 อย่างมีนัยสำคัญ | R12: solution-1.md พยายามใช้ local sensor ที่มีอยู่แล้ว ไม่ติดตั้งอุปกรณ์ใหม่ในท่อ ไม่สร้างขยะอิเล็กทรอนิกส์ในระบบระบายน้ำ | S12: solution-1.md ตัดสินใจจากข้อมูลความเร็วการไหลของน้ำและระดับน้ำเชิงกายภาพ มีตรรกะที่เปิดเผยและตรวจสอบได้ | T12: =IF(MIN(B9:S9)=1, "VETOED / ตกเกณฑ์ข้อบังคับวิกฤต (คะแนนระดับ 1)", IF(T9>=80, "ผ่านเกณฑ์ระดับสูง (HIGHLY VIABLE)", IF(T9>=60, "ผ่านแบบมีเงื่อนไข (CONDITIONALLY VIABLE)", "ความเสี่ยงสูง (HIGH RISK)")))
A13: แผนลดขอบเขตงาน & มาตรการลดความเสี่ยง (De-scoping Action) | B13: ใช้ Video Ingestion Library มาตรฐานและเชื่อมต่อ REST API เซนเซอร์คลอง | C13: ทำหนังสือขอเชื่อมต่อสัญญาณ RTSP กับสำนักการจราจรและขนส่ง กทม. | D13: ทดสอบอัลกอริทึมในสภาพแสงแดดจ้า แสงสะท้อน และช่วงฝนตกหนักในห้องแล็บก่อน | E13: JK ดูแล Computer Vision, Kin ดูแลการรวมข้อมูลโทรมาตร, Due ดูแลระบบแจ้งเตือน | F13: เลือกใช้อัลกอริทึม Optical Flow มาตรฐานอย่าง Farneback ใน OpenCV แทน PTV เต็มรูปแบบ | G13: คำนวณต้นทุนที่ประหยัดได้จากการลดเที่ยววิ่งตรวจสอบของเจ้าหน้าที่ | H13: ออกแบบระบบ Fallback ไปใช้เฉพาะระดับน้ำในคลองหาก CCTV ออฟไลน์ | I13: ใช้คอมพิวเตอร์ส่วนตัวและเซิร์ฟเวอร์จำลองในการทดสอบทั้งหมด | J13: ติดตั้งโมดูล Edge Anonymization เบลอป้ายทะเบียนและบุคคลก่อนประมวลผล | K13: ใช้ไลบรารีภายใต้สัญญาอนุญาต Apache 2.0 และ MIT | L13: ตั้งค่า Threshold ความเชื่อมั่น หากคะแนนความเชื่อมั่นต่ำให้แจ้งเตือนเป็น Warning | M13: ส่งข้อมูลการแจ้งเตือนเข้าสู่ระบบ LINE Notify ของเจ้าหน้าที่หน้างาน | N13: ติดตั้งกล้องเว็บแคมทดสอบบันทึกภาพผิวน้ำจำลองในมหาวิทยาลัย | O13: สร้างสคริปต์ Python อัตโนมัติสำหรับดึงภาพและวิเคราะห์เฟรมแบบ batch | P13: ล็อกชุดวิดีโอทดสอบภายในสัปดาห์ที่ 9 เพื่อเตรียมทำ PoC ในสัปดาห์ที่ 13 | Q13: จัดทำรายงานสถิติจุดท่อตันเทียบกับประวัติน้ำท่วมซ้ำซาก | R13: ไม่ก่อให้เกิดมลภาวะหรือขยะพลาสติกตกค้างในสิ่งแวดล้อม | S13: บันทึกค่าความเร็วผิวน้ำและระดับน้ำเป็นตัวเลขเชิงประจักษ์ทุก 5 นาที | T13: ปฏิบัติตามแผนลดขอบเขตงาน (De-scoping Advisory)
A15: ตารางสรุปคะแนนแยกตามมิติ TELOS+S (Pillar Score Breakdown)
A16: มิติการประเมิน (TELOS+S Pillar) | B16: สัดส่วนน้ำหนัก (Weight %) | C16: คะแนนเต็มมิติ (Max Points) | D16: คะแนนที่ได้รับจริง (Earned Points) | E16: คะแนนเฉลี่ย (Score 1-5) | F16: ระดับความพร้อม (Readiness Level)
A17: T : ด้านเทคโนโลยีและวิศวกรรม (Technical) | B17: 0.2 | C17: 20 | D17: =SUM(B11:F11)*20 | E17: =IF(C17>0, (D17/C17)*5, 0) | F17: =IF(D17>=16.0, "พร้อมระดับสูง (High)", IF(D17>=12.0, "ปานกลาง (Medium)", "เสี่ยงวิกฤต (Critical)"))
A18: E : ด้านเศรษฐศาสตร์และความคุ้มค่า (Economic) | B18: 0.2 | C18: 20 | D18: =SUM(G11:I11)*20 | E18: =IF(C18>0, (D18/C18)*5, 0) | F18: =IF(D18>=16.0, "พร้อมระดับสูง (High)", IF(D18>=12.0, "ปานกลาง (Medium)", "เสี่ยงวิกฤต (Critical)"))
A19: L : ด้านกฎหมาย ระเบียบ และภาคประชาชน (Legal & Outreach) | B19: 0.15 | C19: 15 | D19: =SUM(J11:K11)*20 | E19: =IF(C19>0, (D19/C19)*5, 0) | F19: =IF(D19>=12.0, "พร้อมระดับสูง (High)", IF(D19>=9.0, "ปานกลาง (Medium)", "เสี่ยงวิกฤต (Critical)"))
A20: O : ด้านการปฏิบัติการและหน้างาน (Operational) | B20: 0.2 | C20: 20 | D20: =SUM(L11:O11)*20 | E20: =IF(C20>0, (D20/C20)*5, 0) | F20: =IF(D20>=16.0, "พร้อมระดับสูง (High)", IF(D20>=12.0, "ปานกลาง (Medium)", "เสี่ยงวิกฤต (Critical)"))
A21: S : ด้านแผนงานและเวลาส่งมอบ (Schedule) | B21: 0.15 | C21: 15 | D21: =P11*20 | E21: =IF(C21>0, (D21/C21)*5, 0) | F21: =IF(D21>=12.0, "พร้อมระดับสูง (High)", IF(D21>=9.0, "ปานกลาง (Medium)", "เสี่ยงวิกฤต (Critical)"))
A22: +S : ด้านความยั่งยืนและสิ่งแวดล้อม (Sustainability / SDG) | B22: 0.1 | C22: 10 | D22: =SUM(Q11:S11)*20 | E22: =IF(C22>0, (D22/C22)*5, 0) | F22: =IF(D22>=8.0, "พร้อมระดับสูง (High)", IF(D22>=6.0, "ปานกลาง (Medium)", "เสี่ยงวิกฤต (Critical)"))
A23: คะแนนรวมทุกมิติ (Total Feasibility Score) | B23: =SUM(B17:B22) | C23: =SUM(C17:C22) | D23: =SUM(D17:D22) | E23: =IF(C23>0, (D23/C23)*5, 0) | F23: =IF(D23>=80, "ผ่านเกณฑ์ระดับสูง (HIGHLY VIABLE)", IF(D23>=60, "ผ่านแบบมีเงื่อนไข (CONDITIONALLY VIABLE)", "ความเสี่ยงสูง (HIGH RISK)"))
A25: เมทริกซ์ประเมินความเข้ากันได้กับองค์ความรู้ด้านวิศวกรรมหุ่นยนต์ (Robotics Knowledge Compatibility)
A26: * หมายเหตุ: การประเมินส่วนนี้วัดศักยภาพในการประยุกต์ใช้องค์ความรู้ด้านวิศวกรรมหุ่นยนต์ (Perception, Control, Actuation, Mechatronics) เต็ม 10 คะแนน | เป็นเอกเทศ ไม่นับรวมในคะแนน TELOS 100 คะแนน
A27: มิติการประเมิน (Robotics Dimension) | B27: คะแนนศักยภาพ (/10) | C27: แกน Perception & Sensing (การรับรู้) | D27: แกน Control & Algorithms (การควบคุม) | E27: แกน Actuation & Mechanisms (กลไก) | F27: บทวิเคราะห์เชิงวิศวกรรมหุ่นยนต์ (FIBO Alignment Rationale)
A28: ศักยภาพการประยุกต์ใช้องค์ความรู้หุ่นยนต์และระบบอัตโนมัติ | B28: 4 | C28: Computer vision optical flow, PIV, PTV for surface runoff velocity estimation and ultrasonic canal level monitoring. | D28: Heuristic threshold classification and drainage capacity diagnostics; lacks dynamic plant state estimation and closed-loop feedback. | E28: Static sensor mounts with zero mechanical actuation, moving parts, or dynamic physical intervention on the environment. | F28: Solution 1 functions as a municipal IoT telemetry and computer vision monitoring system rather than a robotic system. The operational loop breaks at actuation because output is strictly restricted to alerting human operators. It heavily neglects the core mechanical design, power transmission, and physical control capabilities of the team.

Sheet Solution-2
A1: เมทริกซ์ประเมินความเป็นไปได้เชิงระบบ TELOS+S: Sewer Inspection by transmitter and receiver. Mapping Sewer profile
A2: ระบบคะแนนจำนวนเต็มเด็ดขาด: 1, 2, 3, 4, 5 เท่านั้น (ไม่มีจุดทศนิยม / ไม่มี 0.5) | โครงสร้างแบบ Transposed แนวนอน
A4: รหัสคำถาม (Question Code) | B4: T-01 | C4: T-02 | D4: T-03 | E4: T-04 | F4: T-05 | G4: E-01 | H4: E-02 | I4: E-03 | J4: L-01 | K4: L-02 | L4: O-01 | M4: O-02 | N4: O-03 | O4: O-04 | P4: S-01 | Q4: SDG-01 | R4: SDG-02 | S4: SDG-03 | T4: สรุปภาพรวม (SUMMARY)
A5: มิติการประเมิน (TELOS+S Pillar) | B5: ด้านเทคโนโลยีและวิศวกรรม (Technical Feasibility) | C5: ด้านเทคโนโลยีและวิศวกรรม (Technical Feasibility) | D5: ด้านเทคโนโลยีและวิศวกรรม (Technical Feasibility) | E5: ด้านเทคโนโลยีและวิศวกรรม (Technical Feasibility) | F5: ด้านเทคโนโลยีและวิศวกรรม (Technical Feasibility) | G5: ด้านเศรษฐศาสตร์ (Economic Feasibility) | H5: ด้านเศรษฐศาสตร์ (Economic Feasibility) | I5: ด้านเศรษฐศาสตร์ (Economic Feasibility) | J5: ด้านกฎหมายและสถาบัน (Legal & Institutional Feasibility) | K5: ด้านกฎหมายและสถาบัน (Legal & Institutional Feasibility) | L5: ด้านการปฏิบัติการ (Operational Feasibility) | M5: ด้านการปฏิบัติการ (Operational Feasibility) | N5: ด้านการปฏิบัติการ (Operational Feasibility) | O5: ด้านการปฏิบัติการ (Operational Feasibility) | P5: ด้านแผนงานและเวลา (Schedule Feasibility) | Q5: +S ด้านความยั่งยืน (Sustainable Feasibility) | R5: +S ด้านความยั่งยืน (Sustainable Feasibility) | S5: +S ด้านความยั่งยืน (Sustainable Feasibility) | T5: ผลรวมทุกมิติ (All Pillars)
A6: คำถามทดสอบความเสี่ยงจริง (Stress-Test Question) | B6: Implementation (Build vs. Buy Burden): ภาระการสร้างเองกับการเลือกซื้ออุปกรณ์สำเร็จรูป (COTS) | C6: Access (Tech Stack & Ecosystem Permissions): สิทธิ์และการเข้าถึงสแตกเทคโนโลยีและระบบนิเวศน์ | D6: Base Performance (Technology Readiness Level - TRL): ระดับความพร้อมและความเสถียรของเทคโนโลยีฐาน | E6: Team Compatibility (Manpower & Skill Redundancy): ความเข้ากันได้ของทักษะทีมและความพร้อมทดแทน (SPOF) | F6: Learning Curve ("How much do we have to learn?"): เส้นทางการเรียนรู้และระยะเวลาปรับตัวของทีม | G6: ROI (Payback Period / Value Horizon): ระยะเวลาคืนทุนและกรอบความคุ้มค่าทางการเงิน | H6: Dependency of Component (Vendor Lock-in & Reliability): การพึ่งพาผู้ขายภายนอกและความเสี่ยงการผูกขาด | I6: Scrap Margin (Safety Allowance for Blown ICs & Iterations): สัดส่วนงบสำรองสำหรับความเสียหายและการทดลองซ้ำ | J6: Felony and Civil Law (Regulatory, Traffic & Public Safety Compliance): ความสอดคล้องตามกฎหมายอาญา แพ่ง ระเบียบจราจร และความปลอดภัยสาธารณะ | K6: IP and Licensing: สิทธิ์ในทรัพย์สินทางปัญญาและการอนุญาตใช้งานซอฟต์แวร์/ฮาร์ดแวร์ | L6: User — Failure Impact ("If it fails, how severe is the effect?"): ความรุนแรงของผลกระทบเมื่อระบบขัดข้องต่อผู้ใช้และสาธารณะ | M6: User — Behavior & Problem-Solution Fit: ความสอดคล้องกับพฤติกรรมผู้ใช้และกระบวนการทำงานเดิม | N6: Developer — Contribution Dependency (Administrative & Lab Gatekeeping): การพึ่งพาการอนุมัติและอุปสรรคการเข้าถึงห้องปฏิบัติการ/เครื่องมือ | O6: Developer — Complexity (Step Count & Pipeline Friction): ความซับซ้อนของขั้นตอนการประกอบ ติดตั้ง และบิวด์ระบบ | P6: Production Time (Engineering Design Maturity by 5 Business Weeks): วุฒิภาวะของแบบทางวิศวกรรมและความพร้อมผลิตใน 5 สัปดาห์ทำการ | Q6: SDG-01: Public Impact vs. Academic Greenwashing (SDG 11.5 / 13.1): ผลกระทบเชิงประจักษ์ต่อสาธารณะกับการฟอกเขียวทางวิชาการ | R6: SDG-02: Environmental Footprint & E-Waste ("Do No Harm" — SDG 6.3 / 12.4): ภาระสิ่งแวดล้อมและขยะอิเล็กทรอนิกส์ตามหลักไม่สร้างผลเสียซ้ำซ้อน | S6: SDG-03: Algorithmic Equity & Decision Transparency (SDG 10.2 / 16.6): ความเป็นธรรมของอัลกอริทึมและความโปร่งใสในการตัดสินใจ | T6: ประเมินคำถามทั้งสิ้น 18 ข้อ
A7: เหตุผลในการถาม & โหมดความล้มเหลวที่เฝ้าระวัง (Rationale) | B7: ประเมินภาระงานวิจัยและพัฒนาชิ้นส่วนฮาร์ดแวร์/เฟิร์มแวร์ว่าต้องสร้างขึ้นใหม่ตั้งแต่ศูนย์หรือใช้อุปกรณ์สำเร็จรูปมาตรฐาน เพื่อควบคุมความเสี่ยงด้านความผิดพลาดและระยะเวลาพัฒนา | C7: ประเมินข้อจำกัดในการเข้าถึงซอร์สโค้ด สิทธิ์การพัฒนา สิทธิ์การเชื่อมต่อระบบคลาวด์ และสิทธิ์ผู้ดูแลระบบ เพื่อป้องกันปัญหาติดล็อกระบบปิด (Walled Garden) | D7: ประเมินระดับความพร้อมของเทคโนโลยีต้นแบบ (TRL) ว่าอยู่ในระดับแล็บหรือผ่านการทดสอบภาคสนามจริงมาแล้ว เพื่อลดความเสี่ยงจากการนำเทคโนโลยีที่ยังไม่เสถียรมาใช้งาน | E7: ประเมินการกระจายทักษะทางเทคนิคและความเสี่ยงจากการมีผู้เชี่ยวชาญเพียงคนเดียว (Single Point of Failure: SPOF) หากสมาชิกหลักไม่อยู่ โครงการจะหยุดชะงักหรือไม่ | F7: ประเมินช่องว่างทางความรู้และทักษะที่ทีมต้องเรียนรู้เพิ่มขึ้นเมื่อเทียบกับประสบการณ์เดิม ป้องกันปัญหางานสะดุดจากการติดขัดช่วงเริ่มต้นการเรียนรู้เทคโนโลยีใหม่ | G7: ประเมินระยะเวลาในการคืนทุนและมูลค่าทางเศรษฐกิจที่ได้กลับคืนจากการลดความสูญเสียเมื่อเทียบกับเงินลงทุนเริ่มต้น (CapEx) และค่าใช้จ่ายดำเนินงาน (OpEx) | H7: ประเมินความเสี่ยงจากการพึ่งพาระบบคลาวด์เฉพาะ อะไหล่ผูกขาด หรือค่าธรรมเนียมรายปีที่ส่งผลกระทบต่องบประมาณระยะยาวและความยืดหยั่งของระบบ | I7: ประเมินความเพียงพอของงบประมาณสำรองสำหรับชิ้นส่วนที่อาจเสียหายระหว่างการทดสอบ (Burn-in/Debugging) ป้องกันโครงการหยุดชะงักเมื่ออุปกรณ์เสียหาย | J7: ประเมินความเสี่ยงต่อการละเมิดกฎหมาย พ.ร.บ. คุ้มครองข้อมูลส่วนบุคคล (PDPA) การรบกวนสัญญาณคลื่นวิทยุ (กสทช.) หรือการติดตั้งที่กีดขวางทางสัญจรและเสี่ยงต่ออันตรายสาธารณะ | K7: ประเมินข้อกำหนดด้านสัญญาอนุญาตสิทธิ์ (Software/Hardware Licenses) และความเสี่ยงต่อการละเมิดสิทธิบัตรหรือข้อจำกัดแบบไวรัสลิขสิทธิ์ (Viral Copyleft) | L7: ประเมินความรุนแรงของผลกระทบกรณีระบบล้มเหลว (System Failure) ต่อชีวิต ทรัพย์สิน และการปฏิบัติการฉุกเฉินของเจ้าหน้าที่ เพื่อป้องกันโหมดความล้มเหลวขั้นวิกฤต | M7: ประเมินแรงต้านทานในการเปลี่ยนแปลงขั้นตอนการทำงานของผู้ปฏิบัติงาน (Operational Resistance) และภาระงานเอกสารหรือการฝึกอบรมที่เพิ่มขึ้น | N7: ประเมินขั้นตอนความยุ่งยากทางธุรการ การขออนุญาตเข้าใช้สถานที่ และการเข้าถึงอุปกรณ์เครื่องมือในการพัฒนาว่ามีความคล่องตัวหรือถูกปิดกั้น | O7: ประเมินจำนวนขั้นตอนและความเปราะบางของกระบวนการบิวด์ ติดตั้ง และทดสอบระบบ เพื่อลดโอกาสเกิดข้อผิดพลาดจากมนุษย์ (Human Error) | P7: ประเมินความสมบูรณ์ของแบบวิศวกรรม (CAD, Schematics, PCB Gerber, Firmware) เทียบกับกรอบเวลา 5 สัปดาห์ทำการก่อนช่วงสอบและการส่งมอบชิ้นงาน | Q7: ประเมินว่าโครงการสร้างผลกระทบที่วัดผลได้จริงในการลดความสูญเสียจากภัยพิบัติหรือฟื้นฟูเมือง หรือเป็นเพียงข้ออ้างด้านความยั่งยืนเชิงสัญลักษณ์ | R7: ประเมินวงจรชีวิตของอุปกรณ์ การปลดปล่อยสารพิษ ปัญหาขยะอิเล็กทรอนิกส์ (E-Waste) และการหลุดรอดของสารเคมีลงสู่แหล่งน้ำสาธารณะ | S7: ประเมินความโปร่งใสของตรรกะการตัดสินใจและเกณฑ์การตัดคัดกรองเคส เพื่อป้องกันการเลือกปฏิบัติหรือการเพิกเฉยต่อพื้นที่ชุมชนเปราะบาง | T7: สังเคราะห์จาก AI Agents Group 2
A8: เกณฑ์การให้คะแนน (Scoring Rubric Definition: ระดับ 1, 2, 3, 4, 5 ครบทุกระดับ) | B8: 1: Build from Scratch (100% custom R&D required; custom mechanism, bare-metal schematics, custom algorithm derivation; no reference designs or libraries exist) 2: Heavy Customization (Core components exist, but requires extensive custom adaptation, structural machining, and custom wrapper code) 3: Hybrid / COTS Integration (Standard off-the-shelf breakout boards and modules assembled with custom brackets, intermediate wiring, and glue code) 4: Modular COTS Assembly (Pre-engineered building blocks with standard mounting and standard communication buses e.g. DIN-rail modules, I2C/CAN shields; minimal custom fabrication) 5: Buy and Use / COTS (Buy and deploy directly out of the box / Plug-and-Play; zero mechanical or electrical fabrication required) | C8: 1: Strictly Restricted (Proprietary stack under NDA, locked enterprise firewalls, or unavailable developer licenses) 2: Limited Access (Closed binary blobs or third-party proprietary firmware; black-box operation with zero telemetry or source code) 3: Request-Based Access (Educational/evaluation tier with strict rate limits or quotas; requires formal request or approval delays) 4: Open Developer Access (Free public SDKs, full documentation, and open developer APIs, but core low-level architecture cannot be modified) 5: Full-Stack Access (Fully open source with permissive license and open hardware; team has root/admin rights to inspect, modify, and deploy as both user and developer) | D8: 1: Proof of Concept (TRL 2–3: Bench breadboard, simulation, or pure mathematical model; verified only in controlled laboratory conditions) 2: Functional Breadboard (TRL 4: Integrated components working together in a lab; fragile wiring, uncalibrated for harsh field environments) 3: Alpha Prototype (TRL 5–6: Enclosed prototype tested in a relevant simulated environment; operational, but requires human supervision) 4: Beta / Field-Proven (TRL 7: Pre-production hardware operating reliably in the actual operating environment under real-world stress) 5: Commercial Product (TRL 8–9: Fully certified, production-grade commercial product with documented MTBF and mass field reliability) | E8: 1: Single Point of Failure / SPOF (Only 1 person has the required skill; if they are unavailable, subsystem development halts 100%) 2: Solo Lead with Minimal Backup (1 core developer; 1 teammate understands basic concepts but cannot debug code or fix hardware alone) 3: Primary + Secondary Pair (1 primary lead and 1 competent secondary backup who can maintain, troubleshoot, and push updates) 4: Broad Competence (3+ teammates can actively design, assemble, and debug the subsystem with minimal ramp-up time) 5: Full Team Redundancy (All team members are fully proficient; tasks can be swapped across anyone with zero friction or velocity loss) | F8: 1: Total Reset (Every step requires learning completely unfamiliar tools, languages, and hardware from scratch with zero prior baseline) 2: Steep Learning Curve (High theoretical understanding, but zero hands-on experience; debugging basic syntax or wiring stalls progress) 3: Moderate Ramp-up (Proven adjacent mastery e.g. Arduino/ESP32 moving to STM32, or SolidWorks to Fusion 360; manageable 1-week curve) 4: Minor Adaptation (Familiar tech stack; only requires learning a specific minor library, sensor API, or configuration syntax) 5: Zero Learning Curve (Team can deploy verified past code, existing toolchains, and established muscle memory directly; no new learning required) | G8: 1: Long Payback (>= 10 Years: High initial CapEx with minimal recurring savings; economically non-viable for rapid deployment) 2: Slow Return (6–9 Years: Substantial capital investment with a long break-even horizon; requires long-term subsidization) 3: Moderate Return (3–5 Years: Reasonable public infrastructure payback; offsets costs across multi-year operational cycles) 4: Fast Return (2–3 Years: Strong operational cost reduction in fuel, labor, scrap; breaks even within normal equipment lifecycle) 5: Immediate Payback (<= 1–2 Years: Rapid break-even; eliminates major recurring operational losses within the first operating season) | H8: 1: Total Vendor Lock-in (100% dependent on proprietary cloud backend, encrypted telemetry, and single-source proprietary connectors) 2: High Dependency (Hardware requires vendor-licensed diagnostic tools or annual subscription fees to maintain operation) 3: Semi-Independent (Core hardware relies on proprietary firmware, but allows open API export and standard electrical interfaces) 4: High Autonomy (Uses standard open communication protocols e.g. Modbus, MQTT, CAN; parts can be serviced using generic tools) 5: Complete Independence (100% open architecture; hardware is interchangeable with generic substitutes; self-serviceable by any engineer) | I8: 1: Zero Buffer (0%: Exactly 1x BOM purchased; any fried chip, cracked bracket, or wiring mistake halts the project) 2: Fragile Buffer (20–30%: Spares only for passive components; no backup microcontrollers or expensive sensors) 3: Moderate Buffer (50%: Spares for all critical passive parts and 1 spare for the primary controller board) 4: High Buffer (80%: Spares for nearly every active component and sensor; can sustain multiple prototype burn-ins) 5: Full Redundancy (>= 100%: Complete 2x BOM budget on hand; can build two complete working units simultaneously) | J8: 1: Severe Violation / No Privilege (Direct breach of statutory law e.g. unconsented public surveillance/PDPA, hazardous road blockage, illegal RF transmission) 2: High Legal Exposure (Ambiguous legal zone; high risk of civic complaints or traffic disruption; requires complex technical waivers) 3: Conditional / Requires Permit (Permitted strictly under formal written approval, official agency MoU, or municipal permits) 4: Low Legal Friction (Operates within standard public engineering exemptions; simple standard notification/safety compliance needed) 5: 100% Free Domain (Fully exempt from statutory licensing; zero public safety risk, zero personal data/Zero PII, fully unrestricted) | K8: 1: Closed Commercial Barrier (Proprietary commercial license; cannot compile, flash, or operate without paying expensive commercial seat licenses) 2: Ambiguous / Gray IP (Unclear licensing terms or unlicensed public repos; risk of copyright strike or IP dispute upon public demonstration) 3: Restrictive Open Source / Copyleft (Permitted for educational use, but viral licenses e.g. GPLv3 force your entire codebase to be made public if distributed) 4: Permissive Open Source (Open source with minimal conditions e.g. LGPL, CC-BY; allows proprietary wrapping with simple attribution) 5: Completely Permissive / Public Domain (Permissive open source e.g. MIT, Apache 2.0, BSD or Public Domain; unrestricted freedom to commercialize, modify, and contribute) | L8: 1: Life-Threatening (Failure causes electrocution, fire, traffic collisions, toxic chemical exposure, or structural collapse) 2: Severe Physical Hazard (Equipment destroys itself, causes acute environmental contamination, or halts major emergency infrastructure) 3: Chaotic Response from User (Panic, operational deadlock, conflicting manual dispatches, and severe operational confusion) 4: Minor Operational Delay (System trips safely; requires a manual reboot or standard fallback procedure; no safety risk or chaos) 5: Benign Budget Loss Only (Failure causes zero human or operational harm; results only in minor, easily absorbed component/battery replacement costs) | M8: 1: Disruptive Overhaul (Forces operators to abandon existing standard procedures, adds 5+ extra tedious forms, and faces active user rejection) 2: High Friction (Adds notable extra documentation or redundant verification steps; operators will actively look for ways to bypass it) 3: Moderate Adaptation (Modifies daily routines slightly; requires 1–2 training sessions, but delivers clear operational trade-offs) 4: Low Friction (Integrates directly into existing tools e.g. sends alerts to existing LINE/Telegram or ticketing dashboard; minimal habit changes) 5: Smooth Transient Operation (Zero workflow disruption; runs transparently in the background and automates existing manual paperwork seamlessly) | N8: 1: Heavy Gatekeeping (Blocked by supervisor approvals, locked lab cabinets, NDA signatures, purchasing bureaucracy, and restricted git branches) 2: Moderate Bureaucracy (Requires departmental request forms, tool booking queues, and waiting 3–5 days for administrative sign-offs) 3: Standard Campus Access (Workable access during university open hours; minor approval delays for specialized equipment or lab keys) 4: High Autonomy (Team has full repository write access, open 24/7 lab entry, and pre-approved discretionary stipends for rapid purchases) 5: Frictionless Contribution (Complete autonomy; decentralized cloud CI/CD, local prototyping tools at home/bench, zero administrative blockers) | O8: 1: Highly Convoluted (Dozens of fragile build steps, complex toolchain dependencies, and high probability of human error during setup) 2: High Complexity (Multi-stage manual toolchains; frequent dependency conflicts and difficult multi-board flashing procedures) 3: Moderate Complexity (Standard multi-step build/assembly pipeline; manageable and repeatable when following a documented checklist) 4: Low Complexity (Straightforward workflow using automated build scripts, standard IDEs, or single-command flashing) 5: Simple & Direct (Plug-and-play, 1-step linear workflow; idiot-proof setup requiring zero multi-stage manual configuration) | P8: 1: Concept Only (0% Design: Napkin sketches and verbal ideas; 0% CAD models, 0% schematics, 0% firmware written) 2: Rough Drafts (25% Design: Preliminary block diagrams, hand-drawn schematics, unverified parts list, rough 3D bounding boxes) 3: Intermediate Maturity (50% Design: Complete CAD assembly with untested clearances, schematic capture complete, draft firmware architecture mapped) 4: Pre-Production (75–80% Design: Detailed 3D CAD ready for 3D print/CNC, routed PCB Gerber files verified with DRC, pinouts locked down) 5: Fully Engineered Design (100% Production Ready: Complete manufacturing package: verified Gerbers, mechanical tolerance drawings, locked BOM, and flashing scripts ready) | Q8: 1: Pure Buzzword / Greenwashing (Claims sustainability benefits with zero data, zero measurable effect, and solves no real municipal problem) 2: Superficial Correlation (Indirect impact; functions only as an isolated school demo with no realistic way to measure damage prevention) 3: Localized Proof (Delivers a measurable, verified benefit e.g. cuts response time or drops localized temperature on a single test strip, but lacks a scaling model) 4: District-Level Viability (Clear pathway to protect municipal infrastructure or reduce public losses across multiple roads/alleys during extreme weather) 5: Systemic City Resilience (Backed by concrete empirical data showing significant reduction in public economic losses, vehicle damage, or human hazard) | R8: 1: Toxic Field Hazard (Enclosure degrades under UV, or unsealed batteries leak toxic chemicals and detach into the urban drainage network as marine litter) 2: Fragile Disposable Tech (Short operational lifespan; sensors foul or corrode within 2–3 weeks and are abandoned because retrieval is impractical) 3: Standard Field Footprint (Requires periodic battery replacement and creates standard electronic scrap, but uses basic tethering to prevent total hardware loss) 4: Low-Impact Enclosure (Solar-trickle or long-life low-power architecture; uses recyclable casing and redundant physical tethers e.g. dual stainless lanyards) 5: Fully Circular & Zero Footprint (100% fail-safe retrieval design; uses non-toxic materials, consumes minimal public resources, and leaves zero field trace) | S8: 1: Opaque Black Box (Proprietary or unexplained threshold that cancels dispatches or alters public services with zero explanation, risking neglect of vulnerable areas) 2: Ambiguous Logic (Decision rules are buried in messy heuristic code; field operators cannot explain to a citizen why an alert was triggered or suppressed) 3: Documented Internal Rules (Logic is documented on paper for engineers, but has no public audit trail or clear appeal mechanism if the sensor misreads) 4: Open Empirical Standards (Decisions are driven by transparent physical equations applied equally across all city zones) 5: 100% Auditable & Equitable (Full tamper-evident digital audit trail; open logic accessible to officials and citizens, guaranteeing equal public protection regardless of district wealth) | T8: เกณฑ์รวม: >=80 ผ่านสูง, >=60 มีเงื่อนไข, <60 เสี่ยงสูง | หากมีข้อใดได้ 1 = VETOED ตกเกณฑ์ทันที
A9: คะแนนที่ได้รับ (ASSIGNED SCORE: 1, 2, 3, 4, 5 STRICT INTEGER) | B9: 3 | C9: 4 | D9: 2 | E9: 3 | F9: 2 | G9: 4 | H9: 4 | I9: 3 | J9: 3 | K9: 3 | L9: 4 | M9: 4 | N9: 3 | O9: 3 | P9: 3 | Q9: 4 | R9: 5 | S9: 4 | T9: =IF(T10>0, (T11/T10)*20, 0)
A10: ค่าน้ำหนัก (Weight %) | B10: 0.04 | C10: 0.04 | D10: 0.04 | E10: 0.04 | F10: 0.04 | G10: 0.0667 | H10: 0.0667 | I10: 0.0666 | J10: 0.075 | K10: 0.075 | L10: 0.05 | M10: 0.05 | N10: 0.05 | O10: 0.05 | P10: 0.15 | Q10: 0.0333 | R10: 0.0333 | S10: 0.0334 | T10: =SUM(B10:S10)
A11: คะแนนถ่วงน้ำหนัก (=Score * Weight) | B11: =B9*B10 | C11: =C9*C10 | D11: =D9*D10 | E11: =E9*E10 | F11: =F9*F10 | G11: =G9*G10 | H11: =H9*H10 | I11: =I9*I10 | ... S11: =S9*S10 | T11: =SUM(B11:S11)
A12: คำอธิบาย & หลักฐานอ้างอิงจากไฟล์ Intake (Evidence Citation) | B12: solution-2.md ส่วน Operation flow ต้องประกอบชุด Transmitter และ Receiver ก้านหย่อน และวงจรวิเคราะห์สัญญาณเสียง (Hybrid Integration) | C12: solution-2.md ใช้หลักการ Airborne Acoustic Reflectometry และการกรองสัญญาณ เป็นหลักฟิสิกส์เปิดที่ทีมพัฒนาโค้ดประมวลผลได้เอง | D12: solution-2.md Weak point ระบุว่า 'Can’t use in water in pipe situation' แต่ท่อ กทม. มีน้ำขังตลอดเวลา อยู่ในระดับ Functional Breadboard (TRL 4) | E12: due.md (ระบบเสียง/แอมป์ MAX98357), fifa.md (โครงสร้างก้านหย่อน), jk.md (ฟิสิกส์คลื่น/การคำนวณ) มีทีมงานหลัก 3 คน | F12: solution-2.md การสร้างภาพตัดขวาง 2D ของท่อจากการลดทอนของพลังงานเสียงในอากาศเป็นทฤษฎีใหม่ที่ทีมไม่มีประสบการณ์ตรง (Steep Curve) | G12: solution-2.md ช่วยคัดกรองสภาพท่อได้อย่างรวดเร็ว ลดการส่งรถดูดเลนไปล้างท่อที่ไม่ตัน ประหยัดงบประมาณบำรุงรักษา คืนทุนใน 2-3 ปี | H12: solution-2.md หัวส่งสัญญาณ ตัวรับสัญญาณ และอุปกรณ์ประมวลผลสามารถหาซื้อได้ทั่วไป ไม่ผูกขาดกับผู้ผลิตรายเดียว | I12: solution-2.md การหย่อนอุปกรณ์ลงในบ่อพักน้ำมีความเสี่ยงต่อความชื้นและน้ำกระเด็น งบประมาณสำรองชิ้นส่วนรองรับที่ 50% | J12: solution-2.md การเปิดฝาท่อพักน้ำเพื่อวางตัวรับ-ส่งสัญญาณบนทางเท้า ต้องขออนุญาตสำนักงานเขตและวางกรวยกั้นความปลอดภัยจราจร | K12: solution-2.md ระบบตรวจวัดด้วยเสียงในท่อมีสิทธิบัตรคุ้มครองของ SL-RAT ในต่างประเทศ ทำเพื่อการศึกษาได้แต่ต้องระวังหากผลิตเชิงพาณิชย์ | L12: solution-2.md ปฏิบัติงานจากผิวทางเท้าโดยไม่ต้องมุดลงไปในท่อระบายน้ำ หากอุปกรณ์ขัดข้องไม่ส่งผลกระทบต่อความปลอดภัยของมนุษย์ | M12: solution-2.md แสดงผลเป็นภาพตัดขวาง 2D และจำแนก Good/Bad เข้าใจง่าย สอดคล้องกับความต้องการของฝ่ายวางแผนจัดคิวลอกท่อ | N12: solution-2.md ต้องขออนุญาตเข้าใช้สถานที่ทดสอบท่อระบายน้ำจำลองในมหาวิทยาลัยเพื่อสอบเทียบค่าการลดทอนของเสียง | O12: solution-2.md มีขั้นตอนการตั้งค่าความถี่เสียง การตัดสัญญาณรบกวน และการจัดแนวหัวส่ง-รับให้ตรงกันในท่อ | P12: schedule.md สามารถสร้างต้นแบบกระบอกส่ง-รับสัญญาณเสียงและโค้ดวิเคราะห์ระดับ TRL 3 ได้ใน 5 สัปดาห์ก่อนสอบ | Q12: solution-2.md ช่วยสนับสนุนการทำแผนที่ท่อระบายน้ำและวางแผนซ่อมบำรุงเชิงรุก ลดความเสี่ยงน้ำท่วมเมืองตาม SDG 11.5 | R12: solution-2.md เครื่องมือติดอยู่กับก้านหย่อน ไม่ทิ้งอุปกรณ์หรือสารเคมีไว้ในท่อระบายน้ำ ปลอดภัยต่อสิ่งแวดล้อม 100% | S12: solution-2.md ประเมินจากค่าการลดทอนของพลังงานเสียงตามหลักฟิสิกส์ โปร่งใส ขจัดปัญหาการใช้ดุลยพินิจส่วนบุคคล | T12: =IF(MIN(B9:S9)=1, "VETOED / ตกเกณฑ์ข้อบังคับวิกฤต (คะแนนระดับ 1)", IF(T9>=80, "ผ่านเกณฑ์ระดับสูง (HIGHLY VIABLE)", IF(T9>=60, "ผ่านแบบมีเงื่อนไข (CONDITIONALLY VIABLE)", "ความเสี่ยงสูง (HIGH RISK)")))
A13: แผนลดขอบเขตงาน & มาตรการลดความเสี่ยง (De-scoping Action) | B13: ใช้โมดูลลำโพงและไมโครโฟน COTS ประกบกับก้านวัดสำเร็จรูป | C13: เขียนเฟิร์มแวร์วิเคราะห์สัญญาณเสียงสะท้อนด้วย C/C++ บน ESP32 | D13: ทดสอบในท่อคอนกรีตจำลองที่มีระดับน้ำขังและความชื้นสูงเพื่อหาข้อจำกัด | E13: Due ดูแลวงจรกำเนิดและรับเสียง, Fifa ดูแลงานกลไก, JK คำนวณการลดทอนของคลื่น | F13: ปรึกษาอาจารย์ภาควิชาฟิสิกส์/วิศวกรรมเรื่อง Acoustic Attenuation | G13: ทำตารางเปรียบเทียบค่าใช้จ่ายการตรวจด้วยเสียงเทียบกับการใช้กล้องมุดท่อ | H13: เลือกลำโพงและไมโครโฟนเกรดกันน้ำที่มีจำหน่ายแพร่หลาย | I13: จัดซื้อหัวไมโครโฟนและทรานสดิวเซอร์สำรองอย่างน้อย 1 ชุด | J13: ทำหนังสือขออนุญาตลงพื้นที่และจัดเตรียมกรวยจราจรสะท้อนแสง | K13: ศึกษารายละเอียดสิทธิบัตรเพื่อหลีกเลี่ยงการละเมิดกระบวนการเฉพาะ | L13: กำหนดแนวทางปฏิบัติห้ามเจ้าหน้าที่ลงไปในท่อระบายน้ำโดยเด็ดขาด | M13: ออกแบบหน้าจอสรุปผลบนสมาร์ตโฟนแสดงผลแถบสี เขียว-เหลือง-แดง | N13: ติดต่อห้องปฏิบัติการสิ่งแวดล้อมเพื่อขอใช้ท่อทดสอบ | O13: ทำเครื่องหมายล็อกตำแหน่งบนก้านหย่อนเพื่อความแม่นยำในการวางตำแหน่ง | P13: ขึ้นรูปเคส 3D Print สำหรับยึดลำโพงและไมโครโฟนให้เสร็จในสัปดาห์ที่ 11 | Q13: นำร่องตรวจประเมินท่อระบายน้ำรอบมหาวิทยาลัยเพื่อสร้างฐานข้อมูลตัวอย่าง | R13: ใช้วัสดุก้านหย่อนที่ทนทานและเช็ดทำความสะอาดได้ง่าย | S13: แสดงค่ากราฟการลดทอนของคลื่นเสียงเป็นหลักฐานประกอบทุกรายงาน | T13: ปฏิบัติตามแผนลดขอบเขตงาน (De-scoping Advisory)
A15: ตารางสรุปคะแนนแยกตามมิติ TELOS+S (Pillar Score Breakdown)
A16: มิติการประเมิน (TELOS+S Pillar) | B16: สัดส่วนน้ำหนัก (Weight %) | C16: คะแนนเต็มมิติ (Max Points) | D16: คะแนนที่ได้รับจริง (Earned Points) | E16: คะแนนเฉลี่ย (Score 1-5) | F16: ระดับความพร้อม (Readiness Level)
A17: T : ด้านเทคโนโลยีและวิศวกรรม (Technical) | B17: 0.2 | C17: 20 | D17: =SUM(B11:F11)*20 | E17: =IF(C17>0, (D17/C17)*5, 0) | F17: =IF(D17>=16.0, "พร้อมระดับสูง (High)", IF(D17>=12.0, "ปานกลาง (Medium)", "เสี่ยงวิกฤต (Critical)"))
A18: E : ด้านเศรษฐศาสตร์และความคุ้มค่า (Economic) | B18: 0.2 | C18: 20 | D18: =SUM(G11:I11)*20 | E18: =IF(C18>0, (D18/C18)*5, 0) | F18: =IF(D18>=16.0, "พร้อมระดับสูง (High)", IF(D18>=12.0, "ปานกลาง (Medium)", "เสี่ยงวิกฤต (Critical)"))
A19: L : ด้านกฎหมาย ระเบียบ และภาคประชาชน (Legal & Outreach) | B19: 0.15 | C19: 15 | D19: =SUM(J11:K11)*20 | E19: =IF(C19>0, (D19/C19)*5, 0) | F19: =IF(D19>=12.0, "พร้อมระดับสูง (High)", IF(D19>=9.0, "ปานกลาง (Medium)", "เสี่ยงวิกฤต (Critical)"))
A20: O : ด้านการปฏิบัติการและหน้างาน (Operational) | B20: 0.2 | C20: 20 | D20: =SUM(L11:O11)*20 | E20: =IF(C20>0, (D20/C20)*5, 0) | F20: =IF(D20>=16.0, "พร้อมระดับสูง (High)", IF(D20>=12.0, "ปานกลาง (Medium)", "เสี่ยงวิกฤต (Critical)"))
A21: S : ด้านแผนงานและเวลาส่งมอบ (Schedule) | B21: 0.15 | C21: 15 | D21: =P11*20 | E21: =IF(C21>0, (D21/C21)*5, 0) | F21: =IF(D21>=12.0, "พร้อมระดับสูง (High)", IF(D21>=9.0, "ปานกลาง (Medium)", "เสี่ยงวิกฤต (Critical)"))
A22: +S : ด้านความยั่งยืนและสิ่งแวดล้อม (Sustainability / SDG) | B22: 0.1 | C22: 10 | D22: =SUM(Q11:S11)*20 | E22: =IF(C22>0, (D22/C22)*5, 0) | F22: =IF(D22>=8.0, "พร้อมระดับสูง (High)", IF(D22>=6.0, "ปานกลาง (Medium)", "เสี่ยงวิกฤต (Critical)"))
A23: คะแนนรวมทุกมิติ (Total Feasibility Score) | B23: =SUM(B17:B22) | C23: =SUM(C17:C22) | D23: =SUM(D17:D22) | E23: =IF(C23>0, (D23/C23)*5, 0) | F23: =IF(D23>=80, "ผ่านเกณฑ์ระดับสูง (HIGHLY VIABLE)", IF(D23>=60, "ผ่านแบบมีเงื่อนไข (CONDITIONALLY VIABLE)", "ความเสี่ยงสูง (HIGH RISK)"))
A25: เมทริกซ์ประเมินความเข้ากันได้กับองค์ความรู้ด้านวิศวกรรมหุ่นยนต์ (Robotics Knowledge Compatibility)
A26: * หมายเหตุ: การประเมินส่วนนี้วัดศักยภาพในการประยุกต์ใช้องค์ความรู้ด้านวิศวกรรมหุ่นยนต์ (Perception, Control, Actuation, Mechatronics) เต็ม 10 คะแนน | เป็นเอกเทศ ไม่นับรวมในคะแนน TELOS 100 คะแนน
A27: มิติการประเมิน (Robotics Dimension) | B27: คะแนนศักยภาพ (/10) | C27: แกน Perception & Sensing (การรับรู้) | D27: แกน Control & Algorithms (การควบคุม) | E27: แกน Actuation & Mechanisms (กลไก) | F27: บทวิเคราะห์เชิงวิศวกรรมหุ่นยนต์ (FIBO Alignment Rationale)
A28: ศักยภาพการประยุกต์ใช้องค์ความรู้หุ่นยนต์และระบบอัตโนมัติ | B28: 3.5 | C28: Airborne Acoustic Reflectometry (AAR) using acoustic transceivers to measure sound attenuation and acoustic impedance within sewer pipes. | D28: Digital signal processing (FFT, bandpass filtering, time-of-flight cross-correlation) and cross-sectional 2D profile reconstruction without feedback control. | E28: Purely manual transmitter/receiver deployment across manholes; actuation is limited to acoustic transducer sound vibration without mechanical traversal or robotic manipulation. | F28: Solution 2 is an acoustic Non-Destructive Testing (NDT) diagnostic instrument rather than an autonomous robotic system. While technically grounded in sensor wave physics, it operates in an open loop terminating at human-interpreted cross-section imagery. It lacks any automated locomotion or physical actuation, underutilizing mechanical and control engineering competencies.

Sheet Solution-3
A1: เมทริกซ์ประเมินความเป็นไปได้เชิงระบบ TELOS+S: ระบบปล่อยน้ำแบบ Adaptive เพื่อระบายความร้อนบนทางเดินเท้าและตรอกซอยอย่างมีประสิทธิภาพสูงสุด
A2: ระบบคะแนนจำนวนเต็มเด็ดขาด: 1, 2, 3, 4, 5 เท่านั้น (ไม่มีจุดทศนิยม / ไม่มี 0.5) | โครงสร้างแบบ Transposed แนวนอน
A4: รหัสคำถาม (Question Code) | B4: T-01 | C4: T-02 | D4: T-03 | E4: T-04 | F4: T-05 | G4: E-01 | H4: E-02 | I4: E-03 | J4: L-01 | K4: L-02 | L4: O-01 | M4: O-02 | N4: O-03 | O4: O-04 | P4: S-01 | Q4: SDG-01 | R4: SDG-02 | S4: SDG-03 | T4: สรุปภาพรวม (SUMMARY)
