Workbook

Sheet เปรียบเทียบทุก Solution
A1: ตารางเปรียบเทียบความเป็นไปได้ของทุกข้อเสนอ (Multi-Solution Feasibility Summary)
A2: วิเคราะห์เปรียบเทียบเชิงระบบตามเกณฑ์ TELOS+S (เต็ม 100) และเมทริกซ์ศักยภาพด้านวิศวกรรมหุ่นยนต์ (เต็ม 12 แยกอิสระ)
A4: ลำดับ | B4: รหัสข้อเสนอ (Solution ID) | C4: ชื่อแนวทางแก้ปัญหา (Title / Concept) | D4: คะแนนรวม (เต็ม 100) | E4: T: เทคนิค (/20) | F4: E: เศรษฐศาสตร์ (/20) | G4: L: กฎหมาย (/15) | H4: O: ปฏิบัติการ (/20) | I4: S: แผนงาน (/15) | J4: +S: ยั่งยืน (/10) | K4: ผลการประเมิน (Verdict) | L4: จุดแข็งสำคัญ (Key Strengths) | M4: จุดติดขัดวิกฤต (Critical Bottlenecks) | N4: คำแนะนำเชิงระบบ (Strategic Advice) | O4: Robotics Potential (/12) | P4: เหตุผลความเข้ากันได้ด้านหุ่นยนต์ (Robotics Engineering Rationale)
A5: 1 | B5: Solution_1_CCTV_Flow | C5: CCTV on the road (Visual water flow) + ultrasonic to measure the flow rate of the canal + alarm | D5: ='Solution_1_CCTV_Flow'!S9 | E5: ='Solution_1_CCTV_Flow'!D17 | F5: ='Solution_1_CCTV_Flow'!D18 | G5: ='Solution_1_CCTV_Flow'!D19 | H5: ='Solution_1_CCTV_Flow'!D20 | I5: ='Solution_1_CCTV_Flow'!D21 | J5: ='Solution_1_CCTV_Flow'!D22 | K5: ='Solution_1_CCTV_Flow'!S12 | L5: ใช้โครงสร้างพื้นฐานเดิมของเมือง (กล้อง CCTV กทม. และเซนเซอร์วัดระดับน้ำในคลอง) ทำให้ต้นทุน CapEx เริ่มแรกต่ำมาก | M5: ติดกำแพงไฟร์วอลล์และสิทธิ์เข้าถึงสตรีมกล้อง กทม. (T-02=1), อัลกอริทึม PIV/PTV จากกล้องที่ไม่มีการสอบเทียบเป็นเพียง TRL 2-3 (T-03=1), และพึ่งพา JK เพียงคนเดียว (T-04=1) | N5: ยกเลิกการพึ่งพากล้องวงจรปิด กทม. แล้วหันมาใช้กล้องหรือเซนเซอร์วัดระดับน้ำ/แรงดันของทีมเองในจุดทดสอบเฉพาะ พร้อมใช้อัลกอริทึมตรวจจับความเคลื่อนไหวพื้นฐานแทน PIV | O5: 6 | P5: Solution 1 operates as a smart city telemetry and video monitoring platform rather than a robotic system. It suffers from a broken Sense-Think-Act triad, as actuation terminates in human alerts. It underutilizes team capabilities in mechanical design, fabrication, custom PCB design, and dynamic feedback control.
A6: 2 | B6: Solution_2_Acoustic_Sewer | C6: Sewer Inspection by transmitter and receiver. Mapping Sewer profile | D6: ='Solution_2_Acoustic_Sewer'!S9 | E6: ='Solution_2_Acoustic_Sewer'!D17 | F6: ='Solution_2_Acoustic_Sewer'!D18 | G6: ='Solution_2_Acoustic_Sewer'!D19 | H6: ='Solution_2_Acoustic_Sewer'!D20 | I6: ='Solution_2_Acoustic_Sewer'!D21 | J6: ='Solution_2_Acoustic_Sewer'!D22 | K6: ='Solution_2_Acoustic_Sewer'!S12 | L6: ใช้วิธีตรวจจับคลื่นเสียงสะท้อนผ่านอากาศในท่อ (Airborne Acoustic Reflectometry) ตรวจได้รวดเร็ว สามารถคำนวณพื้นที่หน้าตัด 2D และแปลงผลเป็นระดับความสะอาด 0-10 สเกล เพื่อจัดคิวลอกท่อได้ทันที ปลอดสารพิษ ไร้ e-waste (SDG Score สูงสุด) | M6: การเปิดฝาท่อบนผิวถนนมีความเสี่ยงด้านความปลอดภัยและกฎหมายจราจร/พื้นที่อับอากาศ (L-01=2) และไม่สามารถตรวจวัดในช่วงที่มีน้ำท่วมขังสูงในท่อได้ (ต้องตรวจช่วงปกติที่น้ำต่ำ) | N6: จำกัดการทดสอบภาคเรียนนี้ในท่อจำลองพีวีซีบนโต๊ะทดลองแล็บหรือท่อระบายน้ำภายใน มจธ. และลดทอนการประมวลผลภาพ 2D ให้เหลือเพียงการคำนวณการสูญเสียพลังงานเสียงเทียบกับ Look-up table เพื่อลดความซับซ้อน | O6: 8 | P6: Solution 2 is an advanced acoustic Non-Destructive Testing (NDT) diagnostic instrument. The user clarification regarding low-water operating protocol and automated 0-10 cleanliness classification elevates its sensing and DSP depth. However, it remains an open-loop diagnostic tool lacking autonomous locomotion or physical actuation, underutilizing the team's mechanical fabrication and transmission design skills.
A7: 3 | B7: Solution_3_Adaptive_Misting | C7: ระบบปล่อยน้ำแบบ Adaptive เพื่อระบายความร้อนบนทางเดินเท้าและตรอกซอยอย่างมีประสิทธิภาพสูงสุด | D7: ='Solution_3_Adaptive_Misting'!S9 | E7: ='Solution_3_Adaptive_Misting'!D17 | F7: ='Solution_3_Adaptive_Misting'!D18 | G7: ='Solution_3_Adaptive_Misting'!D19 | H7: ='Solution_3_Adaptive_Misting'!D20 | I7: ='Solution_3_Adaptive_Misting'!D21 | J7: ='Solution_3_Adaptive_Misting'!D22 | K7: ='Solution_3_Adaptive_Misting'!S12 | L7: เป็นระบบหุ่นยนต์และเมคคาทรอนิกส์แบบ Closed-loop สมบูรณ์ (Robotics Score 8.0/10 สูงสุด) ใช้ COTS สำเร็จรูป ทีมงานมีความพร้อมทางเทคนิคครบถ้วน (TRL 7) | M7: ตกเกณฑ์ข้อบังคับวิกฤตด้านเศรษฐศาสตร์ (E-01=1 VETOED) เนื่องจากใช้น้ำประปาและพลังงานต่อเนื่องโดยไม่มีผลตอบแทนทางการเงิน และมีความเสี่ยงสูงต่อการลื่นล้มของคนเดินถนน (O-01=2) รวมถึงการต่อต้านจากร้านค้าริมทาง (O-02=2) | N7: เปลี่ยนพื้นที่ติดตั้งจากตรอกซอยทางเดินแคบไปเป็นศาลาพักผู้โดยสารหรือลานกิจกรรมกลางแจ้งที่มีระบบระบายน้ำ และใช้น้ำฝนบำบัดแทนน้ำประปา พร้อมติดแผ่นยางกันลื่น | O7: 10 | P7: Solution 3 represents a complete closed-loop cyber-physical mechatronic automation system (Sense -> Think -> Act -> Feedback). It achieves 100% synergy with the team's multidisciplinary curriculum, fully engaging CAD/FEA mechanical design (Fifa/Jay), custom driver PCB and firmware (Due), feedback control theory and differential heat modeling (JK), and telemetry analytics (Kin). It scores 10.0/12.0 due to its stationary configuration lacking multi-DOF kinematics or mobile locomotion.

Sheet Solution_1_CCTV_Flow
A1: เมทริกซ์ประเมินความเป็นไปได้เชิงระบบ TELOS+S: CCTV on the road (Visual water flow) + ultrasonic to measure the flow rate of the canal + alarm
A2: ระบบคะแนนจำนวนเต็มเด็ดขาด: 1, 2, 3, 4, 5 เท่านั้น (ไม่มีจุดทศนิยม / ไม่มี 0.5) | โครงสร้างแบบ Transposed แนวนอน
A4: รหัสคำถาม (Question Code) | B4: T-01 | C4: T-02 | D4: T-03 | E4: T-04 | F4: T-05 | G4: E-01 | H4: E-02 | I4: E-03 | J4: L-01 | K4: L-02 | L4: O-01 | M4: O-02 | N4: O-03 | O4: O-04 | P4: S-01 | Q4: SDG-01 | R4: SDG-02 | S4: สรุปภาพรวม (SUMMARY)
A5: มิติการประเมิน (TELOS+S Pillar) | B5: ด้านเทคนิค (Technical 2.2) | C5: ด้านเทคนิค (Technical 2.2) | D5: ด้านเทคนิค (Technical 2.2) | E5: ด้านเทคนิค (Technical 2.2) | F5: ด้านเทคนิค (Technical 2.2) | G5: ด้านเศรษฐศาสตร์ (Economic 2.3) | H5: ด้านเศรษฐศาสตร์ (Economic 2.3) | I5: ด้านเศรษฐศาสตร์ (Economic 2.3) | J5: ด้านกฎหมายและสถาบัน (Legal 2.4) | K5: ด้านกฎหมายและสถาบัน (Legal 2.4) | L5: ด้านปฏิบัติการ (Operational 2.5) | M5: ด้านปฏิบัติการ (Operational 2.5) | N5: ด้านปฏิบัติการ (Operational 2.5) | O5: ด้านปฏิบัติการ (Operational 2.5) | P5: ด้านแผนงานและเวลา (Schedule 2.6) | Q5: ด้านความยั่งยืน (+S / SDGs 2.7) | R5: ด้านความยั่งยืน (+S / SDGs 2.7) | S5: ผลรวมทุกมิติ (All Pillars)
A6: คำถามทดสอบความเสี่ยงจริง (Stress-Test Question) | B6: ระดับการสร้างเองเทียบกับการซื้อสำเร็จรูป (Build vs. Buy Burden) ของระบบตรวจจับการไหลด้วยกล้องและเซนเซอร์คลอง? | C6: สิทธิ์ในการเข้าถึงสตรีมวิดีโอและระบบนิเวศข้อมูล (Access & Permissions) ของกล้อง CCTV กทม. และเซนเซอร์คลองเดิม? | D6: ระดับความพร้อมทางเทคโนโลยี (Base Performance / TRL) ของการคำนวณการไหลของน้ำบนผิวถนนด้วยกล้อง CCTV ในสภาพแสงธรรมชาติ? | E6: ความพร้อมและความซ้ำซ้อนของทักษะสมาชิกในทีม (Team Compatibility & SPOF Risk) ในด้าน Computer Vision และ Fluid Dynamics? | F6: ช่วงการเรียนรู้ทางเทคโนโลยีใหม่ (Learning Curve Burden) สำหรับการประมวลผล Particle Image/Tracking Velocimetry? | G6: ระยะเวลาคืนทุนและความคุ้มค่าทางเศรษฐกิจ (ROI & Payback Horizon) จากการลดความเสียหายน้ำท่วม? | H6: ระดับการพึ่งพาชิ้นส่วนและสถาปัตยกรรมระบบ (Vendor Lock-in & Autonomy) ของการดึงข้อมูลสตรีมและเซนเซอร์? | I6: สัดส่วนงบประมาณสำรองความเสียหายของชิ้นส่วน (Scrap Margin Allowance) สำหรับการทดสอบต้นแบบ? | J6: การปฏิบัติตามกฎหมายจราจร ความปลอดภัยสาธารณะ และ พ.ร.บ. คุ้มครองข้อมูลส่วนบุคคล (PDPA Compliance)? | K6: เงื่อนไขสัญญาอนุญาตซอฟต์แวร์และทรัพย์สินทางปัญญา (IP & Licensing Framework)? | L6: ระดับความรุนแรงของผลกระทบเมื่อระบบขัดข้อง (User Failure Impact & Safety)? | M6: ความสอดคล้องกับพฤติกรรมผู้ใช้และแรงต้านทานในการปฏิบัติงาน (User Behavior & Solution Fit)? | N6: ข้อจำกัดด้านการเข้าถึงสถานที่และสิ่งอำนวยความสะดวกในการพัฒนา (Developer Contribution Dependency)? | O6: ความซับซ้อนในขั้นตอนการพัฒนาและการติดตั้งระบบ (Developer Complexity & Pipeline Friction)? | P6: ความพร้อมของแบบทางวิศวกรรมภายในกรอบเวลา 5 สัปดาห์ทำงาน (Engineering Design Maturity)? | Q6: ระดับการครอบคลุมเสาหลักความยั่งยืนตามโมเดล Stockholm Wedding Cake (Planet, People, Prosperity)? | R6: รอยเท้าทางสิ่งแวดล้อม ขยะอิเล็กทรอนิกส์ และหลักการไม่สร้างผลเสีย (Do No Harm & E-Waste)? | S6: ประเมินคำถามทั้งสิ้น 17 ข้อ
A7: เหตุผลในการถาม & โหมดความล้มเหลวที่เฝ้าระวัง (Rationale) | B7: ประเมินภาระการวิจัยและพัฒนาชิ้นส่วนกลไก อิเล็กทรอนิกส์ และอัลกอริทึม ป้องกันการเสียเวลากับงานประดิษฐ์ขึ้นใหม่โดยไม่จำเป็น | C7: ตรวจสอบข้อจำกัดด้านกรรมสิทธิ์ การล็อกไฟร์วอลล์ และการอนุญาตเข้าถึง เพื่อป้องกันการพัฒนาระบบบนฐานข้อมูลที่ไม่สามารถเข้าถึงได้จริง | D7: วัดวุฒิภาวะของเทคโนโลยีว่าผ่านการพิสูจน์ในสภาพแวดล้อมจริงแล้ว หรือเป็นเพียงแนวคิดเชิงทฤษฎีในห้องปฏิบัติการ | E7: ป้องกันความเสี่ยง Single Point of Failure (SPOF) ที่การดำเนินงานขึ้นอยู่กับสมาชิกเพียงคนเดียวจนไม่สามารถทดแทนกันได้ | F7: ประเมินระยะเวลาและภาระที่ทีมงานต้องใช้ในการฝึกฝนเครื่องมือ ภาษา หรือเทคโนโลยีใหม่ เพื่อไม่ให้กระทบต่อตารางส่งมอบ | G7: ประเมินผลตอบแทนทางการเงินและการประหยัดงบประมาณภาครัฐเทียบกับเงินลงทุน เพื่อป้องกันโครงการที่ใช้งบประมาณเกินคุ้มค่า | H7: ประเมินความเสี่ยงจากการผูกขาดเทคโนโลยีและค่าลิขสิทธิ์ต่อเนื่อง เพื่อให้ระบบสามารถบำรุงรักษาได้อย่างเป็นอิสระ | I7: ประเมินขีดความสามารถทางการเงินในการรองรับความเสียหายของอุปกรณ์จากการทดลอง เพื่อไม่ให้โครงการหยุดชะงักเมื่อเกิดข้อผิดพลาด | J7: ตรวจสอบความสอดคล้องกับข้อกำหนดทางกฎหมายและสิทธิ์ความเป็นส่วนตัว เพื่อป้องกันการถูกระงับโครงการหรือดำเนินคดี | K7: ป้องกันการละเมิดลิขสิทธิ์ซอฟต์แวร์หรือข้อผูกมัดทางกฎหมายแบบ Copyleft ที่อาจบังคับเปิดเผยทรัพย์สินทางปัญญาของระบบ | L7: ประเมินความปลอดภัยของผู้ใช้งานและประชาชนเมื่อระบบเกิดความผิดพลาด ป้องกันความเสียหายต่อชีวิตและทรัพย์สิน | M7: ป้องกัน The Tech Trap โดยตรวจสอบว่าผู้ปฏิบัติงานหน้างานยินดีใช้งานจริงและไม่เกิดแรงต้านในกระบวนการทำงาน | N7: ประเมินความคล่องตัวในการเข้าถึงเครื่องมือ ห้องปฏิบัติการ และสิทธิ์ของนักพัฒนา เพื่อป้องกันการติดขัดจากระเบียบธุรการ | O7: ประเมินความซับซ้อนของขั้นตอนการบิวด์ คอมไพล์ และติดตั้ง เพื่อลดโอกาสเกิด Human Error ระหว่างพัฒนา | P7: ประเมินวุฒิภาวะของการออกแบบเมื่อเทียบกับกรอบเวลา 5 สัปดาห์ทำการจริง และช่วงสอบคั่นกลาง 4 สัปดาห์ | Q7: ประเมินความครอบคลุมของผลกระทบเชิงระบบว่าตอบโจทย์เสาหลักความยั่งยืน 3 ชั้นหลักของ Stockholm Resilience Centre (ชีวมณฑล/Planet, สังคม/People, และเศรษฐกิจ/Prosperity) อย่างเป็นองค์รวม ไม่ใช่โครงการแก้ปัญหาจุดเดียวที่ละเลยมิติอื่น | R7: ป้องกันการทอดทิ้งขยะอิเล็กทรอนิกส์หรือสารพิษลงสู่ระบบระบายน้ำและสิ่งแวดล้อมเมือง (SDG 6.3 / 12.4) | S7: สังเคราะห์จาก AI Agents Group 2
A8: เกณฑ์การให้คะแนน (Scoring Rubric Definition: ระดับ 1, 2, 3, 4, 5 ครบทุกระดับ) | B8: 1: ต้องวิจัยและสร้างขึ้นเองทั้งหมด 100% (ไม่มีพิมพ์เขียว อัลกอริทึม หรือไลบรารีอ้างอิง) 2: มีชิ้นส่วนหลักในท้องตลาด แต่ต้องดัดแปลงโครงสร้างอย่างหนักและเขียนโค้ดเชื่อมต่อเองทั้งหมด 3: บูรณาการชิ้นส่วน COTS เข้ากับแท่นยึดแบบกำหนดเอง และเขียนโค้ดเชื่อมต่อบางส่วน 4: ประกอบจากโมดูลมาตรฐานสำเร็จรูป (DIN-rail, I2C/CAN shields) มีงานประกอบกลไกเล็กน้อย 5: ซื้อมาติดตั้งใช้งานได้ทันที (Plug-and-Play) ไม่ต้องตัดกลึงหรือบัดกรีวงจรเพิ่มเติม | C8: 1: ล็อกสิทธิ์ภายใต้สัญญา NDA ระบบปิด ติดไฟร์วอลล์องค์กร หรือไม่มีสิทธิ์เข้าถึงฝั่งนักพัฒนา 2: ซอฟต์แวร์หรือเฟิร์มแวร์กรรมสิทธิ์ปิด ทำงานแบบ Black-box โดยไม่มี Source Code หรือ Telemetry 3: บัญชีเพื่อการศึกษา/ทดลองใช้ที่มีโควตาหรือ Rate Limit เข้มงวด ต้องรอการอนุมัติอย่างเป็นทางการ 4: มี SDK หรือ Open API สาธารณะพร้อมเอกสารครบถ้วน แต่ไม่สามารถแก้ไขสถาปัตยกรรมระดับล่างได้ 5: สถาปัตยกรรมเปิดสมบูรณ์ (Open Source/Open HW) ทีมงานมีสิทธิ์ระดับ Root/Admin เต็มรูปแบบ | D8: 1: ระดับแนวคิด/สมการคณิตศาสตร์ (TRL 2–3) ทดสอบเฉพาะในห้องทดลองที่ควบคุมสภาพแวดล้อมได้ 2: เบรดบอร์ดทำงานได้ในแล็บ (TRL 4) สายไฟเปราะบาง ยังไม่ผ่านการสอบเทียบในสภาพแวดล้อมจริง 3: ตัวต้นแบบประกอบลงกล่อง (TRL 5–6) ผ่านการทดสอบในสภาพแวดล้อมจำลอง ต้องมีคนคอยดูแล 4: ต้นแบบระดับพรีโปรดักชัน (TRL 7) ทำงานได้อย่างมีเสถียรภาพในสภาพแวดล้อมปฏิบัติงานจริง 5: ผลิตภัณฑ์เชิงพาณิชย์สมบูรณ์ (TRL 8–9) ผ่านการรับรองมาตรฐาน มีค่า MTBF ยืนยันความทนทาน | E8: 1: มีผู้เชี่ยวชาญเพียงคนเดียว (SPOF) หากไม่อยู่ การพัฒนาระบบจะหยุดชะงัก 100% 2: มีหัวหน้าทีมคนเดียว มีสมาชิกเข้าใจหลักการพื้นฐานแต่ไม่สามารถดีบักโค้ดหรือซ่อมแซมฮาร์ดแวร์ได้ 3: มีผู้รับผิดชอบหลักและผู้ช่วยสำรอง 1 คู่ที่สามารถดูแล แก้ไขปัญหา และปรับปรุงระบบทดแทนกันได้ 4: มีสมาชิกในทีมอย่างน้อย 3 คนที่มีความชำนาญ สามารถออกแบบ ประกอบ และแก้ไขระบบได้ทันที 5: ทีมงานทุกคนมีความเชี่ยวชาญเต็มเปี่ยม สามารถสลับสับเปลี่ยนหน้าที่กันได้โดยไม่กระทบความเร็วงาน | F8: 1: ต้องเริ่มเรียนรู้ใหม่ทั้งหมดจากศูนย์ ทั้งภาษา เครื่องมือ และฮาร์ดแวร์ที่ไม่เคยใช้งานมาก่อน 2: มีความเข้าใจเชิงทฤษฎี แต่ขาดประสบการณ์ปฏิบัติจริง การเขียนโค้ดและต่อวงจรติดขัดล่าช้า 3: มีทักษะในเทคโนโลยีใกล้เคียงที่เทียบเคียงได้ ใช้เวลาปรับตัวและฝึกฝนประมาณ 1 สัปดาห์ 4: คุ้นเคยกับชุดเครื่องมืออยู่แล้ว เพียงเรียนรู้ไลบรารีหรือคำสั่งเฉพาะของเซนเซอร์เพิ่มเติมเล็กน้อย 5: ไม่ต้องเรียนรู้ใหม่ สามารถนำโค้ด เครื่องมือ และทักษะที่มีอยู่เดิมมาประยุกต์ใช้งานได้ทันที | G8: 1: ระยะเวลาคืนทุนนานมาก (>= 10 ปี) ต้นทุนเริ่มแรกสูงแต่ประหยัดค่าใช้จ่ายได้น้อยมาก ไม่คุ้มค่าเชิงพาณิชย์ 2: คืนทุนช้า (6–9 ปี) ใช้เงินลงทุนสูงและต้องได้รับการอุดหนุนงบประมาณระยะยาว 3: คืนทุนปานกลาง (3–5 ปี) เหมาะสมกับโครงสร้างพื้นฐานสาธารณะ ชดเชยต้นทุนได้ตามรอบงบประมาณ 4: คืนทุนเร็ว (2–3 ปี) ลดค่าใช้จ่ายด้านแรงงาน เชื้อเพลิง หรือการสูญเสียได้อย่างมีนัยสำคัญ 5: คืนทุนทันที (<= 1–2 ปี) ลดความสูญเสียจากภัยพิบัติหรือความเสียหายซ้ำซากได้ตั้งแต่ฤดูกาลแรก | H8: 1: ผูกขาดกับผู้ขาย 100% พึ่งพาคลาวด์และตัวเชื่อมต่อเฉพาะทางที่เข้ารหัส ปิดกั้นการซ่อมบำรุง 2: ต้องใช้เครื่องมือตรวจวิเคราะห์เฉพาะของผู้ผลิต หรือเสียค่าธรรมเนียมรายปีเพื่อเปิดใช้งาน 3: ฮาร์ดแวร์หลักใช้เฟิร์มแวร์กรรมสิทธิ์ แต่เปิดช่องทาง API และใช้อินเทอร์เฟซไฟฟ้าตามมาตรฐาน 4: ใช้โพรโทคอลสื่อสารมาตรฐานเปิด (MQTT, Modbus, CAN) ซ่อมบำรุงด้วยเครื่องมือทั่วไปได้ 5: สถาปัตยกรรมเปิดสมบูรณ์ ชิ้นส่วนทุกชิ้นมีอะไหล่ทดแทนในท้องตลาด วิศวกรซ่อมบำรุงได้เอง 100% | I8: 1: ไม่มีงบสำรองอะไหล่ (0%) ซื้อฮาร์ดแวร์เพียง 1 ชุด หากชิปไหม้หรือโครงสร้างเสียหาย โครงการจะหยุดชะงัก 2: งบสำรองเปราะบาง (20–30%) มีอะไหล่เฉพาะชิ้นส่วนพาสซีฟ ไม่มีไมโครคอนโทรลเลอร์หรือเซนเซอร์สำรอง 3: งบสำรองปานกลาง (50%) มีอะไหล่พาสซีฟครบถ้วน และมีบอร์ดควบคุมหลักสำรอง 1 ชุด 4: งบสำรองสูง (80%) มีอะไหล่สำรองสำหรับชิ้นส่วนแอคทีฟและเซนเซอร์เกือบทุกตัว รองรับความผิดพลาดได้หลายครั้ง 5: มีอะไหล่ทดแทนสมบูรณ์ (>= 100%) สามารถประกอบชุดฮาร์ดแวร์ทำงานได้พร้อมกัน 2 ระบบเต็มรูปแบบ | J8: 1: ฝ่าฝืนกฎหมายชัดเจน (ละเมิด PDPA จากการสอดส่องที่สาธารณะ, กีดขวางการจราจร, คลื่นวิทยุผิดกฎหมาย) 2: มีความเสี่ยงทางกฎหมายสูง มีข้อร้องเรียนเรื่องการสัญจรหรือความปลอดภัย ต้องขอข้อยกเว้นทางเทคนิคซับซ้อน 3: ปฏิบัติการได้ภายใต้เงื่อนไข ต้องมีหนังสืออนุญาต บันทึกข้อตกลง (MoU) หรือใบอนุญาตจากเทศบาล 4: ความเสี่ยงต่ำ ปฏิบัติการภายใต้ข้อยกเว้นงานวิจัยทางวิศวกรรมสาธารณะ เพียงแจ้งหน่วยงานและปฏิบัติตามมาตรฐาน 5: ได้รับการยกเว้นตามกฎหมาย 100% ไม่มีความเสี่ยงต่อความปลอดภัยสาธารณะ และไม่มีการเก็บข้อมูลส่วนบุคคล (Zero PII) | K8: 1: สัญญาอนุญาตเชิงพาณิชย์แบบปิด ต้องจ่ายค่าลิขสิทธิ์ราคาสูงจึงจะสามารถคอมไพล์หรือใช้งานได้ 2: สถานะทรัพย์สินทางปัญญาคลุมเครือ ไม่มีสัญญาอนุญาตชัดเจน เสี่ยงต่อการถูกฟ้องร้องละเมิดลิขสิทธิ์ 3: สัญญาอนุญาตแบบ Copyleft เข้มงวด (เช่น GPLv3) บังคับให้ต้องเปิดเผยโค้ดทั้งหมดหากมีการแจกจ่าย 4: สัญญาอนุญาตแบบเปิดที่มีเงื่อนไขน้อย (เช่น LGPL, CC-BY) อนุญาตให้นำไปพัฒนาต่อได้โดยระบุที่มา 5: สัญญาอนุญาตแบบเสรีสมบูรณ์ (MIT, Apache 2.0, BSD) หรือเป็นสมบัติสาธารณะ นำไปใช้ประโยชน์ได้อิสระ 100% | L8: 1: อันตรายถึงชีวิต เกิดไฟฟ้าดูด เพลิงไหม้ อุบัติเหตุทางถนน หรือการพังทลายของโครงสร้าง 2: อันตรายทางกายภาพรุนแรง อุปกรณ์เสียหายหนัก ก่อสารพิษ หรือหยุดชะงักโครงสร้างพื้นฐานฉุกเฉิน 3: ผู้ใช้เกิดความโกลาหล สับสนในข้อมูล มีการสั่งการทับซ้อนและระบบหยุดชะงัก 4: เกิดความล่าช้าเล็กน้อยในการปฏิบัติการ ระบบตัดการทำงานอย่างปลอดภัย สามารถรีบูตหรือสลับไปใช้ระบบสำรองได้ 5: เสียหายเพียงงบประมาณเล็กน้อย ไม่ก่ออันตรายต่อมนุษย์หรือกระทบกระบวนการทำงานหลัก | M8: 1: รื้อระบบการทำงานเดิมทั้งหมด บังคับกรอกเอกสารเพิ่ม 5 ขั้นตอนขึ้นไป และผู้ปฏิบัติงานต่อต้านไม่ยอมใช้ 2: เพิ่มภาระการบันทึกข้อมูลอย่างมาก ผู้ปฏิบัติงานจะพยายามหาทางหลีกเลี่ยงหรือบายพาสระบบ 3: ปรับเปลี่ยนกิจวัตรเล็กน้อย ต้องจัดอบรม 1–2 ครั้ง แต่ผู้ใช้ยอมรับแลกกับประสิทธิภาพที่ได้รับ 4: ผสานรวมเข้ากับระบบงานเดิมได้อย่างราบรื่น (ส่งแจ้งเตือนเข้า LINE/Dashboard ที่ใช้อยู่แล้ว) 5: ทำงานอยู่เบื้องหลังแบบอัตโนมัติ 100% ไร้แรงเสียดทาน ผู้ปฏิบัติงานไม่ต้องเปลี่ยนขั้นตอนใดๆ | N8: 1: ติดขั้นตอนอนุมัติราชการเข้มงวด ต้องเซ็น NDA ล็อกตู้แล็บ และถูกจำกัดสิทธิ์ Git Branch 2: ต้องกรอกแบบฟอร์มขอใช้อุปกรณ์ของคณะ รอคิวเครื่องจักร และรอการอนุมัติ 3–5 วันทำการ 3: เข้าใช้งานห้องแล็บและเครื่องมือได้ตามเวลาเปิดทำการปกติของมหาวิทยาลัย 4: มีสิทธิ์เข้าแล็บ 24 ชม. มีสิทธิ์เขียนโค้ดลง Repository และมีงบประมาณย่อยพร้อมเบิกจ่ายทันที 5: ทำงานได้อิสระ 100% ใช้ระบบ CI/CD บนคลาวด์ มีเครื่องมือประกอบต้นแบบที่บ้าน ไร้อุปสรรคทางธุรการ | O8: 1: ขั้นตอนการบิวด์และติดตั้งซับซ้อนมาก เครื่องมือพึ่งพาแพ็กเกจเปราะบาง เสี่ยงต่อข้อผิดพลาดสูง 2: ต้องรันกระบวนการด้วยมือหลายขั้นตอน ติดปัญหาความไม่เข้ากันของไลบรารี และแฟลชบอร์ดได้ยาก 3: กระบวนการประกอบและบิวด์ระบบมีหลายขั้นตอนตามมาตรฐาน สามารถทำซ้ำได้ตามคู่มือและเช็กลิสต์ 4: เวิร์กโฟลว์ตรงไปตรงมา ใช้ระบบสคริปต์อัตโนมัติ รันผ่าน IDE มาตรฐาน คำสั่งเดียวแฟลชบอร์ดได้ 5: ระบบเรียบง่ายแบบ Plug-and-Play ทำงานได้ในขั้นตอนเดียว ไม่ต้องตั้งค่าซับซ้อน | P8: 1: อยู่ในระดับแนวคิดเท่านั้น (0% Design) ไม่มีโมเดล CAD ไม่มีผังวงจร และยังไม่ได้เขียนเฟิร์มแวร์ 2: แบบร่างเบื้องต้น (25% Design) มีเพียงบล็อกไดอะแกรม ผังวงจรวาดมือ รายการชิ้นส่วนที่ยังไม่ได้สอบทาน 3: ความพร้อมระดับปานกลาง (50% Design) ประกอบ CAD ครบ มีผังวงจร Schematic สมบูรณ์ วางสถาปัตยกรรมโค้ดแล้ว 4: พร้อมทดสอบพรีโปรดักชัน (75–80% Design) โมเดล 3D พร้อมพิมพ์/กัด มีไฟล์ Gerber ตรวจสอบ DRC แล้ว 5: ออกแบบเสร็จสมบูรณ์ 100% (Production Ready) มีไฟล์ผลิตครบถ้วน ล็อกรายการ BOM และมีสคริปต์แฟลชพร้อมผลิต | Q8: 1: หลุดจาก Wedding Cake หรือสร้างผลกระทบเชิงลบต่อเสาหลักใดเสาหลักหนึ่งอย่างรุนแรง 2: สัมผัสเพียง 1 เสาหลักอย่างผิวเผิน ขาดการเชื่อมโยงเชิงประจักษ์ไปยังสังคมหรือสิ่งแวดล้อมจริง 3: ครอบคลุม 1 เสาหลักอย่างเป็นรูปธรรม หรือ 2 เสาหลักแบบมีข้อจำกัดเฉพาะจุด/เฉพาะช่วงเวลา 4: บูรณาการ 2 เสาหลักสำคัญ (เช่น Planet + People) ควบคู่กันอย่างชัดเจนและมีตัวชี้วัดรองรับ 5: บูรณาการครบทั้ง 3 เสาหลัก (Planet, People, Prosperity) อย่างสมดุลและครบวงจร | R8: 1: ก่ออันตรายและสารพิษในพื้นที่ กล่องอุปกรณ์แตกสลาย หรือแบตเตอรี่รั่วไหลหลุดลงสู่ระบบระบายน้ำ 2: เทคโนโลยีเปราะบางแบบใช้แล้วทิ้ง เซนเซอร์อุดตันหรือผุกร่อนภายใน 2–3 สัปดาห์ และถูกทิ้งร้างในพื้นที่ 3: มีรอยเท้าสิ่งแวดล้อมตามมาตรฐาน ต้องเปลี่ยนแบตเตอรี่ตามรอบ มีสายยึดป้องกันอุปกรณ์สูญหาย 4: กล่องหุ้มทนทานผลกระทบต่ำ กินไฟต่ำ ใช้วัสดุรีไซเคิลได้ และมีสายสลิงยึดโยงเพื่อความปลอดภัย 5: ออกแบบตามหลักเศรษฐกิจหมุนเวียน 100% กู้คืนอุปกรณ์ได้ปลอดภัย ใช้วัสดุไม่เป็นพิษ ไร้รอยเท้าสิ่งแวดล้อม | S8: เกณฑ์รวม: >=80 ผ่านสูง, >=60 มีเงื่อนไข, <60 เสี่ยงสูง | หากมีข้อใดได้ 1 = VETOED ตกเกณฑ์ทันที
A9: คะแนนที่ได้รับ (ASSIGNED SCORE: 1, 2, 3, 4, 5 STRICT INTEGER) | B9: 2 | C9: 1 | D9: 1 | E9: 1 | F9: 2 | G9: 5 | H9: 4 | I9: 5 | J9: 3 | K9: 5 | L9: 4 | M9: 4 | N9: 3 | O9: 3 | P9: 3 | Q9: 3 | R9: 4 | S9: =IF(S10>0, (S11/S10)*20, 0)
A10: ค่าน้ำหนัก (Weight %) | B10: 0.04 | C10: 0.04 | D10: 0.04 | E10: 0.04 | F10: 0.04 | G10: 0.0667 | H10: 0.0667 | I10: 0.0666 | J10: 0.075 | K10: 0.075 | L10: 0.05 | M10: 0.05 | N10: 0.05 | O10: 0.05 | P10: 0.15 | Q10: 0.05 | R10: 0.05 | S10: =SUM(B10:R10)
A11: คะแนนถ่วงน้ำหนัก (=Score * Weight) | B11: =B9*B10 | C11: =C9*C10 | D11: =D9*D10 | E11: =E9*E10 | F11: =F9*F10 | G11: =G9*G10 | H11: =H9*H10 | I11: =I9*I10 | ... R11: =R9*R10 | S11: =SUM(B11:R11)
A12: คำอธิบาย & หลักฐานอ้างอิงจากไฟล์ Intake (Evidence Citation) | B12: solution-details/solution-1.md lines 36-41; OpenCV exists but outdoor PTV/PIV hydrological velocimetry requires extensive custom homography rectification, rain-streak filtering, and wrapper code. | C12: solution-details/solution-1.md lines 14-15; BMA Traffic CCTV video feeds and DDS canal ultrasonic telemetry are locked behind municipal government intranets/firewalls with zero public developer API or RTSP access, triggering a fatal flaw VETO. | D12: solution-details/solution-1.md lines 18-32; uncalibrated ambient-light street CCTV runoff velocimetry without seeding particles is at TRL 2-3 academic proof-of-concept level, failing field operational stability. | E12: team-skills/jk.md line 42 vs. due.md, fifa.md, jay.md, kin.md; only JK has basic OpenCV experience, and zero team members have fluid velocimetry expertise, creating a complete Single Point of Failure (SPOF). | F12: team-skills/jk.md lines 32-44; team has general math background but zero hands-on experience with fluid PIV/PTV cross-correlation, homography calibration, or outdoor illumination noise filtering. | G12: Leverages existing municipal CCTV infrastructure and canal ultrasonic level telemetry with near-zero new hardware CapEx, delivering immediate payback within <= 1-2 years by preventing recurring monsoon flash-flood damages and misdirected dredging dispatches in the first operating season. | H12: Utilizes standard open streaming (RTSP/ONVIF) and telemetry protocols (MQTT/REST) compatible with generic IP cameras and ultrasonic gauges, though data ingestion depends on BMA centralized network access. | I12: Minimal physical hardware BOM for bench TRL 2-4 validation (ESP32 and ultrasonic sensor < 1,500 THB total) allows the team to maintain a >= 100% duplicate spare buffer, fully accommodating JK's soldering limitations. | J12: Processing public roadway CCTV streams captures personal data (faces, license plates) subject to Thailand's PDPA B.E. 2562, and pulling municipal feeds requires formal written approval/MoU from BMA under the Computer Crime Act. | K12: Core OpenCV computer vision pipeline is Apache 2.0, Python analytics stack is BSD/MIT, and ESP-IDF firmware is Apache 2.0, completely free of commercial seat fees or viral copyleft restrictions. | L12: อ้างอิง solution-1.md บรรทัดที่ 14, 18, 33: ระบบทำหน้าที่แจ้ง alert เข้าหน่วยงานที่เกี่ยวข้อง (QRT/ฝ่ายซ่อมบำรุง) หากระบบ Optical Flow ขัดข้องในเวลากลางคืนหรือสภาพแสงน้อย ระบบจะส่งสัญญาณเตือนล่าช้าหรือหลุดการตรวจจับ แต่ไม่มีกลไกเชิงกายภาพหรือไฟฟ้าแรงสูงที่ก่อให้เกิดอันตรายถึงชีวิต เจ้าหน้าที่หน้างานสลับไปใช้ขั้นตอนมาตรฐานเดิมได้ทันที (Minor Operational Delay) | M12: อ้างอิง solution-1.md บรรทัดที่ 7-11, 30-33: วัตถุประสงค์หลักถูกออกแบบให้ลงตัวกับจุดคานงัดเดิม (Leverage point fit: QRT, Maintenance Queue) และส่งการแจ้งเตือนอัตโนมัติไปยังหน่วยงานที่รับผิดชอบ ซึ่งสอดคล้องกับพฤติกรรมการรับงานผ่านระบบแจ้งเหตุฉุกเฉิน (LINE Alert / Dashboard) ของเจ้าหน้าที่ กทม. ไม่ต้องบังคับให้เจ้าหน้าที่เปลี่ยนขั้นตอนการทำงานภาคสนาม (Low Friction) | N12: อ้างอิง solution-1.md บรรทัดที่ 15, 24, 41: ระบบต้องดึงข้อมูลภาพวิดีโอจากกล้อง CCTV และระดับน้ำในคลองเดิม สำหรับการพัฒนาโครงงานในระดับมหาวิทยาลัย ทีมงานสามารถเข้าถึงฟีดกล้อง CCTV และระบบระบายน้ำภายในวิทยาเขต มจธ. ได้ในช่วงเวลาทำการปกติของมหาวิทยาลัย โดยมี JK (team-skills/jk.md บรรทัดที่ 48-50) ที่มีความพร้อมในการสื่อสารและประสานงานหน้างาน (Standard Campus Access) | O12: อ้างอิง solution-1.md บรรทัดที่ 27-40: ต้องประมวลผล Optical Flow, Particle Image Velocimetry (PIV), และ Particle Tracking Velocimetry (PTV) ร่วมกับการเกลี่ยข้อมูลระดับน้ำ 5 นาที แม้ JK มีทักษะพื้นฐานด้าน OpenCV (team-skills/jk.md บรรทัดที่ 42) แต่การต่อท่อส่งข้อมูลสตรีมวิดีโอเข้าสู่อัลกอริทึมประมวลผลเวกเตอร์ความเร็วยังคงเป็นกระบวนการหลายขั้นตอนที่ต้องทำตามคู่มืออย่างเป็นระบบ (Moderate Complexity) | P12: อ้างอิง schedule-details/schedule.md: กำหนดกรอบเวลาทำงานจริง 5 สัปดาห์ทำการ (สัปดาห์ที่ 10, 11, 12, 14, 15) โดยมีช่วงสอบมหาวิทยาลัยคั่นกลางถึง 4 สัปดาห์ โครงงาน Solution 1 เน้นการประมวลผลซอฟต์แวร์บนฮาร์ดแวร์ COTS เดิม ไม่ต้องรอกัดกลึงชิ้นส่วนกลไก ทำให้ทีมสามารถส่งมอบแบบจำลองอัลกอริทึมและผังโครงสร้างสถาปัตยกรรมระดับต้นแบบห้องปฏิบัติการได้ตามกำหนด (Intermediate Maturity: 50% Design) | Q12: Solution-1 touches across the Wedding Cake tiers: (1) Planet/Biosphere via SDG 13.1 (flood risk mitigation) & SDG 6.3 (canal level monitoring); (2) People/Society via SDG 11.5 (urban road flood alerting to reduce vehicle & commuter losses); and (3) Prosperity/Economy via SDG 12.5 (municipal asset sweating by reusing existing CCTV and canal gauges). However, its operation is strictly daylight-only ('ภายในช่วงที่มีแสง') with blind spots outside camera FOV ('บางท่ออยู่นอกขอบเขตของ CCTV'), meaning its societal alerting and environmental tracking remain a localized proof-of-concept rather than an all-weather district-wide systemic integration (Level 3: Robust Single-Pillar / Limited Dual-Tier). | R12: Solution-1 prioritizes existing municipal infrastructure reuse ('พยายามใช้ local sensor ที่มีก่อน' - CCTV and canal ultrasonic gauges). By mounting non-contact optical and ultrasonic sensors on elevated roadside poles and bridges, it completely avoids deploying submerged battery-powered electronic devices inside flowing sewers or canals. This prevents sensor dislodgement, casing breakdown, or toxic battery leakage into the drainage network (SDG 6.3 / 12.4). New hardware is confined to pole-mounted edge compute gateways with low environmental footprint. | S12: =IF(MIN(B9:R9)=1, "VETOED / ตกเกณฑ์ข้อบังคับวิกฤต (คะแนนระดับ 1)", IF(S9>=80, "ผ่านเกณฑ์ระดับสูง (HIGHLY VIABLE)", IF(S9>=60, "ผ่านแบบมีเงื่อนไข (CONDITIONALLY VIABLE)", "ความเสี่ยงสูง (HIGH RISK)")))
A13: แผนลดขอบเขตงาน & มาตรการลดความเสี่ยง (De-scoping Action) | B13: Descope from uncalibrated CCTV computer vision to installing standard COTS ultrasonic distance/depth sensors inside drainage catch basins reading water levels directly. | C13: Abandon municipal CCTV infrastructure entirely; deploy team-owned standalone camera modules or IoT microcontrollers on private property with signed landowner consent. | D13: Pivot from video velocimetry to a physical pressure transducer or float switch in the catch basin, operating at commercial maturity (TRL 8-9). | E13: Replace video flow tracking with standard sensor telemetry (water level/pressure) where Due, Fifa, and JK share broad redundant embedded C/C++ firmware capabilities. | F13: Descope quantitative fluid discharge calculation (m3/s) to basic frame-differencing motion detection (e.g. MOG2 background subtractor) to detect mere presence of standing water. | G13: Pilot initial software deployment on 5 critical flood-prone road intersections to validate immediate flood damage reduction within season 1. | H13: Implement a generic camera/sensor ingestion abstraction layer supporting both municipal CCTV streams and standalone COTS bench cameras. | I13: Deploy pre-soldered ESP32 boards with screw-terminal breakout shields and maintain duplicate bench rigs. | J13: Implement real-time edge blurring/masking of license plates and pedestrians before optical flow processing to guarantee Zero PII retention, backed by a formal KMUTT-BMA educational research MoU. | K13: Use OpenCV's native Farneback/Lucas-Kanade optical flow routines under Apache 2.0 rather than external GPLv3-licensed academic PIV code. | L13: ติดตั้งระบบตรวจจับค่าความเชื่อมั่น (Confidence Threshold Scoring) หากค่าความสว่างของแสงหรือคุณภาพเฟรมต่ำกว่าเกณฑ์ ให้ตัดเข้าสู่โหมดเตือน 'Degraded - Manual Verification Required' พร้อมแนบลิงก์สตรีมภาพสดให้เจ้าหน้าที่กดดูเพื่อยืนยันสถานะได้ใน 1 คลิก | M13: ออกแบบการส่งข้อความแจ้งเตือนผ่าน LINE Messaging API แบบ Flex Message ที่สรุปค่าความเร็วการไหล ระดับน้ำคลอง และการวินิจฉัยต้นเหตุ (ฝนตก vs ท่อตัน) เป็นการ์ดสรุปข้อมูลที่เข้าใจได้ใน 3 วินาที | N13: บันทึกไฟล์วิดีโอน้ำไหลจำลองและชุดข้อมูลระดับน้ำในคลองของมหาวิทยาลัยเก็บไว้ใน Local Server/NAS เพื่อให้ทีมพัฒนาอัลกอริทึมได้ตลอด 24 ชม. โดยไม่ต้องพึ่งพาการเชื่อมต่อสัญญาณสดจากภายนอกตลอดเวลา | O13: ปรับลดความซับซ้อนจากการใช้ PIV/PTV เต็มรูปแบบ มาเป็นการใช้ Farneback Dense Optical Flow ของ OpenCV ที่กำหนดกรอบความสนใจ (ROI) เฉพาะผิวน้ำ และรวบกระบวนการติดตั้งไว้ใน Docker Container คำสั่งเดียว | P13: ล็อกชุดข้อมูลวิดีโอทดสอบและสูตรสมการคำนวณการไหลให้เสร็จสิ้นภายในสัปดาห์ที่ 11 เพื่อนำไปใช้ทดสอบ Bench PoC ในสัปดาห์ที่ 12-13 โดยสงวนสัปดาห์ที่ 14-15 ไว้สำหรับการรวมระบบและการจัดทำเอกสารรายงานฉบับสมบูรณ์ | Q13: Deploy near-infrared (NIR) feature tracking with rain-streak filtering, and cross-reference TMD weather radar data to ensure night-time continuity, expanding Wedding Cake resilience across Planet and People to 24/7 coverage. | R13: House edge compute hardware in IP67-rated, UV-stabilized 100% recyclable polycarbonate (PC) enclosures with dual stainless steel safety lanyards; establish a formal end-of-life (EoL) hardware recycling agreement with BMA Department of Drainage and Sewerage (DDS). | S13: ปฏิบัติตามแผนลดขอบเขตงาน (De-scoping Advisory)
A15: ตารางสรุปคะแนนแยกตามมิติ TELOS+S (Pillar Score Breakdown)
A16: มิติการประเมิน (TELOS+S Pillar) | B16: สัดส่วนน้ำหนัก (Weight %) | C16: คะแนนเต็มมิติ (Max Points) | D16: คะแนนที่ได้รับจริง (Earned Points) | E16: คะแนนเฉลี่ย (Score 1-5) | F16: ระดับความพร้อม (Readiness Level)
A17: T : ด้านเทคโนโลยีและวิศวกรรม (Technical) | B17: 0.2 | C17: 20 | D17: =SUM(B11:F11)*20 | E17: =IF(C17>0, (D17/C17)*5, 0) | F17: =IF(D17>=16.0, "พร้อมระดับสูง (High)", IF(D17>=12.0, "ปานกลาง (Medium)", "เสี่ยงวิกฤต (Critical)"))
A18: E : ด้านเศรษฐศาสตร์และความคุ้มค่า (Economic) | B18: 0.2 | C18: 20 | D18: =SUM(G11:I11)*20 | E18: =IF(C18>0, (D18/C18)*5, 0) | F18: =IF(D18>=16.0, "พร้อมระดับสูง (High)", IF(D18>=12.0, "ปานกลาง (Medium)", "เสี่ยงวิกฤต (Critical)"))
A19: L : ด้านกฎหมาย ระเบียบ และภาคประชาชน (Legal & Outreach) | B19: 0.15 | C19: 15 | D19: =SUM(J11:K11)*20 | E19: =IF(C19>0, (D19/C19)*5, 0) | F19: =IF(D19>=12.0, "พร้อมระดับสูง (High)", IF(D19>=9.0, "ปานกลาง (Medium)", "เสี่ยงวิกฤต (Critical)"))
A20: O : ด้านการปฏิบัติการและหน้างาน (Operational) | B20: 0.2 | C20: 20 | D20: =SUM(L11:O11)*20 | E20: =IF(C20>0, (D20/C20)*5, 0) | F20: =IF(D20>=16.0, "พร้อมระดับสูง (High)", IF(D20>=12.0, "ปานกลาง (Medium)", "เสี่ยงวิกฤต (Critical)"))
A21: S : ด้านแผนงานและเวลาส่งมอบ (Schedule) | B21: 0.15 | C21: 15 | D21: =P11*20 | E21: =IF(C21>0, (D21/C21)*5, 0) | F21: =IF(D21>=12.0, "พร้อมระดับสูง (High)", IF(D21>=9.0, "ปานกลาง (Medium)", "เสี่ยงวิกฤต (Critical)"))
A22: +S : ด้านความยั่งยืนและสิ่งแวดล้อม (Sustainability / SDG) | B22: 0.1 | C22: 10 | D22: =SUM(Q11:R11)*20 | E22: =IF(C22>0, (D22/C22)*5, 0) | F22: =IF(D22>=8.0, "พร้อมระดับสูง (High)", IF(D22>=6.0, "ปานกลาง (Medium)", "เสี่ยงวิกฤต (Critical)"))
A23: คะแนนรวมทุกมิติ (Total Feasibility Score) | B23: =SUM(B17:B22) | C23: =SUM(C17:C22) | D23: =SUM(D17:D22) | E23: =IF(C23>0, (D23/C23)*5, 0) | F23: =IF(D23>=80, "ผ่านเกณฑ์ระดับสูง (HIGHLY VIABLE)", IF(D23>=60, "ผ่านแบบมีเงื่อนไข (CONDITIONALLY VIABLE)", "ความเสี่ยงสูง (HIGH RISK)"))
A25: เมทริกซ์ประเมินความเข้ากันได้กับองค์ความรู้ด้านวิศวกรรมหุ่นยนต์ (Robotics Knowledge Compatibility)
A26: * หมายเหตุ: การประเมินส่วนนี้วัดศักยภาพในการประยุกต์ใช้องค์ความรู้ด้านวิศวกรรมหุ่นยนต์ (Perception, Control, Actuation) เต็ม 12 คะแนน (แกนละ 4 คะแนน) | เป็นเอกเทศ ไม่นับรวมในคะแนน TELOS 100 คะแนน
A27: มิติการประเมิน (Robotics Dimension) | B27: คะแนนศักยภาพ (/12) | C27: แกน Perception & Sensing (การรับรู้) | D27: แกน Control & Algorithms (การควบคุม) | E27: แกน Actuation & Mechanisms (กลไก) | F27: บทวิเคราะห์เชิงวิศวกรรมหุ่นยนต์ (FIBO Alignment Rationale)
A28: ศักยภาพการประยุกต์ใช้องค์ความรู้หุ่นยนต์และระบบอัตโนมัติ | B28: 6 | C28: Level 3.0 / 4.0: Computer vision optical flow, PIV, and PTV via municipal CCTV combined with ultrasonic canal water level sensing. | D28: Level 2.0 / 4.0: Rule-based diagnostic threshold logic separating rain runoff from clogged sewers; lacks dynamic plant state estimation and closed-loop feedback. | E28: Level 1.0 / 4.0: Static mounting brackets with zero mechanical actuation, moving parts, power transmission, or physical intervention on the environment. | F28: Solution 1 operates as a smart city telemetry and video monitoring platform rather than a robotic system. It suffers from a broken Sense-Think-Act triad, as actuation terminates in human alerts. It underutilizes team capabilities in mechanical design, fabrication, custom PCB design, and dynamic feedback control.

Sheet Solution_2_Acoustic_Sewer
A1: เมทริกซ์ประเมินความเป็นไปได้เชิงระบบ TELOS+S: Sewer Inspection by transmitter and receiver. Mapping Sewer profile
A2: ระบบคะแนนจำนวนเต็มเด็ดขาด: 1, 2, 3, 4, 5 เท่านั้น (ไม่มีจุดทศนิยม / ไม่มี 0.5) | โครงสร้างแบบ Transposed แนวนอน
A4: รหัสคำถาม (Question Code) | B4: T-01 | C4: T-02 | D4: T-03 | E4: T-04 | F4: T-05 | G4: E-01 | H4: E-02 | I4: E-03 | J4: L-01 | K4: L-02 | L4: O-01 | M4: O-02 | N4: O-03 | O4: O-04 | P4: S-01 | Q4: SDG-01 | R4: SDG-02 | S4: สรุปภาพรวม (SUMMARY)
A5: มิติการประเมิน (TELOS+S Pillar) | B5: ด้านเทคนิค (Technical 2.2) | C5: ด้านเทคนิค (Technical 2.2) | D5: ด้านเทคนิค (Technical 2.2) | E5: ด้านเทคนิค (Technical 2.2) | F5: ด้านเทคนิค (Technical 2.2) | G5: ด้านเศรษฐศาสตร์ (Economic 2.3) | H5: ด้านเศรษฐศาสตร์ (Economic 2.3) | I5: ด้านเศรษฐศาสตร์ (Economic 2.3) | J5: ด้านกฎหมายและสถาบัน (Legal 2.4) | K5: ด้านกฎหมายและสถาบัน (Legal 2.4) | L5: ด้านปฏิบัติการ (Operational 2.5) | M5: ด้านปฏิบัติการ (Operational 2.5) | N5: ด้านปฏิบัติการ (Operational 2.5) | O5: ด้านปฏิบัติการ (Operational 2.5) | P5: ด้านแผนงานและเวลา (Schedule 2.6) | Q5: ด้านความยั่งยืน (+S / SDGs 2.7) | R5: ด้านความยั่งยืน (+S / SDGs 2.7) | S5: ผลรวมทุกมิติ (All Pillars)
A6: คำถามทดสอบความเสี่ยงจริง (Stress-Test Question) | B6: ระดับการสร้างเองเทียบกับการซื้อสำเร็จรูป (Build vs. Buy Burden) ของระบบหัวส่ง-หัวรับคลื่นเสียงในท่อระบายน้ำ? | C6: สิทธิ์ในการเข้าถึงสตรีมวิดีโอและระบบนิเวศข้อมูล (Access & Permissions) ของระบบตรวจวัดคลื่นเสียงสะท้อน? | D6: ระดับความพร้อมทางเทคโนโลยี (Base Performance / TRL) ของเทคโนโลยี Airborne Acoustic Reflectometry ในท่อ? | E6: ความพร้อมและความซ้ำซ้อนของทักษะสมาชิกในทีม (Team Compatibility & SPOF Risk) ในด้านสัญญาณเสียง ไมโครคอนโทรลเลอร์ และการขึ้นรูปแท่นจับ? | F6: ช่วงการเรียนรู้ทางเทคโนโลยีใหม่ (Learning Curve Burden) สำหรับการขับสัญญาณเสียง Chirp Sweep และการประมวลผล Cross-correlation? | G6: ระยะเวลาคืนทุนและความคุ้มค่าทางเศรษฐกิจ (ROI & Payback Horizon) ของการคัดกรองท่อก่อนส่งรถดูดเลน? | H6: ระดับการพึ่งพาชิ้นส่วนและสถาปัตยกรรมระบบ (Vendor Lock-in & Autonomy) ของทรานสดิวเซอร์เสียงและไมโครโฟน? | I6: สัดส่วนงบประมาณสำรองความเสียหายของชิ้นส่วน (Scrap Margin Allowance) สำหรับวงจรขับเสียงและหัววัด? | J6: การปฏิบัติตามกฎหมายจราจร ความปลอดภัยในพื้นที่อับอากาศ และระเบียบการเปิดฝาท่อสาธารณะ? | K6: เงื่อนไขสัญญาอนุญาตซอฟต์แวร์และทรัพย์สินทางปัญญา (IP & Licensing Framework) ของอัลกอริทึมวิเคราะห์สัญญาณเสียง? | L6: ระดับความรุนแรงของผลกระทบเมื่อระบบขัดข้อง (User Failure Impact & Safety) ระหว่างการตรวจวัดท่อ? | M6: ความสอดคล้องกับพฤติกรรมผู้ใช้และแรงต้านทานในการปฏิบัติงาน (User Behavior & Solution Fit) ของคะแนนความสะอาด 0-10? | N6: ข้อจำกัดด้านการเข้าถึงสถานที่และสิ่งอำนวยความสะดวกในการพัฒนา (Developer Contribution Dependency) สำหรับการทดสอบท่อ? | O6: ความซับซ้อนในขั้นตอนการพัฒนาและการติดตั้งระบบ (Developer Complexity & Pipeline Friction) ของการประมวลผลเสียง? | P6: ความพร้อมของแบบทางวิศวกรรมภายในกรอบเวลา 5 สัปดาห์ทำงาน (Engineering Design Maturity) สำหรับชุดตรวจวัดคลื่นเสียง? | Q6: ระดับการครอบคลุมเสาหลักความยั่งยืนตามโมเดล Stockholm Wedding Cake (Planet, People, Prosperity)? | R6: รอยเท้าทางสิ่งแวดล้อม ขยะอิเล็กทรอนิกส์ และหลักการไม่สร้างผลเสีย (Do No Harm & E-Waste) ของหัววัดแบบพกพา? | S6: ประเมินคำถามทั้งสิ้น 17 ข้อ
A7: เหตุผลในการถาม & โหมดความล้มเหลวที่เฝ้าระวัง (Rationale) | B7: ประเมินภาระการวิจัยและพัฒนาชิ้นส่วนกลไก อิเล็กทรอนิกส์ และอัลกอริทึม ป้องกันการเสียเวลากับงานประดิษฐ์ขึ้นใหม่โดยไม่จำเป็น | C7: ตรวจสอบข้อจำกัดด้านกรรมสิทธิ์ การล็อกไฟร์วอลล์ และการอนุญาตเข้าถึง เพื่อป้องกันการพัฒนาระบบบนฐานข้อมูลที่ไม่สามารถเข้าถึงได้จริง | D7: วัดวุฒิภาวะของเทคโนโลยีว่าผ่านการพิสูจน์ในสภาพแวดล้อมจริงแล้ว หรือเป็นเพียงแนวคิดเชิงทฤษฎีในห้องปฏิบัติการ | E7: ป้องกันความเสี่ยง Single Point of Failure (SPOF) ที่การดำเนินงานขึ้นอยู่กับสมาชิกเพียงคนเดียวจนไม่สามารถทดแทนกันได้ | F7: ประเมินระยะเวลาและภาระที่ทีมงานต้องใช้ในการฝึกฝนเครื่องมือ ภาษา หรือเทคโนโลยีใหม่ เพื่อไม่ให้กระทบต่อตารางส่งมอบ | G7: ประเมินผลตอบแทนทางการเงินและการประหยัดงบประมาณภาครัฐเทียบกับเงินลงทุน เพื่อป้องกันโครงการที่ใช้งบประมาณเกินคุ้มค่า | H7: ประเมินความเสี่ยงจากการผูกขาดเทคโนโลยีและค่าลิขสิทธิ์ต่อเนื่อง เพื่อให้ระบบสามารถบำรุงรักษาได้อย่างเป็นอิสระ | I7: ประเมินขีดความสามารถทางการเงินในการรองรับความเสียหายของอุปกรณ์จากการทดลอง เพื่อไม่ให้โครงการหยุดชะงักเมื่อเกิดข้อผิดพลาด | J7: ตรวจสอบความสอดคล้องกับข้อกำหนดทางกฎหมายและสิทธิ์ความเป็นส่วนตัว เพื่อป้องกันการถูกระงับโครงการหรือดำเนินคดี | K7: ป้องกันการละเมิดลิขสิทธิ์ซอฟต์แวร์หรือข้อผูกมัดทางกฎหมายแบบ Copyleft ที่อาจบังคับเปิดเผยทรัพย์สินทางปัญญาของระบบ | L7: ประเมินความปลอดภัยของผู้ใช้งานและประชาชนเมื่อระบบเกิดความผิดพลาด ป้องกันความเสียหายต่อชีวิตและทรัพย์สิน | M7: ป้องกัน The Tech Trap โดยตรวจสอบว่าผู้ปฏิบัติงานหน้างานยินดีใช้งานจริงและไม่เกิดแรงต้านในกระบวนการทำงาน | N7: ประเมินความคล่องตัวในการเข้าถึงเครื่องมือ ห้องปฏิบัติการ และสิทธิ์ของนักพัฒนา เพื่อป้องกันการติดขัดจากระเบียบธุรการ | O7: ประเมินความซับซ้อนของขั้นตอนการบิวด์ คอมไพล์ และติดตั้ง เพื่อลดโอกาสเกิด Human Error ระหว่างพัฒนา | P7: ประเมินวุฒิภาวะของการออกแบบเมื่อเทียบกับกรอบเวลา 5 สัปดาห์ทำการจริง และช่วงสอบคั่นกลาง 4 สัปดาห์ | Q7: ประเมินความครอบคลุมของผลกระทบเชิงระบบว่าตอบโจทย์เสาหลักความยั่งยืน 3 ชั้นหลักของ Stockholm Resilience Centre (ชีวมณฑล/Planet, สังคม/People, และเศรษฐกิจ/Prosperity) อย่างเป็นองค์รวม ไม่ใช่โครงการแก้ปัญหาจุดเดียวที่ละเลยมิติอื่น | R7: ป้องกันการทอดทิ้งขยะอิเล็กทรอนิกส์หรือสารพิษลงสู่ระบบระบายน้ำและสิ่งแวดล้อมเมือง (SDG 6.3 / 12.4) | S7: สังเคราะห์จาก AI Agents Group 2
A8: เกณฑ์การให้คะแนน (Scoring Rubric Definition: ระดับ 1, 2, 3, 4, 5 ครบทุกระดับ) | B8: 1: ต้องวิจัยและสร้างขึ้นเองทั้งหมด 100% (ไม่มีพิมพ์เขียว อัลกอริทึม หรือไลบรารีอ้างอิง) 2: มีชิ้นส่วนหลักในท้องตลาด แต่ต้องดัดแปลงโครงสร้างอย่างหนักและเขียนโค้ดเชื่อมต่อเองทั้งหมด 3: บูรณาการชิ้นส่วน COTS เข้ากับแท่นยึดแบบกำหนดเอง และเขียนโค้ดเชื่อมต่อบางส่วน 4: ประกอบจากโมดูลมาตรฐานสำเร็จรูป (DIN-rail, I2C/CAN shields) มีงานประกอบกลไกเล็กน้อย 5: ซื้อมาติดตั้งใช้งานได้ทันที (Plug-and-Play) ไม่ต้องตัดกลึงหรือบัดกรีวงจรเพิ่มเติม | C8: 1: ล็อกสิทธิ์ภายใต้สัญญา NDA ระบบปิด ติดไฟร์วอลล์องค์กร หรือไม่มีสิทธิ์เข้าถึงฝั่งนักพัฒนา 2: ซอฟต์แวร์หรือเฟิร์มแวร์กรรมสิทธิ์ปิด ทำงานแบบ Black-box โดยไม่มี Source Code หรือ Telemetry 3: บัญชีเพื่อการศึกษา/ทดลองใช้ที่มีโควตาหรือ Rate Limit เข้มงวด ต้องรอการอนุมัติอย่างเป็นทางการ 4: มี SDK หรือ Open API สาธารณะพร้อมเอกสารครบถ้วน แต่ไม่สามารถแก้ไขสถาปัตยกรรมระดับล่างได้ 5: สถาปัตยกรรมเปิดสมบูรณ์ (Open Source/Open HW) ทีมงานมีสิทธิ์ระดับ Root/Admin เต็มรูปแบบ | D8: 1: ระดับแนวคิด/สมการคณิตศาสตร์ (TRL 2–3) ทดสอบเฉพาะในห้องทดลองที่ควบคุมสภาพแวดล้อมได้ 2: เบรดบอร์ดทำงานได้ในแล็บ (TRL 4) สายไฟเปราะบาง ยังไม่ผ่านการสอบเทียบในสภาพแวดล้อมจริง 3: ตัวต้นแบบประกอบลงกล่อง (TRL 5–6) ผ่านการทดสอบในสภาพแวดล้อมจำลอง ต้องมีคนคอยดูแล 4: ต้นแบบระดับพรีโปรดักชัน (TRL 7) ทำงานได้อย่างมีเสถียรภาพในสภาพแวดล้อมปฏิบัติงานจริง 5: ผลิตภัณฑ์เชิงพาณิชย์สมบูรณ์ (TRL 8–9) ผ่านการรับรองมาตรฐาน มีค่า MTBF ยืนยันความทนทาน | E8: 1: มีผู้เชี่ยวชาญเพียงคนเดียว (SPOF) หากไม่อยู่ การพัฒนาระบบจะหยุดชะงัก 100% 2: มีหัวหน้าทีมคนเดียว มีสมาชิกเข้าใจหลักการพื้นฐานแต่ไม่สามารถดีบักโค้ดหรือซ่อมแซมฮาร์ดแวร์ได้ 3: มีผู้รับผิดชอบหลักและผู้ช่วยสำรอง 1 คู่ที่สามารถดูแล แก้ไขปัญหา และปรับปรุงระบบทดแทนกันได้ 4: มีสมาชิกในทีมอย่างน้อย 3 คนที่มีความชำนาญ สามารถออกแบบ ประกอบ และแก้ไขระบบได้ทันที 5: ทีมงานทุกคนมีความเชี่ยวชาญเต็มเปี่ยม สามารถสลับสับเปลี่ยนหน้าที่กันได้โดยไม่กระทบความเร็วงาน | F8: 1: ต้องเริ่มเรียนรู้ใหม่ทั้งหมดจากศูนย์ ทั้งภาษา เครื่องมือ และฮาร์ดแวร์ที่ไม่เคยใช้งานมาก่อน 2: มีความเข้าใจเชิงทฤษฎี แต่ขาดประสบการณ์ปฏิบัติจริง การเขียนโค้ดและต่อวงจรติดขัดล่าช้า 3: มีทักษะในเทคโนโลยีใกล้เคียงที่เทียบเคียงได้ ใช้เวลาปรับตัวและฝึกฝนประมาณ 1 สัปดาห์ 4: คุ้นเคยกับชุดเครื่องมืออยู่แล้ว เพียงเรียนรู้ไลบรารีหรือคำสั่งเฉพาะของเซนเซอร์เพิ่มเติมเล็กน้อย 5: ไม่ต้องเรียนรู้ใหม่ สามารถนำโค้ด เครื่องมือ และทักษะที่มีอยู่เดิมมาประยุกต์ใช้งานได้ทันที | G8: 1: ระยะเวลาคืนทุนนานมาก (>= 10 ปี) ต้นทุนเริ่มแรกสูงแต่ประหยัดค่าใช้จ่ายได้น้อยมาก ไม่คุ้มค่าเชิงพาณิชย์ 2: คืนทุนช้า (6–9 ปี) ใช้เงินลงทุนสูงและต้องได้รับการอุดหนุนงบประมาณระยะยาว 3: คืนทุนปานกลาง (3–5 ปี) เหมาะสมกับโครงสร้างพื้นฐานสาธารณะ ชดเชยต้นทุนได้ตามรอบงบประมาณ 4: คืนทุนเร็ว (2–3 ปี) ลดค่าใช้จ่ายด้านแรงงาน เชื้อเพลิง หรือการสูญเสียได้อย่างมีนัยสำคัญ 5: คืนทุนทันที (<= 1–2 ปี) ลดความสูญเสียจากภัยพิบัติหรือความเสียหายซ้ำซากได้ตั้งแต่ฤดูกาลแรก | H8: 1: ผูกขาดกับผู้ขาย 100% พึ่งพาคลาวด์และตัวเชื่อมต่อเฉพาะทางที่เข้ารหัส ปิดกั้นการซ่อมบำรุง 2: ต้องใช้เครื่องมือตรวจวิเคราะห์เฉพาะของผู้ผลิต หรือเสียค่าธรรมเนียมรายปีเพื่อเปิดใช้งาน 3: ฮาร์ดแวร์หลักใช้เฟิร์มแวร์กรรมสิทธิ์ แต่เปิดช่องทาง API และใช้อินเทอร์เฟซไฟฟ้าตามมาตรฐาน 4: ใช้โพรโทคอลสื่อสารมาตรฐานเปิด (MQTT, Modbus, CAN) ซ่อมบำรุงด้วยเครื่องมือทั่วไปได้ 5: สถาปัตยกรรมเปิดสมบูรณ์ ชิ้นส่วนทุกชิ้นมีอะไหล่ทดแทนในท้องตลาด วิศวกรซ่อมบำรุงได้เอง 100% | I8: 1: ไม่มีงบสำรองอะไหล่ (0%) ซื้อฮาร์ดแวร์เพียง 1 ชุด หากชิปไหม้หรือโครงสร้างเสียหาย โครงการจะหยุดชะงัก 2: งบสำรองเปราะบาง (20–30%) มีอะไหล่เฉพาะชิ้นส่วนพาสซีฟ ไม่มีไมโครคอนโทรลเลอร์หรือเซนเซอร์สำรอง 3: งบสำรองปานกลาง (50%) มีอะไหล่พาสซีฟครบถ้วน และมีบอร์ดควบคุมหลักสำรอง 1 ชุด 4: งบสำรองสูง (80%) มีอะไหล่สำรองสำหรับชิ้นส่วนแอคทีฟและเซนเซอร์เกือบทุกตัว รองรับความผิดพลาดได้หลายครั้ง 5: มีอะไหล่ทดแทนสมบูรณ์ (>= 100%) สามารถประกอบชุดฮาร์ดแวร์ทำงานได้พร้อมกัน 2 ระบบเต็มรูปแบบ | J8: 1: ฝ่าฝืนกฎหมายชัดเจน (ละเมิด PDPA จากการสอดส่องที่สาธารณะ, กีดขวางการจราจร, คลื่นวิทยุผิดกฎหมาย) 2: มีความเสี่ยงทางกฎหมายสูง มีข้อร้องเรียนเรื่องการสัญจรหรือความปลอดภัย ต้องขอข้อยกเว้นทางเทคนิคซับซ้อน 3: ปฏิบัติการได้ภายใต้เงื่อนไข ต้องมีหนังสืออนุญาต บันทึกข้อตกลง (MoU) หรือใบอนุญาตจากเทศบาล 4: ความเสี่ยงต่ำ ปฏิบัติการภายใต้ข้อยกเว้นงานวิจัยทางวิศวกรรมสาธารณะ เพียงแจ้งหน่วยงานและปฏิบัติตามมาตรฐาน 5: ได้รับการยกเว้นตามกฎหมาย 100% ไม่มีความเสี่ยงต่อความปลอดภัยสาธารณะ และไม่มีการเก็บข้อมูลส่วนบุคคล (Zero PII) | K8: 1: สัญญาอนุญาตเชิงพาณิชย์แบบปิด ต้องจ่ายค่าลิขสิทธิ์ราคาสูงจึงจะสามารถคอมไพล์หรือใช้งานได้ 2: สถานะทรัพย์สินทางปัญญาคลุมเครือ ไม่มีสัญญาอนุญาตชัดเจน เสี่ยงต่อการถูกฟ้องร้องละเมิดลิขสิทธิ์ 3: สัญญาอนุญาตแบบ Copyleft เข้มงวด (เช่น GPLv3) บังคับให้ต้องเปิดเผยโค้ดทั้งหมดหากมีการแจกจ่าย 4: สัญญาอนุญาตแบบเปิดที่มีเงื่อนไขน้อย (เช่น LGPL, CC-BY) อนุญาตให้นำไปพัฒนาต่อได้โดยระบุที่มา 5: สัญญาอนุญาตแบบเสรีสมบูรณ์ (MIT, Apache 2.0, BSD) หรือเป็นสมบัติสาธารณะ นำไปใช้ประโยชน์ได้อิสระ 100% | L8: 1: อันตรายถึงชีวิต เกิดไฟฟ้าดูด เพลิงไหม้ อุบัติเหตุทางถนน หรือการพังทลายของโครงสร้าง 2: อันตรายทางกายภาพรุนแรง อุปกรณ์เสียหายหนัก ก่อสารพิษ หรือหยุดชะงักโครงสร้างพื้นฐานฉุกเฉิน 3: ผู้ใช้เกิดความโกลาหล สับสนในข้อมูล มีการสั่งการทับซ้อนและระบบหยุดชะงัก 4: เกิดความล่าช้าเล็กน้อยในการปฏิบัติการ ระบบตัดการทำงานอย่างปลอดภัย สามารถรีบูตหรือสลับไปใช้ระบบสำรองได้ 5: เสียหายเพียงงบประมาณเล็กน้อย ไม่ก่ออันตรายต่อมนุษย์หรือกระทบกระบวนการทำงานหลัก | M8: 1: รื้อระบบการทำงานเดิมทั้งหมด บังคับกรอกเอกสารเพิ่ม 5 ขั้นตอนขึ้นไป และผู้ปฏิบัติงานต่อต้านไม่ยอมใช้ 2: เพิ่มภาระการบันทึกข้อมูลอย่างมาก ผู้ปฏิบัติงานจะพยายามหาทางหลีกเลี่ยงหรือบายพาสระบบ 3: ปรับเปลี่ยนกิจวัตรเล็กน้อย ต้องจัดอบรม 1–2 ครั้ง แต่ผู้ใช้ยอมรับแลกกับประสิทธิภาพที่ได้รับ 4: ผสานรวมเข้ากับระบบงานเดิมได้อย่างราบรื่น (ส่งแจ้งเตือนเข้า LINE/Dashboard ที่ใช้อยู่แล้ว) 5: ทำงานอยู่เบื้องหลังแบบอัตโนมัติ 100% ไร้แรงเสียดทาน ผู้ปฏิบัติงานไม่ต้องเปลี่ยนขั้นตอนใดๆ | N8: 1: ติดขั้นตอนอนุมัติราชการเข้มงวด ต้องเซ็น NDA ล็อกตู้แล็บ และถูกจำกัดสิทธิ์ Git Branch 2: ต้องกรอกแบบฟอร์มขอใช้อุปกรณ์ของคณะ รอคิวเครื่องจักร และรอการอนุมัติ 3–5 วันทำการ 3: เข้าใช้งานห้องแล็บและเครื่องมือได้ตามเวลาเปิดทำการปกติของมหาวิทยาลัย 4: มีสิทธิ์เข้าแล็บ 24 ชม. มีสิทธิ์เขียนโค้ดลง Repository และมีงบประมาณย่อยพร้อมเบิกจ่ายทันที 5: ทำงานได้อิสระ 100% ใช้ระบบ CI/CD บนคลาวด์ มีเครื่องมือประกอบต้นแบบที่บ้าน ไร้อุปสรรคทางธุรการ | O8: 1: ขั้นตอนการบิวด์และติดตั้งซับซ้อนมาก เครื่องมือพึ่งพาแพ็กเกจเปราะบาง เสี่ยงต่อข้อผิดพลาดสูง 2: ต้องรันกระบวนการด้วยมือหลายขั้นตอน ติดปัญหาความไม่เข้ากันของไลบรารี และแฟลชบอร์ดได้ยาก 3: กระบวนการประกอบและบิวด์ระบบมีหลายขั้นตอนตามมาตรฐาน สามารถทำซ้ำได้ตามคู่มือและเช็กลิสต์ 4: เวิร์กโฟลว์ตรงไปตรงมา ใช้ระบบสคริปต์อัตโนมัติ รันผ่าน IDE มาตรฐาน คำสั่งเดียวแฟลชบอร์ดได้ 5: ระบบเรียบง่ายแบบ Plug-and-Play ทำงานได้ในขั้นตอนเดียว ไม่ต้องตั้งค่าซับซ้อน | P8: 1: อยู่ในระดับแนวคิดเท่านั้น (0% Design) ไม่มีโมเดล CAD ไม่มีผังวงจร และยังไม่ได้เขียนเฟิร์มแวร์ 2: แบบร่างเบื้องต้น (25% Design) มีเพียงบล็อกไดอะแกรม ผังวงจรวาดมือ รายการชิ้นส่วนที่ยังไม่ได้สอบทาน 3: ความพร้อมระดับปานกลาง (50% Design) ประกอบ CAD ครบ มีผังวงจร Schematic สมบูรณ์ วางสถาปัตยกรรมโค้ดแล้ว 4: พร้อมทดสอบพรีโปรดักชัน (75–80% Design) โมเดล 3D พร้อมพิมพ์/กัด มีไฟล์ Gerber ตรวจสอบ DRC แล้ว 5: ออกแบบเสร็จสมบูรณ์ 100% (Production Ready) มีไฟล์ผลิตครบถ้วน ล็อกรายการ BOM และมีสคริปต์แฟลชพร้อมผลิต | Q8: 1: หลุดจาก Wedding Cake หรือสร้างผลกระทบเชิงลบต่อเสาหลักใดเสาหลักหนึ่งอย่างรุนแรง 2: สัมผัสเพียง 1 เสาหลักอย่างผิวเผิน ขาดการเชื่อมโยงเชิงประจักษ์ไปยังสังคมหรือสิ่งแวดล้อมจริง 3: ครอบคลุม 1 เสาหลักอย่างเป็นรูปธรรม หรือ 2 เสาหลักแบบมีข้อจำกัดเฉพาะจุด/เฉพาะช่วงเวลา 4: บูรณาการ 2 เสาหลักสำคัญ (เช่น Planet + People) ควบคู่กันอย่างชัดเจนและมีตัวชี้วัดรองรับ 5: บูรณาการครบทั้ง 3 เสาหลัก (Planet, People, Prosperity) อย่างสมดุลและครบวงจร | R8: 1: ก่ออันตรายและสารพิษในพื้นที่ กล่องอุปกรณ์แตกสลาย หรือแบตเตอรี่รั่วไหลหลุดลงสู่ระบบระบายน้ำ 2: เทคโนโลยีเปราะบางแบบใช้แล้วทิ้ง เซนเซอร์อุดตันหรือผุกร่อนภายใน 2–3 สัปดาห์ และถูกทิ้งร้างในพื้นที่ 3: มีรอยเท้าสิ่งแวดล้อมตามมาตรฐาน ต้องเปลี่ยนแบตเตอรี่ตามรอบ มีสายยึดป้องกันอุปกรณ์สูญหาย 4: กล่องหุ้มทนทานผลกระทบต่ำ กินไฟต่ำ ใช้วัสดุรีไซเคิลได้ และมีสายสลิงยึดโยงเพื่อความปลอดภัย 5: ออกแบบตามหลักเศรษฐกิจหมุนเวียน 100% กู้คืนอุปกรณ์ได้ปลอดภัย ใช้วัสดุไม่เป็นพิษ ไร้รอยเท้าสิ่งแวดล้อม | S8: เกณฑ์รวม: >=80 ผ่านสูง, >=60 มีเงื่อนไข, <60 เสี่ยงสูง | หากมีข้อใดได้ 1 = VETOED ตกเกณฑ์ทันที
A9: คะแนนที่ได้รับ (ASSIGNED SCORE: 1, 2, 3, 4, 5 STRICT INTEGER) | B9: 3 | C9: 5 | D9: 3 | E9: 3 | F9: 3 | G9: 3 | H9: 4 | I9: 3 | J9: 2 | K9: 5 | L9: 4 | M9: 4 | N9: 3 | O9: 3 | P9: 3 | Q9: 4 | R9: 5 | S9: =IF(S10>0, (S11/S10)*20, 0)
A10: ค่าน้ำหนัก (Weight %) | B10: 0.04 | C10: 0.04 | D10: 0.04 | E10: 0.04 | F10: 0.04 | G10: 0.0667 | H10: 0.0667 | I10: 0.0666 | J10: 0.075 | K10: 0.075 | L10: 0.05 | M10: 0.05 | N10: 0.05 | O10: 0.05 | P10: 0.15 | Q10: 0.05 | R10: 0.05 | S10: =SUM(B10:R10)
A11: คะแนนถ่วงน้ำหนัก (=Score * Weight) | B11: =B9*B10 | C11: =C9*C10 | D11: =D9*D10 | E11: =E9*E10 | F11: =F9*F10 | G11: =G9*G10 | H11: =H9*H10 | I11: =I9*I10 | ... R11: =R9*R10 | S11: =SUM(B11:R11)
A12: คำอธิบาย & หลักฐานอ้างอิงจากไฟล์ Intake (Evidence Citation) | B12: solution-details/solution-2.md lines 17-27, 43-47; team-skills/due.md line 26; standard COTS breakout boards (MAX98357 audio amp, MEMS mic, ESP32) integrated with 3D-printed acoustic horn brackets and custom glue code. | C12: solution-details/solution-2.md lines 43-47; team-skills/due.md line 20, jk.md lines 36-37; fully open-source firmware (ESP-IDF, Arduino) and Python scientific libraries (SciPy, NumPy) with 100% root/admin development rights. | D12: solution-details/solution-2.md lines 17-40; schedule-details/schedule.md line 16; airborne acoustic reflectometry in pipes is verified in relevant simulated pipe networks (TRL 5-6) in literature, well-aligned for reaching course target of TRL 4 by Week 16. | E12: team-skills/due.md line 26, fifa.md lines 12-25, jk.md lines 24-40, kin.md lines 12-32; Due leads audio hardware with Fifa/JK backup; JK leads signal processing/math with Kin/Due backup; Fifa leads mechanical fixtures with Due/Jay backup. | F12: team-skills/due.md line 26, jk.md lines 27, 33-40; team has proven adjacent mastery in ESP32, MAX98357 audio amplifier, and Python signal processing; requires a manageable 1-week curve to calibrate acoustic chirp sweeps and matched filtering. | G12: Acoustic sewer inspection provides fast pipe triage compared to multi-million Baht crawler robots, but its explicit operational limitation (cannot operate during high water/rain) and custom transducer tooling lengthen municipal payback to 3-5 years. | H12: Built using standard generic COTS components (MAX98357 audio amplifier, I2S microphones, ESP32) with open communication protocols, though specialized acoustic waveguide coupling horns require custom fitting. | I12: High-SPL acoustic transducers and audio amplifiers driven near saturation risk thermal burnouts; budget accommodates a 50% buffer (spare MCU and audio ICs), but cannot duplicate full heavy-duty transducer field rigs. | J12: Opening sewer manholes on active public roadways causes severe traffic disruption, hazardous road blockage under Land Traffic Act B.E. 2522, and toxic gas asphyxiation risks under Confined Space Ministerial Regulations B.E. 2562. | K12: Acoustic reflectometry physics is public domain; embedded DSP routines utilize CMSIS-DSP (Apache 2.0) and NumPy/SciPy (BSD) with zero proprietary licensing encumbrances. | L12: อ้างอิง solution-2.md บรรทัดที่ 17, 30, 48-54: การตรวจสอบท่อด้วยคลื่นเสียงสะท้อนดำเนินการโดยการหย่อนหัวส่งและหัวรับจากผิวถนนลงไปที่ปากท่อ ไม่มีการส่งมนุษย์ลงไปใต้ดิน หากอุปกรณ์ขัดข้องหรือสัญญาณสะท้อนผิดเพี้ยนจากระดับน้ำ สามารถดึงก้านหย่อนกลับขึ้นมาได้อย่างปลอดภัย และสลับไปใช้วิธีลอกท่อเชิงกลตามปกติได้โดยปราศจากความเสี่ยงต่อชีวิต (Minor Operational Delay) | M12: อ้างอิง solution-2.md บรรทัดที่ 5-6, 12, 27, 40, 50: จุดเด่นของระบบคือความรวดเร็ว ('Fast') และการแปลงผลลัพธ์เป็นตัวเลขดัชนีความสะอาด 0-10 สเกล พร้อมระบุ Good/Bad ชัดเจนเพื่อจัดคิวลอกท่อ (Maintenance Queue) ได้ทันที เจ้าหน้าที่ภาคสนามไม่ต้องตีความสัญญาณฟิสิกส์ซับซ้อน เกิดแรงต้านในการปรับเปลี่ยนพฤติกรรมต่ำ (Low Friction) | N12: อ้างอิง solution-2.md บรรทัดที่ 17-23, 33-38: การทดสอบระบบรับส่งคลื่นเสียงจำเป็นต้องใช้ท่อทดสอบที่มีมิติจำลองใกล้เคียงท่อจริง ซึ่งทีมงานต้องขอเข้าใช้พื้นที่ห้องปฏิบัติการหรือท่อระบายน้ำภายใน มจธ. ในช่วงเวลาทำการปกติ แต่ชิ้นส่วนอิเล็กทรอนิกส์สามารถประกอบและทดสอบเบื้องต้นบนโต๊ะแล็บได้ (Standard Campus Access) | O12: อ้างอิง solution-2.md บรรทัดที่ 32-46: ระบบต้องสร้างสัญญาณ Chirp, ส่งผ่านแอมป์, ดักจับด้วยไมโครโฟน, กรองสัญญาณ, และคำนวณการลดทอน Due มีทักษะตรงในการต่อโมดูลขยายเสียง MAX98357 และ ESP32 (due.md) ขณะที่ JK เชี่ยวชาญคณิตศาสตร์การประมวลผลสัญญาณ (jk.md) กระบวนการพัฒนาจึงบริหารจัดการได้ตามคู่มือและเช็กลิสต์อย่างเป็นระบบ (Moderate Complexity) | P12: อ้างอิง schedule-details/schedule.md: ภายใต้กรอบเวลา 5 สัปดาห์ทำการ และการหยุดชะงัก 4 สัปดาห์ช่วงสอบ midterms/finals เพื่อมุ่งสู่ TRL3 (สัปดาห์ที่ 13) และ TRL4 (สัปดาห์ที่ 16) ด้วยทักษะการออกแบบ 3D CAD ของ Fifa (fifa.md) และความเชี่ยวชาญด้านเฟิร์มแวร์เสียงของ Due ทำให้ทีมสามารถออกแบบผังวงจร ขึ้นรูปแท่นยึดกระบอกส่งสัญญาณ และสร้างโค้ดทดสอบบน Bench ท่อจำลองได้ทันตามเกณฑ์วุฒิภาวะ 50% (Intermediate Maturity: 50% Design) | Q12: Solution-2 achieves deep systemic alignment across the Wedding Cake: (1) Planet/Biosphere via SDG 6.3 (detecting sludge/grease blockages to prevent foul wastewater overflows into natural waterways); (2) People/Society via SDG 11.5 (pre-monsoon screening mitigating urban road flooding) and SDG 8.8 (protecting municipal workers by eliminating dangerous confined-space manual sewer entries); and (3) Prosperity/Economy by translating acoustic decay into a quantitative 0-10 Cleanliness Score to optimize municipal truck dispatch. It strongly secures Level 4 (robust dual-tier with active economic dispatch linkage). | R12: Solution-2 is an active, human-operated portable diagnostic tool rather than a permanently installed IoT node. Crews temporarily place the transmitter and receiver at opposite manholes, emit acoustic pulses through the sewer air column, record transmission loss, and immediately retrieve the equipment upon test completion. Because zero hardware, probes, or batteries are left unattended in the sewer, it achieves 100% fail-safe retrieval, leaves zero field trace, and generates zero marine litter or toxic leaching into the urban drainage network (SDG 6.3 / 12.4). | S12: =IF(MIN(B9:R9)=1, "VETOED / ตกเกณฑ์ข้อบังคับวิกฤต (คะแนนระดับ 1)", IF(S9>=80, "ผ่านเกณฑ์ระดับสูง (HIGHLY VIABLE)", IF(S9>=60, "ผ่านแบบมีเงื่อนไข (CONDITIONALLY VIABLE)", "ความเสี่ยงสูง (HIGH RISK)")))
A13: แผนลดขอบเขตงาน & มาตรการลดความเสี่ยง (De-scoping Action) | B13: Use pre-assembled commercial acoustic transducers with weather-sealed rubber gaskets and standard 3.5mm jacks to eliminate point-to-point field wiring fragility. | C13: None required. Maintain version-locked requirements (requirements.txt, platformio.ini) in git. | D13: Descope the complex 2D cross-sectional view from angular tomographic imaging to a simplified 1D axial blockage percentage graphic (A_blocked / A_pipe) and 0-10 cleanliness score. | E13: Structure modular interfaces allowing JK and Kin to simulate filtering on recorded WAV audio files while Due and Fifa finalize the acoustic housing. | F13: Generate pre-computed linear chirp audio files stored on an SD card or flash memory to bypass real-time synthetic waveform generation on the microcontroller. | G13: Bundle acoustic screening kits with existing municipal dredging trucks as a rapid pre-screening tool to prioritize crawler camera deployments. | H13: Standardize probe housings on generic commercial 4-ohm drivers and standard 1/2-inch condenser capsules with 3D-printed coupling adapters. | I13: Use pre-assembled Class-D amplifier modules with thermal/short protection and stock a 50% spare reserve of amplifier ICs and microphone capsules. | J13: Confine semester testing to KMUTT campus drainage conduits or an above-ground PVC pipe testbench, requiring official BMA crew accompaniment for any public street trials. | K13: Rely exclusively on Apache 2.0 and MIT signal processing libraries for FFT and cross-correlation filtering. | L13: ติดตั้งสายสลิงนิรภัยคู่ (Dual Mechanical Tether) ยึดหัวเซนเซอร์กับก้านหย่อน และเพิ่มสถานะแจ้งเตือนบนหน้าจอว่า 'Signal Unreliable / High Water Level' เพื่อสั่งยกเลิกการวัดโดยอัตโนมัติเมื่อค่าการสะท้อนผิดเพี้ยน | M13: พัฒนา Web UI บนแท็บเล็ต/สมาร์ตโฟนที่แสดงผลสถานะท่อเป็นสีเขียว-เหลือง-แดง พร้อมปุ่มกดส่งพิกัด GPS เข้าสู่คิวงานบำรุงรักษาได้ทันที เพื่อตัดขั้นตอนการกรอกรายงานด้วยมือ | N13: ประกอบท่อทดสอบจำลอง (Acoustic Testbed) จากท่อพีวีซีขนาดเส้นผ่านศูนย์กลาง 4 นิ้ว ขนาดยาว 3-6 เมตร ติดตั้งไว้ในห้องปฏิบัติการ FIBO เพื่อใช้ทดสอบและสอบเทียบค่าการลดทอนของเสียงได้ตลอดเวลาโดยไม่ต้องลงพื้นที่ท่อจริง | O13: ลดทอนฟังก์ชันการสร้างภาพตัดขวาง 2D ให้เหลือเพียงการคำนวณอัตราส่วนการสูญเสียพลังงานเสียง (Acoustic Energy Attenuation Ratio) แล้วเทียบกับตาราง Look-up Table เพื่อแปลงเป็นคะแนน 0-10 เพื่อตัดความซับซ้อนของอัลกอริทึม Inverse Scattering | P13: จัดซื้อลำโพงกันน้ำขนาดเล็กและไมโครโฟน MEMS I2S สำเร็จรูปภายในสัปดาห์ที่ 9 เพื่อให้ Fifa ขึ้นรูปเคส 3D Print ให้เสร็จสิ้นในสัปดาห์ที่ 11 สำหรับนำไปทดสอบ Proof-of-Concept ในสัปดาห์ที่ 13 | Q13: Integrate acoustic inspection logs into a mobile GIS-based maintenance dispatch pipeline for district public works crews (ฝ่ายโยธา) to formalize multi-subdistrict economic ROI into a full Level 5 city-wide deployment. | R13: Standardize handheld enclosures using non-toxic recyclable TPU and aluminum with replaceable hydrophobic ePTFE acoustic membranes to withstand sewer moisture without requiring harsh chemical cleaning agents. | S13: ปฏิบัติตามแผนลดขอบเขตงาน (De-scoping Advisory)
A15: ตารางสรุปคะแนนแยกตามมิติ TELOS+S (Pillar Score Breakdown)
A16: มิติการประเมิน (TELOS+S Pillar) | B16: สัดส่วนน้ำหนัก (Weight %) | C16: คะแนนเต็มมิติ (Max Points) | D16: คะแนนที่ได้รับจริง (Earned Points) | E16: คะแนนเฉลี่ย (Score 1-5) | F16: ระดับความพร้อม (Readiness Level)
A17: T : ด้านเทคโนโลยีและวิศวกรรม (Technical) | B17: 0.2 | C17: 20 | D17: =SUM(B11:F11)*20 | E17: =IF(C17>0, (D17/C17)*5, 0) | F17: =IF(D17>=16.0, "พร้อมระดับสูง (High)", IF(D17>=12.0, "ปานกลาง (Medium)", "เสี่ยงวิกฤต (Critical)"))
A18: E : ด้านเศรษฐศาสตร์และความคุ้มค่า (Economic) | B18: 0.2 | C18: 20 | D18: =SUM(G11:I11)*20 | E18: =IF(C18>0, (D18/C18)*5, 0) | F18: =IF(D18>=16.0, "พร้อมระดับสูง (High)", IF(D18>=12.0, "ปานกลาง (Medium)", "เสี่ยงวิกฤต (Critical)"))
A19: L : ด้านกฎหมาย ระเบียบ และภาคประชาชน (Legal & Outreach) | B19: 0.15 | C19: 15 | D19: =SUM(J11:K11)*20 | E19: =IF(C19>0, (D19/C19)*5, 0) | F19: =IF(D19>=12.0, "พร้อมระดับสูง (High)", IF(D19>=9.0, "ปานกลาง (Medium)", "เสี่ยงวิกฤต (Critical)"))
A20: O : ด้านการปฏิบัติการและหน้างาน (Operational) | B20: 0.2 | C20: 20 | D20: =SUM(L11:O11)*20 | E20: =IF(C20>0, (D20/C20)*5, 0) | F20: =IF(D20>=16.0, "พร้อมระดับสูง (High)", IF(D20>=12.0, "ปานกลาง (Medium)", "เสี่ยงวิกฤต (Critical)"))
A21: S : ด้านแผนงานและเวลาส่งมอบ (Schedule) | B21: 0.15 | C21: 15 | D21: =P11*20 | E21: =IF(C21>0, (D21/C21)*5, 0) | F21: =IF(D21>=12.0, "พร้อมระดับสูง (High)", IF(D21>=9.0, "ปานกลาง (Medium)", "เสี่ยงวิกฤต (Critical)"))
A22: +S : ด้านความยั่งยืนและสิ่งแวดล้อม (Sustainability / SDG) | B22: 0.1 | C22: 10 | D22: =SUM(Q11:R11)*20 | E22: =IF(C22>0, (D22/C22)*5, 0) | F22: =IF(D22>=8.0, "พร้อมระดับสูง (High)", IF(D22>=6.0, "ปานกลาง (Medium)", "เสี่ยงวิกฤต (Critical)"))
A23: คะแนนรวมทุกมิติ (Total Feasibility Score) | B23: =SUM(B17:B22) | C23: =SUM(C17:C22) | D23: =SUM(D17:D22) | E23: =IF(C23>0, (D23/C23)*5, 0) | F23: =IF(D23>=80, "ผ่านเกณฑ์ระดับสูง (HIGHLY VIABLE)", IF(D23>=60, "ผ่านแบบมีเงื่อนไข (CONDITIONALLY VIABLE)", "ความเสี่ยงสูง (HIGH RISK)"))
A25: เมทริกซ์ประเมินความเข้ากันได้กับองค์ความรู้ด้านวิศวกรรมหุ่นยนต์ (Robotics Knowledge Compatibility)
A26: * หมายเหตุ: การประเมินส่วนนี้วัดศักยภาพในการประยุกต์ใช้องค์ความรู้ด้านวิศวกรรมหุ่นยนต์ (Perception, Control, Actuation) เต็ม 12 คะแนน (แกนละ 4 คะแนน) | เป็นเอกเทศ ไม่นับรวมในคะแนน TELOS 100 คะแนน
A27: มิติการประเมิน (Robotics Dimension) | B27: คะแนนศักยภาพ (/12) | C27: แกน Perception & Sensing (การรับรู้) | D27: แกน Control & Algorithms (การควบคุม) | E27: แกน Actuation & Mechanisms (กลไก) | F27: บทวิเคราะห์เชิงวิศวกรรมหุ่นยนต์ (FIBO Alignment Rationale)
A28: ศักยภาพการประยุกต์ใช้องค์ความรู้หุ่นยนต์และระบบอัตโนมัติ | B28: 8 | C28: Level 3.5 / 4.0: Airborne Acoustic Reflectometry (AAR) measuring acoustic wave propagation and energy attenuation across sewer air cavities under normal low-water conditions. | D28: Level 3.0 / 4.0: Digital signal processing (bandpass filtering, FFT, deconvolution) with 2D cross-sectional reconstruction and automated 0-10 cleanliness scale classification. | E28: Level 1.5 / 4.0: Manual transmitter/receiver placement across manholes; actuation features acoustic transducer sound wave excitation without motorized traversal or mechanical manipulation. | F28: Solution 2 is an advanced acoustic Non-Destructive Testing (NDT) diagnostic instrument. The user clarification regarding low-water operating protocol and automated 0-10 cleanliness classification elevates its sensing and DSP depth. However, it remains an open-loop diagnostic tool lacking autonomous locomotion or physical actuation, underutilizing the team's mechanical fabrication and transmission design skills.

Sheet Solution_3_Adaptive_Misting
A1: เมทริกซ์ประเมินความเป็นไปได้เชิงระบบ TELOS+S: ระบบปล่อยน้ำแบบ Adaptive เพื่อระบายความร้อนบนทางเดินเท้าและตรอกซอยอย่างมีประสิทธิภาพสูงสุด
A2: ระบบคะแนนจำนวนเต็มเด็ดขาด: 1, 2, 3, 4, 5 เท่านั้น (ไม่มีจุดทศนิยม / ไม่มี 0.5) | โครงสร้างแบบ Transposed แนวนอน
A4: รหัสคำถาม (Question Code) | B4: T-01 | C4: T-02 | D4: T-03 | E4: T-04 | F4: T-05 | G4: E-01 | H4: E-02 | I4: E-03 | J4: L-01 | K4: L-02 | L4: O-01 | M4: O-02 | N4: O-03 | O4: O-04 | P4: S-01 | Q4: SDG-01 | R4: SDG-02 | S4: สรุปภาพรวม (SUMMARY)
A5: มิติการประเมิน (TELOS+S Pillar) | B5: ด้านเทคนิค (Technical 2.2) | C5: ด้านเทคนิค (Technical 2.2) | D5: ด้านเทคนิค (Technical 2.2) | E5: ด้านเทคนิค (Technical 2.2) | F5: ด้านเทคนิค (Technical 2.2) | G5: ด้านเศรษฐศาสตร์ (Economic 2.3) | H5: ด้านเศรษฐศาสตร์ (Economic 2.3) | I5: ด้านเศรษฐศาสตร์ (Economic 2.3) | J5: ด้านกฎหมายและสถาบัน (Legal 2.4) | K5: ด้านกฎหมายและสถาบัน (Legal 2.4) | L5: ด้านปฏิบัติการ (Operational 2.5) | M5: ด้านปฏิบัติการ (Operational 2.5) | N5: ด้านปฏิบัติการ (Operational 2.5) | O5: ด้านปฏิบัติการ (Operational 2.5) | P5: ด้านแผนงานและเวลา (Schedule 2.6) | Q5: ด้านความยั่งยืน (+S / SDGs 2.7) | R5: ด้านความยั่งยืน (+S / SDGs 2.7) | S5: ผลรวมทุกมิติ (All Pillars)
