Workbook

Sheet เปรียบเทียบทุก Solution
A1: ตารางเปรียบเทียบความเป็นไปได้ของทุกข้อเสนอ (Multi-Solution Feasibility Summary)
A2: วิเคราะห์เปรียบเทียบเชิงระบบตามเกณฑ์ TELOS+S (เต็ม 100) และเมทริกซ์ศักยภาพด้านวิศวกรรมหุ่นยนต์ (เต็ม 12 แยกอิสระ)
A4: ลำดับ | B4: รหัสข้อเสนอ (Solution ID) | C4: ชื่อแนวทางแก้ปัญหา (Title / Concept) | D4: คะแนนรวม (เต็ม 100) | E4: T: เทคนิค (/20) | F4: E: เศรษฐศาสตร์ (/20) | G4: L: กฎหมาย (/15) | H4: O: ปฏิบัติการ (/20) | I4: S: แผนงาน (/15) | J4: +S: ยั่งยืน (/10) | K4: ผลการประเมิน (Verdict) | L4: จุดแข็งสำคัญ (Key Strengths) | M4: จุดติดขัดวิกฤต (Critical Bottlenecks) | N4: คำแนะนำเชิงระบบ (Strategic Advice) | O4: Robotics Potential (/12) | P4: เหตุผลความเข้ากันได้ด้านหุ่นยนต์ (Robotics Engineering Rationale)
A5: 1 | B5: Solution_1_CCTV_Crawler | C5: Pipe Inspection Robot using CCTV for profiling pipe (4K PTZ Camera + YOLOv8 Wheeled Crawler) | D5: ='Solution_1_CCTV_Crawler'!S9 | E5: ='Solution_1_CCTV_Crawler'!D17 | F5: ='Solution_1_CCTV_Crawler'!D18 | G5: ='Solution_1_CCTV_Crawler'!D19 | H5: ='Solution_1_CCTV_Crawler'!D20 | I5: ='Solution_1_CCTV_Crawler'!D21 | J5: ='Solution_1_CCTV_Crawler'!D22 | K5: ='Solution_1_CCTV_Crawler'!S12 | L5: ให้ภาพวิดีโอความละเอียดสูง (HD/4K) ภายในท่อจริง พร้อมโมเดล AI (YOLOv8) ตรวจจับรอยแตกร้าว รอยรั่ว และสิ่งอุดตันได้โดยอัตโนมัติ | M5: ต้องใช้หุ่นยนต์ลงไปสัมผัสน้ำเสียในท่อจริง การกันน้ำระดับ IP68 ทำได้ยาก มีความเสี่ยงหุ่นยนต์ติดค้าง/สาย Tether พันกันในท่อ (O-01=3), และต้องใช้เวลาสร้างระบบกลไกกันน้ำสูงเกินกรอบเวลา 5 สัปดาห์ (S-01=2) | N5: ลดสโคปกลไกขับเคลื่อนที่ซับซ้อน หันมาใช้โครงสร้างล้อสำเร็จรูป (COTS Crawler Chassis) พร้อมติดตั้งชุดสาย Tether แบบ Slip-Ring คุณภาพสูง และทดสอบระบบกันน้ำในถังทดสอบก่อนลงพื้นที่จริง | O5: 10.5 | P5: Solution 1 implements a genuine closed-loop mobile robotic system across all three FIBO pillars: active high-resolution optical perception, edge neural network defect inferencing, and mobile robotic pipe locomotion, utilizing mechatronics and control skills directly.
A6: 2 | B6: Solution_2_Acoustic_Reflecto | C6: Pipe Inspection Instrument using Acoustic Reflectometry (Airborne Acoustic Inversion + SL-RAT EPA USA Cleanliness Scale) | D6: ='Solution_2_Acoustic_Reflecto'!S9 | E6: ='Solution_2_Acoustic_Reflecto'!D17 | F6: ='Solution_2_Acoustic_Reflecto'!D18 | G6: ='Solution_2_Acoustic_Reflecto'!D19 | H6: ='Solution_2_Acoustic_Reflecto'!D20 | I6: ='Solution_2_Acoustic_Reflecto'!D21 | J6: ='Solution_2_Acoustic_Reflecto'!D22 | K6: ='Solution_2_Acoustic_Reflecto'!S12 | L6: ตรวจประเมินท่อจากผิวดินได้อย่างรวดเร็ว (3–5 นาทีต่อช่วงท่อ) โดยไม่ต้องปล่อยหุ่นยนต์ลงไปสัมผัสน้ำเสีย ใช้พลังงานต่ำ ต้นทุนอุปกรณ์ต่ำมาก และไม่มีความเสี่ยงเรื่องอุปกรณ์ติดค้างในท่อ | M6: ไม่สามารถทำงานได้ในสภาวะที่น้ำท่วมเต็มท่อระบายน้ำ (Airspace ปิดกั้น) และไม่ได้ภาพ 3D เรขาคณิตของผิวท่อ | N6: พัฒนาท่อส่งคลื่นเสียงแบบ Telescoping Pole ที่สามารถปรับระดับความลึกตามปากท่อได้ พร้อมบันทึกพิกัด GPS อัตโนมัติเพื่อเชื่อมต่อแผนที่ระบบท่อของ กทม. | O6: 8.5 | P6: Solution 2 represents an advanced non-destructive testing (NDT) acoustic instrumentation payload with deep digital signal processing, acoustic wave physics modeling, and automated scoring classification, closely aligning with FIBO instrumentation and embedded DSP curriculum.
A7: 3 | B7: Solution_3_Sonar_Profiling | C7: Pipe Inspection Instrument using Sonar Frequency Profiling attaching with Robot (360° Underwater Sonar Scan + Floater/Crawler) | D7: ='Solution_3_Sonar_Profiling'!S9 | E7: ='Solution_3_Sonar_Profiling'!D17 | F7: ='Solution_3_Sonar_Profiling'!D18 | G7: ='Solution_3_Sonar_Profiling'!D19 | H7: ='Solution_3_Sonar_Profiling'!D20 | I7: ='Solution_3_Sonar_Profiling'!D21 | J7: ='Solution_3_Sonar_Profiling'!D22 | K7: ='Solution_3_Sonar_Profiling'!S12 | L7: สามารถส่งคลื่นความถี่อัลตราโซนิกทะลุน้ำเสียและโคลนตม เพื่อสแกนโครงสร้างหน้าตัดท่อแบบ 360 องศา และตรวจวัดปริมาณตะกอนใต้ผิวน้ำได้โดยตรง | M7: ต้องสร้างหรือจัดซื้อหัว Sonar 360° สำหรับสแกนใต้น้ำที่มีราคาสูงมาก (> 100,000 THB) เกินงบประมาณ (E-03=1), ไม่มีสมาชิกที่มีทักษะสร้างวงจรขับ Piezo ใต้น้ำ (T-04=1), ต้องเรียนรู้ใหม่จากศูนย์ (T-05=1), และใช้เวลาสร้างเกินกรอบเวลา 5 สัปดาห์ (S-01=1) | N7: ยกเลิกการพัฒนาหัวสแกน Sonar 360° ใต้น้ำขึ้นเองชั่วคราว หรือเปลี่ยนไปใช้ระบบ Acoustic Reflectometry ผ่านช่องว่างอากาศ (Solution 2) หรือเซนเซอร์วัดระยะแบบจุดเดียวบนทุ่นลอย | O7: 10.5 | P7: Solution 3 represents an exemplary deep robotics sensing system with rotating acoustic transducers and underwater cross-sectional profiling, but exceeds student fabrication and budget reality.
A8: 4 | B8: Solution_4_LiDAR_SLAM | C8: Pipe Inspection Instrument using LiDAR SLAM attaching with Robot (3D LiDAR + Laser SLAM Point Cloud Profiling) | D8: ='Solution_4_LiDAR_SLAM'!S9 | E8: ='Solution_4_LiDAR_SLAM'!D17 | F8: ='Solution_4_LiDAR_SLAM'!D18 | G8: ='Solution_4_LiDAR_SLAM'!D19 | H8: ='Solution_4_LiDAR_SLAM'!D20 | I8: ='Solution_4_LiDAR_SLAM'!D21 | J8: ='Solution_4_LiDAR_SLAM'!D22 | K8: ='Solution_4_LiDAR_SLAM'!S12 | L8: สร้างแผนที่ 3 มิติ (3D Point Cloud) ของท่อระบายน้ำได้อย่างแม่นยำระดับมิลลิเมตร สามารถตรวจวัดปริมาตรตะกอน (Buildup/Debris) และตรวจจับการเสียรูปเชิงเรขาคณิตของท่อได้อย่างชัดเจน | M8: เซนเซอร์ 3D LiDAR และบอร์ดประมวลผล GPU/SBC มีราคาสูงมากเกินงบประมาณ (E-03=1: ไม่มีงบสำรองกรณีเซนเซอร์ตกน้ำ), เลเซอร์ไม่สามารถทะลุน้ำเสียหรือหมอกควันได้ (T-03=2), และต้องใช้เวลาประมวลผล Point Cloud สูง | N8: ลดสโคปจากการใช้ 3D LiDAR ราคาแพง มาใช้ 2D LiDAR ติดตั้งบนแกนหมุน หรือใช้ Depth Camera / Structured Light ในท่อแห้งเพื่อควบคุมต้นทุนไม่ให้เกินงบประมาณ | O8: 11.5 | P8: Solution 4 exercises the peak FIBO robotics curriculum: 3D spatial laser perception, advanced SLAM state estimation, and mobile mechatronic locomotion, representing a gold-standard capstone robotics architecture.

Sheet Solution_1_CCTV_Crawler
A1: เมทริกซ์ประเมินความเป็นไปได้เชิงระบบ TELOS+S: Pipe Inspection Robot using CCTV for profiling pipe (4K PTZ Camera + YOLOv8 Wheeled Crawler)
A2: ระบบคะแนนจำนวนเต็มเด็ดขาด: 1, 2, 3, 4, 5 เท่านั้น (ไม่มีจุดทศนิยม / ไม่มี 0.5) | โครงสร้างแบบ Transposed แนวนอน
A4: รหัสคำถาม (Question Code) | B4: T-01 | C4: T-02 | D4: T-03 | E4: T-04 | F4: T-05 | G4: E-01 | H4: E-02 | I4: E-03 | J4: L-01 | K4: L-02 | L4: O-01 | M4: O-02 | N4: O-03 | O4: O-04 | P4: S-01 | Q4: SDG-01 | R4: SDG-02 | S4: สรุปภาพรวม (SUMMARY)
A5: มิติการประเมิน (TELOS+S Pillar) | B5: ด้านเทคนิค (Technical 2.2) | C5: ด้านเทคนิค (Technical 2.2) | D5: ด้านเทคนิค (Technical 2.2) | E5: ด้านเทคนิค (Technical 2.2) | F5: ด้านเทคนิค (Technical 2.2) | G5: ด้านเศรษฐศาสตร์ (Economic 2.3) | H5: ด้านเศรษฐศาสตร์ (Economic 2.3) | I5: ด้านเศรษฐศาสตร์ (Economic 2.3) | J5: ด้านกฎหมายและสถาบัน (Legal 2.4) | K5: ด้านกฎหมายและสถาบัน (Legal 2.4) | L5: ด้านการปฏิบัติการ (Operational 2.5) | M5: ด้านการปฏิบัติการ (Operational 2.5) | N5: ด้านการปฏิบัติการ (Operational 2.5) | O5: ด้านการปฏิบัติการ (Operational 2.5) | P5: ด้านแผนงานและเวลา (Schedule 2.6) | Q5: ด้านความยั่งยืน (SDGs Feasibility 2.7) | R5: ด้านความยั่งยืน (SDGs Feasibility 2.7) | S5: ผลรวมทุกมิติ (All Pillars)
A6: คำถามทดสอบความเสี่ยงจริง (Stress-Test Question) | B6: ระดับการสร้างเองเทียบกับการซื้อสำเร็จรูป (Build vs. Buy Burden) ของสถาปัตยกรรมระบบตรวจประเมินท่อระบายน้ำ? | C6: สิทธิ์ในการเข้าถึงเทคโนโลยี ซอฟต์แวร์ และระบบนิเวศข้อมูล (Access & Permissions) ของระบบตรวจประเมินท่อ? | D6: ระดับความพร้อมทางเทคโนโลยี (Base Performance / TRL) ในสภาพแวดล้อมจริงของท่อระบายน้ำใต้ดิน? | E6: ความพร้อมและกำลังคนสำรองของทีมงาน (Team Compatibility & Redundancy / Anti-SPOF)? | F6: ความชันในการเรียนรู้และเวลาปรับตัวของทีมงาน (Learning Curve & Ramp-up Time)? | G6: ระยะเวลาคืนทุนและความคุ้มค่าในการลงทุน (ROI / Payback Period) เทียบกับการขุดลอกแบบสุ่ม? | H6: การพึ่งพาผู้จำหน่ายและการผูกขาดชิ้นส่วนเฉพาะ (Component Dependency & Vendor Lock-in)? | I6: วงเงินงบประมาณสำรองความเสียหายและการทำซ้ำ (Scrap Margin & Iteration Allowance)? | J6: การปฏิบัติตามกฎหมายจราจร ความปลอดภัยในที่อับอากาศ และระเบียบพื้นที่สาธารณะ (Felony, Traffic & Confined Space Compliance)? | K6: การปฏิบัติตามสัญญาอนุญาต ทรัพย์สินทางปัญญา และโอเพนซอร์ส (IP & Software Licensing Compliance)? | L6: ผลกระทบและความรุนแรงเมื่อระบบเกิดความขัดข้องหรือติดค้าง (User — Failure Impact & Stuck Hazards)? | M6: ความสอดคล้องกับพฤติกรรมเจ้าหน้าที่และขั้นตอนการทำงานเดิม (User — Workflow Friction & Adoption)? | N6: การพึ่งพาห้องปฏิบัติการและขั้นตอนการขออนุมัติของนักพัฒนา (Developer — Lab & Administrative Gatekeeping)? | O6: ความซับซ้อนของขั้นตอนการประกอบ ติดตั้ง และโปรแกรม (Developer — Setup Steps & Pipeline Friction)? | P6: วุฒิภาวะของการออกแบบทางวิศวรรกรรมภายในกรอบเวลา 5 สัปดาห์ทำงาน (Engineering Design Maturity by 5 Weeks)? | Q6: การบูรณาการตามกรอบ Stockholm Wedding Cake (Biosphere, Society, Economy Integration)? | R6: ผลกระทบสิ่งแวดล้อม ขยะอิเล็กทรอนิกส์ และหลักเศรษฐกิจหมุนเวียน (E-Waste & 'Do No Harm' — SDG 6.3/12.4)? | S6: ประเมินคำถามทั้งสิ้น 17 ข้อ
A7: เหตุผลในการถาม & โหมดความล้มเหลวที่เฝ้าระวัง (Rationale) | B7: ประเมินภาระการวิจัยและพัฒนาชิ้นส่วนกลไก อิเล็กทรอนิกส์ และอัลกอริทึม ป้องกันการเสียเวลากับงานประดิษฐ์ขึ้นใหม่โดยไม่จำเป็น | C7: ตรวจสอบข้อจำกัดด้านกรรมสิทธิ์ การล็อกสิทธิ์ใช้งาน และการอนุญาตเข้าถึง เพื่อป้องกันการพัฒนาระบบบนฐานข้อมูลที่ไม่สามารถเข้าถึงได้จริง | D7: วัดวุฒิภาวะของเทคโนโลยีว่าผ่านการพิสูจน์ในสภาพแวดล้อมใต้ดินที่มีความชื้น สารกัดกร่อน หรือน้ำขังจริงแล้วหรือไม่ | E7: ตรวจสอบความเสี่ยงคอขวดบุคลากร (Single Point of Failure) ป้องกันไม่ให้โครงการหยุดชะงักหากผู้รับผิดชอบหลักไม่ว่าง | F7: ประเมินเวลาที่ทีมต้องใช้ในการเรียนรู้เครื่องมือหรือทฤษฎีใหม่ เพื่อไม่ให้กระทบต่อกำหนดการส่งมอบ 5 สัปดาห์ | G7: วัดความคุ้มค่าทางการเงินและการประหยัดงบประมาณการลอกท่อของหน่วยงานภาครัฐเทียบกับ Baseline เดิม | H7: ตรวจสอบความเสี่ยงจากการพึ่งพาผู้ขายรายเดียว การผูกขาดชิ้นส่วนนำเข้า หรือค่าลิขสิทธิ์ซอฟต์แวร์รายปี | I7: ประเมินขีดความสามารถในการรับมือกับความเสียหายของอุปกรณ์และชิปที่อาจช็อตหรือเสียหายระหว่างการพัฒนา | J7: ตรวจสอบความเสี่ยงต่อการละเมิดกฎหมายจราจร กฎหมายความปลอดภัยในที่อับอากาศ และการปิดกั้นทางสัญจร | K7: ตรวจสอบสิทธิ์การใช้งานซอฟต์แวร์ ไลบรารี และสิทธิบัตร ป้องกันการฟ้องร้องละเมิดลิขสิทธิ์ | L7: ประเมินความเสียหายต่อโครงสร้างพื้นฐาน ความปลอดภัยของเจ้าหน้าที่ และการกลายเป็นสิ่งกีดขวางในท่อระบายน้ำ | M7: ประเมินภาระการฝึกอบรม ความสะดวกในการพกพา และแรงต้านจากเจ้าหน้าที่ภาคสนามของ กทม. | N7: ประเมินอุปสรรคการเข้าถึงเครื่องมือ ช็อปเครื่องกล หรือการต้องรอคิวอนุมัติเอกสารของมหาวิทยาลัย | O7: ประเมินจำนวนขั้นตอนและความเปราะบางของเครื่องมือพัฒนา ป้องกันข้อผิดพลาดจากการตั้งค่าระบบที่ซับซ้อนเกินไป | P7: ทดสอบความเป็นไปได้ในการสร้างชิ้นงานให้สำเร็จตามเป้าหมาย TRL โดยหักสัปดาห์สอบมิดเทอมและไฟนอลออกแล้ว | Q7: ประเมินผลกระทบเชิงบวกที่ครอบคลุมทั้งด้านชีวมณฑล (SDG 6/14), สังคม (SDG 11) และเศรษฐกิจ (SDG 8/12) | R7: ตรวจสอบการป้องกันขยะอิเล็กทรอนิกส์ตกค้างในท่อระบายน้ำ สารพิษรั่วไหล และระบบกู้คืนอุปกรณ์ที่ปลอดภัย 100% | S7: สังเคราะห์จาก AI Agents Group 2
A8: เกณฑ์การให้คะแนน (Scoring Rubric Definition: ระดับ 1, 2, 3, 4, 5 ครบทุกระดับ) | B8: 1: ต้องวิจัยและสร้างขึ้นเองทั้งหมด 100% (ไม่มีพิมพ์เขียว อัลกอริทึม หรือไลบรารีอ้างอิง) 2: มีชิ้นส่วนหลักในท้องตลาด แต่ต้องดัดแปลงโครงสร้างอย่างหนักและเขียนโค้ดเชื่อมต่อเองทั้งหมด 3: บูรณาการชิ้นส่วน COTS เข้ากับแท่นยึดแบบกำหนดเอง และเขียนโค้ดเชื่อมต่อบางส่วน 4: ประกอบจากโมดูลมาตรฐานสำเร็จรูป (DIN-rail, I2C/CAN shields) มีงานประกอบกลไกเล็กน้อย 5: ซื้อมาติดตั้งใช้งานได้ทันที (Plug-and-Play) ไม่ต้องตัดกลึงหรือบัดกรีวงจรเพิ่มเติม | C8: 1: ล็อกสิทธิ์ภายใต้สัญญา NDA ระบบปิด ติดไฟร์วอลล์องค์กร หรือไม่มีสิทธิ์เข้าถึงฝั่งนักพัฒนา 2: ซอฟต์แวร์หรือเฟิร์มแวร์กรรมสิทธิ์ปิด ทำงานแบบ Black-box โดยไม่มี Source Code หรือ Telemetry 3: บัญชีเพื่อการศึกษา/ทดลองใช้ที่มีโควตาหรือ Rate Limit เข้มงวด ต้องรอการอนุมัติอย่างเป็นทางการ 4: มี SDK หรือ Open API สาธารณะพร้อมเอกสารครบถ้วน แต่ไม่สามารถแก้ไขสถาปัตยกรรมระดับล่างได้ 5: สถาปัตยกรรมเปิดสมบูรณ์ (Open Source/Open HW) ทีมงานมีสิทธิ์ระดับ Root/Admin เต็มรูปแบบ | D8: 1: ระดับแนวคิด/สมการคณิตศาสตร์ (TRL 2–3) ทดสอบเฉพาะในห้องทดลองที่ควบคุมสภาพแวดล้อมได้ 2: เบรดบอร์ดทำงานได้ในแล็บ (TRL 4) สายไฟเปราะบาง ยังไม่ผ่านการสอบเทียบในสภาพแวดล้อมจริง 3: ตัวต้นแบบประกอบลงกล่อง (TRL 5–6) ผ่านการทดสอบในสภาพแวดล้อมจำลอง ต้องมีคนคอยดูแล 4: ต้นแบบระดับพรีโปรดักชัน (TRL 7) ทำงานได้อย่างมีเสถียรภาพในสภาพแวดล้อมปฏิบัติงานจริง 5: ผลิตภัณฑ์เชิงพาณิชย์สมบูรณ์ (TRL 8–9) ผ่านการรับรองมาตรฐาน มีค่า MTBF ยืนยันความทนทาน | E8: 1: พึ่งพาผู้เชี่ยวชาญเพียงคนเดียว (SPOF) หากไม่อยู่ โครงการหยุดชะงัก 100% 2: มีหัวหน้าโครงการ 1 คน และมีผู้ช่วยเข้าใจทฤษฎีแต่แก้โค้ดหรือซ่อมฮาร์ดแวร์แทนไม่ได้ 3: มีคู่หลัก-รอง (Primary + Secondary) สามารถแก้ไขปัญหาและดูแลระบบแทนกันได้ 4: สมาชิกตั้งแต่ 3 คนขึ้นไปสามารถร่วมพัฒนา ประกอบ และแก้ไขปัญหาระบบได้โดยตรง 5: สมาชิกทุกคนในทีมมีความเชี่ยวชาญเต็มรูปแบบ สามารถสลับงานแทนกันได้ทันทีอย่างไร้รอยต่อ | F8: 1: ต้องเริ่มเรียนรู้ใหม่จากศูนย์ 100% ทั้งเครื่องมือ ภาษา และฮาร์ดแวร์ที่ไม่เคยใช้งานมาก่อน 2: มีพื้นฐานทฤษฎีแต่ขาดประสบการณ์จริง การติดตั้งและแก้บั๊กเบื้องต้นใช้เวลานานและติดขัด 3: มีความเชี่ยวชาญในเทคโนโลยีใกล้เคียง สามารถปรับตัวและเรียนรู้เพิ่มเติมได้ภายใน 1 สัปดาห์ 4: คุ้นเคยกับเทคโนโลยีหลักอยู่แล้ว เพียงแค่เรียนรู้ไลบรารีหรือการตั้งค่าเฉพาะเพิ่มเติมเล็กน้อย 5: สามารถดึงโค้ดเก่า วงจรที่เคยทำ และประสบการณ์เดิมมาใช้งานได้ทันทีโดยไม่ต้องเรียนรู้ใหม่ | G8: 1: ระยะเวลาคืนทุนนานมาก (≥ 10 ปี) ต้นทุนเริ่มแรกสูงมากและแทบไม่มีผลประหยัดค่าใช้จ่าย 2: ระยะเวลาคืนทุนช้า (6–9 ปี) ใช้เงินลงทุนสูง ต้องอาศัยเงินอุดหนุนระยะยาวจึงจะคุ้มทุน 3: ระยะเวลาคืนทุนปานกลาง (3–5 ปี) ช่วยประหยัดค่าใช้จ่ายการปฏิบัติการในรอบปีงบประมาณปกติ 4: ระยะเวลาคืนทุนเร็ว (2–3 ปี) ลดค่าใช้จ่ายปฏิบัติการ (ค่าน้ำมัน แรงงาน เครื่องจักร) ได้อย่างมีนัยสำคัญ 5: คืนทุนทันที (≤ 1–2 ปี) ลดความสูญเสียจากน้ำท่วมและตัดรอบการลอกท่อที่ไม่จำเป็นได้ตั้งแต่ปีแรก | H8: 1: ผูกขาดกับระบบปิด 100% ต้องใช้คลาวด์ หัวต่อ หรือเซนเซอร์เฉพาะจากผู้ผลิตรายเดียวเท่านั้น 2: พึ่งพาผู้ผลิตสูง ต้องใช้เครื่องมือตรวจวินิจฉัยเฉพาะหรือเสียค่าธรรมเนียมรายปีเพื่อใช้งาน 3: กึ่งอิสระ ฮาร์ดแวร์หลักเป็นระบบปิดแต่รองรับการส่งออกข้อมูลแบบเปิดและใช้อินเทอร์เฟซมาตรฐาน 4: มีความเป็นอิสระสูง ใช้โปรโตคอลสื่อสารมาตรฐาน (Modbus, MQTT, CAN) หาอะไหล่เทียบได้ง่าย 5: เป็นอิสระสมบูรณ์ 100% ใช้อุปกรณ์มาตรฐานทั่วไป สามารถซ่อมบำรุงและเปลี่ยนอะไหล่ได้เอง | I8: 1: งบประมาณสำรอง 0% (ซื้อชุดเดียวพอดี) หากชิปไหม้หรืออุปกรณ์เสียหาย โครงการจะหยุดชะงักทันที 2: งบประมาณสำรอง 20–30% สำรองได้เฉพาะชิ้นส่วนพาสซีฟราคาถูก ไม่มีอะไหล่สำหรับเซนเซอร์หลัก 3: งบประมาณสำรอง 50% มีชิ้นส่วนพาสซีฟสำรองครบ และมีบอร์ดควบคุมหลักสำรอง 1 ชุด 4: งบประมาณสำรอง 80% มีอะไหล่สำรองเกือบครบทุกชิ้นส่วน รองรับการทดสอบพัง (Burn-in) ได้หลายรอบ 5: มีความพร้อมสำรองสมบูรณ์ (≥ 100%) งบประมาณครอบคลุมการสร้างตัวต้นแบบที่ทำงานได้ 2 ชุดพร้อมกัน | J8: 1: ละเมิดกฎหมายโดยตรง (กีดขวางการจราจรสาธารณะร้ายแรง, ละเมิด PDPA รุนแรง, ส่งคลื่นรบกวนผิดกฎหมาย) 2: สุ่มเสี่ยงทางกฎหมายสูง อาจถูกร้องเรียนเรื่องปิดกั้นการจราจรหรือความปลอดภัย ต้องขอผ่อนผันซับซ้อน 3: มีเงื่อนไขทางกฎหมาย ต้องขออนุญาตเปิดฝาท่อและปิดช่องทางจราจรตามระเบียบของหน่วยงานเทศบาล 4: ผลกระทบทางกฎหมายต่ำ ปฏิบัติตามข้อยกเว้นงานวิศวกรรมสาธารณะทั่วไป ใช้เพียงการแจ้งเตือนความปลอดภัย 5: ได้รับการยกเว้นสมบูรณ์ 100% ไม่กีดขวางการจราจร ไม่เข้าข่ายที่อับอากาศ ไม่มีการเก็บข้อมูลส่วนบุคคล (Zero PII) | K8: 1: ติดสัญญาอนุญาตเชิงพาณิชย์แบบปิด ไม่สามารถคอมไพล์ รัน หรือแจกจ่ายได้หากไม่จ่ายค่าลิขสิทธิ์ราคาแพง 2: สถานะทรัพย์สินทางปัญญาคลุมเครือ ไม่มีสัญญาอนุญาตระบุชัดเจน เสี่ยงต่อการถูกระงับเมื่อเปิดเผยต่อสาธารณะ 3: สัญญาอนุญาตแบบ Copyleft เข้มงวด (เช่น GPLv3) บังคับให้ต้องเปิดเผยโค้ดทั้งหมดหากมีการแจกจ่าย 4: สัญญาอนุญาตแบบผ่อนปรน (เช่น LGPL, CC-BY) ใช้งานและห่อหุ้มซอฟต์แวร์ได้โดยมีเงื่อนไขอ้างอิงแหล่งที่มา 5: โอเพนซอร์สสมบูรณ์ (MIT, Apache 2.0, BSD) หรือ Public Domain ใช้งานและต่อยอดได้อย่างอิสระ 100% | L8: 1: เป็นอันตรายต่อชีวิต (ไฟฟ้าดูด เพลิงไหม้ อุบัติเหตุทางถนน สารพิษ หรือโครงสร้างท่อพังทลาย) 2: ก่อให้เกิดอันตรายทางกายภาพร้ายแรง อุปกรณ์ติดค้างกลายเป็นสิ่งอุดตันท่อ หรือระบบน้ำล้นฉับพลัน 3: เกิดความสับสนในการปฏิบัติงาน อุปกรณ์ขัดข้องต้องใช้เวลาหลายชั่วโมงในการกู้คืนหรือส่งทีมไปช่วย 4: เกิดความล่าช้าเล็กน้อย อุปกรณ์ตัดการทำงานอย่างปลอดภัย สามารถกู้คืนได้ตามขั้นตอนมาตรฐาน 5: ความเสียหายจำกัดเฉพาะงบประมาณ ไม่ส่งผลต่อความปลอดภัยหรือการไหลของน้ำ กู้คืนได้ทันที | M8: 1: ขัดขวางขั้นตอนเดิมอย่างรุนแรง บังคับให้เจ้าหน้าที่ต้องเปลี่ยนวิธีทำงานทั้งหมดและกรอกเอกสารเพิ่มมากมาย 2: มีความฝืดสูง เพิ่มขั้นตอนการทำงานและต้องใช้อุปกรณ์เทอะทะ เจ้าหน้าที่มีแนวโน้มหลีกเลี่ยงการใช้งาน 3: ต้องปรับตัวปานกลาง ปรับเปลี่ยนขั้นตอนประจำวันเล็กน้อย ต้องฝึกอบรม 1–2 ครั้ง แต่ได้ผลลัพธ์คุ้มค่า 4: ความฝืดต่ำ บูรณาการเข้ากับเครื่องมือเดิมได้โดยตรง (ส่งค่าเข้า LINE/Dashboard) ปรับพฤติกรรมน้อยมาก 5: ราบรื่นไร้รอยต่อ 100% ทำงานอัตโนมัติในพื้นหลัง ลดภาระงานเอกสารและการลอกท่อเดิมของเจ้าหน้าที่ | N8: 1: ติดคอขวดขั้นตอนอนุมัติหนัก ห้องแล็บปิด ต้องลงนาม NDA หรือรอจัดซื้ออุปกรณ์หลายสัปดาห์ 2: มีขั้นตอนราชการปานกลาง ต้องส่งแบบฟอร์มจองเครื่องมือล่วงหน้า และรออนุมัติ 3–5 วันทำการ 3: เข้าถึงได้ตามเวลาทำการปกติของมหาวิทยาลัย มีความล่าช้าเล็กน้อยในการเบิกใช้เครื่องมือเฉพาะทาง 4: มีอิสระสูง ทีมงานเข้าแล็บได้ตลอด มีสิทธิ์เขียนโค้ดลงบอร์ด และมีงบประมาณย่อยพร้อมใช้งานทันที 5: พัฒนาได้อย่างอิสระสมบูรณ์ 100% มีระบบ CI/CD บนคลาวด์และพัฒนาชิ้นงานได้เองที่บ้าน/หอพัก | O8: 1: ซับซ้อนมาก มีขั้นตอนคอมไพล์และตั้งค่าหลายสิบขั้นตอน เสี่ยงต่อข้อผิดพลาดสูงมาก 2: ความซับซ้อนสูง ต้องใช้เครื่องมือหลายระดับ มีปัญหาความเข้ากันได้ของไลบรารีและแฟลชบอร์ดได้ยาก 3: ความซับซ้อนปานกลาง มีขั้นตอนประกอบและทดสอบตามคู่มือมาตรฐานที่บันทึกไว้ ทำซ้ำได้ไม่ยาก 4: ความซับซ้อนต่ำ ใช้สคริปต์อัตโนมัติ IDE มาตรฐาน หรือแฟลชเฟิร์มแวร์ด้วยคำสั่งเดียว 5: เรียบง่ายและตรงไปตรงมา เป็นระบบ Plug-and-Play ตั้งค่าขั้นตอนเดียวเสร็จสมบูรณ์ | P8: 1: ระดับแนวคิดเท่านั้น (แบบ 0%) มีเพียงภาพสเก็ตช์ ยังไม่มีโมเดล 3D วงจร หรือเฟิร์มแวร์ใดๆ 2: แบบร่างเบื้องต้น (แบบ 25%) มีบล็อกไดอะแกรม วงจรร่างมือ รายการชิ้นส่วนที่ยังไม่ยืนยัน และกล่อง 3D คร่าวๆ 3: วุฒิภาวะปานกลาง (แบบ 50%) แอสเซมบลี CAD ครบ วาดวงจรเสร็จ และวางโครงสร้างเฟิร์มแวร์แล้ว 4: พร้อมผลิตเบื้องต้น (แบบ 75–80%) ไฟล์ CAD พร้อมพิมพ์ 3D/CNC และไฟล์ PCB Gerber ผ่านการตรวจ DRC 5: แบบสมบูรณ์พร้อมผลิต 100% มีเอกสารสั่งผลิตครบ พิกัดความเผื่อ CAD แน่นอน และสคริปต์แฟลชพร้อมทำงาน | Q8: 1: หลุดจากกรอบ Wedding Cake หรือสร้างผลกระทบเชิงลบอย่างรุนแรงต่อสิ่งแวดล้อมหรือสุขอนามัย 2: สัมผัสเพียง 1 เสาหลักอย่างผิวเผิน ขาดการเชื่อมโยงเชิงประจักษ์ไปยังสังคมหรือสิ่งแวดล้อมจริง 3: ครอบคลุม 1 เสาหลักอย่างเป็นรูปธรรม หรือเริ่มแตะ 2 เสาหลักแบบมีข้อจำกัดเฉพาะจุด 4: บูรณาการ 2 เสาหลักสำคัญอย่างมีนัยสำคัญ (เช่น Biosphere + Society) พร้อมตัวชี้วัดรองรับ 5: บูรณาการครบทั้ง 3 เสาหลักของ Wedding Cake อย่างสมบูรณ์ (Biosphere, Society, Economy) | R8: 1: ก่อให้เกิดอันตรายจากสารพิษ แบตเตอรี่รั่วไหล หรืออุปกรณ์หลุดลอยลงสู่แหล่งน้ำสาธารณะเป็นขยะมลพิษ 2: อายุการใช้งานสั้น เซนเซอร์สึกกร่อนหรือเสียหายภายใน 2–3 สัปดาห์ และยากต่อการเก็บกู้คืน 3: มีขยะอิเล็กทรอนิกส์ตามมาตรฐาน ต้องเปลี่ยนแบตเตอรี่เป็นรอบๆ แต่มีสายโยงป้องกันการสูญหายในท่อ 4: ตัวกล่องทนทาน ใช้พลังงานต่ำ ใช้วัสดุรีไซเคิลได้ และมีสลิงสแตนเลสคู่ป้องกันการหลุดหาย 5: หมุนเวียนสมบูรณ์และไร้รอยเท้าสิ่งแวดล้อม กู้คืนได้ 100% จากผิวดิน ใช้วัสดุไม่เป็นพิษและไม่ทิ้งขยะตกค้าง | S8: เกณฑ์รวม: >=80 ผ่านสูง, >=60 มีเงื่อนไข, <60 เสี่ยงสูง | หากมีข้อใดได้ 1 = VETOED ตกเกณฑ์ทันที
A9: คะแนนที่ได้รับ (ASSIGNED SCORE: 1, 2, 3, 4, 5 STRICT INTEGER) | B9: 2 | C9: 5 | D9: 3 | E9: 3 | F9: 3 | G9: 3 | H9: 4 | I9: 2 | J9: 2 | K9: 5 | L9: 3 | M9: 3 | N9: 3 | O9: 2 | P9: 2 | Q9: 4 | R9: 3 | S9: =IF(S10>0, (S11/S10)*20, 0)
A10: ค่าน้ำหนัก (Weight %) | B10: 0.04 | C10: 0.04 | D10: 0.04 | E10: 0.04 | F10: 0.04 | G10: 0.0667 | H10: 0.0667 | I10: 0.0666 | J10: 0.075 | K10: 0.075 | L10: 0.05 | M10: 0.05 | N10: 0.05 | O10: 0.05 | P10: 0.15 | Q10: 0.05 | R10: 0.05 | S10: =SUM(B10:R10)
A11: คะแนนถ่วงน้ำหนัก (=Score * Weight) | B11: =B9*B10 | C11: =C9*C10 | D11: =D9*D10 | E11: =E9*E10 | F11: =F9*F10 | G11: =G9*G10 | H11: =H9*H10 | I11: =I9*I10 | ... R11: =R9*R10 | S11: =SUM(B11:R11)
A12: คำอธิบาย & หลักฐานอ้างอิงจากไฟล์ Intake (Evidence Citation) | B12: solution-details/solution-1.md lines 32-38; requires custom waterproof IP68 motor pods, sealed differential drivetrain, custom chassis fabrication for wastewater resistance, and tether reel slip-ring integration. | C12: solution-details/solution-1.md lines 33-36; utilizes open-source YOLOv8 architecture, standard RTSP video streaming, open Python/OpenCV stacks, and ESP32/STM32 motor control with full root/developer access. | D12: solution-details/solution-1.md lines 40-49; CCTV pipe crawling is established commercially (TRL 8-9), but custom student crawler with YOLOv8 in murky sewer conditions operates at TRL 5-6 (prototype in simulated pipe). | E12: team-skills/due.md, fifa.md, jk.md, kin.md; Fifa and Due form a primary/secondary mechanical/chassis pair, while JK and Kin form a primary/secondary AI/streaming pair. | F12: team-skills/fifa.md, jk.md; team has proven experience in ROS2, OpenCV, and 3D CAD, but waterproofing dynamic rotary wheel shafts and tuning long tether signal integrity requires a 1-week learning ramp-up. | G12: solution-details/solution-1.md lines 6-7, 43; condition-based visual inspection prevents unneeded jetting of 30-40% clean pipes, delivering moderate 3-5 year payback across municipal sewer maintenance cycles. | H12: solution-details/solution-1.md lines 32-38; uses standard COTS DC gearmotors, standard USB/IP camera modules, generic LED drivers, and open communication protocols. | I12: team-skills/due.md, fifa.md; waterproof crawler chassis, 4K PTZ camera, and high-spec tether cable are relatively costly; budget buffer for spare cameras or fried motor drivers is limited to 20-30%. | J12: solution-details/solution-1.md lines 18, 27; deploying wheeled crawler requires opening street manhole covers and setting up a stationary tether station on public roads, creating traffic blockage risks requiring municipal permits. | K12: solution-details/solution-1.md lines 35-36; YOLOv8 educational license, OpenCV (Apache 2.0), and ROS2 (Apache 2.0) are fully permissive with zero commercial barrier for academic project delivery. | L12: solution-details/solution-1.md lines 46-49; if the crawler flips over, gets entangled on tree roots/sludge, or loses power, the tether cable serves as a mechanical tow-line for recovery, but retrieval stalls operations for several hours. | M12: solution-details/solution-1.md lines 6-7, 27-30; operators must carry crawler and heavy cable reel, wash sewage off robot after deployment, but benefit from direct visual evidence for work verification. | N12: team-skills/due.md, fifa.md; mechanical chassis fabrication requires FIBO workshop 3D printers and water test tank during standard university opening hours. | O12: solution-details/solution-1.md lines 27-38; multi-stage pipeline involves sealed mechanical assembly, waterproof wiring, high-bandwidth video tethering, and deep learning model inference setup. | P12: schedule-details/schedule.md lines 8-15; designing, machining, waterproofing, and debugging an IP68 motorized crawler chassis with tether winch within 5 active business weeks under university exam blackout constraints represents extreme schedule pressure. | Q12: solution-details/solution-1.md lines 6-10; strongly addresses Biosphere (SDG 6.3 preventing sewage backup into urban canals) and Society (SDG 11.5 urban flood resilience and pedestrian road safety). | R12: solution-details/solution-1.md lines 47; physical tether prevents total hardware loss, but sewage moisture, grease, and H2S gas cause rapid wear and electronic corrosion over repeated deployments. | S12: =IF(MIN(B9:R9)=1, "VETOED / ตกเกณฑ์ข้อบังคับวิกฤต (คะแนนระดับ 1)", IF(S9>=80, "ผ่านเกณฑ์ระดับสูง (HIGHLY VIABLE)", IF(S9>=60, "ผ่านแบบมีเงื่อนไข (CONDITIONALLY VIABLE)", "ความเสี่ยงสูง (HIGH RISK)")))
A13: แผนลดขอบเขตงาน & มาตรการลดความเสี่ยง (De-scoping Action) | B13: Purchase a pre-sealed commercial off-the-shelf (COTS) IP68 RC crawler chassis and mount camera modules externally to avoid custom rotary shaft seal fabrication. | C13: Maintain fully open-source pipeline using Ultralytics YOLOv8 and standard ROS2 camera drivers. | D13: Conduct bench testing in a dry simulated 300mm PVC pipe before advancing to damp mock-up drainage channels. | E13: Standardize motor driver pinouts and ROS2 messaging so that Due and JK can cross-debug embedded code seamlessly. | F13: Use off-the-shelf industrial magnetic rotary couplers or pre-sealed brushless underwater thrusters/motors. | G13: Focus reporting on high-priority clogged segments to maximize fuel and labor savings per inspection run. | H13: Avoid proprietary camera protocols; use open standard RTSP/UVC drivers for camera interchangeability. | I13: Use lower-cost 1080p wide-angle camera modules (~800 THB) during initial testing to preserve spare budget. | J13: Deploy strictly on pedestrian sidewalk drainage gutters or campus drainage testbeds to bypass public road traffic permit requirements. | K13: Document all open-source licenses in repository attribution headers. | L13: Integrate a high-tensile steel wire safety core inside the tether cable with a manual emergency hand-winch. | M13: Package the system into a ruggedized portable rolling case with an automated one-button cable reel. | N13: Use standard modular 3D printed PETG enclosures assembled with off-the-shelf silicone O-rings. | O13: Containerize YOLOv8 and streaming server inside a single Docker image with a 1-click startup script. | P13: Adopt a modular COTS chassis baseline immediately in Week 9 to freeze mechanical dimensions before midterm. | Q13: Incorporate automated reporting of plastic debris volume to support circular waste collection metrics. | R13: Conformal coat all internal electronics with silicone/polyurethane moisture barrier to extend hardware lifespan. | S13: ปฏิบัติตามแผนลดขอบเขตงาน (De-scoping Advisory)
A15: ตารางสรุปคะแนนแยกตามมิติ TELOS+S (Pillar Score Breakdown)
A16: มิติการประเมิน (TELOS+S Pillar) | B16: สัดส่วนน้ำหนัก (Weight %) | C16: คะแนนเต็มมิติ (Max Points) | D16: คะแนนที่ได้รับจริง (Earned Points) | E16: คะแนนเฉลี่ย (Score 1-5) | F16: ระดับความพร้อม (Readiness Level)
A17: T : ด้านเทคโนโลยีและวิศวกรรม (Technical) | B17: 0.2 | C17: 20 | D17: =SUM(B11:F11)*20 | E17: =IF(C17>0, (D17/C17)*5, 0) | F17: =IF(D17>=16.0, "พร้อมระดับสูง (High)", IF(D17>=12.0, "ปานกลาง (Medium)", "เสี่ยงวิกฤต (Critical)"))
A18: E : ด้านเศรษฐศาสตร์และความคุ้มค่า (Economic) | B18: 0.2 | C18: 20 | D18: =SUM(G11:I11)*20 | E18: =IF(C18>0, (D18/C18)*5, 0) | F18: =IF(D18>=16.0, "พร้อมระดับสูง (High)", IF(D18>=12.0, "ปานกลาง (Medium)", "เสี่ยงวิกฤต (Critical)"))
A19: L : ด้านกฎหมาย ระเบียบ และภาคประชาชน (Legal & Outreach) | B19: 0.15 | C19: 15 | D19: =SUM(J11:K11)*20 | E19: =IF(C19>0, (D19/C19)*5, 0) | F19: =IF(D19>=12.0, "พร้อมระดับสูง (High)", IF(D19>=9.0, "ปานกลาง (Medium)", "เสี่ยงวิกฤต (Critical)"))
A20: O : ด้านการปฏิบัติการและหน้างาน (Operational) | B20: 0.2 | C20: 20 | D20: =SUM(L11:O11)*20 | E20: =IF(C20>0, (D20/C20)*5, 0) | F20: =IF(D20>=16.0, "พร้อมระดับสูง (High)", IF(D20>=12.0, "ปานกลาง (Medium)", "เสี่ยงวิกฤต (Critical)"))
A21: S : ด้านแผนงานและเวลาส่งมอบ (Schedule) | B21: 0.15 | C21: 15 | D21: =P11*20 | E21: =IF(C21>0, (D21/C21)*5, 0) | F21: =IF(D21>=12.0, "พร้อมระดับสูง (High)", IF(D21>=9.0, "ปานกลาง (Medium)", "เสี่ยงวิกฤต (Critical)"))
A22: +S : ด้านความยั่งยืนและสิ่งแวดล้อม (Sustainability / SDG) | B22: 0.1 | C22: 10 | D22: =SUM(Q11:R11)*20 | E22: =IF(C22>0, (D22/C22)*5, 0) | F22: =IF(D22>=8.0, "พร้อมระดับสูง (High)", IF(D22>=6.0, "ปานกลาง (Medium)", "เสี่ยงวิกฤต (Critical)"))
A23: คะแนนรวมทุกมิติ (Total Feasibility Score) | B23: =SUM(B17:B22) | C23: =SUM(C17:C22) | D23: =SUM(D17:D22) | E23: =IF(C23>0, (D23/C23)*5, 0) | F23: =IF(D23>=80, "ผ่านเกณฑ์ระดับสูง (HIGHLY VIABLE)", IF(D23>=60, "ผ่านแบบมีเงื่อนไข (CONDITIONALLY VIABLE)", "ความเสี่ยงสูง (HIGH RISK)"))
A25: เมทริกซ์ประเมินความเข้ากันได้กับองค์ความรู้ด้านวิศวกรรมหุ่นยนต์ (Robotics Knowledge Compatibility)
A26: * หมายเหตุ: การประเมินส่วนนี้วัดศักยภาพในการประยุกต์ใช้องค์ความรู้ด้านวิศวกรรมหุ่นยนต์ (Perception, Control, Actuation) เต็ม 12 คะแนน (แกนละ 4 คะแนน) | เป็นเอกเทศ ไม่นับรวมในคะแนน TELOS 100 คะแนน
A27: มิติการประเมิน (Robotics Dimension) | B27: คะแนนศักยภาพ (/12) | C27: แกน Perception & Sensing (การรับรู้) | D27: แกน Control & Algorithms (การควบคุม) | E27: แกน Actuation & Mechanisms (กลไก) | F27: บทวิเคราะห์เชิงวิศวกรรมหุ่นยนต์ (FIBO Alignment Rationale)
A28: ศักยภาพการประยุกต์ใช้องค์ความรู้หุ่นยนต์และระบบอัตโนมัติ | B28: 10.5 | C28: Score 3.5/4.0: 4K PTZ Optical Camera with High-Power LED array and wheel distance encoders; captures visual defect features under active illumination. | D28: Score 3.5/4.0: Edge AI YOLOv8 deep learning object detection for real-time crack/blockage classification and spatial defect map indexing. | E28: Score 3.5/4.0: Multi-wheel motorized crawler platform traversing hazardous underground pipe geometry with differential steering and tether management. | F28: Solution 1 implements a genuine closed-loop mobile robotic system across all three FIBO pillars: active high-resolution optical perception, edge neural network defect inferencing, and mobile robotic pipe locomotion, utilizing mechatronics and control skills directly.

Sheet Solution_2_Acoustic_Reflecto
A1: เมทริกซ์ประเมินความเป็นไปได้เชิงระบบ TELOS+S: Pipe Inspection Instrument using Acoustic Reflectometry (Airborne Acoustic Inversion + SL-RAT EPA USA Cleanliness Scale)
A2: ระบบคะแนนจำนวนเต็มเด็ดขาด: 1, 2, 3, 4, 5 เท่านั้น (ไม่มีจุดทศนิยม / ไม่มี 0.5) | โครงสร้างแบบ Transposed แนวนอน
A4: รหัสคำถาม (Question Code) | B4: T-01 | C4: T-02 | D4: T-03 | E4: T-04 | F4: T-05 | G4: E-01 | H4: E-02 | I4: E-03 | J4: L-01 | K4: L-02 | L4: O-01 | M4: O-02 | N4: O-03 | O4: O-04 | P4: S-01 | Q4: SDG-01 | R4: SDG-02 | S4: สรุปภาพรวม (SUMMARY)
A5: มิติการประเมิน (TELOS+S Pillar) | B5: ด้านเทคนิค (Technical 2.2) | C5: ด้านเทคนิค (Technical 2.2) | D5: ด้านเทคนิค (Technical 2.2) | E5: ด้านเทคนิค (Technical 2.2) | F5: ด้านเทคนิค (Technical 2.2) | G5: ด้านเศรษฐศาสตร์ (Economic 2.3) | H5: ด้านเศรษฐศาสตร์ (Economic 2.3) | I5: ด้านเศรษฐศาสตร์ (Economic 2.3) | J5: ด้านกฎหมายและสถาบัน (Legal 2.4) | K5: ด้านกฎหมายและสถาบัน (Legal 2.4) | L5: ด้านการปฏิบัติการ (Operational 2.5) | M5: ด้านการปฏิบัติการ (Operational 2.5) | N5: ด้านการปฏิบัติการ (Operational 2.5) | O5: ด้านการปฏิบัติการ (Operational 2.5) | P5: ด้านแผนงานและเวลา (Schedule 2.6) | Q5: ด้านความยั่งยืน (SDGs Feasibility 2.7) | R5: ด้านความยั่งยืน (SDGs Feasibility 2.7) | S5: ผลรวมทุกมิติ (All Pillars)
A6: คำถามทดสอบความเสี่ยงจริง (Stress-Test Question) | B6: ระดับการสร้างเองเทียบกับการซื้อสำเร็จรูป (Build vs. Buy Burden) ของสถาปัตยกรรมระบบตรวจประเมินท่อระบายน้ำ? | C6: สิทธิ์ในการเข้าถึงเทคโนโลยี ซอฟต์แวร์ และระบบนิเวศข้อมูล (Access & Permissions) ของระบบตรวจประเมินท่อ? | D6: ระดับความพร้อมทางเทคโนโลยี (Base Performance / TRL) ในสภาพแวดล้อมจริงของท่อระบายน้ำใต้ดิน? | E6: ความพร้อมและกำลังคนสำรองของทีมงาน (Team Compatibility & Redundancy / Anti-SPOF)? | F6: ความชันในการเรียนรู้และเวลาปรับตัวของทีมงาน (Learning Curve & Ramp-up Time)? | G6: ระยะเวลาคืนทุนและความคุ้มค่าในการลงทุน (ROI / Payback Period) เทียบกับการขุดลอกแบบสุ่ม? | H6: การพึ่งพาผู้จำหน่ายและการผูกขาดชิ้นส่วนเฉพาะ (Component Dependency & Vendor Lock-in)? | I6: วงเงินงบประมาณสำรองความเสียหายและการทำซ้ำ (Scrap Margin & Iteration Allowance)? | J6: การปฏิบัติตามกฎหมายจราจร ความปลอดภัยในที่อับอากาศ และระเบียบพื้นที่สาธารณะ (Felony, Traffic & Confined Space Compliance)? | K6: การปฏิบัติตามสัญญาอนุญาต ทรัพย์สินทางปัญญา และโอเพนซอร์ส (IP & Software Licensing Compliance)? | L6: ผลกระทบและความรุนแรงเมื่อระบบเกิดความขัดข้องหรือติดค้าง (User — Failure Impact & Stuck Hazards)? | M6: ความสอดคล้องกับพฤติกรรมเจ้าหน้าที่และขั้นตอนการทำงานเดิม (User — Workflow Friction & Adoption)? | N6: การพึ่งพาห้องปฏิบัติการและขั้นตอนการขออนุมัติของนักพัฒนา (Developer — Lab & Administrative Gatekeeping)? | O6: ความซับซ้อนของขั้นตอนการประกอบ ติดตั้ง และโปรแกรม (Developer — Setup Steps & Pipeline Friction)? | P6: วุฒิภาวะของการออกแบบทางวิศวกรรมภายในกรอบเวลา 5 สัปดาห์ทำงาน (Engineering Design Maturity by 5 Weeks)? | Q6: การบูรณาการตามกรอบ Stockholm Wedding Cake (Biosphere, Society, Economy Integration)? | R6: ผลกระทบสิ่งแวดล้อม ขยะอิเล็กทรอนิกส์ และหลักเศรษฐกิจหมุนเวียน (E-Waste & 'Do No Harm' — SDG 6.3/12.4)? | S6: ประเมินคำถามทั้งสิ้น 17 ข้อ
A7: เหตุผลในการถาม & โหมดความล้มเหลวที่เฝ้าระวัง (Rationale) | B7: ประเมินภาระการวิจัยและพัฒนาชิ้นส่วนกลไก อิเล็กทรอนิกส์ และอัลกอริทึม ป้องกันการเสียเวลากับงานประดิษฐ์ขึ้นใหม่โดยไม่จำเป็น | C7: ตรวจสอบข้อจำกัดด้านกรรมสิทธิ์ การล็อกสิทธิ์ใช้งาน และการอนุญาตเข้าถึง เพื่อป้องกันการพัฒนาระบบบนฐานข้อมูลที่ไม่สามารถเข้าถึงได้จริง | D7: วัดวุฒิภาวะของเทคโนโลยีว่าผ่านการพิสูจน์ในสภาพแวดล้อมใต้ดินที่มีความชื้น สารกัดกร่อน หรือน้ำขังจริงแล้วหรือไม่ | E7: ตรวจสอบความเสี่ยงคอขวดบุคลากร (Single Point of Failure) ป้องกันไม่ให้โครงการหยุดชะงักหากผู้รับผิดชอบหลักไม่ว่าง | F7: ประเมินเวลาที่ทีมต้องใช้ในการเรียนรู้เครื่องมือหรือทฤษฎีใหม่ เพื่อไม่ให้กระทบต่อกำหนดการส่งมอบ 5 สัปดาห์ | G7: วัดความคุ้มค่าทางการเงินและการประหยัดงบประมาณการลอกท่อของหน่วยงานภาครัฐเทียบกับ Baseline เดิม | H7: ตรวจสอบความเสี่ยงจากการพึ่งพาผู้ขายรายเดียว การผูกขาดชิ้นส่วนนำเข้า หรือค่าลิขสิทธิ์ซอฟต์แวร์รายปี | I7: ประเมินขีดความสามารถในการรับมือกับความเสียหายของอุปกรณ์และชิปที่อาจช็อตหรือเสียหายระหว่างการพัฒนา | J7: ตรวจสอบความเสี่ยงต่อการละเมิดกฎหมายจราจร กฎหมายความปลอดภัยในที่อับอากาศ และการปิดกั้นทางสัญจร | K7: ตรวจสอบสิทธิ์การใช้งานซอฟต์แวร์ ไลบรารี และสิทธิบัตร ป้องกันการฟ้องร้องละเมิดลิขสิทธิ์ | L7: ประเมินความเสียหายต่อโครงสร้างพื้นฐาน ความปลอดภัยของเจ้าหน้าที่ และการกลายเป็นสิ่งกีดขวางในท่อระบายน้ำ | M7: ประเมินภาระการฝึกอบรม ความสะดวกในการพกพา และแรงต้านจากเจ้าหน้าที่ภาคสนามของ กทม. | N7: ประเมินอุปสรรคการเข้าถึงเครื่องมือ ช็อปเครื่องกล หรือการต้องรอคิวอนุมัติเอกสารของมหาวิทยาลัย | O7: ประเมินจำนวนขั้นตอนและความเปราะบางของเครื่องมือพัฒนา ป้องกันข้อผิดพลาดจากการตั้งค่าระบบที่ซับซ้อนเกินไป | P7: ทดสอบความเป็นไปได้ในการสร้างชิ้นงานให้สำเร็จตามเป้าหมาย TRL โดยหักสัปดาห์สอบมิดเทอมและไฟนอลออกแล้ว | Q7: ประเมินผลกระทบเชิงบวกที่ครอบคลุมทั้งด้านชีวมณฑล (SDG 6/14), สังคม (SDG 11) และเศรษฐกิจ (SDG 8/12) | R7: ตรวจสอบการป้องกันขยะอิเล็กทรอนิกส์ตกค้างในท่อระบายน้ำ สารพิษรั่วไหล และระบบกู้คืนอุปกรณ์ที่ปลอดภัย 100% | S7: สังเคราะห์จาก AI Agents Group 2
A8: เกณฑ์การให้คะแนน (Scoring Rubric Definition: ระดับ 1, 2, 3, 4, 5 ครบทุกระดับ) | B8: 1: ต้องวิจัยและสร้างขึ้นเองทั้งหมด 100% (ไม่มีพิมพ์เขียว อัลกอริทึม หรือไลบรารีอ้างอิง) 2: มีชิ้นส่วนหลักในท้องตลาด แต่ต้องดัดแปลงโครงสร้างอย่างหนักและเขียนโค้ดเชื่อมต่อเองทั้งหมด 3: บูรณาการชิ้นส่วน COTS เข้ากับแท่นยึดแบบกำหนดเอง และเขียนโค้ดเชื่อมต่อบางส่วน 4: ประกอบจากโมดูลมาตรฐานสำเร็จรูป (DIN-rail, I2C/CAN shields) มีงานประกอบกลไกเล็กน้อย 5: ซื้อมาติดตั้งใช้งานได้ทันที (Plug-and-Play) ไม่ต้องตัดกลึงหรือบัดกรีวงจรเพิ่มเติม | C8: 1: ล็อกสิทธิ์ภายใต้สัญญา NDA ระบบปิด ติดไฟร์วอลล์องค์กร หรือไม่มีสิทธิ์เข้าถึงฝั่งนักพัฒนา 2: ซอฟต์แวร์หรือเฟิร์มแวร์กรรมสิทธิ์ปิด ทำงานแบบ Black-box โดยไม่มี Source Code หรือ Telemetry 3: บัญชีเพื่อการศึกษา/ทดลองใช้ที่มีโควตาหรือ Rate Limit เข้มงวด ต้องรอการอนุมัติอย่างเป็นทางการ 4: มี SDK หรือ Open API สาธารณะพร้อมเอกสารครบถ้วน แต่ไม่สามารถแก้ไขสถาปัตยกรรมระดับล่างได้ 5: สถาปัตยกรรมเปิดสมบูรณ์ (Open Source/Open HW) ทีมงานมีสิทธิ์ระดับ Root/Admin เต็มรูปแบบ | D8: 1: ระดับแนวคิด/สมการคณิตศาสตร์ (TRL 2–3) ทดสอบเฉพาะในห้องทดลองที่ควบคุมสภาพแวดล้อมได้ 2: เบรดบอร์ดทำงานได้ในแล็บ (TRL 4) สายไฟเปราะบาง ยังไม่ผ่านการสอบเทียบในสภาพแวดล้อมจริง 3: ตัวต้นแบบประกอบลงกล่อง (TRL 5–6) ผ่านการทดสอบในสภาพแวดล้อมจำลอง ต้องมีคนคอยดูแล 4: ต้นแบบระดับพรีโปรดักชัน (TRL 7) ทำงานได้อย่างมีเสถียรภาพในสภาพแวดล้อมปฏิบัติงานจริง 5: ผลิตภัณฑ์เชิงพาณิชย์สมบูรณ์ (TRL 8–9) ผ่านการรับรองมาตรฐาน มีค่า MTBF ยืนยันความทนทาน | E8: 1: พึ่งพาผู้เชี่ยวชาญเพียงคนเดียว (SPOF) หากไม่อยู่ โครงการหยุดชะงัก 100% 2: มีหัวหน้าโครงการ 1 คน และมีผู้ช่วยเข้าใจทฤษฎีแต่แก้โค้ดหรือซ่อมฮาร์ดแวร์แทนไม่ได้ 3: มีคู่หลัก-รอง (Primary + Secondary) สามารถแก้ไขปัญหาและดูแลระบบแทนกันได้ 4: สมาชิกตั้งแต่ 3 คนขึ้นไปสามารถร่วมพัฒนา ประกอบ และแก้ไขปัญหาระบบได้โดยตรง 5: สมาชิกทุกคนในทีมมีความเชี่ยวชาญเต็มรูปแบบ สามารถสลับงานแทนกันได้ทันทีอย่างไร้รอยต่อ | F8: 1: ต้องเริ่มเรียนรู้ใหม่จากศูนย์ 100% ทั้งเครื่องมือ ภาษา และฮาร์ดแวร์ที่ไม่เคยใช้งานมาก่อน 2: มีพื้นฐานทฤษฎีแต่ขาดประสบการณ์จริง การติดตั้งและแก้บั๊กเบื้องต้นใช้เวลานานและติดขัด 3: มีความเชี่ยวชาญในเทคโนโลยีใกล้เคียง สามารถปรับตัวและเรียนรู้เพิ่มเติมได้ภายใน 1 สัปดาห์ 4: คุ้นเคยกับเทคโนโลยีหลักอยู่แล้ว เพียงแค่เรียนรู้ไลบรารีหรือการตั้งค่าเฉพาะเพิ่มเติมเล็กน้อย 5: สามารถดึงโค้ดเก่า วงจรที่เคยทำ และประสบการณ์เดิมมาใช้งานได้ทันทีโดยไม่ต้องเรียนรู้ใหม่ | G8: 1: ระยะเวลาคืนทุนนานมาก (≥ 10 ปี) ต้นทุนเริ่มแรกสูงมากและแทบไม่มีผลประหยัดค่าใช้จ่าย 2: ระยะเวลาคืนทุนช้า (6–9 ปี) ใช้เงินลงทุนสูง ต้องอาศัยเงินอุดหนุนระยะยาวจึงจะคุ้มทุน 3: ระยะเวลาคืนทุนปานกลาง (3–5 ปี) ช่วยประหยัดค่าใช้จ่ายการปฏิบัติการในรอบปีงบประมาณปกติ 4: ระยะเวลาคืนทุนเร็ว (2–3 ปี) ลดค่าใช้จ่ายปฏิบัติการ (ค่าน้ำมัน แรงงาน เครื่องจักร) ได้อย่างมีนัยสำคัญ 5: คืนทุนทันที (≤ 1–2 ปี) ลดความสูญเสียจากน้ำท่วมและตัดรอบการลอกท่อที่ไม่จำเป็นได้ตั้งแต่ปีแรก | H8: 1: ผูกขาดกับระบบปิด 100% ต้องใช้คลาวด์ หัวต่อ หรือเซนเซอร์เฉพาะจากผู้ผลิตรายเดียวเท่านั้น 2: พึ่งพาผู้ผลิตสูง ต้องใช้เครื่องมือตรวจวินิจฉัยเฉพาะหรือเสียค่าธรรมเนียมรายปีเพื่อใช้งาน 3: กึ่งอิสระ ฮาร์ดแวร์หลักเป็นระบบปิดแต่รองรับการส่งออกข้อมูลแบบเปิดและใช้อินเทอร์เฟซมาตรฐาน 4: มีความเป็นอิสระสูง ใช้โปรโตคอลสื่อสารมาตรฐาน (Modbus, MQTT, CAN) หาอะไหล่เทียบได้ง่าย 5: เป็นอิสระสมบูรณ์ 100% ใช้อุปกรณ์มาตรฐานทั่วไป สามารถซ่อมบำรุงและเปลี่ยนอะไหล่ได้เอง | I8: 1: งบประมาณสำรอง 0% (ซื้อชุดเดียวพอดี) หากชิปไหม้หรืออุปกรณ์เสียหาย โครงการจะหยุดชะงักทันที 2: งบประมาณสำรอง 20–30% สำรองได้เฉพาะชิ้นส่วนพาสซีฟราคาถูก ไม่มีอะไหล่สำหรับเซนเซอร์หลัก 3: งบประมาณสำรอง 50% มีชิ้นส่วนพาสซีฟสำรองครบ และมีบอร์ดควบคุมหลักสำรอง 1 ชุด 4: งบประมาณสำรอง 80% มีอะไหล่สำรองเกือบครบทุกชิ้นส่วน รองรับการทดสอบพัง (Burn-in) ได้หลายรอบ 5: มีความพร้อมสำรองสมบูรณ์ (≥ 100%) งบประมาณครอบคลุมการสร้างตัวต้นแบบที่ทำงานได้ 2 ชุดพร้อมกัน | J8: 1: ละเมิดกฎหมายโดยตรง (กีดขวางการจราจรสาธารณะร้ายแรง, ละเมิด PDPA รุนแรง, ส่งคลื่นรบกวนผิดกฎหมาย) 2: สุ่มเสี่ยงทางกฎหมายสูง อาจถูกร้องเรียนเรื่องปิดกั้นการจราจรหรือความปลอดภัย ต้องขอผ่อนผันซับซ้อน 3: มีเงื่อนไขทางกฎหมาย ต้องขออนุญาตเปิดฝาท่อและปิดช่องทางจราจรตามระเบียบของหน่วยงานเทศบาล 4: ผลกระทบทางกฎหมายต่ำ ปฏิบัติตามข้อยกเว้นงานวิศวกรรมสาธารณะทั่วไป ใช้เพียงการแจ้งเตือนความปลอดภัย 5: ได้รับการยกเว้นสมบูรณ์ 100% ไม่กีดขวางการจราจร ไม่เข้าข่ายที่อับอากาศ ไม่มีการเก็บข้อมูลส่วนบุคคล (Zero PII) | K8: 1: ติดสัญญาอนุญาตเชิงพาณิชย์แบบปิด ไม่สามารถคอมไพล์ รัน หรือแจกจ่ายได้หากไม่จ่ายค่าลิขสิทธิ์ราคาแพง 2: สถานะทรัพย์สินทางปัญญาคลุมเครือ ไม่มีสัญญาอนุญาตระบุชัดเจน เสี่ยงต่อการถูกระงับเมื่อเปิดเผยต่อสาธารณะ 3: สัญญาอนุญาตแบบ Copyleft เข้มงวด (เช่น GPLv3) บังคับให้ต้องเปิดเผยโค้ดทั้งหมดหากมีการแจกจ่าย 4: สัญญาอนุญาตแบบผ่อนปรน (เช่น LGPL, CC-BY) ใช้งานและห่อหุ้มซอฟต์แวร์ได้โดยมีเงื่อนไขอ้างอิงแหล่งที่มา 5: โอเพนซอร์สสมบูรณ์ (MIT, Apache 2.0, BSD) หรือ Public Domain ใช้งานและต่อยอดได้อย่างอิสระ 100% | L8: 1: เป็นอันตรายต่อชีวิต (ไฟฟ้าดูด เพลิงไหม้ อุบัติเหตุทางถนน สารพิษ หรือโครงสร้างท่อพังทลาย) 2: ก่อให้เกิดอันตรายทางกายภาพร้ายแรง อุปกรณ์ติดค้างกลายเป็นสิ่งอุดตันท่อ หรือระบบน้ำล้นฉับพลัน 3: เกิดความสับสนในการปฏิบัติงาน อุปกรณ์ขัดข้องต้องใช้เวลาหลายชั่วโมงในการกู้คืนหรือส่งทีมไปช่วย 4: เกิดความล่าช้าเล็กน้อย อุปกรณ์ตัดการทำงานอย่างปลอดภัย สามารถกู้คืนได้ตามขั้นตอนมาตรฐาน 5: ความเสียหายจำกัดเฉพาะงบประมาณ ไม่ส่งผลต่อความปลอดภัยหรือการไหลของน้ำ กู้คืนได้ทันที | M8: 1: ขัดขวางขั้นตอนเดิมอย่างรุนแรง บังคับให้เจ้าหน้าที่ต้องเปลี่ยนวิธีทำงานทั้งหมดและกรอกเอกสารเพิ่มมากมาย 2: มีความฝืดสูง เพิ่มขั้นตอนการทำงานและต้องใช้อุปกรณ์เทอะทะ เจ้าหน้าที่มีแนวโน้มหลีกเลี่ยงการใช้งาน 3: ต้องปรับตัวปานกลาง ปรับเปลี่ยนขั้นตอนประจำวันเล็กน้อย ต้องฝึกอบรม 1–2 ครั้ง แต่ได้ผลลัพธ์คุ้มค่า 4: ความฝืดต่ำ บูรณาการเข้ากับเครื่องมือเดิมได้โดยตรง (ส่งค่าเข้า LINE/Dashboard) ปรับพฤติกรรมน้อยมาก 5: ราบรื่นไร้รอยต่อ 100% ทำงานอัตโนมัติในพื้นหลัง ลดภาระงานเอกสารและการลอกท่อเดิมของเจ้าหน้าที่ | N8: 1: ติดคอขวดขั้นตอนอนุมัติหนัก ห้องแล็บปิด ต้องลงนาม NDA หรือรอจัดซื้ออุปกรณ์หลายสัปดาห์ 2: มีขั้นตอนราชการปานกลาง ต้องส่งแบบฟอร์มจองเครื่องมือล่วงหน้า และรออนุมัติ 3–5 วันทำการ 3: เข้าถึงได้ตามเวลาทำการปกติของมหาวิทยาลัย มีความล่าช้าเล็กน้อยในการเบิกใช้เครื่องมือเฉพาะทาง 4: มีอิสระสูง ทีมงานเข้าแล็บได้ตลอด มีสิทธิ์เขียนโค้ดลงบอร์ด และมีงบประมาณย่อยพร้อมใช้งานทันที 5: พัฒนาได้อย่างอิสระสมบูรณ์ 100% มีระบบ CI/CD บนคลาวด์และพัฒนาชิ้นงานได้เองที่บ้าน/หอพัก | O8: 1: ซับซ้อนมาก มีขั้นตอนคอมไพล์และตั้งค่าหลายสิบขั้นตอน เสี่ยงต่อข้อผิดพลาดสูงมาก 2: ความซับซ้อนสูง ต้องใช้เครื่องมือหลายระดับ มีปัญหาความเข้ากันได้ของไลบรารีและแฟลชบอร์ดได้ยาก 3: ความซับซ้อนปานกลาง มีขั้นตอนประกอบและทดสอบตามคู่มือมาตรฐานที่บันทึกไว้ ทำซ้ำได้ไม่ยาก 4: ความซับซ้อนต่ำ ใช้สคริปต์อัตโนมัติ IDE มาตรฐาน หรือแฟลชเฟิร์มแวร์ด้วยคำสั่งเดียว 5: เรียบง่ายและตรงไปตรงมา เป็นระบบ Plug-and-Play ตั้งค่าขั้นตอนเดียวเสร็จสมบูรณ์ | P8: 1: ระดับแนวคิดเท่านั้น (แบบ 0%) มีเพียงภาพสเก็ตช์ ยังไม่มีโมเดล 3D วงจร หรือเฟิร์มแวร์ใดๆ 2: แบบร่างเบื้องต้น (แบบ 25%) มีบล็อกไดอะแกรม วงจรร่างมือ รายการชิ้นส่วนที่ยังไม่ยืนยัน และกล่อง 3D คร่าวๆ 3: วุฒิภาวะปานกลาง (แบบ 50%) แอสเซมบลี CAD ครบ วาดวงจรเสร็จ และวางโครงสร้างเฟิร์มแวร์แล้ว 4: พร้อมผลิตเบื้องต้น (แบบ 75–80%) ไฟล์ CAD พร้อมพิมพ์ 3D/CNC และไฟล์ PCB Gerber ผ่านการตรวจ DRC 5: แบบสมบูรณ์พร้อมผลิต 100% มีเอกสารสั่งผลิตครบ พิกัดความเผื่อ CAD แน่นอน และสคริปต์แฟลชพร้อมทำงาน | Q8: 1: หลุดจากกรอบ Wedding Cake หรือสร้างผลกระทบเชิงลบอย่างรุนแรงต่อสิ่งแวดล้อมหรือสุขอนามัย 2: สัมผัสเพียง 1 เสาหลักอย่างผิวเผิน ขาดการเชื่อมโยงเชิงประจักษ์ไปยังสังคมหรือสิ่งแวดล้อมจริง 3: ครอบคลุม 1 เสาหลักอย่างเป็นรูปธรรม หรือเริ่มแตะ 2 เสาหลักแบบมีข้อจำกัดเฉพาะจุด 4: บูรณาการ 2 เสาหลักสำคัญอย่างมีนัยสำคัญ (เช่น Biosphere + Society) พร้อมตัวชี้วัดรองรับ 5: บูรณาการครบทั้ง 3 เสาหลักของ Wedding Cake อย่างสมบูรณ์ (Biosphere, Society, Economy) | R8: 1: ก่อให้เกิดอันตรายจากสารพิษ แบตเตอรี่รั่วไหล หรืออุปกรณ์หลุดลอยลงสู่แหล่งน้ำสาธารณะเป็นขยะมลพิษ 2: อายุการใช้งานสั้น เซนเซอร์สึกกร่อนหรือเสียหายภายใน 2–3 สัปดาห์ และยากต่อการเก็บกู้คืน 3: มีขยะอิเล็กทรอนิกส์ตามมาตรฐาน ต้องเปลี่ยนแบตเตอรี่เป็นรอบๆ แต่มีสายโยงป้องกันการสูญหายในท่อ 4: ตัวกล่องทนทาน ใช้พลังงานต่ำ ใช้วัสดุรีไซเคิลได้ และมีสลิงสแตนเลสคู่ป้องกันการหลุดหาย 5: หมุนเวียนสมบูรณ์และไร้รอยเท้าสิ่งแวดล้อม กู้คืนได้ 100% จากผิวดิน ใช้วัสดุไม่เป็นพิษและไม่ทิ้งขยะตกค้าง | S8: เกณฑ์รวม: >=80 ผ่านสูง, >=60 มีเงื่อนไข, <60 เสี่ยงสูง | หากมีข้อใดได้ 1 = VETOED ตกเกณฑ์ทันที
A9: คะแนนที่ได้รับ (ASSIGNED SCORE: 1, 2, 3, 4, 5 STRICT INTEGER) | B9: 3 | C9: 5 | D9: 4 | E9: 4 | F9: 4 | G9: 5 | H9: 5 | I9: 4 | J9: 3 | K9: 5 | L9: 5 | M9: 4 | N9: 5 | O9: 4 | P9: 4 | Q9: 5 | R9: 5 | S9: =IF(S10>0, (S11/S10)*20, 0)
A10: ค่าน้ำหนัก (Weight %) | B10: 0.04 | C10: 0.04 | D10: 0.04 | E10: 0.04 | F10: 0.04 | G10: 0.0667 | H10: 0.0667 | I10: 0.0666 | J10: 0.075 | K10: 0.075 | L10: 0.05 | M10: 0.05 | N10: 0.05 | O10: 0.05 | P10: 0.15 | Q10: 0.05 | R10: 0.05 | S10: =SUM(B10:R10)
A11: คะแนนถ่วงน้ำหนัก (=Score * Weight) | B11: =B9*B10 | C11: =C9*C10 | D11: =D9*D10 | E11: =E9*E10 | F11: =F9*F10 | G11: =G9*G10 | H11: =H9*H10 | I11: =I9*I10 | ... R11: =R9*R10 | S11: =SUM(B11:R11)
A12: คำอธิบาย & หลักฐานอ้างอิงจากไฟล์ Intake (Evidence Citation) | B12: solution-details/solution-2.md lines 33-36; combines standard COTS compression driver horn, precision condenser mic, MAX98357 I2S audio amp, and ESP32 with 3D printed manhole acoustic baffles. | C12: solution-details/solution-2.md lines 27-36; open-source audio DSP algorithms, public EPA SL-RAT mathematical standards, standard Python/SciPy signal processing libraries, and full root developer control on ESP32/STM32. | D12: solution-details/solution-2.md lines 31, 38-40; Acoustic inspection (SL-RAT) is an EPA-verified commercial standard (TRL 7-8) worldwide, operating stably in active sewer airspace under real-world municipal conditions. | E12: team-skills/due.md, jk.md, kin.md; Due has verified hardware experience building MAX98357 audio amp & ESP32 circuits; JK handles DSP math & Fourier analysis; Kin handles data ingestion & scoring backend. | F12: team-skills/due.md, jk.md; team has built audio amplifiers and implemented DSP bandpass filtering in previous projects; ramp-up only requires configuring I2S audio sampling and attenuation lookup tables. | G12: solution-details/solution-2.md lines 6-7, 38; 2-person crew can inspect 2–3 km of sewer network per day in under 3 minutes per segment; eliminates >50% of redundant jetting operations, breaking even in <= 1 year. | H12: solution-details/solution-2.md lines 33-36; 100% generic electronic and acoustic components (compression driver speaker, condenser mic, ESP32); self-serviceable by any engineer with zero proprietary vendor lock-in. | I12: team-skills/due.md; total hardware BOM for audio driver, mic capsule, amplifier, and ESP32 is very low (< 3,000 THB total), allowing the team to purchase 3x full sets of backup components comfortably. | J12: solution-details/solution-2.md lines 27-29; requires opening manhole covers for 3 minutes from sidewalk/road edge; rapid turnaround substantially lowers traffic impact compared to rovers, but requires standard municipal maintenance protocol. | K12: solution-details/solution-2.md lines 31, 34-36; EPA SL-RAT acoustic inspection methodology and mathematical attenuation formulations are in the public domain and widely published in academic literature; open-source SciPy algorithms. | L12: solution-details/solution-2.md lines 27-29, 39; system operates strictly from the surface above the wastewater line; if battery dies or audio fails, the operator simply pulls up the pole; zero risk of blocking pipe. | M12: solution-details/solution-2.md lines 27-31; lightweight handheld poles take < 3 minutes per manhole pair, outputting a clear 0–10 score that directly slots into existing municipal maintenance dispatch logs. | N12: team-skills/due.md, jk.md; audio circuitry and DSP code development can be tested entirely on dorm/lab bench using PVC pipe sections with zero machine shop gatekeeping. | O12: solution-details/solution-2.md lines 27-36; straightforward transmitter-receiver setup with standard ESP32 Arduino/PlatformIO toolchain and automated signal analysis script. | P12: schedule-details/schedule.md lines 8-15; electronic schematics and acoustic software can be finalized in 2 weeks; breadboard PoC achievable before midterm with production testing in Weeks 11-13. | Q12: solution-details/solution-2.md lines 6-10; completely unites Biosphere (SDG 6.3 preventing sewer blockages and dirty overflow), Society (SDG 11.5 urban flood mitigation), and Economy (SDG 8.2 & 12.2 optimizing municipal maintenance resources). | R12: solution-details/solution-2.md lines 38-40; 100% fail-safe surface retrieval; zero electronic components or toxic batteries enter wastewater; ultra-low power consumption with rechargeable lithium cells. | S12: =IF(MIN(B9:R9)=1, "VETOED / ตกเกณฑ์ข้อบังคับวิกฤต (คะแนนระดับ 1)", IF(S9>=80, "ผ่านเกณฑ์ระดับสูง (HIGHLY VIABLE)", IF(S9>=60, "ผ่านแบบมีเงื่อนไข (CONDITIONALLY VIABLE)", "ความเสี่ยงสูง (HIGH RISK)")))
A13: แผนลดขอบเขตงาน & มาตรการลดความเสี่ยง (De-scoping Action) | B13: Use 3D printed acoustic waveguide horns and standard off-the-shelf portable telescoping painter poles. | C13: Implement standard swept-sine excitation and bandpass filtering using open-source Python SciPy signal libraries. | D13: Calibrate swept-sine frequency band (500 Hz - 4 kHz) against standard 300mm to 600mm concrete pipe acoustic resonances. | E13: Due leads hardware assembly while JK and Kin develop audio playback and signal processing scripts in parallel. | F13: Reuse Due's verified ESP32 I2S audio driver code from past embedded projects directly. | G13: Deliver automated dispatch report showing exact pipe segments with Cleanliness Score < 5 to prioritize jetting trucks. | H13: Maintain bill of materials strictly with generic electronic parts purchasable across multiple local vendors. | I13: Order 3 sets of ESP32 and audio breakout boards in a single batch to safeguard against bench testing mishaps. | J13: Conduct initial field verification on university campus manholes with faculty permission. | K13: Cite EPA research documentation and standard acoustic wave attenuation references in the project report. | L13: Add a simple LED status indicator and battery voltage buzzer to alert operators when battery is low. | M13: Design automated Bluetooth transmission of scores directly to a mobile smartphone web app. | N13: Construct a 6-meter PVC pipe test rig on bench for rapid acoustic calibration. | O13: Use a single PlatformIO configuration file with automated library dependency management. | P13: Lock acoustic horn 3D print dimensions by Week 9 to allow parallel firmware and DSP development. | Q13: Include carbon footprint reduction calculation resulting from avoided diesel jetting truck runs. | R13: Use recyclable PETG casing and standardized rechargeable 18650 battery cells. | S13: ปฏิบัติตามแผนลดขอบเขตงาน (De-scoping Advisory)
A15: ตารางสรุปคะแนนแยกตามมิติ TELOS+S (Pillar Score Breakdown)
A16: มิติการประเมิน (TELOS+S Pillar) | B16: สัดส่วนน้ำหนัก (Weight %) | C16: คะแนนเต็มมิติ (Max Points) | D16: คะแนนที่ได้รับจริง (Earned Points) | E16: คะแนนเฉลี่ย (Score 1-5) | F16: ระดับความพร้อม (Readiness Level)
A17: T : ด้านเทคโนโลยีและวิศวกรรม (Technical) | B17: 0.2 | C17: 20 | D17: =SUM(B11:F11)*20 | E17: =IF(C17>0, (D17/C17)*5, 0) | F17: =IF(D17>=16.0, "พร้อมระดับสูง (High)", IF(D17>=12.0, "ปานกลาง (Medium)", "เสี่ยงวิกฤต (Critical)"))
A18: E : ด้านเศรษฐศาสตร์และความคุ้มค่า (Economic) | B18: 0.2 | C18: 20 | D18: =SUM(G11:I11)*20 | E18: =IF(C18>0, (D18/C18)*5, 0) | F18: =IF(D18>=16.0, "พร้อมระดับสูง (High)", IF(D18>=12.0, "ปานกลาง (Medium)", "เสี่ยงวิกฤต (Critical)"))
A19: L : ด้านกฎหมาย ระเบียบ และภาคประชาชน (Legal & Outreach) | B19: 0.15 | C19: 15 | D19: =SUM(J11:K11)*20 | E19: =IF(C19>0, (D19/C19)*5, 0) | F19: =IF(D19>=12.0, "พร้อมระดับสูง (High)", IF(D19>=9.0, "ปานกลาง (Medium)", "เสี่ยงวิกฤต (Critical)"))
A20: O : ด้านการปฏิบัติการและหน้างาน (Operational) | B20: 0.2 | C20: 20 | D20: =SUM(L11:O11)*20 | E20: =IF(C20>0, (D20/C20)*5, 0) | F20: =IF(D20>=16.0, "พร้อมระดับสูง (High)", IF(D20>=12.0, "ปานกลาง (Medium)", "เสี่ยงวิกฤต (Critical)"))
A21: S : ด้านแผนงานและเวลาส่งมอบ (Schedule) | B21: 0.15 | C21: 15 | D21: =P11*20 | E21: =IF(C21>0, (D21/C21)*5, 0) | F21: =IF(D21>=12.0, "พร้อมระดับสูง (High)", IF(D21>=9.0, "ปานกลาง (Medium)", "เสี่ยงวิกฤต (Critical)"))
A22: +S : ด้านความยั่งยืนและสิ่งแวดล้อม (Sustainability / SDG) | B22: 0.1 | C22: 10 | D22: =SUM(Q11:R11)*20 | E22: =IF(C22>0, (D22/C22)*5, 0) | F22: =IF(D22>=8.0, "พร้อมระดับสูง (High)", IF(D22>=6.0, "ปานกลาง (Medium)", "เสี่ยงวิกฤต (Critical)"))
A23: คะแนนรวมทุกมิติ (Total Feasibility Score) | B23: =SUM(B17:B22) | C23: =SUM(C17:C22) | D23: =SUM(D17:D22) | E23: =IF(C23>0, (D23/C23)*5, 0) | F23: =IF(D23>=80, "ผ่านเกณฑ์ระดับสูง (HIGHLY VIABLE)", IF(D23>=60, "ผ่านแบบมีเงื่อนไข (CONDITIONALLY VIABLE)", "ความเสี่ยงสูง (HIGH RISK)"))
A25: เมทริกซ์ประเมินความเข้ากันได้กับองค์ความรู้ด้านวิศวกรรมหุ่นยนต์ (Robotics Knowledge Compatibility)
A26: * หมายเหตุ: การประเมินส่วนนี้วัดศักยภาพในการประยุกต์ใช้องค์ความรู้ด้านวิศวกรรมหุ่นยนต์ (Perception, Control, Actuation) เต็ม 12 คะแนน (แกนละ 4 คะแนน) | เป็นเอกเทศ ไม่นับรวมในคะแนน TELOS 100 คะแนน
A27: มิติการประเมิน (Robotics Dimension) | B27: คะแนนศักยภาพ (/12) | C27: แกน Perception & Sensing (การรับรู้) | D27: แกน Control & Algorithms (การควบคุม) | E27: แกน Actuation & Mechanisms (กลไก) | F27: บทวิเคราะห์เชิงวิศวกรรมหุ่นยนต์ (FIBO Alignment Rationale)
A28: ศักยภาพการประยุกต์ใช้องค์ความรู้หุ่นยนต์และระบบอัตโนมัติ | B28: 8.5 | C28: Score 3.5/4.0: Active airborne acoustic reflectometry transducer, swept-sine/chirp acoustic wave excitation, and precision condenser microphone array capturing acoustic impulse response. | D28: Score 3.5/4.0: Digital signal processing (DSP), acoustic energy attenuation deconvolution, spectral bandpass filtering, and automated 0-10 EPA SL-RAT cleanliness score generation. | E28: Score 1.5/4.0: High-output acoustic compression driver transducer with telescoping manhole deployment rig; non-mobile surface-operated payload. | F28: Solution 2 represents an advanced non-destructive testing (NDT) acoustic instrumentation payload with deep digital signal processing, acoustic wave physics modeling, and automated scoring classification, closely aligning with FIBO instrumentation and embedded DSP curriculum.

Sheet Solution_3_Sonar_Profiling
A1: เมทริกซ์ประเมินความเป็นไปได้เชิงระบบ TELOS+S: Pipe Inspection Instrument using Sonar Frequency Profiling attaching with Robot (360° Underwater Sonar Scan + Floater/Crawler)
A2: ระบบคะแนนจำนวนเต็มเด็ดขาด: 1, 2, 3, 4, 5 เท่านั้น (ไม่มีจุดทศนิยม / ไม่มี 0.5) | โครงสร้างแบบ Transposed แนวนอน
A4: รหัสคำถาม (Question Code) | B4: T-01 | C4: T-02 | D4: T-03 | E4: T-04 | F4: T-05 | G4: E-01 | H4: E-02 | I4: E-03 | J4: L-01 | K4: L-02 | L4: O-01 | M4: O-02 | N4: O-03 | O4: O-04 | P4: S-01 | Q4: SDG-01 | R4: SDG-02 | S4: สรุปภาพรวม (SUMMARY)
A5: มิติการประเมิน (TELOS+S Pillar) | B5: ด้านเทคนิค (Technical 2.2) | C5: ด้านเทคนิค (Technical 2.2) | D5: ด้านเทคนิค (Technical 2.2) | E5: ด้านเทคนิค (Technical 2.2) | F5: ด้านเทคนิค (Technical 2.2) | G5: ด้านเศรษฐศาสตร์ (Economic 2.3) | H5: ด้านเศรษฐศาสตร์ (Economic 2.3) | I5: ด้านเศรษฐศาสตร์ (Economic 2.3) | J5: ด้านกฎหมายและสถาบัน (Legal 2.4) | K5: ด้านกฎหมายและสถาบัน (Legal 2.4) | L5: ด้านการปฏิบัติการ (Operational 2.5) | M5: ด้านการปฏิบัติการ (Operational 2.5) | N5: ด้านการปฏิบัติการ (Operational 2.5) | O5: ด้านการปฏิบัติการ (Operational 2.5) | P5: ด้านแผนงานและเวลา (Schedule 2.6) | Q5: ด้านความยั่งยืน (SDGs Feasibility 2.7) | R5: ด้านความยั่งยืน (SDGs Feasibility 2.7) | S5: ผลรวมทุกมิติ (All Pillars)
A6: คำถามทดสอบความเสี่ยงจริง (Stress-Test Question) | B6: ระดับการสร้างเองเทียบกับการซื้อสำเร็จรูป (Build vs. Buy Burden) ของสถาปัตยกรรมระบบตรวจประเมินท่อระบายน้ำ? | C6: สิทธิ์ในการเข้าถึงเทคโนโลยี ซอฟต์แวร์ และระบบนิเวศข้อมูล (Access & Permissions) ของระบบตรวจประเมินท่อ? | D6: ระดับความพร้อมทางเทคโนโลยี (Base Performance / TRL) ในสภาพแวดล้อมจริงของท่อระบายน้ำใต้ดิน? | E6: ความพร้อมและกำลังคนสำรองของทีมงาน (Team Compatibility & Redundancy / Anti-SPOF)? | F6: ความชันในการเรียนรู้และเวลาปรับตัวของทีมงาน (Learning Curve & Ramp-up Time)? | G6: ระยะเวลาคืนทุนและความคุ้มค่าในการลงทุน (ROI / Payback Period) เทียบกับการขุดลอกแบบสุ่ม? | H6: การพึ่งพาผู้จำหน่ายและการผูกขาดชิ้นส่วนเฉพาะ (Component Dependency & Vendor Lock-in)? | I6: วงเงินงบประมาณสำรองความเสียหายและการทำซ้ำ (Scrap Margin & Iteration Allowance)? | J6: การปฏิบัติตามกฎหมายจราจร ความปลอดภัยในที่อับอากาศ และระเบียบพื้นที่สาธารณะ (Felony, Traffic & Confined Space Compliance)? | K6: การปฏิบัติตามสัญญาอนุญาต ทรัพย์สินทางปัญญา และโอเพนซอร์ส (IP & Software Licensing Compliance)? | L6: ผลกระทบและความรุนแรงเมื่อระบบเกิดความขัดข้องหรือติดค้าง (User — Failure Impact & Stuck Hazards)? | M6: ความสอดคล้องกับพฤติกรรมเจ้าหน้าที่และขั้นตอนการทำงานเดิม (User — Workflow Friction & Adoption)? | N6: การพึ่งพาห้องปฏิบัติการและขั้นตอนการขออนุมัติของนักพัฒนา (Developer — Lab & Administrative Gatekeeping)? | O6: ความซับซ้อนของขั้นตอนการประกอบ ติดตั้ง และโปรแกรม (Developer — Setup Steps & Pipeline Friction)? | P6: วุฒิภาวะของการออกแบบทางวิศวกรรมภายในกรอบเวลา 5 สัปดาห์ทำงาน (Engineering Design Maturity by 5 Weeks)? | Q6: การบูรณาการตามกรอบ Stockholm Wedding Cake (Biosphere, Society, Economy Integration)? | R6: ผลกระทบสิ่งแวดล้อม ขยะอิเล็กทรอนิกส์ และหลักเศรษฐกิจหมุนเวียน (E-Waste & 'Do No Harm' — SDG 6.3/12.4)? | S6: ประเมินคำถามทั้งสิ้น 17 ข้อ
A7: เหตุผลในการถาม & โหมดความล้มเหลวที่เฝ้าระวัง (Rationale) | B7: ประเมินภาระการวิจัยและพัฒนาชิ้นส่วนกลไก อิเล็กทรอนิกส์ และอัลกอริทึม ป้องกันการเสียเวลากับงานประดิษฐ์ขึ้นใหม่โดยไม่จำเป็น | C7: ตรวจสอบข้อจำกัดด้านกรรมสิทธิ์ การล็อกสิทธิ์ใช้งาน และการอนุญาตเข้าถึง เพื่อป้องกันการพัฒนาระบบบนฐานข้อมูลที่ไม่สามารถเข้าถึงได้จริง | D7: วัดวุฒิภาวะของเทคโนโลยีว่าผ่านการพิสูจน์ในสภาพแวดล้อมใต้ดินที่มีความชื้น สารกัดกร่อน หรือน้ำขังจริงแล้วหรือไม่ | E7: ตรวจสอบความเสี่ยงคอขวดบุคลากร (Single Point of Failure) ป้องกันไม่ให้โครงการหยุดชะงักหากผู้รับผิดชอบหลักไม่ว่าง | F7: ประเมินเวลาที่ทีมต้องใช้ในการเรียนรู้เครื่องมือหรือทฤษฎีใหม่ เพื่อไม่ให้กระทบต่อกำหนดการส่งมอบ 5 สัปดาห์ | G7: วัดความคุ้มค่าทางการเงินและการประหยัดงบประมาณการลอกท่อของหน่วยงานภาครัฐเทียบกับ Baseline เดิม | H7: ตรวจสอบความเสี่ยงจากการพึ่งพาผู้ขายรายเดียว การผูกขาดชิ้นส่วนนำเข้า หรือค่าลิขสิทธิ์ซอฟต์แวร์รายปี | I7: ประเมินขีดความสามารถในการรับมือกับความเสียหายของอุปกรณ์และชิปที่อาจช็อตหรือเสียหายระหว่างการพัฒนา | J7: ตรวจสอบความเสี่ยงต่อการละเมิดกฎหมายจราจร กฎหมายความปลอดภัยในที่อับอากาศ และการปิดกั้นทางสัญจร | K7: ตรวจสอบสิทธิ์การใช้งานซอฟต์แวร์ ไลบรารี และสิทธิบัตร ป้องกันการฟ้องร้องละเมิดลิขสิทธิ์ | L7: ประเมินความเสียหายต่อโครงสร้างพื้นฐาน ความปลอดภัยของเจ้าหน้าที่ และการกลายเป็นสิ่งกีดขวางในท่อระบายน้ำ | M7: ประเมินภาระการฝึกอบรม ความสะดวกในการพกพา และแรงต้านจากเจ้าหน้าที่ภาคสนามของ กทม. | N7: ประเมินอุปสรรคการเข้าถึงเครื่องมือ ช็อปเครื่องกล หรือการต้องรอคิวอนุมัติเอกสารของมหาวิทยาลัย | O7: ประเมินจำนวนขั้นตอนและความเปราะบางของเครื่องมือพัฒนา ป้องกันข้อผิดพลาดจากการตั้งค่าระบบที่ซับซ้อนเกินไป | P7: ทดสอบความเป็นไปได้ในการสร้างชิ้นงานให้สำเร็จตามเป้าหมาย TRL โดยหักสัปดาห์สอบมิดเทอมและไฟนอลออกแล้ว | Q7: ประเมินผลกระทบเชิงบวกที่ครอบคลุมทั้งด้านชีวมณฑล (SDG 6/14), สังคม (SDG 11) และเศรษฐกิจ (SDG 8/12) | R7: ตรวจสอบการป้องกันขยะอิเล็กทรอนิกส์ตกค้างในท่อระบายน้ำ สารพิษรั่วไหล และระบบกู้คืนอุปกรณ์ที่ปลอดภัย 100% | S7: สังเคราะห์จาก AI Agents Group 2
