Workbook

Sheet เปรียบเทียบทุก Solution
A1: ตารางเปรียบเทียบความเป็นไปได้ของทุกข้อเสนอ (Multi-Solution Feasibility Summary)
A2: วิเคราะห์เปรียบเทียบเชิงระบบตามเกณฑ์ TELOS+S (เต็ม 100) และเมทริกซ์ศักยภาพด้านวิศวกรรมหุ่นยนต์ (เต็ม 12 แยกอิสระ)
A4: ลำดับ | B4: รหัสข้อเสนอ (Solution ID) | C4: ชื่อแนวทางแก้ปัญหา (Title / Concept) | D4: คะแนนรวม (เต็ม 100) | E4: T: เทคนิค (/20) | F4: E: เศรษฐศาสตร์ (/20) | G4: L: กฎหมาย (/15) | H4: O: ปฏิบัติการ (/20) | I4: S: แผนงาน (/15) | J4: +S: ยั่งยืน (/10) | K4: ผลการประเมิน (Verdict) | L4: จุดแข็งสำคัญ (Key Strengths) | M4: จุดติดขัดวิกฤต (Critical Bottlenecks) | N4: คำแนะนำเชิงระบบ (Strategic Advice) | O4: Robotics Potential (/12) | P4: เหตุผลความเข้ากันได้ด้านหุ่นยนต์ (Robotics Engineering Rationale)
A5: 1 | B5: Solution_2_Acoustic_Reflect | C5: Solution 2: Pipe Inspection Instrument using Acoustic Reflectometry (Airborne Acoustic Inversion + SL-RAT EPA USA Cleanliness Scale) | D5: ='Solution_2_Acoustic_Reflect'!S9 | E5: ='Solution_2_Acoustic_Reflect'!D17 | F5: ='Solution_2_Acoustic_Reflect'!D18 | G5: ='Solution_2_Acoustic_Reflect'!D19 | H5: ='Solution_2_Acoustic_Reflect'!D20 | I5: ='Solution_2_Acoustic_Reflect'!D21 | J5: ='Solution_2_Acoustic_Reflect'!D22 | K5: ='Solution_2_Acoustic_Reflect'!S12 | L5: ตรวจประเมินท่อจากผิวดินได้อย่างรวดเร็ว (3–5 นาทีต่อช่วงท่อ) โดยไม่ต้องปล่อยหุ่นยนต์ลงไปสัมผัสน้ำเสีย ใช้พลังงานต่ำ ต้นทุนอุปกรณ์ต่ำมาก ไม่มีความเสี่ยงเรื่องอุปกรณ์ติดค้างในท่อ และสอดรับกับข้อจำกัดน้ำในท่อไม่เกิน 20% ได้อย่างสมบูรณ์แบบ | M5: ไม่สามารถทำงานได้ในสภาวะที่น้ำท่วมเต็มท่อระบายน้ำ (Airspace ปิดกั้น) และไม่ได้ภาพ 3D เรขาคณิตของผิวท่อ | N5: พัฒนาท่อส่งคลื่นเสียงแบบ Telescoping Pole ที่สามารถปรับระดับความลึกตามปากท่อได้ พร้อมบันทึกพิกัด GPS อัตโนมัติเพื่อเชื่อมต่อแผนที่ระบบท่อของ กทม. | O5: 8.5 | P5: Solution 2 exercises FIBO signal processing, acoustical physics, digital filtering, and sensor interface engineering without unnecessary mechanical locomotion risks in underground sewage.
A6: 2 | B6: Solution_1_CCTV_Crawler | C6: Solution 1: Pipe Inspection Robot using CCTV for profiling pipe (4K PTZ Camera + YOLOv8 Wheeled Crawler) | D6: ='Solution_1_CCTV_Crawler'!S9 | E6: ='Solution_1_CCTV_Crawler'!D17 | F6: ='Solution_1_CCTV_Crawler'!D18 | G6: ='Solution_1_CCTV_Crawler'!D19 | H6: ='Solution_1_CCTV_Crawler'!D20 | I6: ='Solution_1_CCTV_Crawler'!D21 | J6: ='Solution_1_CCTV_Crawler'!D22 | K6: ='Solution_1_CCTV_Crawler'!S12 | L6: ให้ภาพวิดีโอความละเอียดสูง (HD/4K) ภายในท่อจริง พร้อมโมเดล AI (YOLOv8) ตรวจจับรอยแตกร้าว รอยรั่ว และสิ่งอุดตันได้โดยอัตโนมัติ โดยสอดรับกับข้อจำกัดน้ำในท่อไม่เกิน 20% ทำให้กล้องมองเห็นผิวท่อส่วนบนได้ชัดเจน | M6: ต้องใช้หุ่นยนต์ลงไปสัมผัสน้ำเสียในท่อจริง แม้น้ำไม่เกิน 20% แต่ล้อและระบบซีลยังต้องทนทานต่อน้ำและคราบไขมัน (IP68), มีความเสี่ยงหุ่นยนต์ติดค้าง/สาย Tether พันกันในท่อ (O-01=3), และต้องใช้เวลาสร้างระบบกลไกกันน้ำสูงเกินกรอบเวลา 5 สัปดาห์ (S-01=2) | N6: ลดสโคปกลไกขับเคลื่อนที่ซับซ้อน หันมาใช้โครงสร้างล้อสำเร็จรูป (COTS Crawler Chassis) พร้อมติดตั้งชุดสาย Tether แบบ Slip-Ring คุณภาพสูง และทดสอบระบบกันน้ำในถังทดสอบก่อนลงพื้นที่จริง | O6: 10.5 | P6: Solution 1 implements a genuine closed-loop mobile robotic system across all three FIBO pillars: active high-resolution optical perception, edge neural network defect inferencing, and mobile robotic pipe locomotion, utilizing mechatronics and control skills directly.
A7: 3 | B7: Solution_4_LiDAR_SLAM | C7: Solution 4: Pipe Inspection Instrument using LiDAR SLAM attaching with Robot (3D LiDAR + Laser SLAM Point Cloud Profiling) | D7: ='Solution_4_LiDAR_SLAM'!S9 | E7: ='Solution_4_LiDAR_SLAM'!D17 | F7: ='Solution_4_LiDAR_SLAM'!D18 | G7: ='Solution_4_LiDAR_SLAM'!D19 | H7: ='Solution_4_LiDAR_SLAM'!D20 | I7: ='Solution_4_LiDAR_SLAM'!D21 | J7: ='Solution_4_LiDAR_SLAM'!D22 | K7: ='Solution_4_LiDAR_SLAM'!S12 | L7: สร้างแผนที่ 3 มิติ (3D Point Cloud) ของท่อระบายน้ำได้อย่างแม่นยำระดับมิลลิเมตร สามารถตรวจวัดปริมาตรตะกอน (Buildup/Debris) และตรวจจับการเสียรูปเชิงเรขาคณิตของท่อได้อย่างชัดเจน | M7: เซนเซอร์ 3D LiDAR และบอร์ดประมวลผล GPU/SBC มีราคาสูงมากเกินงบประมาณ (E-03=1: ไม่มีงบสำรองกรณีเซนเซอร์ตกน้ำหรือพังเสียหาย เกิด Fatal Flaw ทันที), เลเซอร์ไม่สามารถทะลุน้ำเสียหรือหมอกควันได้ (T-03=2), และต้องใช้เวลาประมวลผล Point Cloud สูง | N7: ลดสโคปจากการใช้ 3D LiDAR ราคาแพง มาใช้ 2D LiDAR ติดตั้งบนแกนหมุน หรือใช้ Depth Camera / Structured Light ในท่อแห้งเพื่อควบคุมต้นทุนไม่ให้เกินงบประมาณและปลดล็อก Fatal Flaw | O7: 11.5 | P7: Solution 4 exercises the peak FIBO robotics curriculum: 3D spatial laser perception, advanced SLAM state estimation, and mobile mechatronic locomotion, representing a gold-standard capstone robotics architecture.

Sheet Solution_2_Acoustic_Reflect
A1: เมทริกซ์ประเมินความเป็นไปได้เชิงระบบ TELOS+S: Solution 2: Pipe Inspection Instrument using Acoustic Reflectometry (Airborne Acoustic Inversion + SL-RAT EPA USA Cleanliness Scale)
A2: ระบบคะแนนจำนวนเต็มเด็ดขาด: 1, 2, 3, 4, 5 เท่านั้น (ไม่มีจุดทศนิยม / ไม่มี 0.5) | โครงสร้างแบบ Transposed แนวนอน
A4: รหัสคำถาม (Question Code) | B4: T-01 | C4: T-02 | D4: T-03 | E4: T-04 | F4: T-05 | G4: E-01 | H4: E-02 | I4: E-03 | J4: L-01 | K4: L-02 | L4: O-01 | M4: O-02 | N4: O-03 | O4: O-04 | P4: S-01 | Q4: SDG-01 | R4: SDG-02 | S4: สรุปภาพรวม (SUMMARY)
A5: มิติการประเมิน (TELOS+S Pillar) | B5: ด้านเทคนิค (Technical 2.2) | C5: ด้านเทคนิค (Technical 2.2) | D5: ด้านเทคนิค (Technical 2.2) | E5: ด้านเทคนิค (Technical 2.2) | F5: ด้านเทคนิค (Technical 2.2) | G5: ด้านเศรษฐศาสตร์ (Economic 2.3) | H5: ด้านเศรษฐศาสตร์ (Economic 2.3) | I5: ด้านเศรษฐศาสตร์ (Economic 2.3) | J5: ด้านกฎหมาย (Legal 2.4) | K5: ด้านกฎหมาย (Legal 2.4) | L5: ด้านปฏิบัติการ (Operational 2.5) | M5: ด้านปฏิบัติการ (Operational 2.5) | N5: ด้านปฏิบัติการ (Operational 2.5) | O5: ด้านปฏิบัติการ (Operational 2.5) | P5: ด้านแผนงาน (Schedule 2.6) | Q5: ความยั่งยืน (SDGs 2.7) | R5: ความยั่งยืน (SDGs 2.7) | S5: ผลรวมทุกมิติ (All Pillars)
A6: คำถามทดสอบความเสี่ยงจริง (Stress-Test Question) | B6: ระดับการสร้างเองเทียบกับการซื้อสำเร็จรูป (Build vs. Buy Burden) ของสถาปัตยกรรมระบบตรวจประเมินท่อระบายน้ำ? | C6: สิทธิ์ในการเข้าถึงเทคโนโลยี ซอฟต์แวร์ และระบบนิเวศข้อมูล (Access & Permissions) ของระบบตรวจประเมินท่อ? | D6: ระดับความพร้อมทางเทคโนโลยี (Base Performance / TRL) ในสภาพแวดล้อมจริงของท่อระบายน้ำใต้ดิน? | E6: ความเข้ากันได้ของทีม (Manpower & Skill Redundancy) ด้านวิศวกรรมเฉพาะทาง? | F6: ความชันของเส้นทางการเรียนรู้ (Learning Curve) ด้านวิศวกรรมระบบ? | G6: ระยะเวลาคืนทุนและความคุ้มค่าในการลงทุน (Payback Period / Value Horizon) ของระบบ? | H6: ระดับการพึ่งพาชิ้นส่วนและผู้จัดจำหน่ายภายนอก (Component Dependency & Vendor Lock-in)? | I6: สัดส่วนงบประมาณสำรองความเสียหาย (Scrap Margin / Safety Allowance) ของชิ้นส่วน? | J6: ความสอดคล้องกับกฎหมายความปลอดภัยสาธารณะและการจราจร (Regulatory & Public Safety Compliance)? | K6: ทรัพย์สินทางปัญญา ลิขสิทธิ์ซอฟต์แวร์ และสิทธิบัตร (IP & Software Licensing)? | L6: ผลกระทบต่อระบบหากเกิดความล้มเหลวขณะปฏิบัติงาน (Operational Failure Impact)? | M6: ความสอดคล้องกับพฤติกรรมผู้ใช้และสภาพหน้างานจริง (User Behavior & Problem-Solution Fit)? | N6: การพึ่งพาห้องปฏิบัติการและขั้นตอนเชิงบริหารของนักพัฒนา (Administrative & Lab Dependency)? | O6: ความซับซ้อนของขั้นตอนการประมวลผลและการเตรียมระบบ (Step Count & Pipeline Friction)? | P6: ความพร้อมของระบบและการส่งมอบต้นแบบภายในกรอบเวลา 5 สัปดาห์ทำงาน (Design Maturity & Schedule Compliance)? | Q6: ผลกระทบต่อสิ่งแวดล้อม สังคม และเศรษฐกิจตามกรอบ SDG Wedding Cake (Biosphere, Society, Economy)? | R6: รอยเท้าสิ่งแวดล้อม ขยะอิเล็กทรอนิกส์ และระบบเก็บกู้ที่ปลอดภัย (Environmental Footprint & E-Waste Safeguards)? | S6: ประเมินคำถามทั้งสิ้น 17 ข้อ
A7: เหตุผลในการถาม & โหมดความล้มเหลวที่เฝ้าระวัง (Rationale) | B7: ประเมินภาระการวิจัยและพัฒนาชิ้นส่วนกลไก อิเล็กทรอนิกส์ และอัลกอริทึม ป้องกันการเสียเวลากับงานประดิษฐ์ขึ้นใหม่โดยไม่จำเป็น | C7: ตรวจสอบข้อจำกัดด้านกรรมสิทธิ์ การล็อกสิทธิ์ใช้งาน และการอนุญาตเข้าถึง เพื่อป้องกันการพัฒนาระบบบนฐานข้อมูลที่ไม่สามารถเข้าถึงได้จริง | D7: วัดวุฒิภาวะของเทคโนโลยีว่าผ่านการพิสูจน์ในสภาพแวดล้อมใต้ดินที่มีความชื้น สารกัดกร่อน หรือน้ำขังจริงแล้วหรือไม่ | E7: ประเมินความเสี่ยงกรณีขาดแคลนบุคลากรที่มีความเชี่ยวชาญเฉพาะด้าน (Bus Factor) ว่ามีคนทำงานทดแทนกันได้หรือไม่ | F7: ประเมินเวลาและความยากในการเรียนรู้เทคโนโลยีใหม่ ว่าทีมงานสามารถเข้าใจและนำมาใช้ได้ทันเวลาหรือไม่ | G7: ประเมินผลตอบแทนทางเศรษฐศาสตร์และการลดต้นทุนการขุดลอกท่อระบายน้ำของหน่วยงานรัฐ | H7: ประเมินความเสี่ยงด้านห่วงโซ่อุปทานและการผูกขาดชิ้นส่วน ป้องกันระบบล่มสลายจากผู้ผลิตรายเดียว | I7: ตรวจสอบความปลอดภัยทางการเงินกรณีทำอุปกรณ์เสียหายระหว่างการทดลองในน้ำเสีย | J7: ประเมินความเสี่ยงการละเมิดกฎหมายควบคุมอาคาร ระเบียบงานทาง และข้อบังคับการจราจรขณะปฏิบัติงาน | K7: ตรวจสอบความปลอดภัยด้านสิทธิบัตรเพื่อป้องกันการถูกฟ้องร้องละเมิดทรัพย์สินทางปัญญา | L7: ประเมินความรุนแรงของผลกระทบกรณีระบบขัดข้อง ว่าทำให้อุดตันท่อหรือระบบระบายน้ำเสียหายหรือไม่ | M7: ประเมินความสะดวกของเจ้าหน้าที่หน้างาน ว่าระบบใช้งานง่ายและตอบสนองขั้นตอนการทำงานจริงหรือไม่ | N7: ประเมินความคล่องตัวในการพัฒนา ว่าต้องรอการอนุมัติหรือติดขัดการใช้ห้องแล็บเฉพาะทางหรือไม่ | O7: วัดจำนวนขั้นตอนและความยุ่งยากในการเตรียมระบบก่อนเริ่มใช้งานจริง | P7: ประเมินความเป็นไปได้ในการสร้าง ทดสอบ และส่งมอบต้นแบบวิศวกรรมให้เสร็จทันกำหนด 5 สัปดาห์ | Q7: ประเมินคุณค่าที่แท้จริงต่อเป้าหมายการพัฒนาที่ยั่งยืน 3 ชั้น ป้องกันการสร้างภาพลักษณ์สีเขียว (Greenwashing) | R7: ตรวจสอบการป้องกันขยะอิเล็กทรอนิกส์ตกค้างในท่อระบายน้ำ สารพิษรั่วไหล และระบบกู้คืนอุปกรณ์ที่ปลอดภัย 100% | S7: สังเคราะห์จาก AI Agents Group 2
A8: เกณฑ์การให้คะแนน (Scoring Rubric Definition: ระดับ 1, 2, 3, 4, 5 ครบทุกระดับ) | B8: 1: ต้องวิจัยและสร้างขึ้นเองทั้งหมด 100% (ไม่มีพิมพ์เขียว อัลกอริทึม หรือไลบรารีอ้างอิง) 2: มีชิ้นส่วนหลักในท้องตลาด แต่ต้องดัดแปลงโครงสร้างอย่างหนักและเขียนโค้ดเชื่อมต่อเองทั้งหมด 3: บูรณาการชิ้นส่วน COTS เข้ากับแท่นยึดแบบกำหนดเอง และเขียนโค้ดเชื่อมต่อบางส่วน 4: ประกอบจากโมดูลมาตรฐานสำเร็จรูป (DIN-rail, I2C/CAN shields) มีงานประกอบกลไกเล็กน้อย 5: ซื้อมาติดตั้งใช้งานได้ทันที (Plug-and-Play) ไม่ต้องตัดกลึงหรือบัดกรีวงจรเพิ่มเติม | C8: 1: ล็อกสิทธิ์ภายใต้สัญญา NDA ระบบปิด ติดไฟร์วอลล์องค์กร หรือไม่มีสิทธิ์เข้าถึงฝั่งนักพัฒนา 2: ซอฟต์แวร์หรือเฟิร์มแวร์กรรมสิทธิ์ปิด ทำงานแบบ Black-box โดยไม่มี Source Code หรือ Telemetry 3: บัญชีเพื่อการศึกษา/ทดลองใช้ที่มีโควตาหรือ Rate Limit เข้มงวด ต้องรอการอนุมัติอย่างเป็นทางการ 4: มี SDK หรือ Open API สาธารณะพร้อมเอกสารครบถ้วน แต่ไม่สามารถแก้ไขสถาปัตยกรรมระดับล่างได้ 5: สถาปัตยกรรมเปิดสมบูรณ์ (Open Source/Open HW) ทีมงานมีสิทธิ์ระดับ Root/Admin เต็มรูปแบบ | D8: 1: ระดับแนวคิด/สมการคณิตศาสตร์ (TRL 2–3) ทดสอบเฉพาะในห้องทดลองที่ควบคุมสภาพแวดล้อมได้ 2: เบรดบอร์ดทำงานได้ในแล็บ (TRL 4) สายไฟเปราะบาง ยังไม่ผ่านการสอบเทียบในสภาพแวดล้อมจริง 3: ตัวต้นแบบประกอบลงกล่อง (TRL 5–6) ผ่านการทดสอบในสภาพแวดล้อมจำลอง ต้องมีคนคอยดูแล 4: ต้นแบบระดับพรีโปรดักชัน (TRL 7) ทำงานได้อย่างมีเสถียรภาพในสภาพแวดล้อมปฏิบัติงานจริง 5: ผลิตภัณฑ์เชิงพาณิชย์สมบูรณ์ (TRL 8–9) ผ่านการรับรองมาตรฐาน มีค่า MTBF ยืนยันความทนทาน | E8: 1: ขาดแคลนทักษะเฉพาะด้านโดยสิ้นเชิง (ไม่มีใครในทีมมีความรู้ในเทคโนโลยีหลักนี้เลย) 2: พึ่งพาผู้เชี่ยวชาญเพียงคนเดียว (Bus Factor = 1) หากคนนี้ไม่อยู่ โครงการจะหยุดชะงักทันที 3: มีผู้รับผิดชอบหลัก 1 คน และมีผู้ช่วยที่พอเข้าใจระบบ แต่ยังแก้ไขปัญหาเชิงลึกแทนไม่ได้ 4: มีทักษะทดแทนกันได้ (Primary & Secondary) อย่างน้อย 2 คนสามารถสลับงานกันได้อย่างราบรื่น 5: สมาชิกทุกคนในทีมมีทักษะระดับสูง ทำงานแทนกันได้ทันที และมีเอกสารคู่มือการทำงานครบถ้วน | F8: 1: เทคโนโลยีใหม่ทั้งหมด ต้องใช้เวลาเรียนรู้เกิน 8 สัปดาห์ และต้องการทักษะคณิตศาสตร์ชั้นสูง 2: มีแนวคิดซับซ้อน ต้องศึกษาทฤษฎีใหม่ที่ไม่เคยเรียนมาก่อน ใช้เวลาทำความเข้าใจ 4–6 สัปดาห์ 3: ต่อยอดจากพื้นฐานเดิมที่เคยเรียน แต่ต้องเรียนรู้เครื่องมือหรือสถาปัตยกรรมใหม่ ใช้เวลา 2–3 สัปดาห์ 4: เป็นเทคโนโลยีที่คุ้นเคย มีตัวอย่างโค้ดและวงจรอ้างอิงชัดเจน ใช้เวลาปรับตัวเพียง 1 สัปดาห์ 5: ทำงานบนพื้นฐานทักษะประจำวันของทีม ทำได้ทันทีโดยไม่ต้องศึกษาทฤษฎีหรือเครื่องมือเพิ่มเติม | G8: 1: ระยะเวลาคืนทุนเกิน 7 ปี หรือต้นทุนการดำเนินงานสูงกว่ามูลค่าความเสียหายที่ป้องกันได้ 2: ระยะเวลาคืนทุน 5–7 ปี ให้ผลตอบแทนทางอ้อมเป็นหลัก และมีความไม่แน่นอนทางการเงินสูง 3: ระยะเวลาคืนทุน 3–5 ปี มีความคุ้มค่าระดับปานกลาง จำเป็นต้องได้รับการอุดหนุนงบประมาณจากรัฐ 4: ระยะเวลาคืนทุน 1–3 ปี ประหยัดค่าใช้จ่ายการซ่อมบำรุงเชิงแก้ไขได้อย่างชัดเจน คุ้มค่าสูง 5: คืนทุนได้ภายใน 1 ปีแรก ลดต้นทุนการบำรุงรักษาได้ทันที และสร้างมูลค่าเพิ่มทางตรงอย่างมหาศาล | H8: 1: ผูกขาดโดยผู้ผลิตรายเดียว (Sole Source) ชิ้นส่วนสั่งทำพิเศษ ขาดตลาดง่าย นำเข้ายาก 2: มีผู้จัดจำหน่าย 2 ราย แต่ชิ้นส่วนมีราคาสูง ใช้เวลาจัดส่งนานเกิน 4 สัปดาห์ และไม่มีอะไหล่ทดแทน 3: ชิ้นส่วนมาตรฐานแต่มีบางโมดูลต้องสั่งนำเข้า มีระยะเวลารอคอย 2–3 สัปดาห์ 4: ใช้ชิ้นส่วนมาตรฐานอุตสาหกรรม (COTS) มีผู้ขายในประเทศหลายราย จัดหาทดแทนได้ใน 3–5 วัน 5: อะไหล่หาง่ายทั่วไปตามร้านค้าอุปกรณ์อิเล็กทรอนิกส์ในประเทศ ซื้อทดแทนได้ทันทีภายใน 24 ชม. | I8: 1: ไม่มีงบสำรองเลย หากชิ้นส่วนพังโครงการจะหยุดชะงักทันที (ราคาชิ้นส่วนเท่ากับงบประมาณทั้งหมด) 2: งบสำรองรองรับการเสียหายได้ไม่เกิน 1 ครั้ง ชิ้นส่วนสำคัญไม่มีอะไหล่สำรอง 3: มีงบสำรอง 20–30% ซื้อชิ้นส่วนราคาปานกลางสำรองได้ แต่ไม่มีอะไหล่สำหรับโมดูลหลักราคาแพง 4: มีงบสำรอง 50% มีชิ้นส่วนหลักและไอซีสำคัญสำรองอย่างน้อย 2–3 ชุด ทดลองได้อย่างมั่นใจ 5: งบประมาณเหลือเฟือ ชิ้นส่วนราคาถูกมาก สามารถซื้อชุดสำรองแบบสมบูรณ์ได้เกิน 3 ชุดขึ้นไป | J8: 1: เสี่ยงต่อการกระทำผิดกฎหมายอาญา ละเมิด พ.ร.บ. ทางหลวงอย่างร้ายแรง และไม่มีทางขออนุญาตได้ 2: ต้องขออนุญาตปิดการจราจรช่องทางหลัก เสี่ยงต่ออุบัติเหตุร้ายแรง และมีขั้นตอนอนุมัติยาวนาน 3: ต้องขออนุญาตทำงานในเขตทางสาธารณะ แต่เป็นงานขนาดเล็ก ใช้กรวยจราจรและป้ายเตือนชั่วคราว 4: ปฏิบัติงานบนทางเท้าหรือขอบทางได้โดยไม่กีดขวางการจราจร สอดคล้องตามระเบียบงานสาธารณูปโภค 5: ไม่กระทบต่อการจราจรและพื้นที่สาธารณะเลย ปฏิบัติการเสร็จสิ้นในเวลารวดเร็วโดยไม่ต้องขออนุญาตพิเศษ | K8: 1: ละเมิดสิทธิบัตรที่ยังมีผลคุ้มครองอย่างชัดเจน หรือใช้ซอฟต์แวร์ผิดสัญญาอนุญาตทางการค้า 2: มีความคลุมเครือด้านสิทธิบัตร มีความเสี่ยงที่จะถูกฟ้องร้องจากเจ้าของเทคโนโลยีเดิม 3: ใช้ไลบรารีที่มีสัญญาอนุญาตแบบ Copyleft เข้มงวด (เช่น AGPL) ซึ่งบังคับให้ต้องเปิดเผยซอร์สโค้ดทั้งหมด 4: ซอฟต์แวร์และฮาร์ดแวร์อยู่ภายใต้สัญญาอนุญาตแบบเสรี (Permissive License เช่น MIT, BSD, Apache 2.0) 5: เทคโนโลยีเป็นสาธารณสมบัติ (Public Domain) สิทธิบัตรหมดอายุแล้ว หรือสร้างสรรค์ขึ้นใหม่ทั้งหมด | L8: 1: อุปกรณ์ติดค้างในท่อกลายเป็นสิ่งกีดขวางทางน้ำอย่างถาวร ต้องทุบถนนขุดลอกท่อเพื่อเก็บกู้ 2: การขัดข้องทำให้ระบบประเมินค่าผิดพลาดจนส่งผลให้เกิดน้ำท่วมขัง และการเก็บกู้ต้องใช้เครื่องมือหนัก 3: อุปกรณ์หยุดทำงานแต่สามารถดึงสายสลิงเก็บกู้ได้ง่าย โดยไม่ส่งผลกระทบต่อการไหลของน้ำ 4: ระบบขัดข้องเฉพาะบางเซนเซอร์ ยังสามารถประเมินผลเบื้องต้นได้ และเก็บกู้ได้ทันทีโดยสลักนิรภัย 5: ทำงานจากผิวดินแบบ Fail-Safe 100% หากระบบหยุดทำงานก็ไม่มีชิ้นส่วนใดค้างอยู่ในท่อระบายน้ำ | M8: 1: ขัดแย้งกับขั้นตอนการทำงานเดิมโดยสิ้นเชิง เจ้าหน้าที่ปฏิเสธการใช้งานเพราะยุ่งยากและอันตราย 2: ต้องใช้เวลาฝึกอบรมเจ้าหน้าที่นานเกิน 4 สัปดาห์ และต้องปรับเปลี่ยนขั้นตอนการทำงานเกือบทั้งหมด 3: เจ้าหน้าที่ยอมรับได้แต่ต้องมีขั้นตอนพิเศษเพิ่มเติม เช่น การต่อสายไฟและตั้งค่าหน้างานหลายขั้นตอน 4: ใช้งานง่าย สอดคล้องกับขั้นตอนการตรวจท่อปกติ เจ้าหน้าที่เรียนรู้การทำงานได้ภายใน 1 วัน 5: ใช้งานได้ทันทีโดยไม่ต้องเปลี่ยนพฤติกรรมเดิม (Zero-learning curve) ออกแบบตามสรีรศาสตร์หน้างาน | N8: 1: ต้องใช้ห้องปฏิบัติการพิเศษที่มีการควบคุมความปลอดภัยสูง ต้องทำเรื่องขออนุมัติล่วงหน้าหลายสัปดาห์ 2: พึ่งพาเครื่องจักรหนักในช็อปวิศวกรรม มีคิวรอใช้งานยาวนาน และเข้าใช้งานได้เฉพาะเวลาทำการ 3: ต้องการพื้นที่ทดสอบจำลองขนาดใหญ่ในแล็บ แต่สามารถจัดสรรเวลาทำงานร่วมกับทีมอื่นได้ 4: ใช้อุปกรณ์ในแล็บทั่วไป มีความพร้อมใช้งานสูง และสามารถนำกลับไปทดสอบต่อที่หอพักได้ 5: พัฒนาและทดสอบได้ทุกที่อย่างอิสระ ไม่ต้องพึ่งพาห้องแล็บหรือการอนุมัติเชิงบริหารใดๆ ทั้งสิ้น | O8: 1: มีขั้นตอนซับซ้อนเกิน 10 ขั้นตอน ต้องปรับเทียบเซนเซอร์และต่อสายสัญญาณยุ่งยากหน้างาน 2: มีขั้นตอน 7–10 ขั้นตอน ต้องใช้คอมพิวเตอร์ตั้งโต๊ะและอุปกรณ์เสริมหลายชิ้นในการเริ่มระบบ 3: มีขั้นตอน 4–6 ขั้นตอน ต้องเชื่อมต่อสายสัญญาณและเปิดโปรแกรมตามลำดับที่กำหนด 4: มีขั้นตอน 2–3 ขั้นตอน เพียงเปิดสวิตช์และกดปุ่มเริ่มทำงาน ระบบจะปรับเทียบตัวเองโดยอัตโนมัติ 5: ทำงานแบบสัมผัสเดียว (One-Touch Operation) เสียบปลั๊ก/เปิดเครื่องแล้วเริ่มประมวลผลได้ทันที | P8: 1: ไม่สามารถทำเสร็จได้ทันใน 5 สัปดาห์แน่นอน ต้องใช้เวลาพัฒนาอย่างน้อย 10–12 สัปดาห์ขึ้นไป 2: มีความเสี่ยงสูงมากที่จะล่าช้า งานวิจัยและพัฒนาชิ้นส่วนกลไกอาจกินเวลาเกินกว่า 6 สัปดาห์ 3: มีความเป็นไปได้แต่ตึงเครียดมาก ต้องทำงานล่วงเวลาและตัดทอนฟังก์ชันย่อยบางส่วนออก 4: มีความเป็นไปได้สูง แผนงานสอดคล้องกับศักยภาพทีม มีเวลาทดสอบระบบรวมอย่างน้อย 1 สัปดาห์ 5: มั่นใจว่าเสร็จสมบูรณ์ก่อนกำหนด มีต้นแบบที่ทำงานได้ในสัปดาห์ที่ 3 และมีเวลาปรับแต่งอย่างเต็มที่ | Q8: 1: สร้างภาพลักษณ์สีเขียวโดยไม่มีผลกระทบเชิงประจักษ์ (Greenwashing) หรือไม่ตอบโจทย์ SDG ชั้นใดเลย 2: ตอบโจทย์เฉพาะชั้นเศรษฐกิจหรือสังคมอย่างผิวเผิน แต่ไม่มีผลกระทบต่อการอนุรักษ์ชีวมณฑล (Biosphere) 3: มีผลกระทบเชิงบวกที่ชัดเจนใน 1 มิติ (เช่น ป้องกันน้ำท่วมในมิติสังคม หรือลดขยะในมิติชีวมณฑล) 4: บูรณาการอย่างเข้มแข็งข้าม 2 มิติ (เช่น ชีวมณฑลด้านการจัดการน้ำ ร่วมกับสังคมเมืองที่ปลอดภัย) 5: บูรณาการครบทั้ง 3 ชั้นของ SDG Wedding Cake: ชีวมณฑล (น้ำสะอาด) + สังคม (เมืองยั่งยืน) + เศรษฐกิจ (คุ้มค่า) | R8: 1: ก่อให้เกิดอันตรายจากสารพิษ แบตเตอรี่รั่วไหล หรืออุปกรณ์หลุดลอยลงสู่แหล่งน้ำสาธารณะเป็นขยะมลพิษ 2: อายุการใช้งานสั้น เซนเซอร์สึกกร่อนหรือเสียหายภายใน 2–3 สัปดาห์ และยากต่อการเก็บกู้คืน 3: มีขยะอิเล็กทรอนิกส์ตามมาตรฐาน ต้องเปลี่ยนแบตเตอรี่เป็นรอบๆ แต่มีสายโยงป้องกันการสูญหายในท่อ 4: ตัวกล่องทนทาน ใช้พลังงานต่ำ ใช้วัสดุรีไซเคิลได้ และมีสลิงสแตนเลสคู่ป้องกันการหลุดหาย 5: หมุนเวียนสมบูรณ์และไร้รอยเท้าสิ่งแวดล้อม กู้คืนได้ 100% จากผิวดิน ใช้วัสดุไม่เป็นพิษและไม่ทิ้งขยะตกค้าง | S8: เกณฑ์รวม: >=80 ผ่านสูง, >=60 มีเงื่อนไข, <60 เสี่ยงสูง | หากมีข้อใดได้ 1 = VETOED ตกเกณฑ์ทันที
A9: คะแนนที่ได้รับ (ASSIGNED SCORE: 1, 2, 3, 4, 5 STRICT INTEGER) | B9: 3 | C9: 5 | D9: 3 | E9: 4 | F9: 4 | G9: 4 | H9: 5 | I9: 4 | J9: 3 | K9: 5 | L9: 5 | M9: 3 | N9: 5 | O9: 4 | P9: 4 | Q9: 5 | R9: 5 | S9: =IF(S10>0, (S11/S10)*20, 0)
A10: ค่าน้ำหนัก (Weight %) | B10: 0.04 | C10: 0.04 | D10: 0.04 | E10: 0.04 | F10: 0.04 | G10: 0.0667 | H10: 0.0667 | I10: 0.0666 | J10: 0.075 | K10: 0.075 | L10: 0.05 | M10: 0.05 | N10: 0.05 | O10: 0.05 | P10: 0.15 | Q10: 0.05 | R10: 0.05 | S10: =SUM(B10:R10)
A11: คะแนนถ่วงน้ำหนัก (=Score * Weight) | B11: =B9*B10 | C11: =C9*C10 | D11: =D9*D10 | E11: =E9*E10 | F11: =F9*F10 | G11: =G9*G10 | H11: =H9*H10 | I11: =I9*I10 | ... R11: =R9*R10 | S11: =SUM(B11:R11)
A12: คำอธิบาย & หลักฐานอ้างอิงจากไฟล์ Intake (Evidence Citation) | B12: solution-details/solution-2.md lines 33-36; combines standard COTS compression driver horn, precision condenser mic, MAX98357 I2S audio amp, and ESP32 with 3D printed manhole acoustic baffles. | C12: solution-details/solution-2.md lines 27-36; open-source audio DSP algorithms, public EPA SL-RAT mathematical standards, standard Python/SciPy signal processing libraries, and full root developer control on ESP32/STM32. | D12: solution-details/solution-2.md lines 15, 31, 38-42; Airborne acoustic reflectometry is an EPA-verified commercial standard (TRL 7-8). Under the newly confirmed constraint of <=20% water depth, 80%+ pipe airspace is open, ensuring robust acoustic propagation; custom student prototype operates at TRL 5-6 requiring water-level compensation baseline calibration. | E12: team-skills/due.md, jk.md, kin.md; Due has verified hardware experience building MAX98357 audio amp & ESP32 circuits; JK handles DSP math & Fourier analysis; Kin handles data ingestion & scoring backend. | F12: team-skills/due.md, jk.md; team has built audio amplifiers and implemented DSP bandpass filtering in previous projects; ramp-up only requires configuring I2S audio sampling and attenuation lookup tables. | G12: solution-details/solution-2.md lines 6-7, 15, 38; 2-person crew inspects 2–3 km/day in under 3 minutes per segment. Under confirmed <=20% water depth, covers ~80-90% of gravity lateral drainage networks without dewatering pumps, achieving rapid payback in 1-2 years. | H12: solution-details/solution-2.md lines 33-36; 100% generic electronic and acoustic components (compression driver speaker, condenser mic, ESP32); self-serviceable by any engineer with zero proprietary vendor lock-in. | I12: team-skills/due.md; total hardware BOM for audio driver, mic capsule, amplifier, and ESP32 is very low (< 3,000 THB total), allowing the team to purchase 3x full sets of backup components comfortably. | J12: solution-details/solution-2.md lines 27-29; requires opening manhole covers for 3 minutes from sidewalk/road edge; rapid turnaround substantially lowers traffic impact compared to rovers, but requires standard municipal maintenance protocol. | K12: solution-details/solution-2.md lines 31, 34-36; EPA SL-RAT acoustic inspection methodology and mathematical attenuation formulations are in the public domain and widely published in academic literature; open-source SciPy algorithms. | L12: solution-details/solution-2.md lines 27-29, 39; system operates strictly from the surface above the wastewater line; if battery dies or audio fails, the operator simply pulls up the pole; zero risk of blocking pipe. | M12: solution-details/solution-2.md lines 15, 27-31, 41-42; Lightweight handheld poles take < 3 minutes per manhole pair. Since water depth is constrained <=20%, field crews can operate with clear air space without crawler retrieval hassles, requiring only simple manhole opening protocol. | N12: team-skills/due.md, jk.md; audio circuitry and DSP code development can be tested entirely on dorm/lab bench using PVC pipe sections with zero machine shop gatekeeping. | O12: solution-details/solution-2.md lines 27-36; straightforward transmitter-receiver setup with standard ESP32 Arduino/PlatformIO toolchain and automated signal analysis script. | P12: schedule-details/schedule.md lines 8-15; electronic schematics and acoustic software can be finalized in 2 weeks; breadboard PoC achievable before midterm with production testing in Weeks 11-13. | Q12: solution-details/solution-2.md lines 6-10, 15; completely unites Biosphere (SDG 6.3 preventing sewer blockages and dirty overflow), Society (SDG 11.5 urban flood mitigation), and Economy (SDG 8.2 & 12.2 optimizing municipal maintenance resources). | R12: solution-details/solution-2.md lines 38-40; 100% fail-safe surface retrieval; zero electronic components or toxic batteries enter wastewater; ultra-low power consumption with rechargeable lithium cells. | S12: =IF(MIN(B9:R9)=1, "VETOED / ตกเกณฑ์ข้อบังคับวิกฤต (คะแนนระดับ 1)", IF(S9>=80, "ผ่านเกณฑ์ระดับสูง (HIGHLY VIABLE)", IF(S9>=60, "ผ่านแบบมีเงื่อนไข (CONDITIONALLY VIABLE)", "ความเสี่ยงสูง (HIGH RISK)")))
A13: แผนลดขอบเขตงาน & มาตรการลดความเสี่ยง (De-scoping Action) | B13: Use modular 3D-printed acoustic impedance horns and commercial I2S microphone/DAC breakout boards to eliminate custom analog PCB revisions. | C13: Implement standard Python/NumPy FFT processing pipeline without proprietary vendor licenses. | D13: Establish a baseline acoustic lookup table on dry and 10-20% flooded PVC pipe mockups before field deployment. | E13: Maintain shared PlatformIO project repo and DSP simulation Jupyter notebook so Due, JK, and Kin can cross-debug. | F13: Utilize existing SciPy signal processing functions rather than deriving custom C++ Fourier transforms from scratch. | G13: Focus initial pilot deployment on high-clogging commercial gravity pipes to demonstrate immediate budget savings. | H13: Select components readily stocked by local electronics distributors (Ban Mo / Shopee TH / INEX). | I13: Pre-purchase 3 complete sets of ESP32 boards, MAX98357 amplifiers, and microphone capsules upfront. | J13: Coordinate testing on KMUTT campus drainage manholes to avoid public street traffic jurisdiction. | K13: Rely exclusively on open academic acoustic reflectometry papers and MIT/Apache-licensed DSP libraries. | L13: Attach safety wrist straps to acoustic wand poles to prevent accidental drops into the manhole. | M13: Provide a simple color-coded LED traffic light display (Green/Yellow/Red) on the pole to indicate blockage score without requiring laptop viewing. | N13: Build a tabletop PVC drainage test pipe in the dorm to conduct all acoustic wave tuning. | O13: Automate chirp triggering via a single physical pushbutton on the transmitter horn unit. | P13: Freeze hardware architecture at Week 9 and focus remaining sprint entirely on software calibration. | Q13: Frame capstone report explicitly using the Stockholm Resilience Centre SDG Wedding Cake model. | R13: Package surface pole electronics in reusable IP65 ABS plastic instrument enclosures. | S13: ปฏิบัติตามแผนลดขอบเขตงาน (De-scoping Advisory)
A15: ตารางสรุปคะแนนแยกตามมิติ TELOS+S (Pillar Score Breakdown)
A16: มิติการประเมิน (TELOS+S Pillar) | B16: สัดส่วนน้ำหนัก (Weight %) | C16: คะแนนเต็มมิติ (Max Points) | D16: คะแนนที่ได้รับจริง (Earned Points) | E16: คะแนนเฉลี่ย (Score 1-5) | F16: ระดับความพร้อม (Readiness Level)
A17: T : ด้านเทคโนโลยีและวิศวกรรม (Technical) | B17: 0.2 | C17: 20 | D17: =SUM(B11:F11)*20 | E17: =IF(C17>0, (D17/C17)*5, 0) | F17: =IF(D17>=16.0, "พร้อมระดับสูง (High)", IF(D17>=12.0, "ปานกลาง (Medium)", "เสี่ยงวิกฤต (Critical)"))
A18: E : ด้านเศรษฐศาสตร์และความคุ้มค่า (Economic) | B18: 0.2 | C18: 20 | D18: =SUM(G11:I11)*20 | E18: =IF(C18>0, (D18/C18)*5, 0) | F18: =IF(D18>=16.0, "พร้อมระดับสูง (High)", IF(D18>=12.0, "ปานกลาง (Medium)", "เสี่ยงวิกฤต (Critical)"))
A19: L : ด้านกฎหมาย ระเบียบ และภาคประชาชน (Legal & Outreach) | B19: 0.15 | C19: 15 | D19: =SUM(J11:K11)*20 | E19: =IF(C19>0, (D19/C19)*5, 0) | F19: =IF(D19>=12.0, "พร้อมระดับสูง (High)", IF(D19>=9.0, "ปานกลาง (Medium)", "เสี่ยงวิกฤต (Critical)"))
A20: O : ด้านการปฏิบัติการและหน้างาน (Operational) | B20: 0.2 | C20: 20 | D20: =SUM(L11:O11)*20 | E20: =IF(C20>0, (D20/C20)*5, 0) | F20: =IF(D20>=16.0, "พร้อมระดับสูง (High)", IF(D20>=12.0, "ปานกลาง (Medium)", "เสี่ยงวิกฤต (Critical)"))
A21: S : ด้านแผนงานและเวลาส่งมอบ (Schedule) | B21: 0.15 | C21: 15 | D21: =P11*20 | E21: =IF(C21>0, (D21/C21)*5, 0) | F21: =IF(D21>=12.0, "พร้อมระดับสูง (High)", IF(D21>=9.0, "ปานกลาง (Medium)", "เสี่ยงวิกฤต (Critical)"))
A22: +S : ด้านความยั่งยืนและสิ่งแวดล้อม (Sustainability / SDG) | B22: 0.1 | C22: 10 | D22: =SUM(Q11:R11)*20 | E22: =IF(C22>0, (D22/C22)*5, 0) | F22: =IF(D22>=8.0, "พร้อมระดับสูง (High)", IF(D22>=6.0, "ปานกลาง (Medium)", "เสี่ยงวิกฤต (Critical)"))
A23: คะแนนรวมทุกมิติ (Total Feasibility Score) | B23: =SUM(B17:B22) | C23: =SUM(C17:C22) | D23: =SUM(D17:D22) | E23: =IF(C23>0, (D23/C23)*5, 0) | F23: =IF(D23>=80, "ผ่านเกณฑ์ระดับสูง (HIGHLY VIABLE)", IF(D23>=60, "ผ่านแบบมีเงื่อนไข (CONDITIONALLY VIABLE)", "ความเสี่ยงสูง (HIGH RISK)"))
A25: เมทริกซ์ประเมินความเข้ากันได้กับองค์ความรู้ด้านวิศวกรรมหุ่นยนต์ (Robotics Knowledge Compatibility)
A26: * หมายเหตุ: การประเมินส่วนนี้วัดศักยภาพในการประยุกต์ใช้องค์ความรู้ด้านวิศวกรรมหุ่นยนต์ (Perception, Control, Actuation) เต็ม 12 คะแนน (แกนละ 4 คะแนน) | เป็นเอกเทศ ไม่นับรวมในคะแนน TELOS 100 คะแนน
A27: มิติการประเมิน (Robotics Dimension) | B27: คะแนนศักยภาพ (/12) | C27: แกน Perception & Sensing (การรับรู้) | D27: แกน Control & Algorithms (การควบคุม) | E27: แกน Actuation & Mechanisms (กลไก) | F27: บทวิเคราะห์เชิงวิศวกรรมหุ่นยนต์ (FIBO Alignment Rationale)
A28: ศักยภาพการประยุกต์ใช้องค์ความรู้หุ่นยนต์และระบบอัตโนมัติ | B28: 8.5 | C28: Score 3.5/4.0: Active airborne acoustic reflectometry transducer, swept-sine/chirp acoustic wave excitation, and precision condenser microphone array capturing acoustic impulse response. | D28: Score 3.5/4.0: Digital signal processing (DSP), acoustic energy attenuation deconvolution, spectral bandpass filtering, and automated 0-10 EPA SL-RAT cleanliness score generation. | E28: Score 1.5/4.0: High-output acoustic compression driver transducer with telescoping manhole deployment rig; non-mobile surface-operated payload. | F28: Solution 2 exercises FIBO signal processing, acoustical physics, digital filtering, and sensor interface engineering without unnecessary mechanical locomotion risks in underground sewage.

Sheet Solution_1_CCTV_Crawler
A1: เมทริกซ์ประเมินความเป็นไปได้เชิงระบบ TELOS+S: Solution 1: Pipe Inspection Robot using CCTV for profiling pipe (4K PTZ Camera + YOLOv8 Wheeled Crawler)
A2: ระบบคะแนนจำนวนเต็มเด็ดขาด: 1, 2, 3, 4, 5 เท่านั้น (ไม่มีจุดทศนิยม / ไม่มี 0.5) | โครงสร้างแบบ Transposed แนวนอน
A4: รหัสคำถาม (Question Code) | B4: T-01 | C4: T-02 | D4: T-03 | E4: T-04 | F4: T-05 | G4: E-01 | H4: E-02 | I4: E-03 | J4: L-01 | K4: L-02 | L4: O-01 | M4: O-02 | N4: O-03 | O4: O-04 | P4: S-01 | Q4: SDG-01 | R4: SDG-02 | S4: สรุปภาพรวม (SUMMARY)
A5: มิติการประเมิน (TELOS+S Pillar) | B5: ด้านเทคนิค (Technical 2.2) | C5: ด้านเทคนิค (Technical 2.2) | D5: ด้านเทคนิค (Technical 2.2) | E5: ด้านเทคนิค (Technical 2.2) | F5: ด้านเทคนิค (Technical 2.2) | G5: ด้านเศรษฐศาสตร์ (Economic 2.3) | H5: ด้านเศรษฐศาสตร์ (Economic 2.3) | I5: ด้านเศรษฐศาสตร์ (Economic 2.3) | J5: ด้านกฎหมาย (Legal 2.4) | K5: ด้านกฎหมาย (Legal 2.4) | L5: ด้านปฏิบัติการ (Operational 2.5) | M5: ด้านปฏิบัติการ (Operational 2.5) | N5: ด้านปฏิบัติการ (Operational 2.5) | O5: ด้านปฏิบัติการ (Operational 2.5) | P5: ด้านแผนงาน (Schedule 2.6) | Q5: ความยั่งยืน (SDGs 2.7) | R5: ความยั่งยืน (SDGs 2.7) | S5: ผลรวมทุกมิติ (All Pillars)
A6: คำถามทดสอบความเสี่ยงจริง (Stress-Test Question) | B6: ระดับการสร้างเองเทียบกับการซื้อสำเร็จรูป (Build vs. Buy Burden) ของสถาปัตยกรรมระบบตรวจประเมินท่อระบายน้ำ? | C6: สิทธิ์ในการเข้าถึงเทคโนโลยี ซอฟต์แวร์ และระบบนิเวศข้อมูล (Access & Permissions) ของระบบตรวจประเมินท่อ? | D6: ระดับความพร้อมทางเทคโนโลยี (Base Performance / TRL) ในสภาพแวดล้อมจริงของท่อระบายน้ำใต้ดิน? | E6: ความเข้ากันได้ของทีม (Manpower & Skill Redundancy) ด้านวิศวกรรมเฉพาะทาง? | F6: ความชันของเส้นทางการเรียนรู้ (Learning Curve) ด้านวิศวกรรมระบบ? | G6: ระยะเวลาคืนทุนและความคุ้มค่าในการลงทุน (Payback Period / Value Horizon) ของระบบ? | H6: ระดับการพึ่งพาชิ้นส่วนและผู้จัดจำหน่ายภายนอก (Component Dependency & Vendor Lock-in)? | I6: สัดส่วนงบประมาณสำรองความเสียหาย (Scrap Margin / Safety Allowance) ของชิ้นส่วน? | J6: ความสอดคล้องกับกฎหมายความปลอดภัยสาธารณะและการจราจร (Regulatory & Public Safety Compliance)? | K6: ทรัพย์สินทางปัญญา ลิขสิทธิ์ซอฟต์แวร์ และสิทธิบัตร (IP & Software Licensing)? | L6: ผลกระทบต่อระบบหากเกิดความล้มเหลวขณะปฏิบัติงาน (Operational Failure Impact)? | M6: ความสอดคล้องกับพฤติกรรมผู้ใช้และสภาพหน้างานจริง (User Behavior & Problem-Solution Fit)? | N6: การพึ่งพาห้องปฏิบัติการและขั้นตอนเชิงบริหารของนักพัฒนา (Administrative & Lab Dependency)? | O6: ความซับซ้อนของขั้นตอนการประมวลผลและการเตรียมระบบ (Step Count & Pipeline Friction)? | P6: ความพร้อมของระบบและการส่งมอบต้นแบบภายในกรอบเวลา 5 สัปดาห์ทำงาน (Design Maturity & Schedule Compliance)? | Q6: ผลกระทบต่อสิ่งแวดล้อม สังคม และเศรษฐกิจตามกรอบ SDG Wedding Cake (Biosphere, Society, Economy)? | R6: รอยเท้าสิ่งแวดล้อม ขยะอิเล็กทรอนิกส์ และระบบเก็บกู้ที่ปลอดภัย (Environmental Footprint & E-Waste Safeguards)? | S6: ประเมินคำถามทั้งสิ้น 17 ข้อ
A7: เหตุผลในการถาม & โหมดความล้มเหลวที่เฝ้าระวัง (Rationale) | B7: ประเมินภาระการวิจัยและพัฒนาชิ้นส่วนกลไก อิเล็กทรอนิกส์ และอัลกอริทึม ป้องกันการเสียเวลากับงานประดิษฐ์ขึ้นใหม่โดยไม่จำเป็น | C7: ตรวจสอบข้อจำกัดด้านกรรมสิทธิ์ การล็อกสิทธิ์ใช้งาน และการอนุญาตเข้าถึง เพื่อป้องกันการพัฒนาระบบบนฐานข้อมูลที่ไม่สามารถเข้าถึงได้จริง | D7: วัดวุฒิภาวะของเทคโนโลยีว่าผ่านการพิสูจน์ในสภาพแวดล้อมใต้ดินที่มีความชื้น สารกัดกร่อน หรือน้ำขังจริงแล้วหรือไม่ | E7: ประเมินความเสี่ยงกรณีขาดแคลนบุคลากรที่มีความเชี่ยวชาญเฉพาะด้าน (Bus Factor) ว่ามีคนทำงานทดแทนกันได้หรือไม่ | F7: ประเมินเวลาและความยากในการเรียนรู้เทคโนโลยีใหม่ ว่าทีมงานสามารถเข้าใจและนำมาใช้ได้ทันเวลาหรือไม่ | G7: ประเมินผลตอบแทนทางเศรษฐศาสตร์และการลดต้นทุนการขุดลอกท่อระบายน้ำของหน่วยงานรัฐ | H7: ประเมินความเสี่ยงด้านห่วงโซ่อุปทานและการผูกขาดชิ้นส่วน ป้องกันระบบล่มสลายจากผู้ผลิตรายเดียว | I7: ตรวจสอบความปลอดภัยทางการเงินกรณีทำอุปกรณ์เสียหายระหว่างการทดลองในน้ำเสีย | J7: ประเมินความเสี่ยงการละเมิดกฎหมายควบคุมอาคาร ระเบียบงานทาง และข้อบังคับการจราจรขณะปฏิบัติงาน | K7: ตรวจสอบความปลอดภัยด้านสิทธิบัตรเพื่อป้องกันการถูกฟ้องร้องละเมิดทรัพย์สินทางปัญญา | L7: ประเมินความรุนแรงของผลกระทบกรณีระบบขัดข้อง ว่าทำให้อุดตันท่อหรือระบบระบายน้ำเสียหายหรือไม่ | M7: ประเมินความสะดวกของเจ้าหน้าที่หน้างาน ว่าระบบใช้งานง่ายและตอบสนองขั้นตอนการทำงานจริงหรือไม่ | N7: ประเมินความคล่องตัวในการพัฒนา ว่าต้องรอการอนุมัติหรือติดขัดการใช้ห้องแล็บเฉพาะทางหรือไม่ | O7: วัดจำนวนขั้นตอนและความยุ่งยากในการเตรียมระบบก่อนเริ่มใช้งานจริง | P7: ประเมินความเป็นไปได้ในการสร้าง ทดสอบ และส่งมอบต้นแบบวิศวกรรมให้เสร็จทันกำหนด 5 สัปดาห์ | Q7: ประเมินคุณค่าที่แท้จริงต่อเป้าหมายการพัฒนาที่ยั่งยืน 3 ชั้น ป้องกันการสร้างภาพลักษณ์สีเขียว (Greenwashing) | R7: ตรวจสอบการป้องกันขยะอิเล็กทรอนิกส์ตกค้างในท่อระบายน้ำ สารพิษรั่วไหล และระบบกู้คืนอุปกรณ์ที่ปลอดภัย 100% | S7: สังเคราะห์จาก AI Agents Group 2
A8: เกณฑ์การให้คะแนน (Scoring Rubric Definition: ระดับ 1, 2, 3, 4, 5 ครบทุกระดับ) | B8: 1: ต้องวิจัยและสร้างขึ้นเองทั้งหมด 100% (ไม่มีพิมพ์เขียว อัลกอริทึม หรือไลบรารีอ้างอิง) 2: มีชิ้นส่วนหลักในท้องตลาด แต่ต้องดัดแปลงโครงสร้างอย่างหนักและเขียนโค้ดเชื่อมต่อเองทั้งหมด 3: บูรณาการชิ้นส่วน COTS เข้ากับแท่นยึดแบบกำหนดเอง และเขียนโค้ดเชื่อมต่อบางส่วน 4: ประกอบจากโมดูลมาตรฐานสำเร็จรูป (DIN-rail, I2C/CAN shields) มีงานประกอบกลไกเล็กน้อย 5: ซื้อมาติดตั้งใช้งานได้ทันที (Plug-and-Play) ไม่ต้องตัดกลึงหรือบัดกรีวงจรเพิ่มเติม | C8: 1: ล็อกสิทธิ์ภายใต้สัญญา NDA ระบบปิด ติดไฟร์วอลล์องค์กร หรือไม่มีสิทธิ์เข้าถึงฝั่งนักพัฒนา 2: ซอฟต์แวร์หรือเฟิร์มแวร์กรรมสิทธิ์ปิด ทำงานแบบ Black-box โดยไม่มี Source Code หรือ Telemetry 3: บัญชีเพื่อการศึกษา/ทดลองใช้ที่มีโควตาหรือ Rate Limit เข้มงวด ต้องรอการอนุมัติอย่างเป็นทางการ 4: มี SDK หรือ Open API สาธารณะพร้อมเอกสารครบถ้วน แต่ไม่สามารถแก้ไขสถาปัตยกรรมระดับล่างได้ 5: สถาปัตยกรรมเปิดสมบูรณ์ (Open Source/Open HW) ทีมงานมีสิทธิ์ระดับ Root/Admin เต็มรูปแบบ | D8: 1: ระดับแนวคิด/สมการคณิตศาสตร์ (TRL 2–3) ทดสอบเฉพาะในห้องทดลองที่ควบคุมสภาพแวดล้อมได้ 2: เบรดบอร์ดทำงานได้ในแล็บ (TRL 4) สายไฟเปราะบาง ยังไม่ผ่านการสอบเทียบในสภาพแวดล้อมจริง 3: ตัวต้นแบบประกอบลงกล่อง (TRL 5–6) ผ่านการทดสอบในสภาพแวดล้อมจำลอง ต้องมีคนคอยดูแล 4: ต้นแบบระดับพรีโปรดักชัน (TRL 7) ทำงานได้อย่างมีเสถียรภาพในสภาพแวดล้อมปฏิบัติงานจริง 5: ผลิตภัณฑ์เชิงพาณิชย์สมบูรณ์ (TRL 8–9) ผ่านการรับรองมาตรฐาน มีค่า MTBF ยืนยันความทนทาน | E8: 1: ขาดแคลนทักษะเฉพาะด้านโดยสิ้นเชิง (ไม่มีใครในทีมมีความรู้ในเทคโนโลยีหลักนี้เลย) 2: พึ่งพาผู้เชี่ยวชาญเพียงคนเดียว (Bus Factor = 1) หากคนนี้ไม่อยู่ โครงการจะหยุดชะงักทันที 3: มีผู้รับผิดชอบหลัก 1 คน และมีผู้ช่วยที่พอเข้าใจระบบ แต่ยังแก้ไขปัญหาเชิงลึกแทนไม่ได้ 4: มีทักษะทดแทนกันได้ (Primary & Secondary) อย่างน้อย 2 คนสามารถสลับงานกันได้อย่างราบรื่น 5: สมาชิกทุกคนในทีมมีทักษะระดับสูง ทำงานแทนกันได้ทันที และมีเอกสารคู่มือการทำงานครบถ้วน | F8: 1: เทคโนโลยีใหม่ทั้งหมด ต้องใช้เวลาเรียนรู้เกิน 8 สัปดาห์ และต้องการทักษะคณิตศาสตร์ชั้นสูง 2: มีแนวคิดซับซ้อน ต้องศึกษาทฤษฎีใหม่ที่ไม่เคยเรียนมาก่อน ใช้เวลาทำความเข้าใจ 4–6 สัปดาห์ 3: ต่อยอดจากพื้นฐานเดิมที่เคยเรียน แต่ต้องเรียนรู้เครื่องมือหรือสถาปัตยกรรมใหม่ ใช้เวลา 2–3 สัปดาห์ 4: เป็นเทคโนโลยีที่คุ้นเคย มีตัวอย่างโค้ดและวงจรอ้างอิงชัดเจน ใช้เวลาปรับตัวเพียง 1 สัปดาห์ 5: ทำงานบนพื้นฐานทักษะประจำวันของทีม ทำได้ทันทีโดยไม่ต้องศึกษาทฤษฎีหรือเครื่องมือเพิ่มเติม | G8: 1: ระยะเวลาคืนทุนเกิน 7 ปี หรือต้นทุนการดำเนินงานสูงกว่ามูลค่าความเสียหายที่ป้องกันได้ 2: ระยะเวลาคืนทุน 5–7 ปี ให้ผลตอบแทนทางอ้อมเป็นหลัก และมีความไม่แน่นอนทางการเงินสูง 3: ระยะเวลาคืนทุน 3–5 ปี มีความคุ้มค่าระดับปานกลาง จำเป็นต้องได้รับการอุดหนุนงบประมาณจากรัฐ 4: ระยะเวลาคืนทุน 1–3 ปี ประหยัดค่าใช้จ่ายการซ่อมบำรุงเชิงแก้ไขได้อย่างชัดเจน คุ้มค่าสูง 5: คืนทุนได้ภายใน 1 ปีแรก ลดต้นทุนการบำรุงรักษาได้ทันที และสร้างมูลค่าเพิ่มทางตรงอย่างมหาศาล | H8: 1: ผูกขาดโดยผู้ผลิตรายเดียว (Sole Source) ชิ้นส่วนสั่งทำพิเศษ ขาดตลาดง่าย นำเข้ายาก 2: มีผู้จัดจำหน่าย 2 ราย แต่ชิ้นส่วนมีราคาสูง ใช้เวลาจัดส่งนานเกิน 4 สัปดาห์ และไม่มีอะไหล่ทดแทน 3: ชิ้นส่วนมาตรฐานแต่มีบางโมดูลต้องสั่งนำเข้า มีระยะเวลารอคอย 2–3 สัปดาห์ 4: ใช้ชิ้นส่วนมาตรฐานอุตสาหกรรม (COTS) มีผู้ขายในประเทศหลายราย จัดหาทดแทนได้ใน 3–5 วัน 5: อะไหล่หาง่ายทั่วไปตามร้านค้าอุปกรณ์อิเล็กทรอนิกส์ในประเทศ ซื้อทดแทนได้ทันทีภายใน 24 ชม. | I8: 1: ไม่มีงบสำรองเลย หากชิ้นส่วนพังโครงการจะหยุดชะงักทันที (ราคาชิ้นส่วนเท่ากับงบประมาณทั้งหมด) 2: งบสำรองรองรับการเสียหายได้ไม่เกิน 1 ครั้ง ชิ้นส่วนสำคัญไม่มีอะไหล่สำรอง 3: มีงบสำรอง 20–30% ซื้อชิ้นส่วนราคาปานกลางสำรองได้ แต่ไม่มีอะไหล่สำหรับโมดูลหลักราคาแพง 4: มีงบสำรอง 50% มีชิ้นส่วนหลักและไอซีสำคัญสำรองอย่างน้อย 2–3 ชุด ทดลองได้อย่างมั่นใจ 5: งบประมาณเหลือเฟือ ชิ้นส่วนราคาถูกมาก สามารถซื้อชุดสำรองแบบสมบูรณ์ได้เกิน 3 ชุดขึ้นไป | J8: 1: เสี่ยงต่อการกระทำผิดกฎหมายอาญา ละเมิด พ.ร.บ. ทางหลวงอย่างร้ายแรง และไม่มีทางขออนุญาตได้ 2: ต้องขออนุญาตปิดการจราจรช่องทางหลัก เสี่ยงต่ออุบัติเหตุร้ายแรง และมีขั้นตอนอนุมัติยาวนาน 3: ต้องขออนุญาตทำงานในเขตทางสาธารณะ แต่เป็นงานขนาดเล็ก ใช้กรวยจราจรและป้ายเตือนชั่วคราว 4: ปฏิบัติงานบนทางเท้าหรือขอบทางได้โดยไม่กีดขวางการจราจร สอดคล้องตามระเบียบงานสาธารณูปโภค 5: ไม่กระทบต่อการจราจรและพื้นที่สาธารณะเลย ปฏิบัติการเสร็จสิ้นในเวลารวดเร็วโดยไม่ต้องขออนุญาตพิเศษ | K8: 1: ละเมิดสิทธิบัตรที่ยังมีผลคุ้มครองอย่างชัดเจน หรือใช้ซอฟต์แวร์ผิดสัญญาอนุญาตทางการค้า 2: มีความคลุมเครือด้านสิทธิบัตร มีความเสี่ยงที่จะถูกฟ้องร้องจากเจ้าของเทคโนโลยีเดิม 3: ใช้ไลบรารีที่มีสัญญาอนุญาตแบบ Copyleft เข้มงวด (เช่น AGPL) ซึ่งบังคับให้ต้องเปิดเผยซอร์สโค้ดทั้งหมด 4: ซอฟต์แวร์และฮาร์ดแวร์อยู่ภายใต้สัญญาอนุญาตแบบเสรี (Permissive License เช่น MIT, BSD, Apache 2.0) 5: เทคโนโลยีเป็นสาธารณสมบัติ (Public Domain) สิทธิบัตรหมดอายุแล้ว หรือสร้างสรรค์ขึ้นใหม่ทั้งหมด | L8: 1: อุปกรณ์ติดค้างในท่อกลายเป็นสิ่งกีดขวางทางน้ำอย่างถาวร ต้องทุบถนนขุดลอกท่อเพื่อเก็บกู้ 2: การขัดข้องทำให้ระบบประเมินค่าผิดพลาดจนส่งผลให้เกิดน้ำท่วมขัง และการเก็บกู้ต้องใช้เครื่องมือหนัก 3: อุปกรณ์หยุดทำงานแต่สามารถดึงสายสลิงเก็บกู้ได้ง่าย โดยไม่ส่งผลกระทบต่อการไหลของน้ำ 4: ระบบขัดข้องเฉพาะบางเซนเซอร์ ยังสามารถประเมินผลเบื้องต้นได้ และเก็บกู้ได้ทันทีโดยสลักนิรภัย 5: ทำงานจากผิวดินแบบ Fail-Safe 100% หากระบบหยุดทำงานก็ไม่มีชิ้นส่วนใดค้างอยู่ในท่อระบายน้ำ | M8: 1: ขัดแย้งกับขั้นตอนการทำงานเดิมโดยสิ้นเชิง เจ้าหน้าที่ปฏิเสธการใช้งานเพราะยุ่งยากและอันตราย 2: ต้องใช้เวลาฝึกอบรมเจ้าหน้าที่นานเกิน 4 สัปดาห์ และต้องปรับเปลี่ยนขั้นตอนการทำงานเกือบทั้งหมด 3: เจ้าหน้าที่ยอมรับได้แต่ต้องมีขั้นตอนพิเศษเพิ่มเติม เช่น การต่อสายไฟและตั้งค่าหน้างานหลายขั้นตอน 4: ใช้งานง่าย สอดคล้องกับขั้นตอนการตรวจท่อปกติ เจ้าหน้าที่เรียนรู้การทำงานได้ภายใน 1 วัน 5: ใช้งานได้ทันทีโดยไม่ต้องเปลี่ยนพฤติกรรมเดิม (Zero-learning curve) ออกแบบตามสรีรศาสตร์หน้างาน | N8: 1: ต้องใช้ห้องปฏิบัติการพิเศษที่มีการควบคุมความปลอดภัยสูง ต้องทำเรื่องขออนุมัติล่วงหน้าหลายสัปดาห์ 2: พึ่งพาเครื่องจักรหนักในช็อปวิศวกรรม มีคิวรอใช้งานยาวนาน และเข้าใช้งานได้เฉพาะเวลาทำการ 3: ต้องการพื้นที่ทดสอบจำลองขนาดใหญ่ในแล็บ แต่สามารถจัดสรรเวลาทำงานร่วมกับทีมอื่นได้ 4: ใช้อุปกรณ์ในแล็บทั่วไป มีความพร้อมใช้งานสูง และสามารถนำกลับไปทดสอบต่อที่หอพักได้ 5: พัฒนาและทดสอบได้ทุกที่อย่างอิสระ ไม่ต้องพึ่งพาห้องแล็บหรือการอนุมัติเชิงบริหารใดๆ ทั้งสิ้น | O8: 1: มีขั้นตอนซับซ้อนเกิน 10 ขั้นตอน ต้องปรับเทียบเซนเซอร์และต่อสายสัญญาณยุ่งยากหน้างาน 2: มีขั้นตอน 7–10 ขั้นตอน ต้องใช้คอมพิวเตอร์ตั้งโต๊ะและอุปกรณ์เสริมหลายชิ้นในการเริ่มระบบ 3: มีขั้นตอน 4–6 ขั้นตอน ต้องเชื่อมต่อสายสัญญาณและเปิดโปรแกรมตามลำดับที่กำหนด 4: มีขั้นตอน 2–3 ขั้นตอน เพียงเปิดสวิตช์และกดปุ่มเริ่มทำงาน ระบบจะปรับเทียบตัวเองโดยอัตโนมัติ 5: ทำงานแบบสัมผัสเดียว (One-Touch Operation) เสียบปลั๊ก/เปิดเครื่องแล้วเริ่มประมวลผลได้ทันที | P8: 1: ไม่สามารถทำเสร็จได้ทันใน 5 สัปดาห์แน่นอน ต้องใช้เวลาพัฒนาอย่างน้อย 10–12 สัปดาห์ขึ้นไป 2: มีความเสี่ยงสูงมากที่จะล่าช้า งานวิจัยและพัฒนาชิ้นส่วนกลไกอาจกินเวลาเกินกว่า 6 สัปดาห์ 3: มีความเป็นไปได้แต่ตึงเครียดมาก ต้องทำงานล่วงเวลาและตัดทอนฟังก์ชันย่อยบางส่วนออก 4: มีความเป็นไปได้สูง แผนงานสอดคล้องกับศักยภาพทีม มีเวลาทดสอบระบบรวมอย่างน้อย 1 สัปดาห์ 5: มั่นใจว่าเสร็จสมบูรณ์ก่อนกำหนด มีต้นแบบที่ทำงานได้ในสัปดาห์ที่ 3 และมีเวลาปรับแต่งอย่างเต็มที่ | Q8: 1: สร้างภาพลักษณ์สีเขียวโดยไม่มีผลกระทบเชิงประจักษ์ (Greenwashing) หรือไม่ตอบโจทย์ SDG ชั้นใดเลย 2: ตอบโจทย์เฉพาะชั้นเศรษฐกิจหรือสังคมอย่างผิวเผิน แต่ไม่มีผลกระทบต่อการอนุรักษ์ชีวมณฑล (Biosphere) 3: มีผลกระทบเชิงบวกที่ชัดเจนใน 1 มิติ (เช่น ป้องกันน้ำท่วมในมิติสังคม หรือลดขยะในมิติชีวมณฑล) 4: บูรณาการอย่างเข้มแข็งข้าม 2 มิติ (เช่น ชีวมณฑลด้านการจัดการน้ำ ร่วมกับสังคมเมืองที่ปลอดภัย) 5: บูรณาการครบทั้ง 3 ชั้นของ SDG Wedding Cake: ชีวมณฑล (น้ำสะอาด) + สังคม (เมืองยั่งยืน) + เศรษฐกิจ (คุ้มค่า) | R8: 1: ก่อให้เกิดอันตรายจากสารพิษ แบตเตอรี่รั่วไหล หรืออุปกรณ์หลุดลอยลงสู่แหล่งน้ำสาธารณะเป็นขยะมลพิษ 2: อายุการใช้งานสั้น เซนเซอร์สึกกร่อนหรือเสียหายภายใน 2–3 สัปดาห์ และยากต่อการเก็บกู้คืน 3: มีขยะอิเล็กทรอนิกส์ตามมาตรฐาน ต้องเปลี่ยนแบตเตอรี่เป็นรอบๆ แต่มีสายโยงป้องกันการสูญหายในท่อ 4: ตัวกล่องทนทาน ใช้พลังงานต่ำ ใช้วัสดุรีไซเคิลได้ และมีสลิงสแตนเลสคู่ป้องกันการหลุดหาย 5: หมุนเวียนสมบูรณ์และไร้รอยเท้าสิ่งแวดล้อม กู้คืนได้ 100% จากผิวดิน ใช้วัสดุไม่เป็นพิษและไม่ทิ้งขยะตกค้าง | S8: เกณฑ์รวม: >=80 ผ่านสูง, >=60 มีเงื่อนไข, <60 เสี่ยงสูง | หากมีข้อใดได้ 1 = VETOED ตกเกณฑ์ทันที
A9: คะแนนที่ได้รับ (ASSIGNED SCORE: 1, 2, 3, 4, 5 STRICT INTEGER) | B9: 2 | C9: 5 | D9: 3 | E9: 3 | F9: 3 | G9: 3 | H9: 4 | I9: 2 | J9: 2 | K9: 5 | L9: 3 | M9: 3 | N9: 3 | O9: 2 | P9: 2 | Q9: 4 | R9: 3 | S9: =IF(S10>0, (S11/S10)*20, 0)
A10: ค่าน้ำหนัก (Weight %) | B10: 0.04 | C10: 0.04 | D10: 0.04 | E10: 0.04 | F10: 0.04 | G10: 0.0667 | H10: 0.0667 | I10: 0.0666 | J10: 0.075 | K10: 0.075 | L10: 0.05 | M10: 0.05 | N10: 0.05 | O10: 0.05 | P10: 0.15 | Q10: 0.05 | R10: 0.05 | S10: =SUM(B10:R10)
A11: คะแนนถ่วงน้ำหนัก (=Score * Weight) | B11: =B9*B10 | C11: =C9*C10 | D11: =D9*D10 | E11: =E9*E10 | F11: =F9*F10 | G11: =G9*G10 | H11: =H9*H10 | I11: =I9*I10 | ... R11: =R9*R10 | S11: =SUM(B11:R11)
A12: คำอธิบาย & หลักฐานอ้างอิงจากไฟล์ Intake (Evidence Citation) | B12: solution-details/solution-1.md lines 32-38; requires custom waterproof IP68 motor pods, sealed differential drivetrain, custom chassis fabrication for wastewater resistance, and tether reel slip-ring integration. | C12: solution-details/solution-1.md lines 33-36; utilizes open-source YOLOv8 architecture, standard RTSP video streaming, open Python/OpenCV stacks, and ESP32/STM32 motor control with full root/developer access. | D12: solution-details/solution-1.md lines 15, 40-49; CCTV pipe crawling is established commercially (TRL 8-9). With water depth confirmed <=20%, the PTZ camera sits in clear air space, avoiding murkiness, but student crawler wheels must negotiate sludge and grease, operating at TRL 5-6. | E12: team-skills/due.md, fifa.md, jk.md, kin.md; Fifa and Due form a primary/secondary mechanical engineering pair; JK and Kin handle computer vision and AI model training. | F12: team-skills/fifa.md, jk.md; team has proven experience in ROS2, OpenCV, and 3D CAD, but waterproofing rotary shafts, tether slip rings, and lighting calibration in reflective wet pipes require a 2-3 week ramp-up. | G12: solution-details/solution-1.md lines 6-7, 15, 43; condition-based visual inspection prevents unnecessary cleanings and provides actionable visual proof; moderate payback period of 3–4 years due to mechanical crawler deployment overhead. | H12: solution-details/solution-1.md lines 32-38; uses standard COTS DC gearmotors, standard USB/RTSP cameras, and open microcontrollers available from multiple domestic vendors. | I12: team-skills/due.md, fifa.md; waterproof crawler chassis, 4K PTZ camera, and high-spec tether cable consume over 60-70% of available team budget, leaving minimal spare funds if the primary camera or drive unit is flooded. | J12: solution-details/solution-1.md lines 18, 27; deploying wheeled crawler requires opening street manholes, stationing cable reels and operators on roadway shoulder for 30–60 minutes per section, requiring formal municipal work permits. | K12: solution-details/solution-1.md lines 35-36; YOLOv8 educational license, OpenCV (Apache 2.0), and open ROS2 packages provide full legal and intellectual property clearance. | L12: solution-details/solution-1.md lines 15, 46-49; operating in <=20% water depth avoids total submergence, but if crawler flips over or gets entangled in debris/grease, manual recovery via tether reel is required (O-01=3). | M12: solution-details/solution-1.md lines 6-7, 27-30; operators must carry crawler and heavy cable spool, wash down the muddy vehicle after each run, and coordinate crawler speed via manual joystick control. | N12: team-skills/due.md, fifa.md; mechanical chassis fabrication requires FIBO workshop 3D printers, laser cutters, and a water immersion pressure tank to verify IP68 sealing. | O12: solution-details/solution-1.md lines 27-38; multi-stage pipeline involves sealed mechanical deployment, tether spool uncoiling, video transmission handshake, and post-processing AI inference pipeline. | P12: schedule-details/schedule.md lines 8-15; designing, machining, waterproofing, and debugging a functional motorized pipe crawler while maintaining midterm/final exam study schedules creates severe delivery risks within 5 business weeks. | Q12: solution-details/solution-1.md lines 6-10; strongly addresses Biosphere (SDG 6.3 preventing untreated sewer overflow) and Society (SDG 11.5 resilient urban drainage), but provides moderate economic efficiency due to mobilization costs. | R12: solution-details/solution-1.md lines 47; physical tether prevents total hardware loss, but sewage moisture, grease, and H2S gas cause rapid wear and electronic corrosion over repeated deployments. | S12: =IF(MIN(B9:R9)=1, "VETOED / ตกเกณฑ์ข้อบังคับวิกฤต (คะแนนระดับ 1)", IF(S9>=80, "ผ่านเกณฑ์ระดับสูง (HIGHLY VIABLE)", IF(S9>=60, "ผ่านแบบมีเงื่อนไข (CONDITIONALLY VIABLE)", "ความเสี่ยงสูง (HIGH RISK)")))
A13: แผนลดขอบเขตงาน & มาตรการลดความเสี่ยง (De-scoping Action) | B13: Purchase a pre-sealed commercial off-the-shelf (COTS) IP68 RC crawler chassis and mount camera modules externally to avoid custom rotary shaft seal fabrication. | C13: Maintain fully open-source pipeline using Ultralytics YOLOv8 and standard ROS2 camera drivers. | D13: Bench-test optical detection under simulated low-light wet pipe conditions using pre-recorded sewer footage before building crawler chassis. | E13: Document motor wiring pinouts and ROS2 camera topics clearly in repo README to avoid single-developer dependency. | F13: Use pre-trained YOLOv8 defect models and off-the-shelf IP68 waterproof cable glands. | G13: Package visual reporting into an automated PDF generation tool for municipal engineers to prove immediate inspection ROI. | H13: Select widely distributed geared motors (e.g. planetary 12V DC) available from Thai hobby and robotics suppliers. | I13: Substitute expensive industrial PTZ camera with a modular waterproof action camera (or sealed webcam with dual servos) to keep unit cost under 1,500 THB. | J13: Restrict field trials to pedestrian sidewalk manholes or off-road residential drainage channels. | K13: Use AGPL-compliant open-source release or standard permissive MIT wrappers. | L13: Incorporate a high-tensile steel recovery cable tether rated for 150 kg pull force. | M13: Design an ergonomic quick-release battery pod and motorized tether winder. | N13: Use commercial waterproof pelican-style cases to avoid custom CNC machining queues. | O13: Automate video recording and YOLOv8 inferencing with an onboard one-button trigger script. | P13: Adapt a pre-built tracked RC vehicle rather than fabricating custom gearboxes and aluminum wheel hubs. | Q13: Quantify municipal carbon footprint reduction achieved by eliminating redundant vacuum truck trips. | R13: Conformal coat all internal electronics with silicone/polyurethane moisture barrier to extend hardware lifespan. | S13: ปฏิบัติตามแผนลดขอบเขตงาน (De-scoping Advisory)
A15: ตารางสรุปคะแนนแยกตามมิติ TELOS+S (Pillar Score Breakdown)
A16: มิติการประเมิน (TELOS+S Pillar) | B16: สัดส่วนน้ำหนัก (Weight %) | C16: คะแนนเต็มมิติ (Max Points) | D16: คะแนนที่ได้รับจริง (Earned Points) | E16: คะแนนเฉลี่ย (Score 1-5) | F16: ระดับความพร้อม (Readiness Level)
A17: T : ด้านเทคโนโลยีและวิศวกรรม (Technical) | B17: 0.2 | C17: 20 | D17: =SUM(B11:F11)*20 | E17: =IF(C17>0, (D17/C17)*5, 0) | F17: =IF(D17>=16.0, "พร้อมระดับสูง (High)", IF(D17>=12.0, "ปานกลาง (Medium)", "เสี่ยงวิกฤต (Critical)"))
A18: E : ด้านเศรษฐศาสตร์และความคุ้มค่า (Economic) | B18: 0.2 | C18: 20 | D18: =SUM(G11:I11)*20 | E18: =IF(C18>0, (D18/C18)*5, 0) | F18: =IF(D18>=16.0, "พร้อมระดับสูง (High)", IF(D18>=12.0, "ปานกลาง (Medium)", "เสี่ยงวิกฤต (Critical)"))
A19: L : ด้านกฎหมาย ระเบียบ และภาคประชาชน (Legal & Outreach) | B19: 0.15 | C19: 15 | D19: =SUM(J11:K11)*20 | E19: =IF(C19>0, (D19/C19)*5, 0) | F19: =IF(D19>=12.0, "พร้อมระดับสูง (High)", IF(D19>=9.0, "ปานกลาง (Medium)", "เสี่ยงวิกฤต (Critical)"))
A20: O : ด้านการปฏิบัติการและหน้างาน (Operational) | B20: 0.2 | C20: 20 | D20: =SUM(L11:O11)*20 | E20: =IF(C20>0, (D20/C20)*5, 0) | F20: =IF(D20>=16.0, "พร้อมระดับสูง (High)", IF(D20>=12.0, "ปานกลาง (Medium)", "เสี่ยงวิกฤต (Critical)"))
A21: S : ด้านแผนงานและเวลาส่งมอบ (Schedule) | B21: 0.15 | C21: 15 | D21: =P11*20 | E21: =IF(C21>0, (D21/C21)*5, 0) | F21: =IF(D21>=12.0, "พร้อมระดับสูง (High)", IF(D21>=9.0, "ปานกลาง (Medium)", "เสี่ยงวิกฤต (Critical)"))
A22: +S : ด้านความยั่งยืนและสิ่งแวดล้อม (Sustainability / SDG) | B22: 0.1 | C22: 10 | D22: =SUM(Q11:R11)*20 | E22: =IF(C22>0, (D22/C22)*5, 0) | F22: =IF(D22>=8.0, "พร้อมระดับสูง (High)", IF(D22>=6.0, "ปานกลาง (Medium)", "เสี่ยงวิกฤต (Critical)"))
A23: คะแนนรวมทุกมิติ (Total Feasibility Score) | B23: =SUM(B17:B22) | C23: =SUM(C17:C22) | D23: =SUM(D17:D22) | E23: =IF(C23>0, (D23/C23)*5, 0) | F23: =IF(D23>=80, "ผ่านเกณฑ์ระดับสูง (HIGHLY VIABLE)", IF(D23>=60, "ผ่านแบบมีเงื่อนไข (CONDITIONALLY VIABLE)", "ความเสี่ยงสูง (HIGH RISK)"))
A25: เมทริกซ์ประเมินความเข้ากันได้กับองค์ความรู้ด้านวิศวกรรมหุ่นยนต์ (Robotics Knowledge Compatibility)
A26: * หมายเหตุ: การประเมินส่วนนี้วัดศักยภาพในการประยุกต์ใช้องค์ความรู้ด้านวิศวกรรมหุ่นยนต์ (Perception, Control, Actuation) เต็ม 12 คะแนน (แกนละ 4 คะแนน) | เป็นเอกเทศ ไม่นับรวมในคะแนน TELOS 100 คะแนน
A27: มิติการประเมิน (Robotics Dimension) | B27: คะแนนศักยภาพ (/12) | C27: แกน Perception & Sensing (การรับรู้) | D27: แกน Control & Algorithms (การควบคุม) | E27: แกน Actuation & Mechanisms (กลไก) | F27: บทวิเคราะห์เชิงวิศวกรรมหุ่นยนต์ (FIBO Alignment Rationale)
A28: ศักยภาพการประยุกต์ใช้องค์ความรู้หุ่นยนต์และระบบอัตโนมัติ | B28: 10.5 | C28: Score 3.5/4.0: 4K PTZ Optical Camera with High-Power LED array and wheel distance encoders; captures visual defect features under active illumination. | D28: Score 3.5/4.0: Edge AI YOLOv8 deep learning object detection for real-time crack/blockage classification and spatial defect map indexing. | E28: Score 3.5/4.0: Multi-wheel motorized crawler platform traversing hazardous underground pipe geometry with differential steering and tether management. | F28: Solution 1 implements a genuine closed-loop mobile robotic system across all three FIBO pillars: active high-resolution optical perception, edge neural network defect inferencing, and mobile robotic pipe locomotion, utilizing mechatronics and control skills directly.

Sheet Solution_4_LiDAR_SLAM
A1: เมทริกซ์ประเมินความเป็นไปได้เชิงระบบ TELOS+S: Solution 4: Pipe Inspection Instrument using LiDAR SLAM attaching with Robot (3D LiDAR + Laser SLAM Point Cloud Profiling)
A2: ระบบคะแนนจำนวนเต็มเด็ดขาด: 1, 2, 3, 4, 5 เท่านั้น (ไม่มีจุดทศนิยม / ไม่มี 0.5) | โครงสร้างแบบ Transposed แนวนอน
A4: รหัสคำถาม (Question Code) | B4: T-01 | C4: T-02 | D4: T-03 | E4: T-04 | F4: T-05 | G4: E-01 | H4: E-02 | I4: E-03 | J4: L-01 | K4: L-02 | L4: O-01 | M4: O-02 | N4: O-03 | O4: O-04 | P4: S-01 | Q4: SDG-01 | R4: SDG-02 | S4: สรุปภาพรวม (SUMMARY)
A5: มิติการประเมิน (TELOS+S Pillar) | B5: ด้านเทคนิค (Technical 2.2) | C5: ด้านเทคนิค (Technical 2.2) | D5: ด้านเทคนิค (Technical 2.2) | E5: ด้านเทคนิค (Technical 2.2) | F5: ด้านเทคนิค (Technical 2.2) | G5: ด้านเศรษฐศาสตร์ (Economic 2.3) | H5: ด้านเศรษฐศาสตร์ (Economic 2.3) | I5: ด้านเศรษฐศาสตร์ (Economic 2.3) | J5: ด้านกฎหมาย (Legal 2.4) | K5: ด้านกฎหมาย (Legal 2.4) | L5: ด้านปฏิบัติการ (Operational 2.5) | M5: ด้านปฏิบัติการ (Operational 2.5) | N5: ด้านปฏิบัติการ (Operational 2.5) | O5: ด้านปฏิบัติการ (Operational 2.5) | P5: ด้านแผนงาน (Schedule 2.6) | Q5: ความยั่งยืน (SDGs 2.7) | R5: ความยั่งยืน (SDGs 2.7) | S5: ผลรวมทุกมิติ (All Pillars)
A6: คำถามทดสอบความเสี่ยงจริง (Stress-Test Question) | B6: ระดับการสร้างเองเทียบกับการซื้อสำเร็จรูป (Build vs. Buy Burden) ของสถาปัตยกรรมระบบตรวจประเมินท่อระบายน้ำ? | C6: สิทธิ์ในการเข้าถึงเทคโนโลยี ซอฟต์แวร์ และระบบนิเวศข้อมูล (Access & Permissions) ของระบบตรวจประเมินท่อ? | D6: ระดับความพร้อมทางเทคโนโลยี (Base Performance / TRL) ในสภาพแวดล้อมจริงของท่อระบายน้ำใต้ดิน? | E6: ความเข้ากันได้ของทีม (Manpower & Skill Redundancy) ด้านวิศวกรรมเฉพาะทาง? | F6: ความชันของเส้นทางการเรียนรู้ (Learning Curve) ด้านวิศวกรรมระบบ? | G6: ระยะเวลาคืนทุนและความคุ้มค่าในการลงทุน (Payback Period / Value Horizon) ของระบบ? | H6: ระดับการพึ่งพาชิ้นส่วนและผู้จัดจำหน่ายภายนอก (Component Dependency & Vendor Lock-in)? | I6: สัดส่วนงบประมาณสำรองความเสียหาย (Scrap Margin / Safety Allowance) ของชิ้นส่วน? | J6: ความสอดคล้องกับกฎหมายความปลอดภัยสาธารณะและการจราจร (Regulatory & Public Safety Compliance)? | K6: ทรัพย์สินทางปัญญา ลิขสิทธิ์ซอฟต์แวร์ และสิทธิบัตร (IP & Software Licensing)? | L6: ผลกระทบต่อระบบหากเกิดความล้มเหลวขณะปฏิบัติงาน (Operational Failure Impact)? | M6: ความสอดคล้องกับพฤติกรรมผู้ใช้และสภาพหน้างานจริง (User Behavior & Problem-Solution Fit)? | N6: การพึ่งพาห้องปฏิบัติการและขั้นตอนเชิงบริหารของนักพัฒนา (Administrative & Lab Dependency)? | O6: ความซับซ้อนของขั้นตอนการประมวลผลและการเตรียมระบบ (Step Count & Pipeline Friction)? | P6: ความพร้อมของระบบและการส่งมอบต้นแบบภายในกรอบเวลา 5 สัปดาห์ทำงาน (Design Maturity & Schedule Compliance)? | Q6: ผลกระทบต่อสิ่งแวดล้อม สังคม และเศรษฐกิจตามกรอบ SDG Wedding Cake (Biosphere, Society, Economy)? | R6: รอยเท้าสิ่งแวดล้อม ขยะอิเล็กทรอนิกส์ และระบบเก็บกู้ที่ปลอดภัย (Environmental Footprint & E-Waste Safeguards)? | S6: ประเมินคำถามทั้งสิ้น 17 ข้อ
A7: เหตุผลในการถาม & โหมดความล้มเหลวที่เฝ้าระวัง (Rationale) | B7: ประเมินภาระการวิจัยและพัฒนาชิ้นส่วนกลไก อิเล็กทรอนิกส์ และอัลกอริทึม ป้องกันการเสียเวลากับงานประดิษฐ์ขึ้นใหม่โดยไม่จำเป็น | C7: ตรวจสอบข้อจำกัดด้านกรรมสิทธิ์ การล็อกสิทธิ์ใช้งาน และการอนุญาตเข้าถึง เพื่อป้องกันการพัฒนาระบบบนฐานข้อมูลที่ไม่สามารถเข้าถึงได้จริง | D7: วัดวุฒิภาวะของเทคโนโลยีว่าผ่านการพิสูจน์ในสภาพแวดล้อมใต้ดินที่มีความชื้น สารกัดกร่อน หรือน้ำขังจริงแล้วหรือไม่ | E7: ประเมินความเสี่ยงกรณีขาดแคลนบุคลากรที่มีความเชี่ยวชาญเฉพาะด้าน (Bus Factor) ว่ามีคนทำงานทดแทนกันได้หรือไม่ | F7: ประเมินเวลาและความยากในการเรียนรู้เทคโนโลยีใหม่ ว่าทีมงานสามารถเข้าใจและนำมาใช้ได้ทันเวลาหรือไม่ | G7: ประเมินผลตอบแทนทางเศรษฐศาสตร์และการลดต้นทุนการขุดลอกท่อระบายน้ำของหน่วยงานรัฐ | H7: ประเมินความเสี่ยงด้านห่วงโซ่อุปทานและการผูกขาดชิ้นส่วน ป้องกันระบบล่มสลายจากผู้ผลิตรายเดียว | I7: ตรวจสอบความปลอดภัยทางการเงินกรณีทำอุปกรณ์เสียหายระหว่างการทดลองในน้ำเสีย | J7: ประเมินความเสี่ยงการละเมิดกฎหมายควบคุมอาคาร ระเบียบงานทาง และข้อบังคับการจราจรขณะปฏิบัติงาน | K7: ตรวจสอบความปลอดภัยด้านสิทธิบัตรเพื่อป้องกันการถูกฟ้องร้องละเมิดทรัพย์สินทางปัญญา | L7: ประเมินความรุนแรงของผลกระทบกรณีระบบขัดข้อง ว่าทำให้อุดตันท่อหรือระบบระบายน้ำเสียหายหรือไม่ | M7: ประเมินความสะดวกของเจ้าหน้าที่หน้างาน ว่าระบบใช้งานง่ายและตอบสนองขั้นตอนการทำงานจริงหรือไม่ | N7: ประเมินความคล่องตัวในการพัฒนา ว่าต้องรอการอนุมัติหรือติดขัดการใช้ห้องแล็บเฉพาะทางหรือไม่ | O7: วัดจำนวนขั้นตอนและความยุ่งยากในการเตรียมระบบก่อนเริ่มใช้งานจริง | P7: ประเมินความเป็นไปได้ในการสร้าง ทดสอบ และส่งมอบต้นแบบวิศวกรรมให้เสร็จทันกำหนด 5 สัปดาห์ | Q7: ประเมินคุณค่าที่แท้จริงต่อเป้าหมายการพัฒนาที่ยั่งยืน 3 ชั้น ป้องกันการสร้างภาพลักษณ์สีเขียว (Greenwashing) | R7: ตรวจสอบการป้องกันขยะอิเล็กทรอนิกส์ตกค้างในท่อระบายน้ำ สารพิษรั่วไหล และระบบกู้คืนอุปกรณ์ที่ปลอดภัย 100% | S7: สังเคราะห์จาก AI Agents Group 2
